<?xml version="1.0" ?>
<robot name="soccerbot_noarms">
  <gazebo>
    <plugin name="gazebo_ros_control" filename="libgazebo_ros_control.so">
      <robotNamespace>/soccerbot</robotNamespace>
      <robotSimType>gazebo_ros_control/DefaultRobotHWSim</robotSimType>
    </plugin>
  </gazebo>

  <!-- Joint to keep the robot up in midair -->
  <link name="world" />
  <joint name="world_base_link" type="fixed">
    <parent link="world"/>
    <child link="base_link"/>
    <origin rpy="0  0 0" xyz="0 0 0"/>
    <axis xyz="1  0  0"/>
  </joint>

  <!-- Links -->
  <link name="base_link" />
  <link name="torso">
    <inertial>
      <mass value="1219.727"/>
      <origin rpy="1.57 0 1.57" xyz="0 0 0"/>
      <inertia ixx="8.01" ixy="0.075" ixz="0.032" iyy="3.08" iyz="0.708" izz="8.75"/>
    </inertial>
    <collision name="collision">
      <origin rpy="1.5708 0 1.5708" xyz="0 0 -0.052"/>
      <geometry>
        <box size="0.152 0.145 0.130"/>
      </geometry>
    </collision>
    <visual name="visual">
      <origin rpy="1.5708 0 1.5708" xyz="0 0 0"/>
      <geometry>
        <mesh filename="package://soccer_description/meshes/soccerbot v4/Torso.stl" scale="0.001 0.001 0.001"/>
      </geometry>
    </visual>
  </link>
  <link name="camera">
    <inertial>
      <mass value="1"/>
      <origin rpy="0  0  0" xyz="0  0  0"/>
      <inertia ixx="0.166667" ixy="0" ixz="0" iyy="0.166667" iyz="0" izz="0.166667"/>
    </inertial>
  </link>
  <gazebo reference="camera">
    <sensor name='main_camera' type='camera'>
      <update_rate>30</update_rate>
      <camera name='__default__'>
        <horizontal_fov>1.39626</horizontal_fov>
        <image>
          <width>320</width>
          <height>240</height>
          <format>R8G8B8</format>
        </image>
        <clip>
          <near>1</near>
          <far>100</far>
        </clip>
        <noise>
          <type>gaussian</type>
          <mean>0</mean>
          <stddev>0.007</stddev>
        </noise>
      </camera>
      <always_on>1</always_on>
      <visualize>1</visualize>
      <plugin name='camera_controller' filename='libgazebo_ros_camera.so'>
        <alwaysOn>true</alwaysOn>
        <updateRate>0.0</updateRate>
        <cameraName>soccerbot/camera1</cameraName>
        <imageTopicName>image_raw</imageTopicName>
        <cameraInfoTopicName>camera_info</cameraInfoTopicName>
        <frameName>camera_link</frameName>
        <hackBaseline>0.07</hackBaseline>
        <distortionK1>0.0</distortionK1>
        <distortionK2>0.0</distortionK2>
        <distortionK3>0.0</distortionK3>
        <distortionT1>0.0</distortionT1>
        <distortionT2>0.0</distortionT2>
      </plugin>
    </sensor>
  </gazebo>

  <link name="head">
    <inertial>
      <mass value="282.919"/>
      <origin rpy="0  0  0" xyz="0  0  0"/>
      <inertia ixx="0.400" ixy="0" ixz="0" iyy="0.170" iyz="0.015" izz="0.392"/>
    </inertial>
    <collision name="collision">
      <origin rpy="0  0  0" xyz="0 0.02648  0"/>
      <geometry>
        <box size="0.094 0.0779 0.0712"/>
      </geometry>
    </collision>
    <visual name="visual">
      <origin rpy="0  0  0" xyz="0  0  0"/>
      <geometry>
        <mesh filename="package://soccer_description/meshes/soccerbot v4/Head.stl" scale="0.001 0.001 0.001"/>
      </geometry>
    </visual>
  </link>
  <link name="left_ankle">
    <inertial>
      <mass value="153.186"/>
      <origin rpy="0 0 0" xyz="0  0  0"/>
      <inertia ixx="0.205" ixy="0.0" ixz="0" iyy="0.173" iyz="0.038" izz="0.060"/>
    </inertial>
    <collision name="collision">
      <origin rpy="0 1.5708 0" xyz="0 0.01031 -0.02014"/>
      <geometry>
        <box size="0.090769 0.0506 0.042"/>
      </geometry>
    </collision>
    <visual name="visual">
      <origin rpy="0  0  0" xyz="0  0  0"/>
      <geometry>
        <mesh filename="package://soccer_description/meshes/soccerbot v4/Left Ankle.stl" scale="0.001 0.001 0.001"/>
      </geometry>
    </visual>
  </link>
  <link name="left_calve">
    <inertial>
      <mass value="86.598"/>
      <origin rpy="0  0  0" xyz="0 0  0"/>
      <inertia ixx="0.077" ixy="0" ixz="0" iyy="0.019" iyz="0.001" izz="0.085"/>
    </inertial>
    <collision name="collision">
      <origin rpy="0  1.5708  0" xyz="0      -0.03385  0"/>
      <geometry>
        <box size="0.031883 0.105683 0.048"/>
      </geometry>
    </collision>
    <visual name="visual">
      <origin rpy="0  0  0" xyz="0 -0.0827  0"/>
      <geometry>
        <mesh filename="package://soccer_description/meshes/soccerbot v4/Left Calve.stl" scale="0.001 0.001 0.001"/>
      </geometry>
    </visual>
  </link>
  <link name="left_foot">
    <inertial>
      <mass value="23.216"/>
      <origin rpy="0 0 0" xyz="0  0  0"/>
      <inertia ixx="0.026" ixy="0" ixz="0" iyy="0.023" iyz="0" izz="0.013"/>
    </inertial>
    <collision name="collision">
      <origin rpy="0 1.5708 0" xyz="-0.00401 -0.00737  0.00385"/>
      <geometry>
        <box size="0.09 0.03674 0.07"/>
      </geometry>
    </collision>
    <visual name="visual">
      <origin rpy="0  0  0" xyz="0  0  0"/>
      <geometry>
        <mesh filename="package://soccer_description/meshes/soccerbot v4/Left Foot.stl" scale="0.001 0.001 0.001"/>
      </geometry>
    </visual>
  </link>
  <link name="left_hip_front">
    <inertial>
      <mass value="153.238"/>
      <origin rpy="0  0  0" xyz="0  0  0"/>
      <inertia ixx="0.205" ixy="0" ixz="0" iyy="0.173" iyz="0.038" izz="0.060"/>
    </inertial>
    <collision name="collision">
      <origin rpy="0 1.5707 0" xyz="0 -0.01332 -0.02187"/> <!-- 0.01332-->
      <geometry>
        <box size="0.083747 0.0506 0.04885"/>
      </geometry>
    </collision>
    <visual name="visual">
      <origin rpy="0  0  0" xyz="0  0  0"/>
      <geometry>
        <mesh filename="package://soccer_description/meshes/soccerbot v4/Left Hip Front.stl" scale="0.001 0.001 0.001"/>
      </geometry>
    </visual>
  </link>
  <link name="left_hip_side">
    <inertial>
      <mass value="9.364"/>
      <origin rpy="0  0  0" xyz="0  0  0"/>
      <inertia ixx="0.007" ixy="0" ixz="0" iyy="0.004" iyz="0" izz="0.004"/>
    </inertial>
    <collision name="collision">
      <origin rpy="0  0  0" xyz="0       0.00899  0"/>
      <geometry>
        <box size="0.022 0.039 0.0475"/>
      </geometry>
    </collision>
    <visual name="visual">
      <origin rpy="0  0  0" xyz="0  0  0"/>
      <geometry>
        <mesh filename="package://soccer_description/meshes/soccerbot v4/Left Hip Side.stl" scale="0.001 0.001 0.001"/>
      </geometry>
    </visual>
  </link>
  <link name="left_thigh">
    <inertial>
      <mass value="21.438"/>
      <origin rpy="0  0  0" xyz="0  0  0"/>
      <inertia ixx="0.063" ixy="0" ixz="0" iyy="0.011" iyz="0" izz="0.072"/>
    </inertial>
    <collision name="collision">
      <origin rpy="0 1.5708 0" xyz="0     -0.0445  0"/>
      <geometry>
        <box size="0.022 0.111 0.048"/>
      </geometry>
    </collision>
    <visual name="visual">
      <origin rpy="0  0  0" xyz="0  0  0"/>
      <geometry>
        <mesh filename="package://soccer_description/meshes/soccerbot v4/Left Thigh.stl" scale="0.001 0.001 0.001"/>
      </geometry>
    </visual>
  </link>
  <link name="neck">
    <inertial>
      <mass value="70.031"/>
      <origin rpy="0  0  0" xyz="0  0  0"/>
      <inertia ixx="0.009" ixy="0" ixz="0" iyy="0.031" iyz="0" izz="0.034"/>
    </inertial>
    <collision name="collision">
      <origin rpy="0  0  0" xyz="0      0.0165  0"/>
      <geometry>
        <box size="0.0523 0.033 0.022"/>
      </geometry>
    </collision>
    <visual name="visual">
      <origin rpy="0  0  0" xyz="0  0  0"/>
      <geometry>
        <mesh filename="package://soccer_description/meshes/soccerbot v4/Neck.stl" scale="0.001 0.001 0.001"/>
      </geometry>
    </visual>
  </link>
  <link name="right_ankle">
    <inertial>
      <mass value="153.238"/>
      <origin rpy="0 0 0" xyz="0  0  0"/>
      <inertia ixx="0.205" ixy="0" ixz="0" iyy="0.173" iyz="0.038" izz="0.060"/>
    </inertial>
    <collision name="collision">
      <origin rpy="0 1.5708 0" xyz="0 0.01031 -0.02014"/>
      <geometry>
        <box size="0.090769 0.0506 0.042"/>
      </geometry>
    </collision>
    <visual name="visual">
      <origin rpy="0  0  0" xyz="0  0  0"/>
      <geometry>
        <mesh filename="package://soccer_description/meshes/soccerbot v4/Right Ankle.stl" scale="0.001 0.001 0.001"/>
      </geometry>
    </visual>
  </link>
  <link name="right_calve">
    <inertial>
      <mass value="86.598"/>
      <origin rpy="0  0  0" xyz="0 0 0"/>
      <inertia ixx="0.077" ixy="0" ixz="0" iyy="0.019" iyz="0.001" izz="0.085"/>
    </inertial>
    <collision name="collision">
      <origin rpy="0  1.5708  0" xyz="0      -0.03385  0"/>
      <geometry>
        <box size="0.031883 0.105683 0.048"/>
      </geometry>
    </collision>
    <visual name="visual">
      <origin rpy="0  0  0" xyz="0     -0.0827  0"/>
      <geometry>
        <mesh filename="package://soccer_description/meshes/soccerbot v4/Right Calve.stl" scale="0.001 0.001 0.001"/>
      </geometry>
    </visual>
  </link>
  <link name="right_foot">
    <inertial>
      <mass value="23.216"/>
      <origin rpy="0 0 0" xyz="0  0  0"/>
      <inertia ixx="0.026" ixy="0" ixz="0" iyy="0.022" iyz="0" izz="0.013"/>
    </inertial>
    <collision name="collision">
      <origin rpy="0 1.5708 0" xyz="0.00401 -0.00737  0.00385"/>
      <geometry>
        <box size="0.09 0.03674 0.07"/>
      </geometry>
    </collision>
    <visual name="visual">
      <origin rpy="0  0  0" xyz="0  0  0"/>
      <geometry>
        <mesh filename="package://soccer_description/meshes/soccerbot v4/Right Foot.stl" scale="0.001 0.001 0.001"/>
      </geometry>
    </visual>
  </link>
  <link name="right_hip_front">
    <inertial>
      <mass value="153.238"/>
      <origin rpy="0 0 0" xyz="0 0 0"/>
      <inertia ixx="0.204" ixy="0.00" ixz="0" iyy="0.172" iyz="0.038" izz="0.060"/>
    </inertial>
    <collision name="collision">
      <origin rpy="0  1.5708  0" xyz="0 -0.01332 -0.02187"/>
      <geometry>
        <box size="0.083747 0.0506 0.04885"/>
      </geometry>
    </collision>
    <visual name="visual">
      <origin rpy="0  0  0" xyz="0  0  0"/>
      <geometry>
        <mesh filename="package://soccer_description/meshes/soccerbot v4/Right Hip Front.stl" scale="0.001 0.001 0.001"/>
      </geometry>
    </visual>
  </link>
  <link name="right_hip_side">
    <inertial>
      <mass value="9.364"/>
      <origin rpy="0  0  0" xyz="0  0  0"/>
      <inertia ixx="0.007" ixy="0" ixz="0" iyy="0.004" iyz="0" izz="0.004"/>
    </inertial>
    <collision name="collision">
      <origin rpy="0  0  0" xyz="0       0.00899  0"/>
      <geometry>
        <box size="0.022 0.039 0.0475"/>
      </geometry>
    </collision>
    <visual name="visual">
      <origin rpy="0  0  0" xyz="0  0  0"/>
      <geometry>
        <mesh filename="package://soccer_description/meshes/soccerbot v4/Right Hip Side.stl" scale="0.001 0.001 0.001"/>
      </geometry>
    </visual>
  </link>
  <link name="right_thigh">
    <inertial>
      <mass value="21.438"/>
      <origin rpy="0 0 0" xyz="0  0  0"/>
      <inertia ixx="0.063" ixy="0" ixz="0" iyy="0.011" iyz="0" izz="0.072"/>
    </inertial>
    <collision name="collision">
      <origin rpy="0 1.5708 0" xyz="0     -0.0445  0"/>
      <geometry>
        <box size="0.022 0.111 0.048"/>
      </geometry>
    </collision>
    <visual name="visual">
      <origin rpy="0  0  0" xyz="0  0  0"/>
      <geometry>
        <mesh filename="package://soccer_description/meshes/soccerbot v4/Right Thigh.stl" scale="0.001 0.001 0.001"/>
      </geometry>
    </visual>
  </link>
  <link name="right_bicep">
    <inertial>
      <mass value="203.882"/>
      <origin rpy="0  0  0" xyz="0  0  0"/>
      <inertia ixx="0.122" ixy="0.177" ixz="0" iyy="0.024" iyz="0.004" izz="0.114"/>
    </inertial>
    <collision name="collision">
      <origin rpy="0  0  0" xyz="0     -0.04   -0.0225"/>
      <geometry>
        <box size="0.04 0.103 0.045"/>
      </geometry>
    </collision>
    <visual name="visual">
      <origin rpy="0  0  0" xyz="0  0  0"/>
      <geometry>
        <mesh filename="package://soccer_description/meshes/soccerbot v4/Right Bicep.stl" scale="0.001 0.001 0.001"/>
      </geometry>
    </visual>
  </link>
  <link name="left_bicep">
    <inertial>
      <mass value="203.882"/>
      <origin rpy="0  0  0" xyz="0  0  0"/>
      <inertia ixx="0.122" ixy="0.177" ixz="0" iyy="0.024" iyz="0" izz="0.114"/>
    </inertial>
    <collision name="collision">
      <origin rpy="0  0  0" xyz="0     -0.04    0.0225"/>
      <geometry>
        <box size="0.04 0.103 0.045"/>
      </geometry>
    </collision>
    <visual name="visual">
      <origin rpy="0  0  0" xyz="0  0  0"/>
      <geometry>
        <mesh filename="package://soccer_description/meshes/soccerbot v4/Left Bicep.stl" scale="0.001 0.001 0.001"/>
      </geometry>
    </visual>
  </link>
  <link name="left_forearm">
    <inertial>
      <mass value="41.632"/>
      <origin rpy="0  0  0" xyz="0  0  0"/>
      <inertia ixx="0.078" ixy="0.038" ixz="0.013" iyy="0.023" iyz="0.029" izz="0.073"/>
    </inertial>
    <collision name="collision">
      <origin rpy="0  0  0" xyz="-0.0055 -0.049   0.0265"/>
      <geometry>
        <box size="0.035 0.124 0.049"/>
      </geometry>
    </collision>
    <visual name="visual">
      <origin rpy="0  0  0" xyz="0  0  0"/>
      <geometry>
        <mesh filename="package://soccer_description/meshes/soccerbot v4/Left Forearm.stl" scale="0.001 0.001 0.001"/>
      </geometry>
    </visual>
  </link>
  <link name="right_forearm">
    <inertial>
      <mass value="41.632"/>
      <origin rpy="0  0  0" xyz="0  0  0"/>
      <inertia ixx="0.078" ixy="0.038" ixz="0.013" iyy="0.012" iyz="0.029" izz="0.073"/>
    </inertial>
    <collision name="collision">
      <origin rpy="0  0  0" xyz="-0.0055 -0.049  -0.0265"/>
      <geometry>
        <box size="0.035 0.124 0.049"/>
      </geometry>
    </collision>
    <visual name="visual">
      <origin rpy="0  0  0" xyz="0  0  0"/>
      <geometry>
        <mesh filename="package://soccer_description/meshes/soccerbot v4/Right Forearm.stl" scale="0.001 0.001 0.001"/>
      </geometry>
    </visual>
  </link>
  
  <!-- Joints -->
  <joint name="head_camera" type="fixed">
    <parent link="head"/>
    <child link="camera"/>
    <origin rpy="2.35619 -1.57079 2.35619" xyz="0      0.0699  0.07"/>
    <axis xyz="0  0  0"/>
    <dynamics damping="0.0" friction="2000.0" />
    <limit effort="0" lower="0" upper="0" velocity="0"/>
  </joint>
  <joint name="left_ankle_foot" type="revolute">
    <parent link="left_ankle"/>
    <child link="left_foot"/>
    <origin rpy="0 0 0" xyz="0 0 0"/>
    <axis xyz="-1 0 0"/>
    <dynamics damping="0.0" friction="2000.0" />
    <limit effort="31000.0" lower="-1.79769e+308" upper="1.79769e+308" velocity="1.0"/>
  </joint>
  <joint name="left_calve_ankle" type="revolute">
    <parent link="left_calve"/>
    <child link="left_ankle"/>
    <origin rpy="0 0 0" xyz="0 -0.0827 0"/>
    <axis xyz="0 0 1"/>
    <dynamics damping="0.0" friction="2000.0" />
    <limit effort="31000.0" lower="-1.79769e+308" upper="1.79769e+308" velocity="1.0"/>
  </joint>
  <joint name="left_hip_front_thigh" type="revolute">
    <parent link="left_hip_front"/>
    <child link="left_thigh"/>
    <origin rpy="0 0 0" xyz="0 0 0"/>
    <axis xyz="0  0  1"/>
    <dynamics damping="0.0" friction="2000.0" />
    <limit effort="31000.0" lower="-1.79769e+308" upper="1.79769e+308" velocity="1.0"/>
  </joint>
  <joint name="left_hip_side_hip_front" type="revolute">
    <parent link="left_hip_side"/>
    <child link="left_hip_front"/>
    <origin rpy="0 0 0" xyz="0 0 0"/>
    <axis xyz="-1  0  0"/>
    <dynamics damping="0.0" friction="2000.0" />
    <limit effort="31000.0" lower="-1.79769e+308" upper="1.79769e+308" velocity="1.0"/>
  </joint>
  <joint name="left_thigh_calve" type="revolute">
    <parent link="left_thigh"/>
    <child link="left_calve"/>
    <origin rpy="0 0 0" xyz="0 -0.09290  0"/>
    <axis xyz="0  0  1"/>
    <dynamics damping="0.0" friction="2000.0" />
    <limit effort="31000.0" lower="-1.79769e+308" upper="1.79769e+308" velocity="1.0"/>
  </joint>
  <joint name="neck_head" type="revolute">
    <parent link="neck"/>
    <child link="head"/>
    <origin rpy="0 0 0" xyz="0 0.022 0"/>
    <axis xyz="1 0 0"/>
    <dynamics damping="0.0" friction="2000.0" />
    <limit effort="15000.0" lower="-1.79769e+308" upper="1.79769e+308" velocity="1.0"/>
  </joint>
  <joint name="right_ankle_foot" type="revolute">
    <parent link="right_ankle"/>
    <child link="right_foot"/>
    <origin rpy="0 0 0" xyz="0 0 0"/>
    <axis xyz="-1 0 0"/>
    <dynamics damping="0.0" friction="2000.0" />
    <limit effort="31000.0" lower="-1.79769e+308" upper="1.79769e+308" velocity="1.0"/>
  </joint>
  <joint name="right_calve_ankle" type="revolute">
    <parent link="right_calve"/>
    <child link="right_ankle"/>
    <origin rpy="0 0 0" xyz="0 -0.0827 0"/>
    <axis xyz="0 0 1"/>
    <dynamics damping="0.0" friction="2000.0" />
    <limit effort="31000.0" lower="-1.79769e+308" upper="1.79769e+308" velocity="1.0"/>
  </joint>
  <joint name="right_hip_front_thigh" type="revolute">
    <parent link="right_hip_front"/>
    <child link="right_thigh"/>
    <origin rpy="0 0 0" xyz="0 0 0"/>
    <axis xyz="0 0 1"/>
    <dynamics damping="0.0" friction="2000.0" />
    <limit effort="31000.0" lower="-1.79769e+308" upper="1.79769e+308" velocity="1.0"/>
  </joint>
  <joint name="right_hip_side_hip_front" type="revolute">
    <parent link="right_hip_side"/>
    <child link="right_hip_front"/>
    <origin rpy="0 0 0" xyz="0 0 0"/>
    <axis xyz="-1 0 0"/>
    <dynamics damping="0.0" friction="2000.0" />
    <limit effort="31000.0" lower="-1.79769e+308" upper="1.79769e+308" velocity="1.0"/>
  </joint>
  <joint name="right_thigh_calve" type="revolute">
    <parent link="right_thigh"/>
    <child link="right_calve"/>
    <origin rpy="0 0 0" xyz="0 -0.0929 0"/>
    <axis xyz="0 0 1"/>
    <dynamics damping="0.0" friction="2000.0" />
    <limit effort="31000.0" lower="-1.79769e+308" upper="1.79769e+308" velocity="1.0"/>
  </joint>
  <joint name="torso_left_hip_side" type="revolute">
    <parent link="torso"/>
    <child link="left_hip_side"/>
    <origin rpy="1.5708 0 1.5708" xyz="0.0135 -0.035 -0.156"/>
    <axis xyz="0  -1  0"/>
    <dynamics damping="0.0" friction="2000.0" />
    <limit effort="31000.0" lower="-1.79769e+308" upper="1.79769e+308" velocity="1.0"/>
  </joint>
  <joint name="torso_neck" type="revolute">
    <parent link="torso"/>
    <child link="neck"/>
    <origin rpy="1.57079 0 1.57079" xyz="0.024 0 0.05875"/>
    <axis xyz="0  1  0"/>
    <dynamics damping="0.0" friction="2000.0" />
    <limit effort="15000.0" lower="-1.79769e+308" upper="1.79769e+308" velocity="1.0"/>
  </joint>
  <joint name="torso_right_hip_side" type="revolute">
    <parent link="torso"/>
    <child link="right_hip_side"/>
    <origin rpy="1.5708 0 1.5708" xyz="0.0135 0.035 -0.156"/>
    <axis xyz="0  -1  0"/>
    <dynamics damping="0.0" friction="2000.0" />
    <limit effort="31000.0" lower="-1.79769e+308" upper="1.79769e+308" velocity="1.0"/>
  </joint>
  <joint name="base_link_torso" type="fixed">
    <parent link="base_link"/>
    <child link="torso"/>
    <origin rpy="0 0 0" xyz="0 0 0.3536"/>
    <axis xyz="1 0 0"/>
  </joint>
  <joint name="left_bicep_forearm" type="revolute">
    <parent link="left_bicep"/>
    <child link="left_forearm"/>
    <origin rpy="0 0 0" xyz="0 -0.08 0"/>
    <axis xyz="0 0 1"/>
    <dynamics damping="0.0" friction="2000.0" />
    <limit effort="15000.0" lower="-1.79769e+308" upper="1.79769e+308" velocity="1.0"/>
  </joint>
  <joint name="right_bicep_forearm" type="revolute">
    <parent link="right_bicep"/>
    <child link="right_forearm"/>
    <origin rpy="0 0 0" xyz="0 -0.08 0"/>
    <axis xyz="0 0 1"/>
    <dynamics damping="0.0" friction="2000.0" />
    <limit effort="15000.0" lower="-1.79769e+308" upper="1.79769e+308" velocity="1.0"/>
  </joint>
  <joint name="torso_left_bicep" type="revolute">
    <parent link="torso"/>
    <child link="left_bicep"/>
    <origin rpy="1.5708 0 0" xyz="0 -0.0725 0"/>
    <axis xyz="0 0 1"/>
    <dynamics damping="0.0" friction="2000.0" />
    <limit effort="15000.0" lower="-1.79769e+308" upper="1.79769e+308" velocity="1.0"/>
  </joint>
  <joint name="torso_right_bicep" type="revolute">
    <parent link="torso"/>
    <child link="right_bicep"/>
    <origin rpy="1.5708 0 0" xyz="0 0.0725 0"/>
    <axis xyz="0  0  1"/>
    <dynamics damping="0.0" friction="2000.0" />
    <limit effort="15000.0" lower="-1.79769e+308" upper="1.79769e+308" velocity="1.0"/>
  </joint>

  <!-- Transmission -->
  <transmission name="torso_right_hip_side">
    <type>transmission_interface/SimpleTransmission</type>
    <joint name="torso_right_hip_side">
      <hardwareInterface>hardware_interface/EffortJointInterface</hardwareInterface>
    </joint>
    <actuator name="motor7">
      <hardwareInterface>hardware_interface/EffortJointInterface</hardwareInterface>
      <mechanicalReduction>1</mechanicalReduction>
    </actuator>
  </transmission>
  
  <transmission name="right_hip_side_hip_front">
    <type>transmission_interface/SimpleTransmission</type>
    <joint name="right_hip_side_hip_front">
      <hardwareInterface>hardware_interface/EffortJointInterface</hardwareInterface>
    </joint>
    <actuator name="motor8">
      <hardwareInterface>hardware_interface/EffortJointInterface</hardwareInterface>
      <mechanicalReduction>1</mechanicalReduction>
    </actuator>
  </transmission>
  
  <transmission name="right_hip_front_thigh">
    <type>transmission_interface/SimpleTransmission</type>
    <joint name="right_hip_front_thigh">
      <hardwareInterface>hardware_interface/EffortJointInterface</hardwareInterface>
    </joint>
    <actuator name="motor9">
      <hardwareInterface>hardware_interface/EffortJointInterface</hardwareInterface>
      <mechanicalReduction>1</mechanicalReduction>
    </actuator>
  </transmission>
  
  <transmission name="right_thigh_calve">
    <type>transmission_interface/SimpleTransmission</type>
    <joint name="right_thigh_calve">
      <hardwareInterface>hardware_interface/EffortJointInterface</hardwareInterface>
    </joint>
    <actuator name="motor10">
      <hardwareInterface>hardware_interface/EffortJointInterface</hardwareInterface>
      <mechanicalReduction>1</mechanicalReduction>
    </actuator>
  </transmission>
  
  <transmission name="right_calve_ankle">
    <type>transmission_interface/SimpleTransmission</type>
    <joint name="right_calve_ankle">
      <hardwareInterface>hardware_interface/EffortJointInterface</hardwareInterface>
    </joint>
    <actuator name="motor11">
      <hardwareInterface>hardware_interface/EffortJointInterface</hardwareInterface>
      <mechanicalReduction>1</mechanicalReduction>
    </actuator>
  </transmission>
  
  <transmission name="right_ankle_foot">
    <type>transmission_interface/SimpleTransmission</type>
    <joint name="right_ankle_foot">
      <hardwareInterface>hardware_interface/EffortJointInterface</hardwareInterface>
    </joint>
    <actuator name="motor12">
      <hardwareInterface>hardware_interface/EffortJointInterface</hardwareInterface>
      <mechanicalReduction>1</mechanicalReduction>
    </actuator>
  </transmission>
  
  <transmission name="torso_left_hip_side">
    <type>transmission_interface/SimpleTransmission</type>
    <joint name="torso_left_hip_side">
      <hardwareInterface>hardware_interface/EffortJointInterface</hardwareInterface>
    </joint>
    <actuator name="motor6">
      <hardwareInterface>hardware_interface/EffortJointInterface</hardwareInterface>
      <mechanicalReduction>1</mechanicalReduction>
    </actuator>
  </transmission>
  
  <transmission name="left_hip_side_hip_front">
    <type>transmission_interface/SimpleTransmission</type>
    <joint name="left_hip_side_hip_front">
      <hardwareInterface>hardware_interface/EffortJointInterface</hardwareInterface>
    </joint>
    <actuator name="motor5">
      <hardwareInterface>hardware_interface/EffortJointInterface</hardwareInterface>
      <mechanicalReduction>1</mechanicalReduction>
    </actuator>
  </transmission>
  
  <transmission name="left_hip_front_thigh">
    <type>transmission_interface/SimpleTransmission</type>
    <joint name="left_hip_front_thigh">
      <hardwareInterface>hardware_interface/EffortJointInterface</hardwareInterface>
    </joint>
    <actuator name="motor4">
      <hardwareInterface>hardware_interface/EffortJointInterface</hardwareInterface>
      <mechanicalReduction>1</mechanicalReduction>
    </actuator>
  </transmission>
  
  <transmission name="left_thigh_calve">
    <type>transmission_interface/SimpleTransmission</type>
    <joint name="left_thigh_calve">
      <hardwareInterface>hardware_interface/EffortJointInterface</hardwareInterface>
    </joint>
    <actuator name="motor3">
      <hardwareInterface>hardware_interface/EffortJointInterface</hardwareInterface>
      <mechanicalReduction>1</mechanicalReduction>  
    </actuator>
  </transmission>
  
  <transmission name="left_calve_ankle">
    <type>transmission_interface/SimpleTransmission</type>
    <joint name="left_calve_ankle">
      <hardwareInterface>hardware_interface/EffortJointInterface</hardwareInterface>
    </joint>
    <actuator name="motor2">
      <hardwareInterface>hardware_interface/EffortJointInterface</hardwareInterface>
      <mechanicalReduction>1</mechanicalReduction>
    </actuator>
  </transmission>
  
  <transmission name="left_ankle_foot">
    <type>transmission_interface/SimpleTransmission</type>
    <joint name="left_ankle_foot">
      <hardwareInterface>hardware_interface/EffortJointInterface</hardwareInterface>
    </joint>
    <actuator name="motor1">
      <hardwareInterface>hardware_interface/EffortJointInterface</hardwareInterface>
      <mechanicalReduction>1</mechanicalReduction>
    </actuator>
  </transmission>
  
  <transmission name="torso_neck">
    <type>transmission_interface/SimpleTransmission</type>
    <joint name="torso_neck">
      <hardwareInterface>hardware_interface/EffortJointInterface</hardwareInterface>
    </joint>
    <actuator name="motor13">
      <hardwareInterface>hardware_interface/EffortJointInterface</hardwareInterface>
      <mechanicalReduction>1</mechanicalReduction>
    </actuator>
  </transmission>
  
  <transmission name="neck_head">
    <type>transmission_interface/SimpleTransmission</type>
    <joint name="neck_head">
      <hardwareInterface>hardware_interface/EffortJointInterface</hardwareInterface>
    </joint>
    <actuator name="motor14">
      <hardwareInterface>hardware_interface/EffortJointInterface</hardwareInterface>
      <mechanicalReduction>1</mechanicalReduction>
    </actuator>
  </transmission>

  <transmission name="torso_right_bicep">
    <type>transmission_interface/SimpleTransmission</type>
    <joint name="torso_right_bicep">
      <hardwareInterface>hardware_interface/EffortJointInterface</hardwareInterface>
    </joint>
    <actuator name="motor15">
      <hardwareInterface>hardware_interface/EffortJointInterface</hardwareInterface>
      <mechanicalReduction>1</mechanicalReduction>
    </actuator>
  </transmission>

  <transmission name="right_bicep_forearm">
    <type>transmission_interface/SimpleTransmission</type>
    <joint name="right_bicep_forearm">
      <hardwareInterface>hardware_interface/EffortJointInterface</hardwareInterface>
    </joint>
    <actuator name="motor16">
      <hardwareInterface>hardware_interface/EffortJointInterface</hardwareInterface>
      <mechanicalReduction>1</mechanicalReduction>
    </actuator>
  </transmission>

  <transmission name="torso_left_bicep">
    <type>transmission_interface/SimpleTransmission</type>
    <joint name="torso_left_bicep">
      <hardwareInterface>hardware_interface/EffortJointInterface</hardwareInterface>
    </joint>
    <actuator name="motor17">
      <hardwareInterface>hardware_interface/EffortJointInterface</hardwareInterface>
      <mechanicalReduction>1</mechanicalReduction>
    </actuator>
  </transmission>

  <transmission name="left_bicep_forearm">
    <type>transmission_interface/SimpleTransmission</type>
    <joint name="left_bicep_forearm">
      <hardwareInterface>hardware_interface/EffortJointInterface</hardwareInterface>
    </joint>
    <actuator name="motor18">
      <hardwareInterface>hardware_interface/EffortJointInterface</hardwareInterface>
      <mechanicalReduction>1</mechanicalReduction>
    </actuator>
  </transmission>

</robot>
