<?xml version="1.0" ?>
<robot name="soccerbot">
  <joint name="head_camera" type="fixed">
    <parent link="head"/>
    <child link="camera"/>
    <origin rpy="2.35619 -1.57079  2.35619" xyz="0      0.0699  0.1"/>
    <axis xyz="0  0  0"/>
    <limit effort="0" lower="0" upper="0" velocity="0"/>
  </joint>
  <joint name="left_ankle_foot" type="revolute">
    <parent link="left_ankle"/>
    <child link="left_foot"/>
    <origin rpy="0  0  0" xyz="0  0  0"/>
    <axis xyz="1  0  0"/>
    <limit effort="-1.0" lower="-1.79769e+308" upper="1.79769e+308" velocity="-1.0"/>
  </joint>
  <joint name="left_bicep_forearm" type="revolute">
    <parent link="left_bicep"/>
    <child link="left_forearm"/>
    <origin rpy="0  0  0" xyz="0   -0.08  0"/>
    <axis xyz="0 -1  0"/>
    <limit effort="-1.0" lower="-1.79769e+308" upper="1.79769e+308" velocity="-1.0"/>
  </joint>
  <joint name="left_calve_ankle" type="revolute">
    <parent link="left_calve"/>
    <child link="left_ankle"/>
    <origin rpy="-6.00000000e-05   0.00000000e+00   0.00000000e+00" xyz="0     -0.0827  0"/>
    <axis xyz="0.00000000e+00   1.00000000e+00   6.00000000e-05"/>
    <limit effort="-1.0" lower="-1.79769e+308" upper="1.79769e+308" velocity="-1.0"/>
  </joint>
  <joint name="left_hip_front_thigh" type="revolute">
    <parent link="left_hip_front"/>
    <child link="left_thigh"/>
    <origin rpy="1.00000000e-05   0.00000000e+00   0.00000000e+00" xyz="0  0  0"/>
    <axis xyz="1  0  0"/>
    <limit effort="-1.0" lower="-1.79769e+308" upper="1.79769e+308" velocity="-1.0"/>
  </joint>
  <joint name="left_hip_side_hip_front" type="revolute">
    <parent link="left_hip_side"/>
    <child link="left_hip_front"/>
    <origin rpy="-2.3562  -1.57079  2.35619" xyz="0  0  0"/>
    <axis xyz="0  1  0"/>
    <limit effort="-1.0" lower="-1.79769e+308" upper="1.79769e+308" velocity="-1.0"/>
  </joint>
  <joint name="left_thigh_calve" type="revolute">
    <parent link="left_thigh"/>
    <child link="left_calve"/>
    <origin rpy="-1.00000000e-05   0.00000000e+00   0.00000000e+00" xyz="0      -0.08897  0"/>
    <axis xyz="0  1  0"/>
    <limit effort="-1.0" lower="-1.79769e+308" upper="1.79769e+308" velocity="-1.0"/>
  </joint>
  <joint name="neck_head" type="revolute">
    <parent link="neck"/>
    <child link="head"/>
    <origin rpy="1.00000000e-05   1.00000000e-05   0.00000000e+00" xyz="0     0.022  0"/>
    <axis xyz="0  0  1"/>
    <limit effort="-1.0" lower="-1.79769e+308" upper="1.79769e+308" velocity="-1.0"/>
  </joint>
  <joint name="right_ankle_foot" type="revolute">
    <parent link="right_ankle"/>
    <child link="right_foot"/>
    <origin rpy="0  0  0" xyz="0  0  0"/>
    <axis xyz="1  0  0"/>
    <limit effort="-1.0" lower="-1.79769e+308" upper="1.79769e+308" velocity="-1.0"/>
  </joint>
  <joint name="right_bicep_forearm" type="revolute">
    <parent link="right_bicep"/>
    <child link="right_forearm"/>
    <origin rpy="0  0  0" xyz="0   -0.08  0"/>
    <axis xyz="0  1  0"/>
    <limit effort="-1.0" lower="-1.79769e+308" upper="1.79769e+308" velocity="-1.0"/>
  </joint>
  <joint name="right_calve_ankle" type="revolute">
    <parent link="right_calve"/>
    <child link="right_ankle"/>
    <origin rpy="-6.00000000e-05   0.00000000e+00   0.00000000e+00" xyz="0     -0.0827  0"/>
    <axis xyz="0.00000000e+00   1.00000000e+00   6.00000000e-05"/>
    <limit effort="-1.0" lower="-1.79769e+308" upper="1.79769e+308" velocity="-1.0"/>
  </joint>
  <joint name="right_hip_front_thigh" type="revolute">
    <parent link="right_hip_front"/>
    <child link="right_thigh"/>
    <origin rpy="1.00000000e-05   0.00000000e+00   0.00000000e+00" xyz="0  0  0"/>
    <axis xyz="0  1  0"/>
    <limit effort="-1.0" lower="-1.79769e+308" upper="1.79769e+308" velocity="-1.0"/>
  </joint>
  <joint name="right_hip_side_hip_front" type="revolute">
    <parent link="right_hip_side"/>
    <child link="right_hip_front"/>
    <origin rpy="-2.3562  -1.57079  2.35619" xyz="0  0  0"/>
    <axis xyz="1  0  0"/>
    <limit effort="-1.0" lower="-1.79769e+308" upper="1.79769e+308" velocity="-1.0"/>
  </joint>
  <joint name="right_thigh_calve" type="revolute">
    <parent link="right_thigh"/>
    <child link="right_calve"/>
    <origin rpy="-1.00000000e-05   0.00000000e+00   0.00000000e+00" xyz="0      -0.08897  0"/>
    <axis xyz="0  1  0"/>
    <limit effort="-1.0" lower="-1.79769e+308" upper="1.79769e+308" velocity="-1.0"/>
  </joint>
  <joint name="torso_left_bicep" type="revolute">
    <parent link="torso"/>
    <child link="left_bicep"/>
    <origin rpy="1.5708  0      0" xyz="0      -0.076    0.34767"/>
    <axis xyz="0 -1  0"/>
    <limit effort="-1.0" lower="-1.79769e+308" upper="1.79769e+308" velocity="-1.0"/>
  </joint>
  <joint name="torso_left_hip_side" type="revolute">
    <parent link="torso"/>
    <child link="left_hip_side"/>
    <origin rpy="1.5708  0      1.5708" xyz="0      -0.03149  0.197"/>
    <axis xyz="1  0  0"/>
    <limit effort="-1.0" lower="-1.79769e+308" upper="1.79769e+308" velocity="-1.0"/>
  </joint>
  <joint name="torso_neck" type="revolute">
    <parent link="torso"/>
    <child link="neck"/>
    <origin rpy="1.57079  0       1.57079" xyz="0       0       0.37391"/>
    <axis xyz="1  0  0"/>
    <limit effort="-1.0" lower="-1.79769e+308" upper="1.79769e+308" velocity="-1.0"/>
  </joint>
  <joint name="torso_right_bicep" type="revolute">
    <parent link="torso"/>
    <child link="right_bicep"/>
    <origin rpy="1.5708  0      0" xyz="0       0.076    0.34767"/>
    <axis xyz="0  1  0"/>
    <limit effort="-1.0" lower="-1.79769e+308" upper="1.79769e+308" velocity="-1.0"/>
  </joint>
  <joint name="torso_right_hip_side" type="revolute">
    <parent link="torso"/>
    <child link="right_hip_side"/>
    <origin rpy="1.5708  0      1.5708" xyz="0       0.03149  0.197"/>
    <axis xyz="1  0  0"/>
    <limit effort="-1.0" lower="-1.79769e+308" upper="1.79769e+308" velocity="-1.0"/>
  </joint>
  <link name="torso">
    <inertial>
      <mass value="1"/>
      <origin rpy="-0.03771  1.57079  1.53308" xyz="0       0       0.30141"/>
      <inertia ixx="0.003149" ixy="0.000127" ixz="0.000124" iyy="0.004988" iyz="8.9e-05" izz="0.003395"/>
    </inertial>
    <collision name="collision">
      <origin rpy="-0.03771  1.57079  1.53308" xyz="0       0       0.30141"/>
      <geometry>
        <box size="0.152 0.1 0.145"/>
      </geometry>
    </collision>
    <visual name="visual">
      <origin rpy="-0.03771  1.57079  1.53308" xyz="0.05    -0.07249  0.37741"/>
      <geometry>
        <mesh filename="package://soccer_gazebo/models/meshes/Torso.stl" scale="0.001 0.001 0.001"/>
      </geometry>
    </visual>
  </link>
  <link name="camera">
    <inertial>
      <mass value="1"/>
      <origin rpy="0  0  0" xyz="0  0  0"/>
      <inertia ixx="0.166667" ixy="0" ixz="0" iyy="0.166667" iyz="0" izz="0.166667"/>
    </inertial>
  </link>
  <link name="head">
    <inertial>
      <mass value="1"/>
      <origin rpy="0  0  0" xyz="0  0  0"/>
      <inertia ixx="0.166667" ixy="0" ixz="0" iyy="0.166667" iyz="0" izz="0.166667"/>
    </inertial>
    <collision name="collision">
      <origin rpy="0  0  0" xyz="0       0.03648  0"/>
      <geometry>
        <box size="0.094 0.09596 0.0712"/>
      </geometry>
    </collision>
    <visual name="visual">
      <origin rpy="0  0  0" xyz="0  0  0"/>
      <geometry>
        <mesh filename="package://soccer_gazebo/models/meshes/Head.stl" scale="0.001 0.001 0.001"/>
      </geometry>
    </visual>
  </link>
  <link name="left_ankle">
    <inertial>
      <mass value="1"/>
      <origin rpy="1.57073  0       0" xyz="0  0  0"/>
      <inertia ixx="0.166667" ixy="0" ixz="0" iyy="0.166667" iyz="0" izz="0.166667"/>
    </inertial>
    <collision name="collision">
      <origin rpy="0  0  0" xyz="-0.02014  0.01031  0"/>
      <geometry>
        <box size="0.090769 0.0506 0.042"/>
      </geometry>
    </collision>
    <visual name="visual">
      <origin rpy="0  0  0" xyz="0  0  0"/>
      <geometry>
        <mesh filename="package://soccer_gazebo/models/meshes/Left Ankle.stl" scale="0.001 0.001 0.001"/>
      </geometry>
    </visual>
  </link>
  <link name="left_bicep">
    <inertial>
      <mass value="1"/>
      <origin rpy="0  0  0" xyz="0  0  0"/>
      <inertia ixx="0.166667" ixy="0" ixz="0" iyy="0.166667" iyz="0" izz="0.166667"/>
    </inertial>
    <collision name="collision">
      <origin rpy="0  0  0" xyz="0     -0.04    0.0225"/>
      <geometry>
        <box size="0.04 0.103 0.045"/>
      </geometry>
    </collision>
    <visual name="visual">
      <origin rpy="0  0  0" xyz="0  0  0"/>
      <geometry>
        <mesh filename="package://soccer_gazebo/models/meshes/Left Bicep.stl" scale="0.001 0.001 0.001"/>
      </geometry>
    </visual>
  </link>
  <link name="left_calve">
    <inertial>
      <mass value="1"/>
      <origin rpy="0  0  0" xyz="0     -0.0827  0"/>
      <inertia ixx="0.166667" ixy="0" ixz="0" iyy="0.166667" iyz="0" izz="0.166667"/>
    </inertial>
    <collision name="collision">
      <origin rpy="0  0  0" xyz="0      -0.03385  0"/>
      <geometry>
        <box size="0.031883 0.105683 0.048"/>
      </geometry>
    </collision>
    <visual name="visual">
      <origin rpy="0  0  0" xyz="0     -0.0827  0"/>
      <geometry>
        <mesh filename="package://soccer_gazebo/models/meshes/Left Calve.stl" scale="0.001 0.001 0.001"/>
      </geometry>
    </visual>
  </link>
  <link name="left_foot">
    <inertial>
      <mass value="1"/>
      <origin rpy="1.57073  0       0" xyz="0  0  0"/>
      <inertia ixx="0.166667" ixy="0" ixz="0" iyy="0.166667" iyz="0" izz="0.166667"/>
    </inertial>
    <collision name="collision">
      <origin rpy="0  0  0" xyz="0.00401 -0.00737  0.00385"/>
      <geometry>
        <box size="0.09 0.03674 0.07"/>
      </geometry>
    </collision>
    <visual name="visual">
      <origin rpy="0  0  0" xyz="0  0  0"/>
      <geometry>
        <mesh filename="package://soccer_gazebo/models/meshes/Left Foot.stl" scale="0.001 0.001 0.001"/>
      </geometry>
    </visual>
  </link>
  <link name="left_forearm">
    <inertial>
      <mass value="1"/>
      <origin rpy="0  0  0" xyz="0  0  0"/>
      <inertia ixx="0.166667" ixy="0" ixz="0" iyy="0.166667" iyz="0" izz="0.166667"/>
    </inertial>
    <collision name="collision">
      <origin rpy="0  0  0" xyz="-0.0055 -0.049   0.0265"/>
      <geometry>
        <box size="0.035 0.124 0.049"/>
      </geometry>
    </collision>
    <visual name="visual">
      <origin rpy="0  0  0" xyz="0  0  0"/>
      <geometry>
        <mesh filename="package://soccer_gazebo/models/meshes/Left Forearm.stl" scale="0.001 0.001 0.001"/>
      </geometry>
    </visual>
  </link>
  <link name="left_hip_front">
    <inertial>
      <mass value="1"/>
      <origin rpy="0  0  0" xyz="0  0  0"/>
      <inertia ixx="0.166667" ixy="0" ixz="0" iyy="0.166667" iyz="0" izz="0.166667"/>
    </inertial>
    <collision name="collision">
      <origin rpy="0  0  0" xyz="-0.02187 -0.01332  0"/>
      <geometry>
        <box size="0.083747 0.0506 0.04885"/>
      </geometry>
    </collision>
    <visual name="visual">
      <origin rpy="0  0  0" xyz="0  0  0"/>
      <geometry>
        <mesh filename="package://soccer_gazebo/models/meshes/Left Hip Front.stl" scale="0.001 0.001 0.001"/>
      </geometry>
    </visual>
  </link>
  <link name="left_hip_side">
    <inertial>
      <mass value="1"/>
      <origin rpy="0  0  0" xyz="0  0  0"/>
      <inertia ixx="0.166667" ixy="0" ixz="0" iyy="0.166667" iyz="0" izz="0.166667"/>
    </inertial>
    <collision name="collision">
      <origin rpy="0  0  0" xyz="0       0.00899  0"/>
      <geometry>
        <box size="0.022 0.039 0.0475"/>
      </geometry>
    </collision>
    <visual name="visual">
      <origin rpy="0  0  0" xyz="0  0  0"/>
      <geometry>
        <mesh filename="package://soccer_gazebo/models/meshes/Left Hip Side.stl" scale="0.001 0.001 0.001"/>
      </geometry>
    </visual>
  </link>
  <link name="left_thigh">
    <inertial>
      <mass value="1"/>
      <origin rpy="0  0  0" xyz="0  0  0"/>
      <inertia ixx="0.166667" ixy="0" ixz="0" iyy="0.166667" iyz="0" izz="0.166667"/>
    </inertial>
    <collision name="collision">
      <origin rpy="0  0  0" xyz="0     -0.0445  0"/>
      <geometry>
        <box size="0.022 0.111 0.048"/>
      </geometry>
    </collision>
    <visual name="visual">
      <origin rpy="0  0  0" xyz="0  0  0"/>
      <geometry>
        <mesh filename="package://soccer_gazebo/models/meshes/Left Thigh.stl" scale="0.001 0.001 0.001"/>
      </geometry>
    </visual>
  </link>
  <link name="neck">
    <inertial>
      <mass value="1"/>
      <origin rpy="0  0  0" xyz="0  0  0"/>
      <inertia ixx="0.166667" ixy="0" ixz="0" iyy="0.166667" iyz="0" izz="0.166667"/>
    </inertial>
    <collision name="collision">
      <origin rpy="0  0  0" xyz="0      0.0165  0"/>
      <geometry>
        <box size="0.0523 0.033 0.022"/>
      </geometry>
    </collision>
    <visual name="visual">
      <origin rpy="0  0  0" xyz="0  0  0"/>
      <geometry>
        <mesh filename="package://soccer_gazebo/models/meshes/Neck.stl" scale="0.001 0.001 0.001"/>
      </geometry>
    </visual>
  </link>
  <link name="right_ankle">
    <inertial>
      <mass value="1"/>
      <origin rpy="1.57073  0       0" xyz="0  0  0"/>
      <inertia ixx="0.166667" ixy="0" ixz="0" iyy="0.166667" iyz="0" izz="0.166667"/>
    </inertial>
    <collision name="collision">
      <origin rpy="0  0  0" xyz="-0.02014  0.01031  0"/>
      <geometry>
        <box size="0.090769 0.0506 0.042"/>
      </geometry>
    </collision>
    <visual name="visual">
      <origin rpy="0  0  0" xyz="0  0  0"/>
      <geometry>
        <mesh filename="package://soccer_gazebo/models/meshes/Right Ankle.stl" scale="0.001 0.001 0.001"/>
      </geometry>
    </visual>
  </link>
  <link name="right_bicep">
    <inertial>
      <mass value="1"/>
      <origin rpy="0  0  0" xyz="0  0  0"/>
      <inertia ixx="0.166667" ixy="0" ixz="0" iyy="0.166667" iyz="0" izz="0.166667"/>
    </inertial>
    <collision name="collision">
      <origin rpy="0  0  0" xyz="0     -0.04   -0.0225"/>
      <geometry>
        <box size="0.04 0.103 0.045"/>
      </geometry>
    </collision>
    <visual name="visual">
      <origin rpy="0  0  0" xyz="0  0  0"/>
      <geometry>
        <mesh filename="package://soccer_gazebo/models/meshes/Right Bicep.stl" scale="0.001 0.001 0.001"/>
      </geometry>
    </visual>
  </link>
  <link name="right_calve">
    <inertial>
      <mass value="1"/>
      <origin rpy="0  0  0" xyz="0     -0.0827  0"/>
      <inertia ixx="0.166667" ixy="0" ixz="0" iyy="0.166667" iyz="0" izz="0.166667"/>
    </inertial>
    <collision name="collision">
      <origin rpy="0  0  0" xyz="0      -0.03385  0"/>
      <geometry>
        <box size="0.031883 0.105683 0.048"/>
      </geometry>
    </collision>
    <visual name="visual">
      <origin rpy="0  0  0" xyz="0     -0.0827  0"/>
      <geometry>
        <mesh filename="package://soccer_gazebo/models/meshes/Right Calve.stl" scale="0.001 0.001 0.001"/>
      </geometry>
    </visual>
  </link>
  <link name="right_foot">
    <inertial>
      <mass value="1"/>
      <origin rpy="1.57073  0       0" xyz="0  0  0"/>
      <inertia ixx="0.166667" ixy="0" ixz="0" iyy="0.166667" iyz="0" izz="0.166667"/>
    </inertial>
    <collision name="collision">
      <origin rpy="0  0  0" xyz="0.00401 -0.00737  0.00385"/>
      <geometry>
        <box size="0.09 0.03674 0.07"/>
      </geometry>
    </collision>
    <visual name="visual">
      <origin rpy="0  0  0" xyz="0  0  0"/>
      <geometry>
        <mesh filename="package://soccer_gazebo/models/meshes/Right foot.stl" scale="0.001 0.001 0.001"/>
      </geometry>
    </visual>
  </link>
  <link name="right_forearm">
    <inertial>
      <mass value="1"/>
      <origin rpy="0  0  0" xyz="0  0  0"/>
      <inertia ixx="0.166667" ixy="0" ixz="0" iyy="0.166667" iyz="0" izz="0.166667"/>
    </inertial>
    <collision name="collision">
      <origin rpy="0  0  0" xyz="-0.0055 -0.049  -0.0265"/>
      <geometry>
        <box size="0.035 0.124 0.049"/>
      </geometry>
    </collision>
    <visual name="visual">
      <origin rpy="0  0  0" xyz="0  0  0"/>
      <geometry>
        <mesh filename="package://soccer_gazebo/models/meshes/Right Forearm.stl" scale="0.001 0.001 0.001"/>
      </geometry>
    </visual>
  </link>
  <link name="right_hip_front">
    <inertial>
      <mass value="1"/>
      <origin rpy="0  0  0" xyz="0  0  0"/>
      <inertia ixx="0.166667" ixy="0" ixz="0" iyy="0.166667" iyz="0" izz="0.166667"/>
    </inertial>
    <collision name="collision">
      <origin rpy="0  0  0" xyz="-0.02187 -0.01332  0"/>
      <geometry>
        <box size="0.083747 0.0506 0.04885"/>
      </geometry>
    </collision>
    <visual name="visual">
      <origin rpy="0  0  0" xyz="0  0  0"/>
      <geometry>
        <mesh filename="package://soccer_gazebo/models/meshes/Right Hip Front.stl" scale="0.001 0.001 0.001"/>
      </geometry>
    </visual>
  </link>
  <link name="right_hip_side">
    <inertial>
      <mass value="1"/>
      <origin rpy="0  0  0" xyz="0  0  0"/>
      <inertia ixx="0.166667" ixy="0" ixz="0" iyy="0.166667" iyz="0" izz="0.166667"/>
    </inertial>
    <collision name="collision">
      <origin rpy="0  0  0" xyz="0       0.00899  0"/>
      <geometry>
        <box size="0.022 0.039 0.0475"/>
      </geometry>
    </collision>
    <visual name="visual">
      <origin rpy="0  0  0" xyz="0  0  0"/>
      <geometry>
        <mesh filename="package://soccer_gazebo/models/meshes/Right Hip Side.stl" scale="0.001 0.001 0.001"/>
      </geometry>
    </visual>
  </link>
  <link name="right_thigh">
    <inertial>
      <mass value="1"/>
      <origin rpy="0  0  0" xyz="0  0  0"/>
      <inertia ixx="0.166667" ixy="0" ixz="0" iyy="0.166667" iyz="0" izz="0.166667"/>
    </inertial>
    <collision name="collision">
      <origin rpy="0  0  0" xyz="0     -0.0445  0"/>
      <geometry>
        <box size="0.022 0.111 0.048"/>
      </geometry>
    </collision>
    <visual name="visual">
      <origin rpy="0  0  0" xyz="0  0  0"/>
      <geometry>
        <mesh filename="package://soccer_gazebo/models/meshes/Right Thigh.stl" scale="0.001 0.001 0.001"/>
      </geometry>
    </visual>
  </link>
  <transmission name='torso_right_hip_side'>
    <type>transmission_interface/SimpleTransmission</type>
    <robotNamespace>${name}</robotNamespace>
    <joint name="torso_right_hip_side">
      <hardwareInterface>PositionJointInterface</hardwareInterface>
    </joint>
    <actuator name="motor7">
      <hardwareInterface>PositionJointInterface</hardwareInterface> 
    </actuator>
  </transmission>
  <transmission name='right_hip_side_hip_front'>
    <type>transmission_interface/SimpleTransmission</type>
    <robotNamespace>${name}</robotNamespace>
    <joint name="right_hip_side_hip_front">
      <hardwareInterface>PositionJointInterface</hardwareInterface>
    </joint>
    <actuator name="motor8">
      <hardwareInterface>PositionJointInterface</hardwareInterface> 
    </actuator>
  </transmission>
  <transmission name='right_hip_front_thigh'>
    <type>transmission_interface/SimpleTransmission</type>
    <robotNamespace>${name}</robotNamespace>
    <joint name="right_hip_front_thigh">
      <hardwareInterface>PositionJointInterface</hardwareInterface>
    </joint>
    <actuator name="motor9">
      <hardwareInterface>PositionJointInterface</hardwareInterface> 
    </actuator>
  </transmission>
  <transmission name='right_thigh_calve'>
    <type>transmission_interface/SimpleTransmission</type>
    <robotNamespace>${name}</robotNamespace>
    <joint name="right_thigh_calve">
      <hardwareInterface>PositionJointInterface</hardwareInterface>
    </joint>
    <actuator name="motor10">
      <hardwareInterface>PositionJointInterface</hardwareInterface> 
    </actuator>
  </transmission>
  <transmission name='right_calve_ankle'>
    <type>transmission_interface/SimpleTransmission</type>
    <robotNamespace>${name}</robotNamespace>
    <joint name="right_calve_ankle">
      <hardwareInterface>PositionJointInterface</hardwareInterface>
    </joint>
    <actuator name="motor11">
      <hardwareInterface>PositionJointInterface</hardwareInterface> 
    </actuator>
  </transmission>
  <transmission name='right_ankle_foot'>
    <type>transmission_interface/SimpleTransmission</type>
    <robotNamespace>${name}</robotNamespace>
    <joint name="right_ankle_foot">
      <hardwareInterface>PositionJointInterface</hardwareInterface>
    </joint>
    <actuator name="motor12">
      <hardwareInterface>PositionJointInterface</hardwareInterface> 
    </actuator>
  </transmission>
  <transmission name='torso_left_hip_side'>
    <type>transmission_interface/SimpleTransmission</type>
    <robotNamespace>${name}</robotNamespace>
    <joint name="torso_left_hip_side">
      <hardwareInterface>PositionJointInterface</hardwareInterface>
    </joint>
    <actuator name="motor6">
      <hardwareInterface>PositionJointInterface</hardwareInterface> 
    </actuator>
  </transmission>
  <transmission name='left_hip_side_hip_front'>
    <type>transmission_interface/SimpleTransmission</type>
    <robotNamespace>${name}</robotNamespace>
    <joint name="left_hip_side_hip_front">
      <hardwareInterface>PositionJointInterface</hardwareInterface>
    </joint>
    <actuator name="motor5">
      <hardwareInterface>PositionJointInterface</hardwareInterface> 
    </actuator>
  </transmission>
  <transmission name='left_hip_front_thigh'>
    <type>transmission_interface/SimpleTransmission</type>
    <robotNamespace>${name}</robotNamespace>
    <joint name="left_hip_front_thigh">
      <hardwareInterface>PositionJointInterface</hardwareInterface>
    </joint>
    <actuator name="motor4">
      <hardwareInterface>PositionJointInterface</hardwareInterface> 
    </actuator>
  </transmission>
  <transmission name='left_thigh_calve'>
    <type>transmission_interface/SimpleTransmission</type>
    <robotNamespace>${name}</robotNamespace>
    <joint name="left_thigh_calve">
      <hardwareInterface>PositionJointInterface</hardwareInterface>
    </joint>
    <actuator name="motor3">
      <hardwareInterface>PositionJointInterface</hardwareInterface> 
    </actuator>
  </transmission>
  <transmission name='left_calve_ankle'>
    <type>transmission_interface/SimpleTransmission</type>
    <robotNamespace>${name}</robotNamespace>
    <joint name="left_calve_ankle">
      <hardwareInterface>PositionJointInterface</hardwareInterface>
    </joint>
    <actuator name="motor2">
      <hardwareInterface>PositionJointInterface</hardwareInterface> 
    </actuator>
  </transmission>
  <transmission name='left_ankle_foot'>
    <type>transmission_interface/SimpleTransmission</type>
    <robotNamespace>${name}</robotNamespace>
    <joint name="left_ankle_foot">
      <hardwareInterface>PositionJointInterface</hardwareInterface>
    </joint>
    <actuator name="motor1">
      <hardwareInterface>PositionJointInterface</hardwareInterface> 
    </actuator>
  </transmission>
  <transmission name='torso_right_bicep'>
    <type>transmission_interface/SimpleTransmission</type>
    <robotNamespace>${name}</robotNamespace>
    <joint name="torso_right_bicep">
      <hardwareInterface>PositionJointInterface</hardwareInterface>
    </joint>
    <actuator name="motor15">
      <hardwareInterface>PositionJointInterface</hardwareInterface> 
    </actuator>
  </transmission>
  <transmission name='right_bicep_forearm'>
    <type>transmission_interface/SimpleTransmission</type>
    <robotNamespace>${right_bicep_forearm}</robotNamespace>
    <joint name="torso_neck">
      <hardwareInterface>PositionJointInterface</hardwareInterface>
    </joint>
    <actuator name="motor16">
      <hardwareInterface>PositionJointInterface</hardwareInterface> 
    </actuator>
  </transmission>
  <transmission name='torso_left_bicep'>
    <type>transmission_interface/SimpleTransmission</type>
    <robotNamespace>${name}</robotNamespace>
    <joint name="torso_left_bicep">
      <hardwareInterface>PositionJointInterface</hardwareInterface>
    </joint>
    <actuator name="motor17">
      <hardwareInterface>PositionJointInterface</hardwareInterface> 
    </actuator>
  </transmission>
  <transmission name='left_bicep_forearm'>
    <type>transmission_interface/SimpleTransmission</type>
    <robotNamespace>${name}</robotNamespace>
    <joint name="left_bicep_forearm">
      <hardwareInterface>PositionJointInterface</hardwareInterface>
    </joint>
    <actuator name="motor18">
      <hardwareInterface>PositionJointInterface</hardwareInterface> 
    </actuator>
  </transmission>
  <transmission name='torso_neck'>
    <type>transmission_interface/SimpleTransmission</type>
    <robotNamespace>${name}</robotNamespace>
    <joint name="torso_neck">
      <hardwareInterface>PositionJointInterface</hardwareInterface>
    </joint>
    <actuator name="motor13">
      <hardwareInterface>PositionJointInterface</hardwareInterface> 
    </actuator>
  </transmission>
  <transmission name='neck_head'>
    <type>transmission_interface/SimpleTransmission</type>
    <robotNamespace>${name}</robotNamespace>
    <joint name="neck_head">
      <hardwareInterface>PositionJointInterface</hardwareInterface>
    </joint>
    <actuator name="motor14">
      <hardwareInterface>PositionJointInterface</hardwareInterface> 
    </actuator>
  </transmission>
</robot>
