<?xml version="1.0" ?>
<robot name="hip-rejoint" xmlns:xacro="http://www.ros.org/wiki/xacro">
  <!-- 
    Steps to generate model:

    - Joint and export in Fusion
    - Fix inertias in the URDF with `%s/i\(\w\)\1="\-*0.0"/i\1\1="1E-06"/g`
    - Rename `base_link` to `trunk` in the URDF to accomodate placo
    - Rejoint `trunk` to a new root link with a `floating` joint in URDF (i.e. `<link name="root" /><joint name="root-float" type="floating"><child link="trunk" /><parent link="root" /></joint>`
    - Fix servo masses based on enclosure (masses currently include all optional enclosures)
    - Fix necessary placo names (left_foot, right_foot, trunk) which have `_1` or some other digit appended by Fusion unique ID system
    - Generate URDF from xacro via:
      - `conda activate py2; rosrun xacro xacro '/path/to/model.xacro' > '/path/to/model.urdf';`
    - Import to mujoco and save as XML
    - Ensure left and right foot links exist

    Further model fixes:
    - Reorient body to match world frame
    - Add sites to all servos via `%s/<body\(.*\)pos="\([^"]*\)">\(\_.\{-}\)<joint\(.*\)name="\([^"]*\)"/<site name="site_\5" pos="\2" \/><body\1pos="\2">\3<joint\4name="\5"/gi`
    - Add accelerometers and gyros to all sites with `sed` to generate the tag lists:
      - sed 's/<site name="site_\([^"]*\)".*>/\n<accelerometer name="xl_\1" site="site_\1" \/>\n/g' mjmodel.xml | grep '<accelerometer'
    - Disable collision geoms

    - Servo inertias are wrong because they are extracted with all options, including invisible ones. Since they're small, only fix masses depending on the servo enclosure option that is used.
  -->

  <mujoco>
    <compiler meshdir="../meshes" balanceinertia="true" discardvisual="false"/>
  </mujoco>

<xacro:include filename="$(find hip-rejoint_description)/urdf/materials.xacro" />
<xacro:include filename="$(find hip-rejoint_description)/urdf/hip-rejoint.trans" />
<xacro:include filename="$(find hip-rejoint_description)/urdf/hip-rejoint.gazebo" />
<link name="base_link">
  <inertial>
    <origin xyz="0.005 0.005 0.005" rpy="0 0 0"/>
    <mass value="0.00106"/>
    <inertia ixx="1E-06" iyy="1E-06" izz="1E-06" ixy="0.0" iyz="0.0" ixz="0.0"/>
  </inertial>
  <visual>
    <origin xyz="0 0 0" rpy="0 0 0"/>
    <geometry>
      <mesh filename="package://hip-rejoint_description/meshes/base_link.stl" scale="0.001 0.001 0.001"/>
    </geometry>
    <material name="abs_white"/>
  </visual>
  <collision>
    <origin xyz="0 0 0" rpy="0 0 0"/>
    <geometry>
      <mesh filename="package://hip-rejoint_description/meshes/base_link.stl" scale="0.001 0.001 0.001"/>
    </geometry>
  </collision>
</link>

<link name="R8-2RS_Bearing_1">
  <inertial>
    <origin xyz="4.85722573273506e-17 1.6393830737371218e-13 -0.003969249999999997" rpy="0 0 0"/>
    <mass value="0.03206594861680248"/>
    <inertia ixx="2e-06" iyy="2e-06" izz="4e-06" ixy="-0.0" iyz="-0.0" ixz="-0.0"/>
  </inertial>
  <visual>
    <origin xyz="0.025 -0.0592 -0.009763" rpy="0 0 0"/>
    <geometry>
      <mesh filename="package://hip-rejoint_description/meshes/R8-2RS_Bearing_1.stl" scale="0.001 0.001 0.001"/>
    </geometry>
    <material name="steel_satin"/>
  </visual>
  <collision>
    <origin xyz="0.025 -0.0592 -0.009763" rpy="0 0 0"/>
    <geometry>
      <mesh filename="package://hip-rejoint_description/meshes/R8-2RS_Bearing_1.stl" scale="0.001 0.001 0.001"/>
    </geometry>
  </collision>
</link>

<link name="R8-2RS_Bearing_2">
  <inertial>
    <origin xyz="5.551115123125783e-17 1.6397300184323171e-13 0.003968250000000005" rpy="0 0 0"/>
    <mass value="0.03206594861680248"/>
    <inertia ixx="2e-06" iyy="2e-06" izz="4e-06" ixy="0.0" iyz="-0.0" ixz="0.0"/>
  </inertial>
  <visual>
    <origin xyz="0.025 -0.0592 -0.009763" rpy="0 0 0"/>
    <geometry>
      <mesh filename="package://hip-rejoint_description/meshes/R8-2RS_Bearing_2.stl" scale="0.001 0.001 0.001"/>
    </geometry>
    <material name="steel_satin"/>
  </visual>
  <collision>
    <origin xyz="0.025 -0.0592 -0.009763" rpy="0 0 0"/>
    <geometry>
      <mesh filename="package://hip-rejoint_description/meshes/R8-2RS_Bearing_2.stl" scale="0.001 0.001 0.001"/>
    </geometry>
  </collision>
</link>

<link name="R8-2RS_Bearing_3">
  <inertial>
    <origin xyz="-3.469446951953614e-18 1.6287665660641437e-13 -0.003968249999999989" rpy="0 0 0"/>
    <mass value="0.03206594861680248"/>
    <inertia ixx="2e-06" iyy="2e-06" izz="4e-06" ixy="0.0" iyz="0.0" ixz="-0.0"/>
  </inertial>
  <visual>
    <origin xyz="0.025 0.0492 -0.009762" rpy="0 0 0"/>
    <geometry>
      <mesh filename="package://hip-rejoint_description/meshes/R8-2RS_Bearing_3.stl" scale="0.001 0.001 0.001"/>
    </geometry>
    <material name="steel_satin"/>
  </visual>
  <collision>
    <origin xyz="0.025 0.0492 -0.009762" rpy="0 0 0"/>
    <geometry>
      <mesh filename="package://hip-rejoint_description/meshes/R8-2RS_Bearing_3.stl" scale="0.001 0.001 0.001"/>
    </geometry>
  </collision>
</link>

<link name="R8-2RS_Bearing_4">
  <inertial>
    <origin xyz="-3.469446951953614e-18 1.6298074001497298e-13 0.00396825000000001" rpy="0 0 0"/>
    <mass value="0.03206594861680248"/>
    <inertia ixx="2e-06" iyy="2e-06" izz="4e-06" ixy="0.0" iyz="-0.0" ixz="-0.0"/>
  </inertial>
  <visual>
    <origin xyz="0.025 0.0492 -0.009763" rpy="0 0 0"/>
    <geometry>
      <mesh filename="package://hip-rejoint_description/meshes/R8-2RS_Bearing_4.stl" scale="0.001 0.001 0.001"/>
    </geometry>
    <material name="steel_satin"/>
  </visual>
  <collision>
    <origin xyz="0.025 0.0492 -0.009763" rpy="0 0 0"/>
    <geometry>
      <mesh filename="package://hip-rejoint_description/meshes/R8-2RS_Bearing_4.stl" scale="0.001 0.001 0.001"/>
    </geometry>
  </collision>
</link>

<link name="Component2_2">
  <inertial>
    <origin xyz="9.020562075079397e-17 -8.781170235394598e-14 0.006597976249397723" rpy="0 0 0"/>
    <mass value="0.043046314847355716"/>
    <inertia ixx="9e-06" iyy="9e-06" izz="1.6e-05" ixy="0.0" iyz="0.0" ixz="0.0"/>
  </inertial>
  <visual>
    <origin xyz="0.025 -0.0592 -0.009763" rpy="0 0 0"/>
    <geometry>
      <mesh filename="package://hip-rejoint_description/meshes/Component2_2.stl" scale="0.001 0.001 0.001"/>
    </geometry>
    <material name="aluminum_satin"/>
  </visual>
  <collision>
    <origin xyz="0.025 -0.0592 -0.009763" rpy="0 0 0"/>
    <geometry>
      <mesh filename="package://hip-rejoint_description/meshes/Component2_2.stl" scale="0.001 0.001 0.001"/>
    </geometry>
  </collision>
</link>

<link name="Component2_1">
  <inertial>
    <origin xyz="2.0816681711721685e-17 -8.87900863943969e-14 0.0065989762493977346" rpy="0 0 0"/>
    <mass value="0.043046314847355716"/>
    <inertia ixx="9e-06" iyy="9e-06" izz="1.6e-05" ixy="0.0" iyz="0.0" ixz="0.0"/>
  </inertial>
  <visual>
    <origin xyz="0.025 0.0492 -0.009762" rpy="0 0 0"/>
    <geometry>
      <mesh filename="package://hip-rejoint_description/meshes/Component2_1.stl" scale="0.001 0.001 0.001"/>
    </geometry>
    <material name="aluminum_satin"/>
  </visual>
  <collision>
    <origin xyz="0.025 0.0492 -0.009762" rpy="0 0 0"/>
    <geometry>
      <mesh filename="package://hip-rejoint_description/meshes/Component2_1.stl" scale="0.001 0.001 0.001"/>
    </geometry>
  </collision>
</link>

<link name="91590A121_External_Retaining_Ring_v1_2">
  <inertial>
    <origin xyz="1.8943180357666733e-15 0.000286197569581724 0.0003170000000000117" rpy="0 0 0"/>
    <mass value="0.00024760918611349786"/>
    <inertia ixx="1E-06" iyy="1E-06" izz="1E-06" ixy="0.0" iyz="0.0" ixz="-0.0"/>
  </inertial>
  <visual>
    <origin xyz="0.025 0.0492 -0.020718" rpy="0 0 0"/>
    <geometry>
      <mesh filename="package://hip-rejoint_description/meshes/91590A121_External_Retaining_Ring_v1_2.stl" scale="0.001 0.001 0.001"/>
    </geometry>
    <material name="steel_satin"/>
  </visual>
  <collision>
    <origin xyz="0.025 0.0492 -0.020718" rpy="0 0 0"/>
    <geometry>
      <mesh filename="package://hip-rejoint_description/meshes/91590A121_External_Retaining_Ring_v1_2.stl" scale="0.001 0.001 0.001"/>
    </geometry>
  </collision>
</link>

<link name="2025K9_303_Stainless_Steel_Rotary_Shaft_with_Retaining_Ring_Grooves_v1_1">
  <inertial>
    <origin xyz="-3.686981275841106e-14 6.104977634535658e-13 -0.023450621315963708" rpy="0 0 0"/>
    <mass value="0.07269824555688346"/>
    <inertia ixx="3.6e-05" iyy="3.6e-05" izz="1e-06" ixy="-0.0" iyz="0.0" ixz="0.0"/>
  </inertial>
  <visual>
    <origin xyz="0.025 0.0492 -0.021353" rpy="0 0 0"/>
    <geometry>
      <mesh filename="package://hip-rejoint_description/meshes/2025K9_303_Stainless_Steel_Rotary_Shaft_with_Retaining_Ring_Grooves_v1_1.stl" scale="0.001 0.001 0.001"/>
    </geometry>
    <material name="steel_satin"/>
  </visual>
  <collision>
    <origin xyz="0.025 0.0492 -0.021353" rpy="0 0 0"/>
    <geometry>
      <mesh filename="package://hip-rejoint_description/meshes/2025K9_303_Stainless_Steel_Rotary_Shaft_with_Retaining_Ring_Grooves_v1_1.stl" scale="0.001 0.001 0.001"/>
    </geometry>
  </collision>
</link>

<link name="91590A121_External_Retaining_Ring_v1_3">
  <inertial>
    <origin xyz="-1.8561541192951836e-15 -0.00028619756958252196 0.00031759999999999026" rpy="0 0 0"/>
    <mass value="0.00024760918611349786"/>
    <inertia ixx="1E-06" iyy="1E-06" izz="1E-06" ixy="0.0" iyz="-0.0" ixz="-0.0"/>
  </inertial>
  <visual>
    <origin xyz="0.025 0.0492 0.000898" rpy="0 0 0"/>
    <geometry>
      <mesh filename="package://hip-rejoint_description/meshes/91590A121_External_Retaining_Ring_v1_3.stl" scale="0.001 0.001 0.001"/>
    </geometry>
    <material name="steel_satin"/>
  </visual>
  <collision>
    <origin xyz="0.025 0.0492 0.000898" rpy="0 0 0"/>
    <geometry>
      <mesh filename="package://hip-rejoint_description/meshes/91590A121_External_Retaining_Ring_v1_3.stl" scale="0.001 0.001 0.001"/>
    </geometry>
  </collision>
</link>

<link name="91590A121_External_Retaining_Ring_v1_1">
  <inertial>
    <origin xyz="-1.8561541192951836e-15 -0.000286197569582515 -0.0003176000000000255" rpy="0 0 0"/>
    <mass value="0.00024760918611349786"/>
    <inertia ixx="1E-06" iyy="1E-06" izz="1E-06" ixy="0.0" iyz="0.0" ixz="0.0"/>
  </inertial>
  <visual>
    <origin xyz="0.025 0.0492 0.012023" rpy="0 0 0"/>
    <geometry>
      <mesh filename="package://hip-rejoint_description/meshes/91590A121_External_Retaining_Ring_v1_1.stl" scale="0.001 0.001 0.001"/>
    </geometry>
    <material name="steel_satin"/>
  </visual>
  <collision>
    <origin xyz="0.025 0.0492 0.012023" rpy="0 0 0"/>
    <geometry>
      <mesh filename="package://hip-rejoint_description/meshes/91590A121_External_Retaining_Ring_v1_1.stl" scale="0.001 0.001 0.001"/>
    </geometry>
  </collision>
</link>

<link name="Component39_1">
  <inertial>
    <origin xyz="-0.004453658050594535 1.0708659631264439e-07 0.007256502814372477" rpy="0 0 0"/>
    <mass value="0.015364690334044086"/>
    <inertia ixx="2e-06" iyy="1e-06" izz="1e-06" ixy="-0.0" iyz="0.0" ixz="-0.0"/>
  </inertial>
  <visual>
    <origin xyz="0.05665 0.049276 0.06012" rpy="0 0 0"/>
    <geometry>
      <mesh filename="package://hip-rejoint_description/meshes/Component39_1.stl" scale="0.001 0.001 0.001"/>
    </geometry>
    <material name="aluminum_satin"/>
  </visual>
  <collision>
    <origin xyz="0.05665 0.049276 0.06012" rpy="0 0 0"/>
    <geometry>
      <mesh filename="package://hip-rejoint_description/meshes/Component39_1.stl" scale="0.001 0.001 0.001"/>
    </geometry>
  </collision>
</link>

<link name="JX_servo_v80_3">
  <inertial>
    <mass value="0.2114"/>
    <origin xyz="-0.03281072928697727 -0.00014307061349972533 -0.016670466018917744" rpy="0 0 0"/>
    <inertia ixx="0.001692" iyy="0.001903" izz="0.001012" ixy="-1e-06" iyz="-0.0" ixz="-4.9e-05"/>
  </inertial>
  <visual>
    <origin xyz="0.06935 0.049276 0.06012" rpy="0 0 0"/>
    <geometry>
      <mesh filename="package://hip-rejoint_description/meshes/JX_servo_v80_3.stl" scale="0.001 0.001 0.001"/>
    </geometry>
    <material name="polystyrene"/>
  </visual>
  <collision>
    <origin xyz="0.06935 0.049276 0.06012" rpy="0 0 0"/>
    <geometry>
      <mesh filename="package://hip-rejoint_description/meshes/JX_servo_v80_3.stl" scale="0.001 0.001 0.001"/>
    </geometry>
  </collision>
</link>

<link name="Component9__1__1">
  <inertial>
    <origin xyz="0.03333629681388652 -0.008439001260076934 -0.00027616991746298725" rpy="0 0 0"/>
    <mass value="0.13759034791983457"/>
    <inertia ixx="1e-05" iyy="5.4e-05" izz="6.2e-05" ixy="-0.0" iyz="0.0" ixz="0.0"/>
  </inertial>
  <visual>
    <origin xyz="0.08185 0.040926 0.11572" rpy="0 0 0"/>
    <geometry>
      <mesh filename="package://hip-rejoint_description/meshes/Component9__1__1.stl" scale="0.001 0.001 0.001"/>
    </geometry>
    <material name="steel_satin"/>
  </visual>
  <collision>
    <origin xyz="0.08185 0.040926 0.11572" rpy="0 0 0"/>
    <geometry>
      <mesh filename="package://hip-rejoint_description/meshes/Component9__1__1.stl" scale="0.001 0.001 0.001"/>
    </geometry>
  </collision>
</link>

<link name="Component4_1">
  <inertial>
    <origin xyz="4.5102810375396984e-17 -2.0160956237802452e-13 -0.0027446731476930067" rpy="0 0 0"/>
    <mass value="0.011955695388392617"/>
    <inertia ixx="1e-06" iyy="1e-06" izz="2e-06" ixy="0.0" iyz="0.0" ixz="0.0"/>
  </inertial>
  <visual>
    <origin xyz="0.025 0.0492 0.012658" rpy="0 0 0"/>
    <geometry>
      <mesh filename="package://hip-rejoint_description/meshes/Component4_1.stl" scale="0.001 0.001 0.001"/>
    </geometry>
    <material name="aluminum_satin"/>
  </visual>
  <collision>
    <origin xyz="0.025 0.0492 0.012658" rpy="0 0 0"/>
    <geometry>
      <mesh filename="package://hip-rejoint_description/meshes/Component4_1.stl" scale="0.001 0.001 0.001"/>
    </geometry>
  </collision>
</link>

<link name="Component32_1">
  <inertial>
    <origin xyz="0.0004621398104596615 -7.798356568446824e-05 -0.016749694753477054" rpy="0 0 0"/>
    <mass value="0.11550269835963742"/>
    <inertia ixx="4.9e-05" iyy="9.9e-05" izz="9.4e-05" ixy="-0.0" iyz="0.0" ixz="-0.0"/>
  </inertial>
  <visual>
    <origin xyz="0.025 0.0492 0.01797" rpy="0 0 0"/>
    <geometry>
      <mesh filename="package://hip-rejoint_description/meshes/Component32_1.stl" scale="0.001 0.001 0.001"/>
    </geometry>
    <material name="aluminum_satin"/>
  </visual>
  <collision>
    <origin xyz="0.025 0.0492 0.01797" rpy="0 0 0"/>
    <geometry>
      <mesh filename="package://hip-rejoint_description/meshes/Component32_1.stl" scale="0.001 0.001 0.001"/>
    </geometry>
  </collision>
</link>

<link name="15T-horn_v13_1">
  <inertial>
    <origin xyz="2.0469737016526324e-16 6.415796262119328e-05 -0.00120040750659281" rpy="0 0 0"/>
    <mass value="0.004179712167666874"/>
    <inertia ixx="1E-06" iyy="1E-06" izz="1E-06" ixy="-0.0" iyz="0.0" ixz="-0.0"/>
  </inertial>
  <visual>
    <origin xyz="0.025 0.0492 -0.036034" rpy="0 0 0"/>
    <geometry>
      <mesh filename="package://hip-rejoint_description/meshes/15T-horn_v13_1.stl" scale="0.001 0.001 0.001"/>
    </geometry>
    <material name="aluminum_satin"/>
  </visual>
  <collision>
    <origin xyz="0.025 0.0492 -0.036034" rpy="0 0 0"/>
    <geometry>
      <mesh filename="package://hip-rejoint_description/meshes/15T-horn_v13_1.stl" scale="0.001 0.001 0.001"/>
    </geometry>
  </collision>
</link>

<link name="JX_servo_v80_1">
  <inertial>
    <origin xyz="-0.0001431777001134303 0.01667036601891729 0.039010829286977536" rpy="0 0 0"/>
    <mass value="0.2114"/>
    <inertia ixx="0.001903" iyy="0.001012" izz="0.001692" ixy="0.0" iyz="-4.9e-05" ixz="1e-06"/>
  </inertial>
  <visual>
    <origin xyz="0.025 0.0492 -0.036134" rpy="0 0 0"/>
    <geometry>
      <mesh filename="package://hip-rejoint_description/meshes/JX_servo_v80_1.stl" scale="0.001 0.001 0.001"/>
    </geometry>
    <material name="polystyrene"/>
  </visual>
  <collision>
    <origin xyz="0.025 0.0492 -0.036134" rpy="0 0 0"/>
    <geometry>
      <mesh filename="package://hip-rejoint_description/meshes/JX_servo_v80_1.stl" scale="0.001 0.001 0.001"/>
    </geometry>
  </collision>
</link>

<link name="JX_servo_v80_2">
  <inertial>
    <mass value="0.379197"/>
    <origin xyz="0.008506622299886635 -0.015338763626409006 0.03892953398108233" rpy="0 0 0"/>
    <inertia ixx="0.001903" iyy="0.001692" izz="0.001012" ixy="1e-06" iyz="4.9e-05" ixz="-0.0"/>
  </inertial>
  <visual>
    <origin xyz="0.033249 0.036576 0.11572" rpy="0 0 0"/>
    <geometry>
      <mesh filename="package://hip-rejoint_description/meshes/JX_servo_v80_2.stl" scale="0.001 0.001 0.001"/>
    </geometry>
    <material name="polystyrene"/>
  </visual>
  <collision>
    <origin xyz="0.033249 0.036576 0.11572" rpy="0 0 0"/>
    <geometry>
      <mesh filename="package://hip-rejoint_description/meshes/JX_servo_v80_2.stl" scale="0.001 0.001 0.001"/>
    </geometry>
  </collision>
</link>

<link name="91590A121_External_Retaining_Ring_v1_4">
  <inertial>
    <origin xyz="-1.8006429680639258e-15 -0.0002861975695817448 -0.0003176000000000342" rpy="0 0 0"/>
    <mass value="0.00024760918611349786"/>
    <inertia ixx="1E-06" iyy="1E-06" izz="1E-06" ixy="0.0" iyz="0.0" ixz="0.0"/>
  </inertial>
  <visual>
    <origin xyz="0.025 -0.0592 0.012023" rpy="0 0 0"/>
    <geometry>
      <mesh filename="package://hip-rejoint_description/meshes/91590A121_External_Retaining_Ring_v1_4.stl" scale="0.001 0.001 0.001"/>
    </geometry>
    <material name="steel_satin"/>
  </visual>
  <collision>
    <origin xyz="0.025 -0.0592 0.012023" rpy="0 0 0"/>
    <geometry>
      <mesh filename="package://hip-rejoint_description/meshes/91590A121_External_Retaining_Ring_v1_4.stl" scale="0.001 0.001 0.001"/>
    </geometry>
  </collision>
</link>

<link name="Component4_2">
  <inertial>
    <origin xyz="1.1796119636642288e-16 -2.0084628404859473e-13 -0.002744673147693012" rpy="0 0 0"/>
    <mass value="0.011955695388392617"/>
    <inertia ixx="1e-06" iyy="1e-06" izz="2e-06" ixy="0.0" iyz="0.0" ixz="0.0"/>
  </inertial>
  <visual>
    <origin xyz="0.025 -0.0592 0.012658" rpy="0 0 0"/>
    <geometry>
      <mesh filename="package://hip-rejoint_description/meshes/Component4_2.stl" scale="0.001 0.001 0.001"/>
    </geometry>
    <material name="aluminum_satin"/>
  </visual>
  <collision>
    <origin xyz="0.025 -0.0592 0.012658" rpy="0 0 0"/>
    <geometry>
      <mesh filename="package://hip-rejoint_description/meshes/Component4_2.stl" scale="0.001 0.001 0.001"/>
    </geometry>
  </collision>
</link>

<link name="Component32_2">
  <inertial>
    <origin xyz="0.00046213981045967883 -7.798356568361475e-05 -0.016749694753476874" rpy="0 0 0"/>
    <mass value="0.11550269835963742"/>
    <inertia ixx="4.9e-05" iyy="9.9e-05" izz="9.4e-05" ixy="-0.0" iyz="0.0" ixz="-0.0"/>
  </inertial>
  <visual>
    <origin xyz="0.025 -0.0592 0.01797" rpy="0 0 0"/>
    <geometry>
      <mesh filename="package://hip-rejoint_description/meshes/Component32_2.stl" scale="0.001 0.001 0.001"/>
    </geometry>
    <material name="aluminum_satin"/>
  </visual>
  <collision>
    <origin xyz="0.025 -0.0592 0.01797" rpy="0 0 0"/>
    <geometry>
      <mesh filename="package://hip-rejoint_description/meshes/Component32_2.stl" scale="0.001 0.001 0.001"/>
    </geometry>
  </collision>
</link>

<link name="Component39_2">
  <inertial>
    <origin xyz="-0.004453658050594431 1.0708659720082281e-07 0.0072565028143726645" rpy="0 0 0"/>
    <mass value="0.015364690334044086"/>
    <inertia ixx="2e-06" iyy="1e-06" izz="1e-06" ixy="-0.0" iyz="0.0" ixz="-0.0"/>
  </inertial>
  <visual>
    <origin xyz="0.05665 -0.059124 0.06012" rpy="0 0 0"/>
    <geometry>
      <mesh filename="package://hip-rejoint_description/meshes/Component39_2.stl" scale="0.001 0.001 0.001"/>
    </geometry>
    <material name="aluminum_satin"/>
  </visual>
  <collision>
    <origin xyz="0.05665 -0.059124 0.06012" rpy="0 0 0"/>
    <geometry>
      <mesh filename="package://hip-rejoint_description/meshes/Component39_2.stl" scale="0.001 0.001 0.001"/>
    </geometry>
  </collision>
</link>

<link name="JX_servo_v80_5">
  <inertial>
    <origin xyz="-0.03281072928697726 -0.00014307061349891348 -0.016670466018917536" rpy="0 0 0"/>
    <mass value="0.2114"/>
    <inertia ixx="0.001692" iyy="0.001903" izz="0.001012" ixy="-1e-06" iyz="-0.0" ixz="-4.9e-05"/>
  </inertial>
  <visual>
    <origin xyz="0.06935 -0.059124 0.06012" rpy="0 0 0"/>
    <geometry>
      <mesh filename="package://hip-rejoint_description/meshes/JX_servo_v80_5.stl" scale="0.001 0.001 0.001"/>
    </geometry>
    <material name="polystyrene"/>
  </visual>
  <collision>
    <origin xyz="0.06935 -0.059124 0.06012" rpy="0 0 0"/>
    <geometry>
      <mesh filename="package://hip-rejoint_description/meshes/JX_servo_v80_5.stl" scale="0.001 0.001 0.001"/>
    </geometry>
  </collision>
</link>

<link name="JX_servo_v80_7">
  <inertial>
    <mass value="0.379197"/>
    <origin xyz="-0.00850702229988633 -0.010061022200362549 0.03892953398108248" rpy="0 0 0"/>
    <inertia ixx="0.001903" iyy="0.001692" izz="0.001012" ixy="1e-06" iyz="-4.9e-05" ixz="0.0"/>
  </inertial>
  <visual>
    <origin xyz="0.016249 -0.071824 0.11572" rpy="0 0 0"/>
    <geometry>
      <mesh filename="package://hip-rejoint_description/meshes/JX_servo_v80_7.stl" scale="0.001 0.001 0.001"/>
    </geometry>
    <material name="polystyrene"/>
  </visual>
  <collision>
    <origin xyz="0.016249 -0.071824 0.11572" rpy="0 0 0"/>
    <geometry>
      <mesh filename="package://hip-rejoint_description/meshes/JX_servo_v80_7.stl" scale="0.001 0.001 0.001"/>
    </geometry>
  </collision>
</link>

<link name="Component9__1__2">
  <inertial>
    <origin xyz="0.03333629681388656 -0.008439001260075997 -0.00027616991746280684" rpy="0 0 0"/>
    <mass value="0.13759034791983457"/>
    <inertia ixx="1e-05" iyy="5.4e-05" izz="6.2e-05" ixy="-0.0" iyz="0.0" ixz="0.0"/>
  </inertial>
  <visual>
    <origin xyz="0.08185 -0.067474 0.11572" rpy="0 0 0"/>
    <geometry>
      <mesh filename="package://hip-rejoint_description/meshes/Component9__1__2.stl" scale="0.001 0.001 0.001"/>
    </geometry>
    <material name="steel_satin"/>
  </visual>
  <collision>
    <origin xyz="0.08185 -0.067474 0.11572" rpy="0 0 0"/>
    <geometry>
      <mesh filename="package://hip-rejoint_description/meshes/Component9__1__2.stl" scale="0.001 0.001 0.001"/>
    </geometry>
  </collision>
</link>

<link name="91590A121_External_Retaining_Ring_v1_5">
  <inertial>
    <origin xyz="-1.8006429680639258e-15 -0.000286197569581606 0.00031759999999995026" rpy="0 0 0"/>
    <mass value="0.00024760918611349786"/>
    <inertia ixx="1E-06" iyy="1E-06" izz="1E-06" ixy="0.0" iyz="0.0" ixz="-0.0"/>
  </inertial>
  <visual>
    <origin xyz="0.025 -0.0592 0.000898" rpy="0 0 0"/>
    <geometry>
      <mesh filename="package://hip-rejoint_description/meshes/91590A121_External_Retaining_Ring_v1_5.stl" scale="0.001 0.001 0.001"/>
    </geometry>
    <material name="steel_satin"/>
  </visual>
  <collision>
    <origin xyz="0.025 -0.0592 0.000898" rpy="0 0 0"/>
    <geometry>
      <mesh filename="package://hip-rejoint_description/meshes/91590A121_External_Retaining_Ring_v1_5.stl" scale="0.001 0.001 0.001"/>
    </geometry>
  </collision>
</link>

<link name="91590A121_External_Retaining_Ring_v1_6">
  <inertial>
    <origin xyz="1.9463597400459776e-15 0.00028619756958262604 0.0003180000000000058" rpy="0 0 0"/>
    <mass value="0.00024760918611349786"/>
    <inertia ixx="1E-06" iyy="1E-06" izz="1E-06" ixy="0.0" iyz="0.0" ixz="0.0"/>
  </inertial>
  <visual>
    <origin xyz="0.025 -0.0592 -0.020717" rpy="0 0 0"/>
    <geometry>
      <mesh filename="package://hip-rejoint_description/meshes/91590A121_External_Retaining_Ring_v1_6.stl" scale="0.001 0.001 0.001"/>
    </geometry>
    <material name="steel_satin"/>
  </visual>
  <collision>
    <origin xyz="0.025 -0.0592 -0.020717" rpy="0 0 0"/>
    <geometry>
      <mesh filename="package://hip-rejoint_description/meshes/91590A121_External_Retaining_Ring_v1_6.stl" scale="0.001 0.001 0.001"/>
    </geometry>
  </collision>
</link>

<link name="2025K9_303_Stainless_Steel_Rotary_Shaft_with_Retaining_Ring_Grooves_v1_2">
  <inertial>
    <origin xyz="-3.676572934985245e-14 6.113304307220346e-13 -0.023450621315963708" rpy="0 0 0"/>
    <mass value="0.07269824555688346"/>
    <inertia ixx="3.6e-05" iyy="3.6e-05" izz="1e-06" ixy="0.0" iyz="0.0" ixz="0.0"/>
  </inertial>
  <visual>
    <origin xyz="0.025 -0.0592 -0.021353" rpy="0 0 0"/>
    <geometry>
      <mesh filename="package://hip-rejoint_description/meshes/2025K9_303_Stainless_Steel_Rotary_Shaft_with_Retaining_Ring_Grooves_v1_2.stl" scale="0.001 0.001 0.001"/>
    </geometry>
    <material name="steel_satin"/>
  </visual>
  <collision>
    <origin xyz="0.025 -0.0592 -0.021353" rpy="0 0 0"/>
    <geometry>
      <mesh filename="package://hip-rejoint_description/meshes/2025K9_303_Stainless_Steel_Rotary_Shaft_with_Retaining_Ring_Grooves_v1_2.stl" scale="0.001 0.001 0.001"/>
    </geometry>
  </collision>
</link>

<link name="Component6_2">
  <inertial>
    <origin xyz="2.6020852139652106e-16 6.415796262213003e-05 -0.0012004075065928446" rpy="0 0 0"/>
    <mass value="0.004179712167666874"/>
    <inertia ixx="1E-06" iyy="1E-06" izz="1E-06" ixy="-0.0" iyz="0.0" ixz="-0.0"/>
  </inertial>
  <visual>
    <origin xyz="0.025 -0.0592 -0.036034" rpy="0 0 0"/>
    <geometry>
      <mesh filename="package://hip-rejoint_description/meshes/Component6_2.stl" scale="0.001 0.001 0.001"/>
    </geometry>
    <material name="aluminum_satin"/>
  </visual>
  <collision>
    <origin xyz="0.025 -0.0592 -0.036034" rpy="0 0 0"/>
    <geometry>
      <mesh filename="package://hip-rejoint_description/meshes/Component6_2.stl" scale="0.001 0.001 0.001"/>
    </geometry>
  </collision>
</link>

<link name="JX_servo_v80_4">
  <inertial>
    <origin xyz="0.00014317770011336786 -0.01667036601891722 0.039010829286977286" rpy="0 0 0"/>
    <mass value="0.2114"/>
    <inertia ixx="0.001903" iyy="0.001012" izz="0.001692" ixy="0.0" iyz="4.9e-05" ixz="-1e-06"/>
  </inertial>
  <visual>
    <origin xyz="0.025 -0.0592 -0.036134" rpy="0 0 0"/>
    <geometry>
      <mesh filename="package://hip-rejoint_description/meshes/JX_servo_v80_4.stl" scale="0.001 0.001 0.001"/>
    </geometry>
    <material name="polystyrene"/>
  </visual>
  <collision>
    <origin xyz="0.025 -0.0592 -0.036134" rpy="0 0 0"/>
    <geometry>
      <mesh filename="package://hip-rejoint_description/meshes/JX_servo_v80_4.stl" scale="0.001 0.001 0.001"/>
    </geometry>
  </collision>
</link>

<link name="Component5_Mirror__1">
  <inertial>
    <origin xyz="0.00849980000000125 -0.015790650242165985 -0.03724237703561162" rpy="0 0 0"/>
    <mass value="0.09281870151638756"/>
    <inertia ixx="0.000217" iyy="0.000101" izz="0.000141" ixy="0.0" iyz="1e-06" ixz="0.0"/>
  </inertial>
  <visual>
    <origin xyz="0.033399 -0.082599 0.27572" rpy="0 0 0"/>
    <geometry>
      <mesh filename="package://hip-rejoint_description/meshes/Component5_Mirror__1.stl" scale="0.001 0.001 0.001"/>
    </geometry>
    <material name="abs_white"/>
  </visual>
  <collision>
    <origin xyz="0.033399 -0.082599 0.27572" rpy="0 0 0"/>
    <geometry>
      <mesh filename="package://hip-rejoint_description/meshes/Component5_Mirror__1.stl" scale="0.001 0.001 0.001"/>
    </geometry>
  </collision>
</link>

<link name="JX_servo_v46_Mirror__2">
  <inertial>
    <origin xyz="0.0002863268626021806 -0.03684144889674791 0.015402123693879166" rpy="0 0 0"/>
    <mass value="0.2114"/>
    <inertia ixx="0.000552" iyy="0.00038" izz="0.000359" ixy="-6e-06" iyz="4.4e-05" ixz="-0.0"/>
  </inertial>
  <visual>
    <origin xyz="0.024899 -0.104999 0.35932" rpy="0 0 0"/>
    <geometry>
      <mesh filename="package://hip-rejoint_description/meshes/JX_servo_v46_Mirror__2.stl" scale="0.001 0.001 0.001"/>
    </geometry>
    <material name="polystyrene"/>
  </visual>
  <collision>
    <origin xyz="0.024899 -0.104999 0.35932" rpy="0 0 0"/>
    <geometry>
      <mesh filename="package://hip-rejoint_description/meshes/JX_servo_v46_Mirror__2.stl" scale="0.001 0.001 0.001"/>
    </geometry>
  </collision>
</link>

<link name="L_Mirror__1">
  <inertial>
    <origin xyz="-0.042580019575537656 -0.014976084097356332 -0.010919051242128275" rpy="0 0 0"/>
    <mass value="0.045500552100246464"/>
    <inertia ixx="4.6e-05" iyy="6.7e-05" izz="4.1e-05" ixy="-0.0" iyz="-0.0" ixz="-1.8e-05"/>
  </inertial>
  <visual>
    <origin xyz="0.016399 -0.083299 0.30372" rpy="0 0 0"/>
    <geometry>
      <mesh filename="package://hip-rejoint_description/meshes/L_Mirror__1.stl" scale="0.001 0.001 0.001"/>
    </geometry>
    <material name="abs_white"/>
  </visual>
  <collision>
    <origin xyz="0.016399 -0.083299 0.30372" rpy="0 0 0"/>
    <geometry>
      <mesh filename="package://hip-rejoint_description/meshes/L_Mirror__1.stl" scale="0.001 0.001 0.001"/>
    </geometry>
  </collision>
</link>

<link name="JX_servo_v46_Mirror__3">
  <inertial>
    <origin xyz="-0.011241755983359566 -0.008786419775988846 -0.04019787630612176" rpy="0 0 0"/>
    <mass value="0.2114"/>
    <inertia ixx="0.00038" iyy="0.000552" izz="0.000359" ixy="6e-06" iyz="0.0" ixz="4.4e-05"/>
  </inertial>
  <visual>
    <origin xyz="0.083399 -0.076799 0.30382" rpy="0 0 0"/>
    <geometry>
      <mesh filename="package://hip-rejoint_description/meshes/JX_servo_v46_Mirror__3.stl" scale="0.001 0.001 0.001"/>
    </geometry>
    <material name="polystyrene"/>
  </visual>
  <collision>
    <origin xyz="0.083399 -0.076799 0.30382" rpy="0 0 0"/>
    <geometry>
      <mesh filename="package://hip-rejoint_description/meshes/JX_servo_v46_Mirror__3.stl" scale="0.001 0.001 0.001"/>
    </geometry>
  </collision>
</link>

<link name="left_foot">
  <inertial>
    <origin xyz="0.05767572802039587 0.00822898838496594 -0.03620809725608026" rpy="0 0 0"/>
    <mass value="0.18549302395679304"/>
    <inertia ixx="0.000167" iyy="0.000496" izz="0.000598" ixy="-8e-06" iyz="8e-06" ixz="2.3e-05"/>
  </inertial>
  <visual>
    <origin xyz="0.057799 -0.068299 0.35942" rpy="0 0 0"/>
    <geometry>
      <mesh filename="package://hip-rejoint_description/meshes/left_foot_1.stl" scale="0.001 0.001 0.001"/>
    </geometry>
    <material name="abs_white"/>
  </visual>
  <collision>
    <origin xyz="0.057799 -0.068299 0.35942" rpy="0 0 0"/>
    <geometry>
      <mesh filename="package://hip-rejoint_description/meshes/left_foot_1.stl" scale="0.001 0.001 0.001"/>
    </geometry>
  </collision>
</link>

<link name="Component4__2__1">
  <inertial>
    <origin xyz="0.0031599193508261396 -0.03836265805370774 -0.08477215129035257" rpy="0 0 0"/>
    <mass value="0.15906974524164488"/>
    <inertia ixx="0.000652" iyy="0.000427" izz="0.000271" ixy="0.0" iyz="1e-06" ixz="9e-06"/>
  </inertial>
  <visual>
    <origin xyz="0.024899 -0.104299 0.06012" rpy="0 0 0"/>
    <geometry>
      <mesh filename="package://hip-rejoint_description/meshes/Component4__2__1.stl" scale="0.001 0.001 0.001"/>
    </geometry>
    <material name="abs_white"/>
  </visual>
  <collision>
    <origin xyz="0.024899 -0.104299 0.06012" rpy="0 0 0"/>
    <geometry>
      <mesh filename="package://hip-rejoint_description/meshes/Component4__2__1.stl" scale="0.001 0.001 0.001"/>
    </geometry>
  </collision>
</link>

<link name="JX_servo_v46_Mirror__1">
  <inertial>
    <origin xyz="-0.0002867268625995935 -0.03684144889674752 -0.015402323693878978" rpy="0 0 0"/>
    <mass value="0.2114"/>
    <inertia ixx="0.000552" iyy="0.00038" izz="0.000359" ixy="6e-06" iyz="-4.4e-05" ixz="-0.0"/>
  </inertial>
  <visual>
    <origin xyz="0.024899 -0.104299 0.22012" rpy="0 0 0"/>
    <geometry>
      <mesh filename="package://hip-rejoint_description/meshes/JX_servo_v46_Mirror__1.stl" scale="0.001 0.001 0.001"/>
    </geometry>
    <material name="polystyrene"/>
  </visual>
  <collision>
    <origin xyz="0.024899 -0.104299 0.22012" rpy="0 0 0"/>
    <geometry>
      <mesh filename="package://hip-rejoint_description/meshes/JX_servo_v46_Mirror__1.stl" scale="0.001 0.001 0.001"/>
    </geometry>
  </collision>
</link>

<link name="Component4_Mirror___1__1">
  <inertial>
    <origin xyz="0.0031599193508256886 0.038362872226935844 -0.0847721512903529" rpy="0 0 0"/>
    <mass value="0.15906974524164494"/>
    <inertia ixx="0.000652" iyy="0.000427" izz="0.000271" ixy="-0.0" iyz="-1e-06" ixz="9e-06"/>
  </inertial>
  <visual>
    <origin xyz="0.024599 0.094451 0.06012" rpy="0 0 0"/>
    <geometry>
      <mesh filename="package://hip-rejoint_description/meshes/Component4_Mirror___1__1.stl" scale="0.001 0.001 0.001"/>
    </geometry>
    <material name="abs_white"/>
  </visual>
  <collision>
    <origin xyz="0.024599 0.094451 0.06012" rpy="0 0 0"/>
    <geometry>
      <mesh filename="package://hip-rejoint_description/meshes/Component4_Mirror___1__1.stl" scale="0.001 0.001 0.001"/>
    </geometry>
  </collision>
</link>

<link name="JX_servo_v46_Mirror__9">
  <inertial>
    <origin xyz="0.00028632686260030016 0.03684166306997537 -0.015402323693878894" rpy="0 0 0"/>
    <mass value="0.2114"/>
    <inertia ixx="0.000552" iyy="0.00038" izz="0.000359" ixy="6e-06" iyz="4.4e-05" ixz="0.0"/>
  </inertial>
  <visual>
    <origin xyz="0.024599 0.094451 0.22012" rpy="0 0 0"/>
    <geometry>
      <mesh filename="package://hip-rejoint_description/meshes/JX_servo_v46_Mirror__9.stl" scale="0.001 0.001 0.001"/>
    </geometry>
    <material name="polystyrene"/>
  </visual>
  <collision>
    <origin xyz="0.024599 0.094451 0.22012" rpy="0 0 0"/>
    <geometry>
      <mesh filename="package://hip-rejoint_description/meshes/JX_servo_v46_Mirror__9.stl" scale="0.001 0.001 0.001"/>
    </geometry>
  </collision>
</link>

<link name="Component5_Mirror__Mirror__1">
  <inertial>
    <origin xyz="0.00849979999999968 0.01579086441539357 -0.03724237703561162" rpy="0 0 0"/>
    <mass value="0.09281870151638758"/>
    <inertia ixx="0.000217" iyy="0.000101" izz="0.000141" ixy="0.0" iyz="-1e-06" ixz="0.0"/>
  </inertial>
  <visual>
    <origin xyz="0.033099 0.072751 0.27572" rpy="0 0 0"/>
    <geometry>
      <mesh filename="package://hip-rejoint_description/meshes/Component5_Mirror__Mirror__1.stl" scale="0.001 0.001 0.001"/>
    </geometry>
    <material name="abs_white"/>
  </visual>
  <collision>
    <origin xyz="0.033099 0.072751 0.27572" rpy="0 0 0"/>
    <geometry>
      <mesh filename="package://hip-rejoint_description/meshes/Component5_Mirror__Mirror__1.stl" scale="0.001 0.001 0.001"/>
    </geometry>
  </collision>
</link>

<link name="JX_servo_v46_Mirror__7">
  <inertial>
    <origin xyz="-0.0002867268626019111 0.03684166306997542 0.015402123693879555" rpy="0 0 0"/>
    <mass value="0.2114"/>
    <inertia ixx="0.000552" iyy="0.00038" izz="0.000359" ixy="-6e-06" iyz="-4.4e-05" ixz="0.0"/>
  </inertial>
  <visual>
    <origin xyz="0.024599 0.095151 0.35932" rpy="0 0 0"/>
    <geometry>
      <mesh filename="package://hip-rejoint_description/meshes/JX_servo_v46_Mirror__7.stl" scale="0.001 0.001 0.001"/>
    </geometry>
    <material name="polystyrene"/>
  </visual>
  <collision>
    <origin xyz="0.024599 0.095151 0.35932" rpy="0 0 0"/>
    <geometry>
      <mesh filename="package://hip-rejoint_description/meshes/JX_servo_v46_Mirror__7.stl" scale="0.001 0.001 0.001"/>
    </geometry>
  </collision>
</link>

<link name="L_Mirror__3">
  <inertial>
    <origin xyz="-0.042580019575540445 0.015023915902644375 -0.010819051242127342" rpy="0 0 0"/>
    <mass value="0.045500552100246464"/>
    <inertia ixx="4.6e-05" iyy="6.7e-05" izz="4.1e-05" ixy="-0.0" iyz="-0.0" ixz="-1.8e-05"/>
  </inertial>
  <visual>
    <origin xyz="0.016099 0.073451 0.30372" rpy="0 0 0"/>
    <geometry>
      <mesh filename="package://hip-rejoint_description/meshes/L_Mirror__3.stl" scale="0.001 0.001 0.001"/>
    </geometry>
    <material name="abs_white"/>
  </visual>
  <collision>
    <origin xyz="0.016099 0.073451 0.30372" rpy="0 0 0"/>
    <geometry>
      <mesh filename="package://hip-rejoint_description/meshes/L_Mirror__3.stl" scale="0.001 0.001 0.001"/>
    </geometry>
  </collision>
</link>

<link name="JX_servo_v46_Mirror__8">
  <inertial>
    <origin xyz="-0.011241755983362356 -0.008786419775988014 0.03500212369387967" rpy="0 0 0"/>
    <mass value="0.2114"/>
    <inertia ixx="0.00038" iyy="0.000552" izz="0.000359" ixy="6e-06" iyz="0.0" ixz="4.4e-05"/>
  </inertial>
  <visual>
    <origin xyz="0.083099 0.049951 0.37892" rpy="0 0 0"/>
    <geometry>
      <mesh filename="package://hip-rejoint_description/meshes/JX_servo_v46_Mirror__8.stl" scale="0.001 0.001 0.001"/>
    </geometry>
    <material name="polystyrene"/>
  </visual>
  <collision>
    <origin xyz="0.083099 0.049951 0.37892" rpy="0 0 0"/>
    <geometry>
      <mesh filename="package://hip-rejoint_description/meshes/JX_servo_v46_Mirror__8.stl" scale="0.001 0.001 0.001"/>
    </geometry>
  </collision>
</link>

<link name="right_foot">
  <inertial>
    <origin xyz="0.05767574370347767 -0.008228774425991459 -0.036208099196046395" rpy="0 0 0"/>
    <mass value="0.1854930080519705"/>
    <inertia ixx="0.000167" iyy="0.000496" izz="0.000598" ixy="8e-06" iyz="-8e-06" ixz="2.3e-05"/>
  </inertial>
  <visual>
    <origin xyz="0.057499 0.058451 0.35932" rpy="0 0 0"/>
    <geometry>
      <mesh filename="package://hip-rejoint_description/meshes/right_foot_1.stl" scale="0.001 0.001 0.001"/>
    </geometry>
    <material name="abs_white"/>
  </visual>
  <collision>
    <origin xyz="0.057499 0.058451 0.35932" rpy="0 0 0"/>
    <geometry>
      <mesh filename="package://hip-rejoint_description/meshes/right_foot_1.stl" scale="0.001 0.001 0.001"/>
    </geometry>
  </collision>
</link>

<link name="Component65_1">
  <inertial>
    <origin xyz="-0.057027622259124396 -0.005184392153188431 -0.031750299999999634" rpy="0 0 0"/>
    <mass value="0.550045164280725"/>
    <inertia ixx="0.002078" iyy="0.000783" izz="0.002491" ixy="-0.0" iyz="0.0" ixz="0.0"/>
  </inertial>
  <visual>
    <origin xyz="0.04015 -0.0102 -0.103234" rpy="0 0 0"/>
    <geometry>
      <mesh filename="package://hip-rejoint_description/meshes/Component65_1.stl" scale="0.001 0.001 0.001"/>
    </geometry>
    <material name="abs_white"/>
  </visual>
  <collision>
    <origin xyz="0.04015 -0.0102 -0.103234" rpy="0 0 0"/>
    <geometry>
      <mesh filename="package://hip-rejoint_description/meshes/Component65_1.stl" scale="0.001 0.001 0.001"/>
    </geometry>
  </collision>
</link>

<link name="Component66_1">
  <inertial>
    <origin xyz="0.023575000000000013 1.7780915628762273e-16 -0.022700299999999646" rpy="0 0 0"/>
    <mass value="0.3199209891539211"/>
    <inertia ixx="0.000447" iyy="0.000104" izz="0.000517" ixy="-0.0" iyz="0.0" ixz="0.0"/>
  </inertial>
  <visual>
    <origin xyz="0.1543 -0.005 -0.103234" rpy="0 0 0"/>
    <geometry>
      <mesh filename="package://hip-rejoint_description/meshes/Component66_1.stl" scale="0.001 0.001 0.001"/>
    </geometry>
    <material name="brass_polished"/>
  </visual>
  <collision>
    <origin xyz="0.1543 -0.005 -0.103234" rpy="0 0 0"/>
    <geometry>
      <mesh filename="package://hip-rejoint_description/meshes/Component66_1.stl" scale="0.001 0.001 0.001"/>
    </geometry>
  </collision>
</link>

<link name="JX_servo_v46_Mirror__10">
  <inertial>
    <origin xyz="-0.00028652686259981325 -0.036841555983361404 -0.015402523693878463" rpy="0 0 0"/>
    <mass value="0.2114"/>
    <inertia ixx="0.000552" iyy="0.00038" izz="0.000359" ixy="6e-06" iyz="-4.4e-05" ixz="-0.0"/>
  </inertial>
  <visual>
    <origin xyz="0.04 0.0966 -0.071484" rpy="0 0 0"/>
    <geometry>
      <mesh filename="package://hip-rejoint_description/meshes/JX_servo_v46_Mirror__10.stl" scale="0.001 0.001 0.001"/>
    </geometry>
    <material name="polystyrene"/>
  </visual>
  <collision>
    <origin xyz="0.04 0.0966 -0.071484" rpy="0 0 0"/>
    <geometry>
      <mesh filename="package://hip-rejoint_description/meshes/JX_servo_v46_Mirror__10.stl" scale="0.001 0.001 0.001"/>
    </geometry>
  </collision>
</link>

<link name="JX_servo_v46_Mirror__11">
  <inertial>
    <origin xyz="0.008213473137395816 0.015141555983359672 -0.04019807630612032" rpy="0 0 0"/>
    <mass value="0.2114"/>
    <inertia ixx="0.000552" iyy="0.00038" izz="0.000359" ixy="-6e-06" iyz="-4.4e-05" ixz="0.0"/>
  </inertial>
  <visual>
    <origin xyz="0.0485 0.1542 -0.015784" rpy="0 0 0"/>
    <geometry>
      <mesh filename="package://hip-rejoint_description/meshes/JX_servo_v46_Mirror__11.stl" scale="0.001 0.001 0.001"/>
    </geometry>
    <material name="polystyrene"/>
  </visual>
  <collision>
    <origin xyz="0.0485 0.1542 -0.015784" rpy="0 0 0"/>
    <geometry>
      <mesh filename="package://hip-rejoint_description/meshes/JX_servo_v46_Mirror__11.stl" scale="0.001 0.001 0.001"/>
    </geometry>
  </collision>
</link>

<link name="JX_servo_v46_Mirror__12">
  <inertial>
    <origin xyz="0.00028652686259972304 0.03684155598336175 -0.015402523693878518" rpy="0 0 0"/>
    <mass value="0.2114"/>
    <inertia ixx="0.000552" iyy="0.00038" izz="0.000359" ixy="6e-06" iyz="4.4e-05" ixz="0.0"/>
  </inertial>
  <visual>
    <origin xyz="0.04 -0.1066 -0.071484" rpy="0 0 0"/>
    <geometry>
      <mesh filename="package://hip-rejoint_description/meshes/JX_servo_v46_Mirror__12.stl" scale="0.001 0.001 0.001"/>
    </geometry>
    <material name="polystyrene"/>
  </visual>
  <collision>
    <origin xyz="0.04 -0.1066 -0.071484" rpy="0 0 0"/>
    <geometry>
      <mesh filename="package://hip-rejoint_description/meshes/JX_servo_v46_Mirror__12.stl" scale="0.001 0.001 0.001"/>
    </geometry>
  </collision>
</link>

<link name="JX_servo_v46_Mirror__13">
  <inertial>
    <origin xyz="0.008786526862586554 -0.015141555983359062 -0.04019807630612043" rpy="0 0 0"/>
    <mass value="0.2114"/>
    <inertia ixx="0.000552" iyy="0.00038" izz="0.000359" ixy="-6e-06" iyz="4.4e-05" ixz="-0.0"/>
  </inertial>
  <visual>
    <origin xyz="0.0485 -0.1642 -0.015784" rpy="0 0 0"/>
    <geometry>
      <mesh filename="package://hip-rejoint_description/meshes/JX_servo_v46_Mirror__13.stl" scale="0.001 0.001 0.001"/>
    </geometry>
    <material name="polystyrene"/>
  </visual>
  <collision>
    <origin xyz="0.0485 -0.1642 -0.015784" rpy="0 0 0"/>
    <geometry>
      <mesh filename="package://hip-rejoint_description/meshes/JX_servo_v46_Mirror__13.stl" scale="0.001 0.001 0.001"/>
    </geometry>
  </collision>
</link>

<link name="Component11_Mirror__2">
  <inertial>
    <origin xyz="1.174060848541103e-14 -0.0015000000000024716 -2.9999999917595943e-07" rpy="0 0 0"/>
    <mass value="0.003775795544427548"/>
    <inertia ixx="1E-06" iyy="1e-06" izz="1E-06" ixy="-0.0" iyz="-0.0" ixz="-0.0"/>
  </inertial>
  <visual>
    <origin xyz="0.04 0.1759 0.039816" rpy="0 0 0"/>
    <geometry>
      <mesh filename="package://hip-rejoint_description/meshes/Component11_Mirror__2.stl" scale="0.001 0.001 0.001"/>
    </geometry>
    <material name="plastic_matte_black"/>
  </visual>
  <collision>
    <origin xyz="0.04 0.1759 0.039816" rpy="0 0 0"/>
    <geometry>
      <mesh filename="package://hip-rejoint_description/meshes/Component11_Mirror__2.stl" scale="0.001 0.001 0.001"/>
    </geometry>
  </collision>
</link>

<link name="Component11_Mirror__3">
  <inertial>
    <origin xyz="-6.654399253847032e-15 0.0015000000000029712 -2.999999990996316e-07" rpy="0 0 0"/>
    <mass value="0.003775795544427548"/>
    <inertia ixx="1E-06" iyy="1e-06" izz="1E-06" ixy="-0.0" iyz="-0.0" ixz="0.0"/>
  </inertial>
  <visual>
    <origin xyz="0.04 -0.1859 0.039816" rpy="0 0 0"/>
    <geometry>
      <mesh filename="package://hip-rejoint_description/meshes/Component11_Mirror__3.stl" scale="0.001 0.001 0.001"/>
    </geometry>
    <material name="plastic_matte_black"/>
  </visual>
  <collision>
    <origin xyz="0.04 -0.1859 0.039816" rpy="0 0 0"/>
    <geometry>
      <mesh filename="package://hip-rejoint_description/meshes/Component11_Mirror__3.stl" scale="0.001 0.001 0.001"/>
    </geometry>
  </collision>
</link>

<link name="trunk">
  <inertial>
    <origin xyz="-0.024999999999999932 2.511766836188478e-13 -4.075620637523491e-05" rpy="0 0 0"/>
    <mass value="0.19337373769234342"/>
    <inertia ixx="0.000494" iyy="4.6e-05" izz="0.000538" ixy="0.0" iyz="0.0" ixz="-0.0"/>
  </inertial>
  <visual>
    <origin xyz="0.0 -0.005 -0.005" rpy="0 0 0"/>
    <geometry>
      <mesh filename="package://hip-rejoint_description/meshes/trunk_1.stl" scale="0.001 0.001 0.001"/>
    </geometry>
    <material name="acrylic_red"/>
  </visual>
  <collision>
    <origin xyz="0.0 -0.005 -0.005" rpy="0 0 0"/>
    <geometry>
      <mesh filename="package://hip-rejoint_description/meshes/trunk_1.stl" scale="0.001 0.001 0.001"/>
    </geometry>
  </collision>
</link>

<link name="custom_servo_support__lower_neck__v2_1">
  <inertial>
    <origin xyz="-0.0001873462042440155 1.1439633962329054e-14 0.001965903992148993" rpy="0 0 0"/>
    <mass value="0.0030444171650099846"/>
    <inertia ixx="1E-06" iyy="1E-06" izz="1e-06" ixy="-0.0" iyz="-0.0" ixz="0.0"/>
  </inertial>
  <visual>
    <origin xyz="0.09715 -0.005 -0.103234" rpy="0 0 0"/>
    <geometry>
      <mesh filename="package://hip-rejoint_description/meshes/custom_servo_support__lower_neck__v2_1.stl" scale="0.001 0.001 0.001"/>
    </geometry>
    <material name="plastic_glossy_black"/>
  </visual>
  <collision>
    <origin xyz="0.09715 -0.005 -0.103234" rpy="0 0 0"/>
    <geometry>
      <mesh filename="package://hip-rejoint_description/meshes/custom_servo_support__lower_neck__v2_1.stl" scale="0.001 0.001 0.001"/>
    </geometry>
  </collision>
</link>

<link name="gobilda-servo_1">
  <inertial>
    <origin xyz="-0.021069107694159497 -1.343324230497489e-09 0.019801967478668275" rpy="0 0 0"/>
    <mass value="0.06058731126055281"/>
    <inertia ixx="7e-06" iyy="1.4e-05" izz="1e-05" ixy="0.0" iyz="0.0" ixz="-0.0"/>
  </inertial>
  <visual>
    <origin xyz="0.077 -0.005 -0.106214" rpy="0 0 0"/>
    <geometry>
      <mesh filename="package://hip-rejoint_description/meshes/gobilda-servo_1.stl" scale="0.001 0.001 0.001"/>
    </geometry>
    <material name="plastic_glossy_grey"/>
  </visual>
  <collision>
    <origin xyz="0.077 -0.005 -0.106214" rpy="0 0 0"/>
    <geometry>
      <mesh filename="package://hip-rejoint_description/meshes/gobilda-servo_1.stl" scale="0.001 0.001 0.001"/>
    </geometry>
  </collision>
</link>

<link name="25t-servo-hub_1">
  <inertial>
    <origin xyz="-4.778934504928722e-07 1.6215494579117223e-07 -0.0003424918529943699" rpy="0 0 0"/>
    <mass value="0.005584850212079893"/>
    <inertia ixx="1E-06" iyy="1E-06" izz="1E-06" ixy="-0.0" iyz="0.0" ixz="-0.0"/>
  </inertial>
  <visual>
    <origin xyz="0.0883 -0.005 -0.147134" rpy="0 0 0"/>
    <geometry>
      <mesh filename="package://hip-rejoint_description/meshes/25t-servo-hub_1.stl" scale="0.001 0.001 0.001"/>
    </geometry>
    <material name="aluminum_satin"/>
  </visual>
  <collision>
    <origin xyz="0.0883 -0.005 -0.147134" rpy="0 0 0"/>
    <geometry>
      <mesh filename="package://hip-rejoint_description/meshes/25t-servo-hub_1.stl" scale="0.001 0.001 0.001"/>
    </geometry>
  </collision>
</link>

<link name="neck_1">
  <inertial>
    <origin xyz="2.761679773755077e-15 -0.001757162936255714 0.016322497824422827" rpy="0 0 0"/>
    <mass value="0.015465374363363156"/>
    <inertia ixx="1.1e-05" iyy="5e-06" izz="9e-06" ixy="-0.0" iyz="0.0" ixz="-0.0"/>
  </inertial>
  <visual>
    <origin xyz="0.0883 -0.005 -0.149928" rpy="0 0 0"/>
    <geometry>
      <mesh filename="package://hip-rejoint_description/meshes/neck_1.stl" scale="0.001 0.001 0.001"/>
    </geometry>
    <material name="abs_white"/>
  </visual>
  <collision>
    <origin xyz="0.0883 -0.005 -0.149928" rpy="0 0 0"/>
    <geometry>
      <mesh filename="package://hip-rejoint_description/meshes/neck_1.stl" scale="0.001 0.001 0.001"/>
    </geometry>
  </collision>
</link>

<link name="25t-servo-hub_2">
  <inertial>
    <origin xyz="-4.778934504928722e-07 -0.0031361918529911464 7.907080462610239e-09" rpy="0 0 0"/>
    <mass value="0.005584850212079893"/>
    <inertia ixx="1E-06" iyy="1E-06" izz="1E-06" ixy="-0.0" iyz="-0.0" ixz="0.0"/>
  </inertial>
  <visual>
    <origin xyz="0.0883 -0.031187 -0.183745" rpy="0 0 0"/>
    <geometry>
      <mesh filename="package://hip-rejoint_description/meshes/25t-servo-hub_2.stl" scale="0.001 0.001 0.001"/>
    </geometry>
    <material name="aluminum_satin"/>
  </visual>
  <collision>
    <origin xyz="0.0883 -0.031187 -0.183745" rpy="0 0 0"/>
    <geometry>
      <mesh filename="package://hip-rejoint_description/meshes/25t-servo-hub_2.stl" scale="0.001 0.001 0.001"/>
    </geometry>
  </collision>
</link>

<link name="gobilda-servo_2">
  <inertial>
    <origin xyz="0.009769107694159326 -0.021117732521328484 1.6871870181511817e-07" rpy="0 0 0"/>
    <mass value="0.06058731126055281"/>
    <inertia ixx="7e-06" iyy="1e-05" izz="1.4e-05" ixy="0.0" iyz="0.0" ixz="-0.0"/>
  </inertial>
  <visual>
    <origin xyz="0.0883 -0.028393 -0.183745" rpy="0 0 0"/>
    <geometry>
      <mesh filename="package://hip-rejoint_description/meshes/gobilda-servo_2.stl" scale="0.001 0.001 0.001"/>
    </geometry>
    <material name="plastic_glossy_grey"/>
  </visual>
  <collision>
    <origin xyz="0.0883 -0.028393 -0.183745" rpy="0 0 0"/>
    <geometry>
      <mesh filename="package://hip-rejoint_description/meshes/gobilda-servo_2.stl" scale="0.001 0.001 0.001"/>
    </geometry>
  </collision>
</link>

<link name="head_1">
  <inertial>
    <origin xyz="0.019537949594635937 0.009180173124962852 0.00755420273403995" rpy="0 0 0"/>
    <mass value="0.007653734054253099"/>
    <inertia ixx="2e-06" iyy="3e-06" izz="3e-06" ixy="0.0" iyz="-0.0" ixz="0.0"/>
  </inertial>
  <visual>
    <origin xyz="0.0996 0.012527 -0.183745" rpy="0 0 0"/>
    <geometry>
      <mesh filename="package://hip-rejoint_description/meshes/head_1.stl" scale="0.001 0.001 0.001"/>
    </geometry>
    <material name="abs_white"/>
  </visual>
  <collision>
    <origin xyz="0.0996 0.012527 -0.183745" rpy="0 0 0"/>
    <geometry>
      <mesh filename="package://hip-rejoint_description/meshes/head_1.stl" scale="0.001 0.001 0.001"/>
    </geometry>
  </collision>
</link>

<link name="camera_1">
  <inertial>
    <origin xyz="0.014184397326867326 -1.0758781820467342e-05 0.01921531813692287" rpy="0 0 0"/>
    <mass value="0.094257141411043"/>
    <inertia ixx="5.2e-05" iyy="4.3e-05" izz="6.9e-05" ixy="0.0" iyz="-0.0" ixz="-1.1e-05"/>
  </inertial>
  <visual>
    <origin xyz="0.0863 -0.005493 -0.204745" rpy="0 0 0"/>
    <geometry>
      <mesh filename="package://hip-rejoint_description/meshes/camera_1.stl" scale="0.001 0.001 0.001"/>
    </geometry>
    <material name="plastic_glossy_black"/>
  </visual>
  <collision>
    <origin xyz="0.0863 -0.005493 -0.204745" rpy="0 0 0"/>
    <geometry>
      <mesh filename="package://hip-rejoint_description/meshes/camera_1.stl" scale="0.001 0.001 0.001"/>
    </geometry>
  </collision>
</link>

<joint name="Rigid 2" type="fixed">
  <origin xyz="-0.025 0.0542 0.004763" rpy="0 0 0"/>
  <parent link="trunk"/>
  <child link="R8-2RS_Bearing_1"/>
</joint>

<joint name="Rigid 3" type="fixed">
  <origin xyz="-0.025 0.0542 0.004763" rpy="0 0 0"/>
  <parent link="trunk"/>
  <child link="R8-2RS_Bearing_2"/>
</joint>

<joint name="Rigid 4" type="fixed">
  <origin xyz="-0.025 -0.0542 0.004762" rpy="0 0 0"/>
  <parent link="trunk"/>
  <child link="R8-2RS_Bearing_3"/>
</joint>

<joint name="Rigid 5" type="fixed">
  <origin xyz="0.0 0.0 1e-06" rpy="0 0 0"/>
  <parent link="R8-2RS_Bearing_3"/>
  <child link="R8-2RS_Bearing_4"/>
</joint>

<joint name="Rigid 6" type="fixed">
  <origin xyz="-0.025 0.0542 0.004763" rpy="0 0 0"/>
  <parent link="trunk"/>
  <child link="Component2_2"/>
</joint>

<joint name="Rigid 7" type="fixed">
  <origin xyz="-0.025 -0.0542 0.004762" rpy="0 0 0"/>
  <parent link="trunk"/>
  <child link="Component2_1"/>
</joint>

<joint name="Rigid 8" type="fixed">
  <origin xyz="0.0 0.0 0.010956" rpy="0 0 0"/>
  <parent link="Component2_1"/>
  <child link="91590A121_External_Retaining_Ring_v1_2"/>
</joint>

<joint name="right_hip_yaw" type="continuous">
  <origin xyz="0.0 0.0 0.000635" rpy="0 0 0"/>
  <parent link="91590A121_External_Retaining_Ring_v1_2"/>
  <child link="2025K9_303_Stainless_Steel_Rotary_Shaft_with_Retaining_Ring_Grooves_v1_1"/>
  <axis xyz="0.0 0.0 -1.0"/>
</joint>

<joint name="Rigid 10" type="fixed">
  <origin xyz="0.0 0.0 -0.022251" rpy="0 0 0"/>
  <parent link="2025K9_303_Stainless_Steel_Rotary_Shaft_with_Retaining_Ring_Grooves_v1_1"/>
  <child link="91590A121_External_Retaining_Ring_v1_3"/>
</joint>

<joint name="Rigid 11" type="fixed">
  <origin xyz="0.0 0.0 -0.033376" rpy="0 0 0"/>
  <parent link="2025K9_303_Stainless_Steel_Rotary_Shaft_with_Retaining_Ring_Grooves_v1_1"/>
  <child link="91590A121_External_Retaining_Ring_v1_1"/>
</joint>

<joint name="Rigid 12" type="fixed">
  <origin xyz="-0.03165 -7.6e-05 -0.04215" rpy="0 0 0"/>
  <parent link="Component32_1"/>
  <child link="Component39_1"/>
</joint>

<joint name="right_hip_roll" type="continuous">
  <origin xyz="-0.0127 0.0 0.0" rpy="0 0 0"/>
  <parent link="Component39_1"/>
  <child link="JX_servo_v80_3"/>
  <axis xyz="1.0 0.0 0.0"/>
</joint>

<joint name="Rigid 15" type="fixed">
  <origin xyz="-0.0125 0.00835 -0.0556" rpy="0 0 0"/>
  <parent link="JX_servo_v80_3"/>
  <child link="Component9__1__1"/>
</joint>

<joint name="Rigid 16" type="fixed">
  <origin xyz="0.0 0.0 -0.000635" rpy="0 0 0"/>
  <parent link="91590A121_External_Retaining_Ring_v1_1"/>
  <child link="Component4_1"/>
</joint>

<joint name="Rigid 17" type="fixed">
  <origin xyz="0.0 0.0 -0.005312" rpy="0 0 0"/>
  <parent link="Component4_1"/>
  <child link="Component32_1"/>
</joint>

<joint name="Rigid 18" type="fixed">
  <origin xyz="0.0 0.0 0.014681" rpy="0 0 0"/>
  <parent link="2025K9_303_Stainless_Steel_Rotary_Shaft_with_Retaining_Ring_Grooves_v1_1"/>
  <child link="15T-horn_v13_1"/>
</joint>

<joint name="Rigid 19" type="fixed">
  <origin xyz="0.0 0.0 0.0001" rpy="0 0 0"/>
  <parent link="15T-horn_v13_1"/>
  <child link="JX_servo_v80_1"/>
</joint>

<joint name="Rigid 20" type="fixed">
  <origin xyz="0.048601 0.00435 0.0" rpy="0 0 0"/>
  <parent link="Component9__1__1"/>
  <child link="JX_servo_v80_2"/>
</joint>

<joint name="Rigid 21" type="fixed">
  <origin xyz="0.0 0.0 -0.033376" rpy="0 0 0"/>
  <parent link="2025K9_303_Stainless_Steel_Rotary_Shaft_with_Retaining_Ring_Grooves_v1_2"/>
  <child link="91590A121_External_Retaining_Ring_v1_4"/>
</joint>

<joint name="Rigid 22" type="fixed">
  <origin xyz="0.0 0.0 -0.000635" rpy="0 0 0"/>
  <parent link="91590A121_External_Retaining_Ring_v1_4"/>
  <child link="Component4_2"/>
</joint>

<joint name="Rigid 23" type="fixed">
  <origin xyz="0.0 0.0 -0.005312" rpy="0 0 0"/>
  <parent link="Component4_2"/>
  <child link="Component32_2"/>
</joint>

<joint name="Rigid 24" type="fixed">
  <origin xyz="-0.03165 -7.6e-05 -0.04215" rpy="0 0 0"/>
  <parent link="Component32_2"/>
  <child link="Component39_2"/>
</joint>

<joint name="left_hip_roll" type="continuous">
  <origin xyz="-0.0127 0.0 0.0" rpy="0 0 0"/>
  <parent link="Component39_2"/>
  <child link="JX_servo_v80_5"/>
  <axis xyz="1.0 0.0 0.0"/>
</joint>

<joint name="Rigid 26" type="fixed">
  <origin xyz="0.065601 0.00435 0.0" rpy="0 0 0"/>
  <parent link="Component9__1__2"/>
  <child link="JX_servo_v80_7"/>
</joint>

<joint name="Rigid 27" type="fixed">
  <origin xyz="-0.0125 0.00835 -0.0556" rpy="0 0 0"/>
  <parent link="JX_servo_v80_5"/>
  <child link="Component9__1__2"/>
</joint>

<joint name="Rigid 28" type="fixed">
  <origin xyz="0.0 0.0 -0.022251" rpy="0 0 0"/>
  <parent link="2025K9_303_Stainless_Steel_Rotary_Shaft_with_Retaining_Ring_Grooves_v1_2"/>
  <child link="91590A121_External_Retaining_Ring_v1_5"/>
</joint>

<joint name="Rigid 29" type="fixed">
  <origin xyz="0.0 0.0 0.010954" rpy="0 0 0"/>
  <parent link="Component2_2"/>
  <child link="91590A121_External_Retaining_Ring_v1_6"/>
</joint>

<joint name="left_hip_yaw" type="continuous">
  <origin xyz="0.0 0.0 0.000636" rpy="0 0 0"/>
  <parent link="91590A121_External_Retaining_Ring_v1_6"/>
  <child link="2025K9_303_Stainless_Steel_Rotary_Shaft_with_Retaining_Ring_Grooves_v1_2"/>
  <axis xyz="0.0 0.0 -1.0"/>
</joint>

<joint name="Rigid 31" type="fixed">
  <origin xyz="0.0 0.0 0.014681" rpy="0 0 0"/>
  <parent link="2025K9_303_Stainless_Steel_Rotary_Shaft_with_Retaining_Ring_Grooves_v1_2"/>
  <child link="Component6_2"/>
</joint>

<joint name="Rigid 32" type="fixed">
  <origin xyz="0.0 0.0 0.0001" rpy="0 0 0"/>
  <parent link="Component6_2"/>
  <child link="JX_servo_v80_4"/>
</joint>

<joint name="Rigid 35" type="fixed">
  <origin xyz="-0.0085 -0.0217 -0.0556" rpy="0 0 0"/>
  <parent link="JX_servo_v46_Mirror__1"/>
  <child link="Component5_Mirror__1"/>
</joint>

<joint name="left_ankle_pitch" type="continuous">
  <origin xyz="0.0085 0.0224 -0.0836" rpy="0 0 0"/>
  <parent link="Component5_Mirror__1"/>
  <child link="JX_servo_v46_Mirror__2"/>
  <axis xyz="-0.0 1.0 -0.0"/>
</joint>

<joint name="Rigid 37" type="fixed">
  <origin xyz="0.0085 -0.0217 0.0556" rpy="0 0 0"/>
  <parent link="JX_servo_v46_Mirror__2"/>
  <child link="L_Mirror__1"/>
</joint>

<joint name="Rigid 38" type="fixed">
  <origin xyz="-0.067 -0.0065 -0.0001" rpy="0 0 0"/>
  <parent link="L_Mirror__1"/>
  <child link="JX_servo_v46_Mirror__3"/>
</joint>

<joint name="left_ankle_roll" type="continuous">
  <origin xyz="0.0256 -0.0085 -0.0556" rpy="0 0 0"/>
  <parent link="JX_servo_v46_Mirror__3"/>
  <child link="left_foot"/>
  <axis xyz="1.0 0.0 -0.0"/>
</joint>

<joint name="left_hip_pitch" type="continuous">
  <origin xyz="-0.00865 0.032475 0.0556" rpy="0 0 0"/>
  <parent link="JX_servo_v80_7"/>
  <child link="Component4__2__1"/>
  <axis xyz="-0.0 -1.0 0.0"/>
</joint>

<joint name="left_knee" type="continuous">
  <origin xyz="0.0 0.0 -0.16" rpy="0 0 0"/>
  <parent link="Component4__2__1"/>
  <child link="JX_servo_v46_Mirror__1"/>
  <axis xyz="-0.0 1.0 -0.0"/>
</joint>

<joint name="right_hip_pitch" type="continuous">
  <origin xyz="0.00865 -0.057875 0.0556" rpy="0 0 0"/>
  <parent link="JX_servo_v80_2"/>
  <child link="Component4_Mirror___1__1"/>
  <axis xyz="0.0 1.0 -0.0"/>
</joint>

<joint name="right_knee" type="continuous">
  <origin xyz="0.0 0.0 -0.16" rpy="0 0 0"/>
  <parent link="Component4_Mirror___1__1"/>
  <child link="JX_servo_v46_Mirror__9"/>
  <axis xyz="0.0 1.0 -0.0"/>
</joint>

<joint name="Rigid 44" type="fixed">
  <origin xyz="-0.0085 0.0217 -0.0556" rpy="0 0 0"/>
  <parent link="JX_servo_v46_Mirror__9"/>
  <child link="Component5_Mirror__Mirror__1"/>
</joint>

<joint name="right_ankle_pitch" type="continuous">
  <origin xyz="0.0085 -0.0224 -0.0836" rpy="0 0 0"/>
  <parent link="Component5_Mirror__Mirror__1"/>
  <child link="JX_servo_v46_Mirror__7"/>
  <axis xyz="-0.0 1.0 -0.0"/>
</joint>

<joint name="Rigid 46" type="fixed">
  <origin xyz="0.0085 0.0217 0.0556" rpy="0 0 0"/>
  <parent link="JX_servo_v46_Mirror__7"/>
  <child link="L_Mirror__3"/>
</joint>

<joint name="Rigid 47" type="fixed">
  <origin xyz="-0.067 0.0235 -0.0752" rpy="0 0 0"/>
  <parent link="L_Mirror__3"/>
  <child link="JX_servo_v46_Mirror__8"/>
</joint>

<joint name="right_ankle_roll" type="continuous">
  <origin xyz="0.0256 -0.0085 0.0196" rpy="0 0 0"/>
  <parent link="JX_servo_v46_Mirror__8"/>
  <child link="right_foot"/>
  <axis xyz="1.0 0.0 -0.0"/>
</joint>

<joint name="Rigid 50" type="fixed">
  <origin xyz="-0.01515 0.0594 0.0671" rpy="0 0 0"/>
  <parent link="JX_servo_v80_1"/>
  <child link="Component65_1"/>
</joint>

<joint name="Rigid 51" type="fixed">
  <origin xyz="-0.11415 -0.0052 0.0" rpy="0 0 0"/>
  <parent link="Component65_1"/>
  <child link="Component66_1"/>
</joint>

<joint name="right_shoulder_pitch" type="continuous">
  <origin xyz="0.00015 -0.1068 -0.03175" rpy="0 0 0"/>
  <parent link="Component65_1"/>
  <child link="JX_servo_v46_Mirror__10"/>
  <axis xyz="0.0 -1.0 -0.0"/>
</joint>

<joint name="Rigid 53" type="fixed">
  <origin xyz="-0.0085 -0.0576 -0.0557" rpy="0 0 0"/>
  <parent link="JX_servo_v46_Mirror__10"/>
  <child link="JX_servo_v46_Mirror__11"/>
</joint>

<joint name="left_shoulder_pitch" type="continuous">
  <origin xyz="0.00015 0.0964 -0.03175" rpy="0 0 0"/>
  <parent link="Component65_1"/>
  <child link="JX_servo_v46_Mirror__12"/>
  <axis xyz="-0.0 1.0 0.0"/>
</joint>

<joint name="Rigid 55" type="fixed">
  <origin xyz="-0.0085 0.0576 -0.0557" rpy="0 0 0"/>
  <parent link="JX_servo_v46_Mirror__12"/>
  <child link="JX_servo_v46_Mirror__13"/>
</joint>

<joint name="right_elbow" type="continuous">
  <origin xyz="0.0085 -0.0217 -0.0556" rpy="0 0 0"/>
  <parent link="JX_servo_v46_Mirror__11"/>
  <child link="Component11_Mirror__2"/>
  <axis xyz="0.0 -1.0 0.0"/>
</joint>

<joint name="left_elbow" type="continuous">
  <origin xyz="0.0085 0.0217 -0.0556" rpy="0 0 0"/>
  <parent link="JX_servo_v46_Mirror__13"/>
  <child link="Component11_Mirror__3"/>
  <axis xyz="-0.0 1.0 0.0"/>
</joint>

<joint name="Rigid 58" type="fixed">
  <origin xyz="0.0 0.005 0.005" rpy="0 0 0"/>
  <parent link="base_link"/>
  <child link="trunk"/>
</joint>

<joint name="Rigid 59" type="fixed">
  <origin xyz="-0.057 -0.0052 0.0" rpy="0 0 0"/>
  <parent link="Component65_1"/>
  <child link="custom_servo_support__lower_neck__v2_1"/>
</joint>

<joint name="Rigid 60" type="fixed">
  <origin xyz="0.02015 0.0 0.00298" rpy="0 0 0"/>
  <parent link="custom_servo_support__lower_neck__v2_1"/>
  <child link="gobilda-servo_1"/>
</joint>

<joint name="Rigid 61" type="fixed">
  <origin xyz="-0.0113 0.0 0.04092" rpy="0 0 0"/>
  <parent link="gobilda-servo_1"/>
  <child link="25t-servo-hub_1"/>
</joint>

<joint name="head_yaw" type="continuous">
  <origin xyz="0.0 0.0 0.002794" rpy="0 0 0"/>
  <parent link="25t-servo-hub_1"/>
  <child link="neck_1"/>
  <axis xyz="-0.0 0.0 1.0"/>
</joint>

<joint name="head_pitch" type="continuous">
  <origin xyz="0.0 0.026187 0.033817" rpy="0 0 0"/>
  <parent link="neck_1"/>
  <child link="25t-servo-hub_2"/>
  <axis xyz="-0.0 1.0 -0.0"/>
</joint>

<joint name="Rigid 64" type="fixed">
  <origin xyz="0.0 -0.002794 0.0" rpy="0 0 0"/>
  <parent link="25t-servo-hub_2"/>
  <child link="gobilda-servo_2"/>
</joint>

<joint name="Rigid 65" type="fixed">
  <origin xyz="-0.0113 -0.04092 0.0" rpy="0 0 0"/>
  <parent link="gobilda-servo_2"/>
  <child link="head_1"/>
</joint>

<joint name="Rigid 66" type="fixed">
  <origin xyz="0.0133 0.01802 0.021" rpy="0 0 0"/>
  <parent link="head_1"/>
  <child link="camera_1"/>
</joint>

</robot>
