<?xml version="1.0" ?>
<!-- =================================================================================== -->
<!-- |    This document was autogenerated by xacro from /home/q/catkin_ws/src/soccerbot/soccer_description/hip-rejoint_description/urdf/hip-rejoint.xacro | -->
<!-- |    EDITING THIS FILE BY HAND IS NOT RECOMMENDED                                 | -->
<!-- =================================================================================== -->
<robot name="hip-rejoint">
  <!-- 
    Steps to generate model:

    - Joint and export in Fusion
    - Fix inertias in the URDF with `%s/i\(\w\)\1="\-*0.0"/i\1\1="1E-06"/g`
    - Rename `base_link` to `trunk` in the URDF to accomodate placo
    - Rejoint `trunk` to a new root link with a `floating` joint in URDF (i.e. `<link name="root" /><joint name="root-float" type="floating"><child link="trunk" /><parent link="root" /></joint>`
    - Fix servo masses based on enclosure (masses currently include all optional enclosures)
    - Fix necessary placo names (left_foot, right_foot, trunk) which have `_1` or some other digit appended by Fusion unique ID system
    - Generate URDF from xacro via:
      - `conda activate py2; rosrun xacro xacro '/path/to/model.xacro' > '/path/to/model.urdf';`
    - Import to mujoco and save as XML
    - Ensure left and right foot links exist

    Further model fixes:
    - Reorient body to match world frame
    - Add sites to all servos via `%s/<body\(.*\)pos="\([^"]*\)">\(\_.\{-}\)<joint\(.*\)name="\([^"]*\)"/<site name="site_\5" pos="\2" \/><body\1pos="\2">\3<joint\4name="\5"/gi`
    - Add accelerometers and gyros to all sites with `sed` to generate the tag lists:
      - sed 's/<site name="site_\([^"]*\)".*>/\n<accelerometer name="xl_\1" site="site_\1" \/>\n/g' mjmodel.xml | grep '<accelerometer'
    - Disable collision geoms

    - Servo inertias are wrong because they are extracted with all options, including invisible ones. Since they're small, only fix masses depending on the servo enclosure option that is used.
  -->
  <mujoco>
    <compiler balanceinertia="true" discardvisual="false" meshdir="../meshes"/>
  </mujoco>
  <material name="silver_default">
    <color rgba="0.700 0.700 0.700 1.000"/>
  </material>
  <material name="steel_satin">
    <color rgba="0.6274509803921569 0.6274509803921569 0.6274509803921569 1.0"/>
  </material>
  <material name="acrylic_red">
    <color rgba="1.0 1.0 1.0 1.0"/>
  </material>
  <material name="aluminum_satin">
    <color rgba="0.9607843137254902 0.9607843137254902 0.9647058823529412 1.0"/>
  </material>
  <material name="polystyrene">
    <color rgba="1.0 1.0 1.0 1.0"/>
  </material>
  <material name="abs_white">
    <color rgba="0.9647058823529412 0.9647058823529412 0.9529411764705882 1.0"/>
  </material>
  <material name="brass_polished">
    <color rgba="0.37254901960784315 0.42745098039215684 0.6901960784313725 1.0"/>
  </material>
  <material name="plastic_matte_black">
    <color rgba="0.09803921568627451 0.09803921568627451 0.09803921568627451 1.0"/>
  </material>
  <material name="plastic_glossy_black">
    <color rgba="0.09803921568627451 0.09803921568627451 0.09803921568627451 1.0"/>
  </material>
  <material name="plastic_glossy_grey">
    <color rgba="0.2901960784313726 0.2901960784313726 0.2901960784313726 1.0"/>
  </material>
  <transmission name="right_hip_yaw_tran">
    <type>transmission_interface/SimpleTransmission</type>
    <joint name="right_hip_yaw">
      <hardwareInterface>hardware_interface/EffortJointInterface</hardwareInterface>
    </joint>
    <actuator name="right_hip_yaw_actr">
      <hardwareInterface>hardware_interface/EffortJointInterface</hardwareInterface>
      <mechanicalReduction>1</mechanicalReduction>
    </actuator>
  </transmission>
  <transmission name="right_hip_roll_tran">
    <type>transmission_interface/SimpleTransmission</type>
    <joint name="right_hip_roll">
      <hardwareInterface>hardware_interface/EffortJointInterface</hardwareInterface>
    </joint>
    <actuator name="right_hip_roll_actr">
      <hardwareInterface>hardware_interface/EffortJointInterface</hardwareInterface>
      <mechanicalReduction>1</mechanicalReduction>
    </actuator>
  </transmission>
  <transmission name="left_hip_roll_tran">
    <type>transmission_interface/SimpleTransmission</type>
    <joint name="left_hip_roll">
      <hardwareInterface>hardware_interface/EffortJointInterface</hardwareInterface>
    </joint>
    <actuator name="left_hip_roll_actr">
      <hardwareInterface>hardware_interface/EffortJointInterface</hardwareInterface>
      <mechanicalReduction>1</mechanicalReduction>
    </actuator>
  </transmission>
  <transmission name="left_hip_yaw_tran">
    <type>transmission_interface/SimpleTransmission</type>
    <joint name="left_hip_yaw">
      <hardwareInterface>hardware_interface/EffortJointInterface</hardwareInterface>
    </joint>
    <actuator name="left_hip_yaw_actr">
      <hardwareInterface>hardware_interface/EffortJointInterface</hardwareInterface>
      <mechanicalReduction>1</mechanicalReduction>
    </actuator>
  </transmission>
  <transmission name="left_ankle_pitch_tran">
    <type>transmission_interface/SimpleTransmission</type>
    <joint name="left_ankle_pitch">
      <hardwareInterface>hardware_interface/EffortJointInterface</hardwareInterface>
    </joint>
    <actuator name="left_ankle_pitch_actr">
      <hardwareInterface>hardware_interface/EffortJointInterface</hardwareInterface>
      <mechanicalReduction>1</mechanicalReduction>
    </actuator>
  </transmission>
  <transmission name="left_ankle_roll_tran">
    <type>transmission_interface/SimpleTransmission</type>
    <joint name="left_ankle_roll">
      <hardwareInterface>hardware_interface/EffortJointInterface</hardwareInterface>
    </joint>
    <actuator name="left_ankle_roll_actr">
      <hardwareInterface>hardware_interface/EffortJointInterface</hardwareInterface>
      <mechanicalReduction>1</mechanicalReduction>
    </actuator>
  </transmission>
  <transmission name="left_hip_pitch_tran">
    <type>transmission_interface/SimpleTransmission</type>
    <joint name="left_hip_pitch">
      <hardwareInterface>hardware_interface/EffortJointInterface</hardwareInterface>
    </joint>
    <actuator name="left_hip_pitch_actr">
      <hardwareInterface>hardware_interface/EffortJointInterface</hardwareInterface>
      <mechanicalReduction>1</mechanicalReduction>
    </actuator>
  </transmission>
  <transmission name="left_knee_tran">
    <type>transmission_interface/SimpleTransmission</type>
    <joint name="left_knee">
      <hardwareInterface>hardware_interface/EffortJointInterface</hardwareInterface>
    </joint>
    <actuator name="left_knee_actr">
      <hardwareInterface>hardware_interface/EffortJointInterface</hardwareInterface>
      <mechanicalReduction>1</mechanicalReduction>
    </actuator>
  </transmission>
  <transmission name="right_hip_pitch_tran">
    <type>transmission_interface/SimpleTransmission</type>
    <joint name="right_hip_pitch">
      <hardwareInterface>hardware_interface/EffortJointInterface</hardwareInterface>
    </joint>
    <actuator name="right_hip_pitch_actr">
      <hardwareInterface>hardware_interface/EffortJointInterface</hardwareInterface>
      <mechanicalReduction>1</mechanicalReduction>
    </actuator>
  </transmission>
  <transmission name="right_knee_tran">
    <type>transmission_interface/SimpleTransmission</type>
    <joint name="right_knee">
      <hardwareInterface>hardware_interface/EffortJointInterface</hardwareInterface>
    </joint>
    <actuator name="right_knee_actr">
      <hardwareInterface>hardware_interface/EffortJointInterface</hardwareInterface>
      <mechanicalReduction>1</mechanicalReduction>
    </actuator>
  </transmission>
  <transmission name="right_ankle_pitch_tran">
    <type>transmission_interface/SimpleTransmission</type>
    <joint name="right_ankle_pitch">
      <hardwareInterface>hardware_interface/EffortJointInterface</hardwareInterface>
    </joint>
    <actuator name="right_ankle_pitch_actr">
      <hardwareInterface>hardware_interface/EffortJointInterface</hardwareInterface>
      <mechanicalReduction>1</mechanicalReduction>
    </actuator>
  </transmission>
  <transmission name="right_ankle_roll_tran">
    <type>transmission_interface/SimpleTransmission</type>
    <joint name="right_ankle_roll">
      <hardwareInterface>hardware_interface/EffortJointInterface</hardwareInterface>
    </joint>
    <actuator name="right_ankle_roll_actr">
      <hardwareInterface>hardware_interface/EffortJointInterface</hardwareInterface>
      <mechanicalReduction>1</mechanicalReduction>
    </actuator>
  </transmission>
  <transmission name="right_shoulder_pitch_tran">
    <type>transmission_interface/SimpleTransmission</type>
    <joint name="right_shoulder_pitch">
      <hardwareInterface>hardware_interface/EffortJointInterface</hardwareInterface>
    </joint>
    <actuator name="right_shoulder_pitch_actr">
      <hardwareInterface>hardware_interface/EffortJointInterface</hardwareInterface>
      <mechanicalReduction>1</mechanicalReduction>
    </actuator>
  </transmission>
  <transmission name="left_shoulder_pitch_tran">
    <type>transmission_interface/SimpleTransmission</type>
    <joint name="left_shoulder_pitch">
      <hardwareInterface>hardware_interface/EffortJointInterface</hardwareInterface>
    </joint>
    <actuator name="left_shoulder_pitch_actr">
      <hardwareInterface>hardware_interface/EffortJointInterface</hardwareInterface>
      <mechanicalReduction>1</mechanicalReduction>
    </actuator>
  </transmission>
  <transmission name="right_elbow_tran">
    <type>transmission_interface/SimpleTransmission</type>
    <joint name="right_elbow">
      <hardwareInterface>hardware_interface/EffortJointInterface</hardwareInterface>
    </joint>
    <actuator name="right_elbow_actr">
      <hardwareInterface>hardware_interface/EffortJointInterface</hardwareInterface>
      <mechanicalReduction>1</mechanicalReduction>
    </actuator>
  </transmission>
  <transmission name="left_elbow_tran">
    <type>transmission_interface/SimpleTransmission</type>
    <joint name="left_elbow">
      <hardwareInterface>hardware_interface/EffortJointInterface</hardwareInterface>
    </joint>
    <actuator name="left_elbow_actr">
      <hardwareInterface>hardware_interface/EffortJointInterface</hardwareInterface>
      <mechanicalReduction>1</mechanicalReduction>
    </actuator>
  </transmission>
  <transmission name="Revolute 62_tran">
    <type>transmission_interface/SimpleTransmission</type>
    <joint name="Revolute 62">
      <hardwareInterface>hardware_interface/EffortJointInterface</hardwareInterface>
    </joint>
    <actuator name="Revolute 62_actr">
      <hardwareInterface>hardware_interface/EffortJointInterface</hardwareInterface>
      <mechanicalReduction>1</mechanicalReduction>
    </actuator>
  </transmission>
  <transmission name="Revolute 63_tran">
    <type>transmission_interface/SimpleTransmission</type>
    <joint name="Revolute 63">
      <hardwareInterface>hardware_interface/EffortJointInterface</hardwareInterface>
    </joint>
    <actuator name="Revolute 63_actr">
      <hardwareInterface>hardware_interface/EffortJointInterface</hardwareInterface>
      <mechanicalReduction>1</mechanicalReduction>
    </actuator>
  </transmission>
  <gazebo>
    <plugin filename="libgazebo_ros_control.so" name="control"/>
  </gazebo>
  <gazebo reference="base_link">
    <material>Gazebo/Silver</material>
    <mu1>0.2</mu1>
    <mu2>0.2</mu2>
    <selfCollide>true</selfCollide>
    <gravity>true</gravity>
  </gazebo>
  <gazebo reference="R8-2RS_Bearing_1">
    <material>Gazebo/Silver</material>
    <mu1>0.2</mu1>
    <mu2>0.2</mu2>
    <selfCollide>true</selfCollide>
  </gazebo>
  <gazebo reference="R8-2RS_Bearing_2">
    <material>Gazebo/Silver</material>
    <mu1>0.2</mu1>
    <mu2>0.2</mu2>
    <selfCollide>true</selfCollide>
  </gazebo>
  <gazebo reference="R8-2RS_Bearing_3">
    <material>Gazebo/Silver</material>
    <mu1>0.2</mu1>
    <mu2>0.2</mu2>
    <selfCollide>true</selfCollide>
  </gazebo>
  <gazebo reference="R8-2RS_Bearing_4">
    <material>Gazebo/Silver</material>
    <mu1>0.2</mu1>
    <mu2>0.2</mu2>
    <selfCollide>true</selfCollide>
  </gazebo>
  <gazebo reference="Component2_2">
    <material>Gazebo/Silver</material>
    <mu1>0.2</mu1>
    <mu2>0.2</mu2>
    <selfCollide>true</selfCollide>
  </gazebo>
  <gazebo reference="Component2_1">
    <material>Gazebo/Silver</material>
    <mu1>0.2</mu1>
    <mu2>0.2</mu2>
    <selfCollide>true</selfCollide>
  </gazebo>
  <gazebo reference="91590A121_External_Retaining_Ring_v1_2">
    <material>Gazebo/Silver</material>
    <mu1>0.2</mu1>
    <mu2>0.2</mu2>
    <selfCollide>true</selfCollide>
  </gazebo>
  <gazebo reference="2025K9_303_Stainless_Steel_Rotary_Shaft_with_Retaining_Ring_Grooves_v1_1">
    <material>Gazebo/Silver</material>
    <mu1>0.2</mu1>
    <mu2>0.2</mu2>
    <selfCollide>true</selfCollide>
  </gazebo>
  <gazebo reference="91590A121_External_Retaining_Ring_v1_3">
    <material>Gazebo/Silver</material>
    <mu1>0.2</mu1>
    <mu2>0.2</mu2>
    <selfCollide>true</selfCollide>
  </gazebo>
  <gazebo reference="91590A121_External_Retaining_Ring_v1_1">
    <material>Gazebo/Silver</material>
    <mu1>0.2</mu1>
    <mu2>0.2</mu2>
    <selfCollide>true</selfCollide>
  </gazebo>
  <gazebo reference="Component39_1">
    <material>Gazebo/Silver</material>
    <mu1>0.2</mu1>
    <mu2>0.2</mu2>
    <selfCollide>true</selfCollide>
  </gazebo>
  <gazebo reference="JX_servo_v80_3">
    <material>Gazebo/Silver</material>
    <mu1>0.2</mu1>
    <mu2>0.2</mu2>
    <selfCollide>true</selfCollide>
  </gazebo>
  <gazebo reference="Component9__1__1">
    <material>Gazebo/Silver</material>
    <mu1>0.2</mu1>
    <mu2>0.2</mu2>
    <selfCollide>true</selfCollide>
  </gazebo>
  <gazebo reference="Component4_1">
    <material>Gazebo/Silver</material>
    <mu1>0.2</mu1>
    <mu2>0.2</mu2>
    <selfCollide>true</selfCollide>
  </gazebo>
  <gazebo reference="Component32_1">
    <material>Gazebo/Silver</material>
    <mu1>0.2</mu1>
    <mu2>0.2</mu2>
    <selfCollide>true</selfCollide>
  </gazebo>
  <gazebo reference="15T-horn_v13_1">
    <material>Gazebo/Silver</material>
    <mu1>0.2</mu1>
    <mu2>0.2</mu2>
    <selfCollide>true</selfCollide>
  </gazebo>
  <gazebo reference="JX_servo_v80_1">
    <material>Gazebo/Silver</material>
    <mu1>0.2</mu1>
    <mu2>0.2</mu2>
    <selfCollide>true</selfCollide>
  </gazebo>
  <gazebo reference="JX_servo_v80_2">
    <material>Gazebo/Silver</material>
    <mu1>0.2</mu1>
    <mu2>0.2</mu2>
    <selfCollide>true</selfCollide>
  </gazebo>
  <gazebo reference="91590A121_External_Retaining_Ring_v1_4">
    <material>Gazebo/Silver</material>
    <mu1>0.2</mu1>
    <mu2>0.2</mu2>
    <selfCollide>true</selfCollide>
  </gazebo>
  <gazebo reference="Component4_2">
    <material>Gazebo/Silver</material>
    <mu1>0.2</mu1>
    <mu2>0.2</mu2>
    <selfCollide>true</selfCollide>
  </gazebo>
  <gazebo reference="Component32_2">
    <material>Gazebo/Silver</material>
    <mu1>0.2</mu1>
    <mu2>0.2</mu2>
    <selfCollide>true</selfCollide>
  </gazebo>
  <gazebo reference="Component39_2">
    <material>Gazebo/Silver</material>
    <mu1>0.2</mu1>
    <mu2>0.2</mu2>
    <selfCollide>true</selfCollide>
  </gazebo>
  <gazebo reference="JX_servo_v80_5">
    <material>Gazebo/Silver</material>
    <mu1>0.2</mu1>
    <mu2>0.2</mu2>
    <selfCollide>true</selfCollide>
  </gazebo>
  <gazebo reference="JX_servo_v80_7">
    <material>Gazebo/Silver</material>
    <mu1>0.2</mu1>
    <mu2>0.2</mu2>
    <selfCollide>true</selfCollide>
  </gazebo>
  <gazebo reference="Component9__1__2">
    <material>Gazebo/Silver</material>
    <mu1>0.2</mu1>
    <mu2>0.2</mu2>
    <selfCollide>true</selfCollide>
  </gazebo>
  <gazebo reference="91590A121_External_Retaining_Ring_v1_5">
    <material>Gazebo/Silver</material>
    <mu1>0.2</mu1>
    <mu2>0.2</mu2>
    <selfCollide>true</selfCollide>
  </gazebo>
  <gazebo reference="91590A121_External_Retaining_Ring_v1_6">
    <material>Gazebo/Silver</material>
    <mu1>0.2</mu1>
    <mu2>0.2</mu2>
    <selfCollide>true</selfCollide>
  </gazebo>
  <gazebo reference="2025K9_303_Stainless_Steel_Rotary_Shaft_with_Retaining_Ring_Grooves_v1_2">
    <material>Gazebo/Silver</material>
    <mu1>0.2</mu1>
    <mu2>0.2</mu2>
    <selfCollide>true</selfCollide>
  </gazebo>
  <gazebo reference="Component6_2">
    <material>Gazebo/Silver</material>
    <mu1>0.2</mu1>
    <mu2>0.2</mu2>
    <selfCollide>true</selfCollide>
  </gazebo>
  <gazebo reference="JX_servo_v80_4">
    <material>Gazebo/Silver</material>
    <mu1>0.2</mu1>
    <mu2>0.2</mu2>
    <selfCollide>true</selfCollide>
  </gazebo>
  <gazebo reference="Component5_Mirror__1">
    <material>Gazebo/Silver</material>
    <mu1>0.2</mu1>
    <mu2>0.2</mu2>
    <selfCollide>true</selfCollide>
  </gazebo>
  <gazebo reference="JX_servo_v46_Mirror__2">
    <material>Gazebo/Silver</material>
    <mu1>0.2</mu1>
    <mu2>0.2</mu2>
    <selfCollide>true</selfCollide>
  </gazebo>
  <gazebo reference="L_Mirror__1">
    <material>Gazebo/Silver</material>
    <mu1>0.2</mu1>
    <mu2>0.2</mu2>
    <selfCollide>true</selfCollide>
  </gazebo>
  <gazebo reference="JX_servo_v46_Mirror__3">
    <material>Gazebo/Silver</material>
    <mu1>0.2</mu1>
    <mu2>0.2</mu2>
    <selfCollide>true</selfCollide>
  </gazebo>
  <gazebo reference="left_foot_1">
    <material>Gazebo/Silver</material>
    <mu1>0.2</mu1>
    <mu2>0.2</mu2>
    <selfCollide>true</selfCollide>
  </gazebo>
  <gazebo reference="Component4__2__1">
    <material>Gazebo/Silver</material>
    <mu1>0.2</mu1>
    <mu2>0.2</mu2>
    <selfCollide>true</selfCollide>
  </gazebo>
  <gazebo reference="JX_servo_v46_Mirror__1">
    <material>Gazebo/Silver</material>
    <mu1>0.2</mu1>
    <mu2>0.2</mu2>
    <selfCollide>true</selfCollide>
  </gazebo>
  <gazebo reference="Component4_Mirror___1__1">
    <material>Gazebo/Silver</material>
    <mu1>0.2</mu1>
    <mu2>0.2</mu2>
    <selfCollide>true</selfCollide>
  </gazebo>
  <gazebo reference="JX_servo_v46_Mirror__9">
    <material>Gazebo/Silver</material>
    <mu1>0.2</mu1>
    <mu2>0.2</mu2>
    <selfCollide>true</selfCollide>
  </gazebo>
  <gazebo reference="Component5_Mirror__Mirror__1">
    <material>Gazebo/Silver</material>
    <mu1>0.2</mu1>
    <mu2>0.2</mu2>
    <selfCollide>true</selfCollide>
  </gazebo>
  <gazebo reference="JX_servo_v46_Mirror__7">
    <material>Gazebo/Silver</material>
    <mu1>0.2</mu1>
    <mu2>0.2</mu2>
    <selfCollide>true</selfCollide>
  </gazebo>
  <gazebo reference="L_Mirror__3">
    <material>Gazebo/Silver</material>
    <mu1>0.2</mu1>
    <mu2>0.2</mu2>
    <selfCollide>true</selfCollide>
  </gazebo>
  <gazebo reference="JX_servo_v46_Mirror__8">
    <material>Gazebo/Silver</material>
    <mu1>0.2</mu1>
    <mu2>0.2</mu2>
    <selfCollide>true</selfCollide>
  </gazebo>
  <gazebo reference="right_foot_1">
    <material>Gazebo/Silver</material>
    <mu1>0.2</mu1>
    <mu2>0.2</mu2>
    <selfCollide>true</selfCollide>
  </gazebo>
  <gazebo reference="Component65_1">
    <material>Gazebo/Silver</material>
    <mu1>0.2</mu1>
    <mu2>0.2</mu2>
    <selfCollide>true</selfCollide>
  </gazebo>
  <gazebo reference="Component66_1">
    <material>Gazebo/Silver</material>
    <mu1>0.2</mu1>
    <mu2>0.2</mu2>
    <selfCollide>true</selfCollide>
  </gazebo>
  <gazebo reference="JX_servo_v46_Mirror__10">
    <material>Gazebo/Silver</material>
    <mu1>0.2</mu1>
    <mu2>0.2</mu2>
    <selfCollide>true</selfCollide>
  </gazebo>
  <gazebo reference="JX_servo_v46_Mirror__11">
    <material>Gazebo/Silver</material>
    <mu1>0.2</mu1>
    <mu2>0.2</mu2>
    <selfCollide>true</selfCollide>
  </gazebo>
  <gazebo reference="JX_servo_v46_Mirror__12">
    <material>Gazebo/Silver</material>
    <mu1>0.2</mu1>
    <mu2>0.2</mu2>
    <selfCollide>true</selfCollide>
  </gazebo>
  <gazebo reference="JX_servo_v46_Mirror__13">
    <material>Gazebo/Silver</material>
    <mu1>0.2</mu1>
    <mu2>0.2</mu2>
    <selfCollide>true</selfCollide>
  </gazebo>
  <gazebo reference="Component11_Mirror__2">
    <material>Gazebo/Silver</material>
    <mu1>0.2</mu1>
    <mu2>0.2</mu2>
    <selfCollide>true</selfCollide>
  </gazebo>
  <gazebo reference="Component11_Mirror__3">
    <material>Gazebo/Silver</material>
    <mu1>0.2</mu1>
    <mu2>0.2</mu2>
    <selfCollide>true</selfCollide>
  </gazebo>
  <gazebo reference="trunk_1">
    <material>Gazebo/Silver</material>
    <mu1>0.2</mu1>
    <mu2>0.2</mu2>
    <selfCollide>true</selfCollide>
  </gazebo>
  <gazebo reference="custom_servo_support__lower_neck__v2_1">
    <material>Gazebo/Silver</material>
    <mu1>0.2</mu1>
    <mu2>0.2</mu2>
    <selfCollide>true</selfCollide>
  </gazebo>
  <gazebo reference="gobilda-servo_1">
    <material>Gazebo/Silver</material>
    <mu1>0.2</mu1>
    <mu2>0.2</mu2>
    <selfCollide>true</selfCollide>
  </gazebo>
  <gazebo reference="25t-servo-hub_1">
    <material>Gazebo/Silver</material>
    <mu1>0.2</mu1>
    <mu2>0.2</mu2>
    <selfCollide>true</selfCollide>
  </gazebo>
  <gazebo reference="neck_1">
    <material>Gazebo/Silver</material>
    <mu1>0.2</mu1>
    <mu2>0.2</mu2>
    <selfCollide>true</selfCollide>
  </gazebo>
  <gazebo reference="25t-servo-hub_2">
    <material>Gazebo/Silver</material>
    <mu1>0.2</mu1>
    <mu2>0.2</mu2>
    <selfCollide>true</selfCollide>
  </gazebo>
  <gazebo reference="gobilda-servo_2">
    <material>Gazebo/Silver</material>
    <mu1>0.2</mu1>
    <mu2>0.2</mu2>
    <selfCollide>true</selfCollide>
  </gazebo>
  <gazebo reference="head_1">
    <material>Gazebo/Silver</material>
    <mu1>0.2</mu1>
    <mu2>0.2</mu2>
    <selfCollide>true</selfCollide>
  </gazebo>
  <gazebo reference="camera_1">
    <material>Gazebo/Silver</material>
    <mu1>0.2</mu1>
    <mu2>0.2</mu2>
    <selfCollide>true</selfCollide>
  </gazebo>
  <link name="base_link">
    <inertial>
      <origin rpy="0 0 0" xyz="0.005 0.005 0.005"/>
      <mass value="0.00106"/>
      <inertia ixx="1E-06" ixy="0.0" ixz="0.0" iyy="1E-06" iyz="0.0" izz="1E-06"/>
    </inertial>
    <visual>
      <origin rpy="0 0 0" xyz="0 0 0"/>
      <geometry>
        <mesh filename="package://hip-rejoint_description/meshes/base_link.stl" scale="0.001 0.001 0.001"/>
      </geometry>
      <material name="abs_white"/>
    </visual>
    <collision>
      <origin rpy="0 0 0" xyz="0 0 0"/>
      <geometry>
        <mesh filename="package://hip-rejoint_description/meshes/base_link.stl" scale="0.001 0.001 0.001"/>
      </geometry>
    </collision>
  </link>
  <link name="R8-2RS_Bearing_1">
    <inertial>
      <origin rpy="0 0 0" xyz="4.85722573273506e-17 1.6393830737371218e-13 -0.003969249999999997"/>
      <mass value="0.03206594861680248"/>
      <inertia ixx="2e-06" ixy="-0.0" ixz="-0.0" iyy="2e-06" iyz="-0.0" izz="4e-06"/>
    </inertial>
    <visual>
      <origin rpy="0 0 0" xyz="0.025 -0.0592 -0.009763"/>
      <geometry>
        <mesh filename="package://hip-rejoint_description/meshes/R8-2RS_Bearing_1.stl" scale="0.001 0.001 0.001"/>
      </geometry>
      <material name="steel_satin"/>
    </visual>
    <collision>
      <origin rpy="0 0 0" xyz="0.025 -0.0592 -0.009763"/>
      <geometry>
        <mesh filename="package://hip-rejoint_description/meshes/R8-2RS_Bearing_1.stl" scale="0.001 0.001 0.001"/>
      </geometry>
    </collision>
  </link>
  <link name="R8-2RS_Bearing_2">
    <inertial>
      <origin rpy="0 0 0" xyz="5.551115123125783e-17 1.6397300184323171e-13 0.003968250000000005"/>
      <mass value="0.03206594861680248"/>
      <inertia ixx="2e-06" ixy="0.0" ixz="0.0" iyy="2e-06" iyz="-0.0" izz="4e-06"/>
    </inertial>
    <visual>
      <origin rpy="0 0 0" xyz="0.025 -0.0592 -0.009763"/>
      <geometry>
        <mesh filename="package://hip-rejoint_description/meshes/R8-2RS_Bearing_2.stl" scale="0.001 0.001 0.001"/>
      </geometry>
      <material name="steel_satin"/>
    </visual>
    <collision>
      <origin rpy="0 0 0" xyz="0.025 -0.0592 -0.009763"/>
      <geometry>
        <mesh filename="package://hip-rejoint_description/meshes/R8-2RS_Bearing_2.stl" scale="0.001 0.001 0.001"/>
      </geometry>
    </collision>
  </link>
  <link name="R8-2RS_Bearing_3">
    <inertial>
      <origin rpy="0 0 0" xyz="-3.469446951953614e-18 1.6287665660641437e-13 -0.003968249999999989"/>
      <mass value="0.03206594861680248"/>
      <inertia ixx="2e-06" ixy="0.0" ixz="-0.0" iyy="2e-06" iyz="0.0" izz="4e-06"/>
    </inertial>
    <visual>
      <origin rpy="0 0 0" xyz="0.025 0.0492 -0.009762"/>
      <geometry>
        <mesh filename="package://hip-rejoint_description/meshes/R8-2RS_Bearing_3.stl" scale="0.001 0.001 0.001"/>
      </geometry>
      <material name="steel_satin"/>
    </visual>
    <collision>
      <origin rpy="0 0 0" xyz="0.025 0.0492 -0.009762"/>
      <geometry>
        <mesh filename="package://hip-rejoint_description/meshes/R8-2RS_Bearing_3.stl" scale="0.001 0.001 0.001"/>
      </geometry>
    </collision>
  </link>
  <link name="R8-2RS_Bearing_4">
    <inertial>
      <origin rpy="0 0 0" xyz="-3.469446951953614e-18 1.6298074001497298e-13 0.00396825000000001"/>
      <mass value="0.03206594861680248"/>
      <inertia ixx="2e-06" ixy="0.0" ixz="-0.0" iyy="2e-06" iyz="-0.0" izz="4e-06"/>
    </inertial>
    <visual>
      <origin rpy="0 0 0" xyz="0.025 0.0492 -0.009763"/>
      <geometry>
        <mesh filename="package://hip-rejoint_description/meshes/R8-2RS_Bearing_4.stl" scale="0.001 0.001 0.001"/>
      </geometry>
      <material name="steel_satin"/>
    </visual>
    <collision>
      <origin rpy="0 0 0" xyz="0.025 0.0492 -0.009763"/>
      <geometry>
        <mesh filename="package://hip-rejoint_description/meshes/R8-2RS_Bearing_4.stl" scale="0.001 0.001 0.001"/>
      </geometry>
    </collision>
  </link>
  <link name="Component2_2">
    <inertial>
      <origin rpy="0 0 0" xyz="9.020562075079397e-17 -8.781170235394598e-14 0.006597976249397723"/>
      <mass value="0.043046314847355716"/>
      <inertia ixx="9e-06" ixy="0.0" ixz="0.0" iyy="9e-06" iyz="0.0" izz="1.6e-05"/>
    </inertial>
    <visual>
      <origin rpy="0 0 0" xyz="0.025 -0.0592 -0.009763"/>
      <geometry>
        <mesh filename="package://hip-rejoint_description/meshes/Component2_2.stl" scale="0.001 0.001 0.001"/>
      </geometry>
      <material name="aluminum_satin"/>
    </visual>
    <collision>
      <origin rpy="0 0 0" xyz="0.025 -0.0592 -0.009763"/>
      <geometry>
        <mesh filename="package://hip-rejoint_description/meshes/Component2_2.stl" scale="0.001 0.001 0.001"/>
      </geometry>
    </collision>
  </link>
  <link name="Component2_1">
    <inertial>
      <origin rpy="0 0 0" xyz="2.0816681711721685e-17 -8.87900863943969e-14 0.0065989762493977346"/>
      <mass value="0.043046314847355716"/>
      <inertia ixx="9e-06" ixy="0.0" ixz="0.0" iyy="9e-06" iyz="0.0" izz="1.6e-05"/>
    </inertial>
    <visual>
      <origin rpy="0 0 0" xyz="0.025 0.0492 -0.009762"/>
      <geometry>
        <mesh filename="package://hip-rejoint_description/meshes/Component2_1.stl" scale="0.001 0.001 0.001"/>
      </geometry>
      <material name="aluminum_satin"/>
    </visual>
    <collision>
      <origin rpy="0 0 0" xyz="0.025 0.0492 -0.009762"/>
      <geometry>
        <mesh filename="package://hip-rejoint_description/meshes/Component2_1.stl" scale="0.001 0.001 0.001"/>
      </geometry>
    </collision>
  </link>
  <link name="91590A121_External_Retaining_Ring_v1_2">
    <inertial>
      <origin rpy="0 0 0" xyz="1.8943180357666733e-15 0.000286197569581724 0.0003170000000000117"/>
      <mass value="0.00024760918611349786"/>
      <inertia ixx="1E-06" ixy="0.0" ixz="-0.0" iyy="1E-06" iyz="0.0" izz="1E-06"/>
    </inertial>
    <visual>
      <origin rpy="0 0 0" xyz="0.025 0.0492 -0.020718"/>
      <geometry>
        <mesh filename="package://hip-rejoint_description/meshes/91590A121_External_Retaining_Ring_v1_2.stl" scale="0.001 0.001 0.001"/>
      </geometry>
      <material name="steel_satin"/>
    </visual>
    <collision>
      <origin rpy="0 0 0" xyz="0.025 0.0492 -0.020718"/>
      <geometry>
        <mesh filename="package://hip-rejoint_description/meshes/91590A121_External_Retaining_Ring_v1_2.stl" scale="0.001 0.001 0.001"/>
      </geometry>
    </collision>
  </link>
  <link name="2025K9_303_Stainless_Steel_Rotary_Shaft_with_Retaining_Ring_Grooves_v1_1">
    <inertial>
      <origin rpy="0 0 0" xyz="-3.686981275841106e-14 6.104977634535658e-13 -0.023450621315963708"/>
      <mass value="0.07269824555688346"/>
      <inertia ixx="3.6e-05" ixy="-0.0" ixz="0.0" iyy="3.6e-05" iyz="0.0" izz="1e-06"/>
    </inertial>
    <visual>
      <origin rpy="0 0 0" xyz="0.025 0.0492 -0.021353"/>
      <geometry>
        <mesh filename="package://hip-rejoint_description/meshes/2025K9_303_Stainless_Steel_Rotary_Shaft_with_Retaining_Ring_Grooves_v1_1.stl" scale="0.001 0.001 0.001"/>
      </geometry>
      <material name="steel_satin"/>
    </visual>
    <collision>
      <origin rpy="0 0 0" xyz="0.025 0.0492 -0.021353"/>
      <geometry>
        <mesh filename="package://hip-rejoint_description/meshes/2025K9_303_Stainless_Steel_Rotary_Shaft_with_Retaining_Ring_Grooves_v1_1.stl" scale="0.001 0.001 0.001"/>
      </geometry>
    </collision>
  </link>
  <link name="91590A121_External_Retaining_Ring_v1_3">
    <inertial>
      <origin rpy="0 0 0" xyz="-1.8561541192951836e-15 -0.00028619756958252196 0.00031759999999999026"/>
      <mass value="0.00024760918611349786"/>
      <inertia ixx="1E-06" ixy="0.0" ixz="-0.0" iyy="1E-06" iyz="-0.0" izz="1E-06"/>
    </inertial>
    <visual>
      <origin rpy="0 0 0" xyz="0.025 0.0492 0.000898"/>
      <geometry>
        <mesh filename="package://hip-rejoint_description/meshes/91590A121_External_Retaining_Ring_v1_3.stl" scale="0.001 0.001 0.001"/>
      </geometry>
      <material name="steel_satin"/>
    </visual>
    <collision>
      <origin rpy="0 0 0" xyz="0.025 0.0492 0.000898"/>
      <geometry>
        <mesh filename="package://hip-rejoint_description/meshes/91590A121_External_Retaining_Ring_v1_3.stl" scale="0.001 0.001 0.001"/>
      </geometry>
    </collision>
  </link>
  <link name="91590A121_External_Retaining_Ring_v1_1">
    <inertial>
      <origin rpy="0 0 0" xyz="-1.8561541192951836e-15 -0.000286197569582515 -0.0003176000000000255"/>
      <mass value="0.00024760918611349786"/>
      <inertia ixx="1E-06" ixy="0.0" ixz="0.0" iyy="1E-06" iyz="0.0" izz="1E-06"/>
    </inertial>
    <visual>
      <origin rpy="0 0 0" xyz="0.025 0.0492 0.012023"/>
      <geometry>
        <mesh filename="package://hip-rejoint_description/meshes/91590A121_External_Retaining_Ring_v1_1.stl" scale="0.001 0.001 0.001"/>
      </geometry>
      <material name="steel_satin"/>
    </visual>
    <collision>
      <origin rpy="0 0 0" xyz="0.025 0.0492 0.012023"/>
      <geometry>
        <mesh filename="package://hip-rejoint_description/meshes/91590A121_External_Retaining_Ring_v1_1.stl" scale="0.001 0.001 0.001"/>
      </geometry>
    </collision>
  </link>
  <link name="Component39_1">
    <inertial>
      <origin rpy="0 0 0" xyz="-0.004453658050594535 1.0708659631264439e-07 0.007256502814372477"/>
      <mass value="0.015364690334044086"/>
      <inertia ixx="2e-06" ixy="-0.0" ixz="-0.0" iyy="1e-06" iyz="0.0" izz="1e-06"/>
    </inertial>
    <visual>
      <origin rpy="0 0 0" xyz="0.05665 0.049276 0.06012"/>
      <geometry>
        <mesh filename="package://hip-rejoint_description/meshes/Component39_1.stl" scale="0.001 0.001 0.001"/>
      </geometry>
      <material name="aluminum_satin"/>
    </visual>
    <collision>
      <origin rpy="0 0 0" xyz="0.05665 0.049276 0.06012"/>
      <geometry>
        <mesh filename="package://hip-rejoint_description/meshes/Component39_1.stl" scale="0.001 0.001 0.001"/>
      </geometry>
    </collision>
  </link>
  <link name="JX_servo_v80_3">
    <inertial>
      <mass value="0.2114"/>
      <origin rpy="0 0 0" xyz="-0.03281072928697727 -0.00014307061349972533 -0.016670466018917744"/>
      <inertia ixx="0.001692" ixy="-1e-06" ixz="-4.9e-05" iyy="0.001903" iyz="-0.0" izz="0.001012"/>
    </inertial>
    <visual>
      <origin rpy="0 0 0" xyz="0.06935 0.049276 0.06012"/>
      <geometry>
        <mesh filename="package://hip-rejoint_description/meshes/JX_servo_v80_3.stl" scale="0.001 0.001 0.001"/>
      </geometry>
      <material name="polystyrene"/>
    </visual>
    <collision>
      <origin rpy="0 0 0" xyz="0.06935 0.049276 0.06012"/>
      <geometry>
        <mesh filename="package://hip-rejoint_description/meshes/JX_servo_v80_3.stl" scale="0.001 0.001 0.001"/>
      </geometry>
    </collision>
  </link>
  <link name="Component9__1__1">
    <inertial>
      <origin rpy="0 0 0" xyz="0.03333629681388652 -0.008439001260076934 -0.00027616991746298725"/>
      <mass value="0.13759034791983457"/>
      <inertia ixx="1e-05" ixy="-0.0" ixz="0.0" iyy="5.4e-05" iyz="0.0" izz="6.2e-05"/>
    </inertial>
    <visual>
      <origin rpy="0 0 0" xyz="0.08185 0.040926 0.11572"/>
      <geometry>
        <mesh filename="package://hip-rejoint_description/meshes/Component9__1__1.stl" scale="0.001 0.001 0.001"/>
      </geometry>
      <material name="steel_satin"/>
    </visual>
    <collision>
      <origin rpy="0 0 0" xyz="0.08185 0.040926 0.11572"/>
      <geometry>
        <mesh filename="package://hip-rejoint_description/meshes/Component9__1__1.stl" scale="0.001 0.001 0.001"/>
      </geometry>
    </collision>
  </link>
  <link name="Component4_1">
    <inertial>
      <origin rpy="0 0 0" xyz="4.5102810375396984e-17 -2.0160956237802452e-13 -0.0027446731476930067"/>
      <mass value="0.011955695388392617"/>
      <inertia ixx="1e-06" ixy="0.0" ixz="0.0" iyy="1e-06" iyz="0.0" izz="2e-06"/>
    </inertial>
    <visual>
      <origin rpy="0 0 0" xyz="0.025 0.0492 0.012658"/>
      <geometry>
        <mesh filename="package://hip-rejoint_description/meshes/Component4_1.stl" scale="0.001 0.001 0.001"/>
      </geometry>
      <material name="aluminum_satin"/>
    </visual>
    <collision>
      <origin rpy="0 0 0" xyz="0.025 0.0492 0.012658"/>
      <geometry>
        <mesh filename="package://hip-rejoint_description/meshes/Component4_1.stl" scale="0.001 0.001 0.001"/>
      </geometry>
    </collision>
  </link>
  <link name="Component32_1">
    <inertial>
      <origin rpy="0 0 0" xyz="0.0004621398104596615 -7.798356568446824e-05 -0.016749694753477054"/>
      <mass value="0.11550269835963742"/>
      <inertia ixx="4.9e-05" ixy="-0.0" ixz="-0.0" iyy="9.9e-05" iyz="0.0" izz="9.4e-05"/>
    </inertial>
    <visual>
      <origin rpy="0 0 0" xyz="0.025 0.0492 0.01797"/>
      <geometry>
        <mesh filename="package://hip-rejoint_description/meshes/Component32_1.stl" scale="0.001 0.001 0.001"/>
      </geometry>
      <material name="aluminum_satin"/>
    </visual>
    <collision>
      <origin rpy="0 0 0" xyz="0.025 0.0492 0.01797"/>
      <geometry>
        <mesh filename="package://hip-rejoint_description/meshes/Component32_1.stl" scale="0.001 0.001 0.001"/>
      </geometry>
    </collision>
  </link>
  <link name="15T-horn_v13_1">
    <inertial>
      <origin rpy="0 0 0" xyz="2.0469737016526324e-16 6.415796262119328e-05 -0.00120040750659281"/>
      <mass value="0.004179712167666874"/>
      <inertia ixx="1E-06" ixy="-0.0" ixz="-0.0" iyy="1E-06" iyz="0.0" izz="1E-06"/>
    </inertial>
    <visual>
      <origin rpy="0 0 0" xyz="0.025 0.0492 -0.036034"/>
      <geometry>
        <mesh filename="package://hip-rejoint_description/meshes/15T-horn_v13_1.stl" scale="0.001 0.001 0.001"/>
      </geometry>
      <material name="aluminum_satin"/>
    </visual>
    <collision>
      <origin rpy="0 0 0" xyz="0.025 0.0492 -0.036034"/>
      <geometry>
        <mesh filename="package://hip-rejoint_description/meshes/15T-horn_v13_1.stl" scale="0.001 0.001 0.001"/>
      </geometry>
    </collision>
  </link>
  <link name="JX_servo_v80_1">
    <inertial>
      <origin rpy="0 0 0" xyz="-0.0001431777001134303 0.01667036601891729 0.039010829286977536"/>
      <mass value="0.2114"/>
      <inertia ixx="0.001903" ixy="0.0" ixz="1e-06" iyy="0.001012" iyz="-4.9e-05" izz="0.001692"/>
    </inertial>
    <visual>
      <origin rpy="0 0 0" xyz="0.025 0.0492 -0.036134"/>
      <geometry>
        <mesh filename="package://hip-rejoint_description/meshes/JX_servo_v80_1.stl" scale="0.001 0.001 0.001"/>
      </geometry>
      <material name="polystyrene"/>
    </visual>
    <collision>
      <origin rpy="0 0 0" xyz="0.025 0.0492 -0.036134"/>
      <geometry>
        <mesh filename="package://hip-rejoint_description/meshes/JX_servo_v80_1.stl" scale="0.001 0.001 0.001"/>
      </geometry>
    </collision>
  </link>
  <link name="JX_servo_v80_2">
    <inertial>
      <mass value="0.379197"/>
      <origin rpy="0 0 0" xyz="0.008506622299886635 -0.015338763626409006 0.03892953398108233"/>
      <inertia ixx="0.001903" ixy="1e-06" ixz="-0.0" iyy="0.001692" iyz="4.9e-05" izz="0.001012"/>
    </inertial>
    <visual>
      <origin rpy="0 0 0" xyz="0.033249 0.036576 0.11572"/>
      <geometry>
        <mesh filename="package://hip-rejoint_description/meshes/JX_servo_v80_2.stl" scale="0.001 0.001 0.001"/>
      </geometry>
      <material name="polystyrene"/>
    </visual>
    <collision>
      <origin rpy="0 0 0" xyz="0.033249 0.036576 0.11572"/>
      <geometry>
        <mesh filename="package://hip-rejoint_description/meshes/JX_servo_v80_2.stl" scale="0.001 0.001 0.001"/>
      </geometry>
    </collision>
  </link>
  <link name="91590A121_External_Retaining_Ring_v1_4">
    <inertial>
      <origin rpy="0 0 0" xyz="-1.8006429680639258e-15 -0.0002861975695817448 -0.0003176000000000342"/>
      <mass value="0.00024760918611349786"/>
      <inertia ixx="1E-06" ixy="0.0" ixz="0.0" iyy="1E-06" iyz="0.0" izz="1E-06"/>
    </inertial>
    <visual>
      <origin rpy="0 0 0" xyz="0.025 -0.0592 0.012023"/>
      <geometry>
        <mesh filename="package://hip-rejoint_description/meshes/91590A121_External_Retaining_Ring_v1_4.stl" scale="0.001 0.001 0.001"/>
      </geometry>
      <material name="steel_satin"/>
    </visual>
    <collision>
      <origin rpy="0 0 0" xyz="0.025 -0.0592 0.012023"/>
      <geometry>
        <mesh filename="package://hip-rejoint_description/meshes/91590A121_External_Retaining_Ring_v1_4.stl" scale="0.001 0.001 0.001"/>
      </geometry>
    </collision>
  </link>
  <link name="Component4_2">
    <inertial>
      <origin rpy="0 0 0" xyz="1.1796119636642288e-16 -2.0084628404859473e-13 -0.002744673147693012"/>
      <mass value="0.011955695388392617"/>
      <inertia ixx="1e-06" ixy="0.0" ixz="0.0" iyy="1e-06" iyz="0.0" izz="2e-06"/>
    </inertial>
    <visual>
      <origin rpy="0 0 0" xyz="0.025 -0.0592 0.012658"/>
      <geometry>
        <mesh filename="package://hip-rejoint_description/meshes/Component4_2.stl" scale="0.001 0.001 0.001"/>
      </geometry>
      <material name="aluminum_satin"/>
    </visual>
    <collision>
      <origin rpy="0 0 0" xyz="0.025 -0.0592 0.012658"/>
      <geometry>
        <mesh filename="package://hip-rejoint_description/meshes/Component4_2.stl" scale="0.001 0.001 0.001"/>
      </geometry>
    </collision>
  </link>
  <link name="Component32_2">
    <inertial>
      <origin rpy="0 0 0" xyz="0.00046213981045967883 -7.798356568361475e-05 -0.016749694753476874"/>
      <mass value="0.11550269835963742"/>
      <inertia ixx="4.9e-05" ixy="-0.0" ixz="-0.0" iyy="9.9e-05" iyz="0.0" izz="9.4e-05"/>
    </inertial>
    <visual>
      <origin rpy="0 0 0" xyz="0.025 -0.0592 0.01797"/>
      <geometry>
        <mesh filename="package://hip-rejoint_description/meshes/Component32_2.stl" scale="0.001 0.001 0.001"/>
      </geometry>
      <material name="aluminum_satin"/>
    </visual>
    <collision>
      <origin rpy="0 0 0" xyz="0.025 -0.0592 0.01797"/>
      <geometry>
        <mesh filename="package://hip-rejoint_description/meshes/Component32_2.stl" scale="0.001 0.001 0.001"/>
      </geometry>
    </collision>
  </link>
  <link name="Component39_2">
    <inertial>
      <origin rpy="0 0 0" xyz="-0.004453658050594431 1.0708659720082281e-07 0.0072565028143726645"/>
      <mass value="0.015364690334044086"/>
      <inertia ixx="2e-06" ixy="-0.0" ixz="-0.0" iyy="1e-06" iyz="0.0" izz="1e-06"/>
    </inertial>
    <visual>
      <origin rpy="0 0 0" xyz="0.05665 -0.059124 0.06012"/>
      <geometry>
        <mesh filename="package://hip-rejoint_description/meshes/Component39_2.stl" scale="0.001 0.001 0.001"/>
      </geometry>
      <material name="aluminum_satin"/>
    </visual>
    <collision>
      <origin rpy="0 0 0" xyz="0.05665 -0.059124 0.06012"/>
      <geometry>
        <mesh filename="package://hip-rejoint_description/meshes/Component39_2.stl" scale="0.001 0.001 0.001"/>
      </geometry>
    </collision>
  </link>
  <link name="JX_servo_v80_5">
    <inertial>
      <origin rpy="0 0 0" xyz="-0.03281072928697726 -0.00014307061349891348 -0.016670466018917536"/>
      <mass value="0.2114"/>
      <inertia ixx="0.001692" ixy="-1e-06" ixz="-4.9e-05" iyy="0.001903" iyz="-0.0" izz="0.001012"/>
    </inertial>
    <visual>
      <origin rpy="0 0 0" xyz="0.06935 -0.059124 0.06012"/>
      <geometry>
        <mesh filename="package://hip-rejoint_description/meshes/JX_servo_v80_5.stl" scale="0.001 0.001 0.001"/>
      </geometry>
      <material name="polystyrene"/>
    </visual>
    <collision>
      <origin rpy="0 0 0" xyz="0.06935 -0.059124 0.06012"/>
      <geometry>
        <mesh filename="package://hip-rejoint_description/meshes/JX_servo_v80_5.stl" scale="0.001 0.001 0.001"/>
      </geometry>
    </collision>
  </link>
  <link name="JX_servo_v80_7">
    <inertial>
      <mass value="0.379197"/>
      <origin rpy="0 0 0" xyz="-0.00850702229988633 -0.010061022200362549 0.03892953398108248"/>
      <inertia ixx="0.001903" ixy="1e-06" ixz="0.0" iyy="0.001692" iyz="-4.9e-05" izz="0.001012"/>
    </inertial>
    <visual>
      <origin rpy="0 0 0" xyz="0.016249 -0.071824 0.11572"/>
      <geometry>
        <mesh filename="package://hip-rejoint_description/meshes/JX_servo_v80_7.stl" scale="0.001 0.001 0.001"/>
      </geometry>
      <material name="polystyrene"/>
    </visual>
    <collision>
      <origin rpy="0 0 0" xyz="0.016249 -0.071824 0.11572"/>
      <geometry>
        <mesh filename="package://hip-rejoint_description/meshes/JX_servo_v80_7.stl" scale="0.001 0.001 0.001"/>
      </geometry>
    </collision>
  </link>
  <link name="Component9__1__2">
    <inertial>
      <origin rpy="0 0 0" xyz="0.03333629681388656 -0.008439001260075997 -0.00027616991746280684"/>
      <mass value="0.13759034791983457"/>
      <inertia ixx="1e-05" ixy="-0.0" ixz="0.0" iyy="5.4e-05" iyz="0.0" izz="6.2e-05"/>
    </inertial>
    <visual>
      <origin rpy="0 0 0" xyz="0.08185 -0.067474 0.11572"/>
      <geometry>
        <mesh filename="package://hip-rejoint_description/meshes/Component9__1__2.stl" scale="0.001 0.001 0.001"/>
      </geometry>
      <material name="steel_satin"/>
    </visual>
    <collision>
      <origin rpy="0 0 0" xyz="0.08185 -0.067474 0.11572"/>
      <geometry>
        <mesh filename="package://hip-rejoint_description/meshes/Component9__1__2.stl" scale="0.001 0.001 0.001"/>
      </geometry>
    </collision>
  </link>
  <link name="91590A121_External_Retaining_Ring_v1_5">
    <inertial>
      <origin rpy="0 0 0" xyz="-1.8006429680639258e-15 -0.000286197569581606 0.00031759999999995026"/>
      <mass value="0.00024760918611349786"/>
      <inertia ixx="1E-06" ixy="0.0" ixz="-0.0" iyy="1E-06" iyz="0.0" izz="1E-06"/>
    </inertial>
    <visual>
      <origin rpy="0 0 0" xyz="0.025 -0.0592 0.000898"/>
      <geometry>
        <mesh filename="package://hip-rejoint_description/meshes/91590A121_External_Retaining_Ring_v1_5.stl" scale="0.001 0.001 0.001"/>
      </geometry>
      <material name="steel_satin"/>
    </visual>
    <collision>
      <origin rpy="0 0 0" xyz="0.025 -0.0592 0.000898"/>
      <geometry>
        <mesh filename="package://hip-rejoint_description/meshes/91590A121_External_Retaining_Ring_v1_5.stl" scale="0.001 0.001 0.001"/>
      </geometry>
    </collision>
  </link>
  <link name="91590A121_External_Retaining_Ring_v1_6">
    <inertial>
      <origin rpy="0 0 0" xyz="1.9463597400459776e-15 0.00028619756958262604 0.0003180000000000058"/>
      <mass value="0.00024760918611349786"/>
      <inertia ixx="1E-06" ixy="0.0" ixz="0.0" iyy="1E-06" iyz="0.0" izz="1E-06"/>
    </inertial>
    <visual>
      <origin rpy="0 0 0" xyz="0.025 -0.0592 -0.020717"/>
      <geometry>
        <mesh filename="package://hip-rejoint_description/meshes/91590A121_External_Retaining_Ring_v1_6.stl" scale="0.001 0.001 0.001"/>
      </geometry>
      <material name="steel_satin"/>
    </visual>
    <collision>
      <origin rpy="0 0 0" xyz="0.025 -0.0592 -0.020717"/>
      <geometry>
        <mesh filename="package://hip-rejoint_description/meshes/91590A121_External_Retaining_Ring_v1_6.stl" scale="0.001 0.001 0.001"/>
      </geometry>
    </collision>
  </link>
  <link name="2025K9_303_Stainless_Steel_Rotary_Shaft_with_Retaining_Ring_Grooves_v1_2">
    <inertial>
      <origin rpy="0 0 0" xyz="-3.676572934985245e-14 6.113304307220346e-13 -0.023450621315963708"/>
      <mass value="0.07269824555688346"/>
      <inertia ixx="3.6e-05" ixy="0.0" ixz="0.0" iyy="3.6e-05" iyz="0.0" izz="1e-06"/>
    </inertial>
    <visual>
      <origin rpy="0 0 0" xyz="0.025 -0.0592 -0.021353"/>
      <geometry>
        <mesh filename="package://hip-rejoint_description/meshes/2025K9_303_Stainless_Steel_Rotary_Shaft_with_Retaining_Ring_Grooves_v1_2.stl" scale="0.001 0.001 0.001"/>
      </geometry>
      <material name="steel_satin"/>
    </visual>
    <collision>
      <origin rpy="0 0 0" xyz="0.025 -0.0592 -0.021353"/>
      <geometry>
        <mesh filename="package://hip-rejoint_description/meshes/2025K9_303_Stainless_Steel_Rotary_Shaft_with_Retaining_Ring_Grooves_v1_2.stl" scale="0.001 0.001 0.001"/>
      </geometry>
    </collision>
  </link>
  <link name="Component6_2">
    <inertial>
      <origin rpy="0 0 0" xyz="2.6020852139652106e-16 6.415796262213003e-05 -0.0012004075065928446"/>
      <mass value="0.004179712167666874"/>
      <inertia ixx="1E-06" ixy="-0.0" ixz="-0.0" iyy="1E-06" iyz="0.0" izz="1E-06"/>
    </inertial>
    <visual>
      <origin rpy="0 0 0" xyz="0.025 -0.0592 -0.036034"/>
      <geometry>
        <mesh filename="package://hip-rejoint_description/meshes/Component6_2.stl" scale="0.001 0.001 0.001"/>
      </geometry>
      <material name="aluminum_satin"/>
    </visual>
    <collision>
      <origin rpy="0 0 0" xyz="0.025 -0.0592 -0.036034"/>
      <geometry>
        <mesh filename="package://hip-rejoint_description/meshes/Component6_2.stl" scale="0.001 0.001 0.001"/>
      </geometry>
    </collision>
  </link>
  <link name="JX_servo_v80_4">
    <inertial>
      <origin rpy="0 0 0" xyz="0.00014317770011336786 -0.01667036601891722 0.039010829286977286"/>
      <mass value="0.2114"/>
      <inertia ixx="0.001903" ixy="0.0" ixz="-1e-06" iyy="0.001012" iyz="4.9e-05" izz="0.001692"/>
    </inertial>
    <visual>
      <origin rpy="0 0 0" xyz="0.025 -0.0592 -0.036134"/>
      <geometry>
        <mesh filename="package://hip-rejoint_description/meshes/JX_servo_v80_4.stl" scale="0.001 0.001 0.001"/>
      </geometry>
      <material name="polystyrene"/>
    </visual>
    <collision>
      <origin rpy="0 0 0" xyz="0.025 -0.0592 -0.036134"/>
      <geometry>
        <mesh filename="package://hip-rejoint_description/meshes/JX_servo_v80_4.stl" scale="0.001 0.001 0.001"/>
      </geometry>
    </collision>
  </link>
  <link name="Component5_Mirror__1">
    <inertial>
      <origin rpy="0 0 0" xyz="0.00849980000000125 -0.015790650242165985 -0.03724237703561162"/>
      <mass value="0.09281870151638756"/>
      <inertia ixx="0.000217" ixy="0.0" ixz="0.0" iyy="0.000101" iyz="1e-06" izz="0.000141"/>
    </inertial>
    <visual>
      <origin rpy="0 0 0" xyz="0.033399 -0.082599 0.27572"/>
      <geometry>
        <mesh filename="package://hip-rejoint_description/meshes/Component5_Mirror__1.stl" scale="0.001 0.001 0.001"/>
      </geometry>
      <material name="abs_white"/>
    </visual>
    <collision>
      <origin rpy="0 0 0" xyz="0.033399 -0.082599 0.27572"/>
      <geometry>
        <mesh filename="package://hip-rejoint_description/meshes/Component5_Mirror__1.stl" scale="0.001 0.001 0.001"/>
      </geometry>
    </collision>
  </link>
  <link name="JX_servo_v46_Mirror__2">
    <inertial>
      <origin rpy="0 0 0" xyz="0.0002863268626021806 -0.03684144889674791 0.015402123693879166"/>
      <mass value="0.2114"/>
      <inertia ixx="0.000552" ixy="-6e-06" ixz="-0.0" iyy="0.00038" iyz="4.4e-05" izz="0.000359"/>
    </inertial>
    <visual>
      <origin rpy="0 0 0" xyz="0.024899 -0.104999 0.35932"/>
      <geometry>
        <mesh filename="package://hip-rejoint_description/meshes/JX_servo_v46_Mirror__2.stl" scale="0.001 0.001 0.001"/>
      </geometry>
      <material name="polystyrene"/>
    </visual>
    <collision>
      <origin rpy="0 0 0" xyz="0.024899 -0.104999 0.35932"/>
      <geometry>
        <mesh filename="package://hip-rejoint_description/meshes/JX_servo_v46_Mirror__2.stl" scale="0.001 0.001 0.001"/>
      </geometry>
    </collision>
  </link>
  <link name="L_Mirror__1">
    <inertial>
      <origin rpy="0 0 0" xyz="-0.042580019575537656 -0.014976084097356332 -0.010919051242128275"/>
      <mass value="0.045500552100246464"/>
      <inertia ixx="4.6e-05" ixy="-0.0" ixz="-1.8e-05" iyy="6.7e-05" iyz="-0.0" izz="4.1e-05"/>
    </inertial>
    <visual>
      <origin rpy="0 0 0" xyz="0.016399 -0.083299 0.30372"/>
      <geometry>
        <mesh filename="package://hip-rejoint_description/meshes/L_Mirror__1.stl" scale="0.001 0.001 0.001"/>
      </geometry>
      <material name="abs_white"/>
    </visual>
    <collision>
      <origin rpy="0 0 0" xyz="0.016399 -0.083299 0.30372"/>
      <geometry>
        <mesh filename="package://hip-rejoint_description/meshes/L_Mirror__1.stl" scale="0.001 0.001 0.001"/>
      </geometry>
    </collision>
  </link>
  <link name="JX_servo_v46_Mirror__3">
    <inertial>
      <origin rpy="0 0 0" xyz="-0.011241755983359566 -0.008786419775988846 -0.04019787630612176"/>
      <mass value="0.2114"/>
      <inertia ixx="0.00038" ixy="6e-06" ixz="4.4e-05" iyy="0.000552" iyz="0.0" izz="0.000359"/>
    </inertial>
    <visual>
      <origin rpy="0 0 0" xyz="0.083399 -0.076799 0.30382"/>
      <geometry>
        <mesh filename="package://hip-rejoint_description/meshes/JX_servo_v46_Mirror__3.stl" scale="0.001 0.001 0.001"/>
      </geometry>
      <material name="polystyrene"/>
    </visual>
    <collision>
      <origin rpy="0 0 0" xyz="0.083399 -0.076799 0.30382"/>
      <geometry>
        <mesh filename="package://hip-rejoint_description/meshes/JX_servo_v46_Mirror__3.stl" scale="0.001 0.001 0.001"/>
      </geometry>
    </collision>
  </link>
  <link name="left_foot">
    <inertial>
      <origin rpy="0 0 0" xyz="0.05767572802039587 0.00822898838496594 -0.03620809725608026"/>
      <mass value="0.18549302395679304"/>
      <inertia ixx="0.000167" ixy="-8e-06" ixz="2.3e-05" iyy="0.000496" iyz="8e-06" izz="0.000598"/>
    </inertial>
    <visual>
      <origin rpy="0 0 0" xyz="0.057799 -0.068299 0.35942"/>
      <geometry>
        <mesh filename="package://hip-rejoint_description/meshes/left_foot_1.stl" scale="0.001 0.001 0.001"/>
      </geometry>
      <material name="abs_white"/>
    </visual>
    <collision>
      <origin rpy="0 0 0" xyz="0.057799 -0.068299 0.35942"/>
      <geometry>
        <mesh filename="package://hip-rejoint_description/meshes/left_foot_1.stl" scale="0.001 0.001 0.001"/>
      </geometry>
    </collision>
  </link>
  <link name="Component4__2__1">
    <inertial>
      <origin rpy="0 0 0" xyz="0.0031599193508261396 -0.03836265805370774 -0.08477215129035257"/>
      <mass value="0.15906974524164488"/>
      <inertia ixx="0.000652" ixy="0.0" ixz="9e-06" iyy="0.000427" iyz="1e-06" izz="0.000271"/>
    </inertial>
    <visual>
      <origin rpy="0 0 0" xyz="0.024899 -0.104299 0.06012"/>
      <geometry>
        <mesh filename="package://hip-rejoint_description/meshes/Component4__2__1.stl" scale="0.001 0.001 0.001"/>
      </geometry>
      <material name="abs_white"/>
    </visual>
    <collision>
      <origin rpy="0 0 0" xyz="0.024899 -0.104299 0.06012"/>
      <geometry>
        <mesh filename="package://hip-rejoint_description/meshes/Component4__2__1.stl" scale="0.001 0.001 0.001"/>
      </geometry>
    </collision>
  </link>
  <link name="JX_servo_v46_Mirror__1">
    <inertial>
      <origin rpy="0 0 0" xyz="-0.0002867268625995935 -0.03684144889674752 -0.015402323693878978"/>
      <mass value="0.2114"/>
      <inertia ixx="0.000552" ixy="6e-06" ixz="-0.0" iyy="0.00038" iyz="-4.4e-05" izz="0.000359"/>
    </inertial>
    <visual>
      <origin rpy="0 0 0" xyz="0.024899 -0.104299 0.22012"/>
      <geometry>
        <mesh filename="package://hip-rejoint_description/meshes/JX_servo_v46_Mirror__1.stl" scale="0.001 0.001 0.001"/>
      </geometry>
      <material name="polystyrene"/>
    </visual>
    <collision>
      <origin rpy="0 0 0" xyz="0.024899 -0.104299 0.22012"/>
      <geometry>
        <mesh filename="package://hip-rejoint_description/meshes/JX_servo_v46_Mirror__1.stl" scale="0.001 0.001 0.001"/>
      </geometry>
    </collision>
  </link>
  <link name="Component4_Mirror___1__1">
    <inertial>
      <origin rpy="0 0 0" xyz="0.0031599193508256886 0.038362872226935844 -0.0847721512903529"/>
      <mass value="0.15906974524164494"/>
      <inertia ixx="0.000652" ixy="-0.0" ixz="9e-06" iyy="0.000427" iyz="-1e-06" izz="0.000271"/>
    </inertial>
    <visual>
      <origin rpy="0 0 0" xyz="0.024599 0.094451 0.06012"/>
      <geometry>
        <mesh filename="package://hip-rejoint_description/meshes/Component4_Mirror___1__1.stl" scale="0.001 0.001 0.001"/>
      </geometry>
      <material name="abs_white"/>
    </visual>
    <collision>
      <origin rpy="0 0 0" xyz="0.024599 0.094451 0.06012"/>
      <geometry>
        <mesh filename="package://hip-rejoint_description/meshes/Component4_Mirror___1__1.stl" scale="0.001 0.001 0.001"/>
      </geometry>
    </collision>
  </link>
  <link name="JX_servo_v46_Mirror__9">
    <inertial>
      <origin rpy="0 0 0" xyz="0.00028632686260030016 0.03684166306997537 -0.015402323693878894"/>
      <mass value="0.2114"/>
      <inertia ixx="0.000552" ixy="6e-06" ixz="0.0" iyy="0.00038" iyz="4.4e-05" izz="0.000359"/>
    </inertial>
    <visual>
      <origin rpy="0 0 0" xyz="0.024599 0.094451 0.22012"/>
      <geometry>
        <mesh filename="package://hip-rejoint_description/meshes/JX_servo_v46_Mirror__9.stl" scale="0.001 0.001 0.001"/>
      </geometry>
      <material name="polystyrene"/>
    </visual>
    <collision>
      <origin rpy="0 0 0" xyz="0.024599 0.094451 0.22012"/>
      <geometry>
        <mesh filename="package://hip-rejoint_description/meshes/JX_servo_v46_Mirror__9.stl" scale="0.001 0.001 0.001"/>
      </geometry>
    </collision>
  </link>
  <link name="Component5_Mirror__Mirror__1">
    <inertial>
      <origin rpy="0 0 0" xyz="0.00849979999999968 0.01579086441539357 -0.03724237703561162"/>
      <mass value="0.09281870151638758"/>
      <inertia ixx="0.000217" ixy="0.0" ixz="0.0" iyy="0.000101" iyz="-1e-06" izz="0.000141"/>
    </inertial>
    <visual>
      <origin rpy="0 0 0" xyz="0.033099 0.072751 0.27572"/>
      <geometry>
        <mesh filename="package://hip-rejoint_description/meshes/Component5_Mirror__Mirror__1.stl" scale="0.001 0.001 0.001"/>
      </geometry>
      <material name="abs_white"/>
    </visual>
    <collision>
      <origin rpy="0 0 0" xyz="0.033099 0.072751 0.27572"/>
      <geometry>
        <mesh filename="package://hip-rejoint_description/meshes/Component5_Mirror__Mirror__1.stl" scale="0.001 0.001 0.001"/>
      </geometry>
    </collision>
  </link>
  <link name="JX_servo_v46_Mirror__7">
    <inertial>
      <origin rpy="0 0 0" xyz="-0.0002867268626019111 0.03684166306997542 0.015402123693879555"/>
      <mass value="0.2114"/>
      <inertia ixx="0.000552" ixy="-6e-06" ixz="0.0" iyy="0.00038" iyz="-4.4e-05" izz="0.000359"/>
    </inertial>
    <visual>
      <origin rpy="0 0 0" xyz="0.024599 0.095151 0.35932"/>
      <geometry>
        <mesh filename="package://hip-rejoint_description/meshes/JX_servo_v46_Mirror__7.stl" scale="0.001 0.001 0.001"/>
      </geometry>
      <material name="polystyrene"/>
    </visual>
    <collision>
      <origin rpy="0 0 0" xyz="0.024599 0.095151 0.35932"/>
      <geometry>
        <mesh filename="package://hip-rejoint_description/meshes/JX_servo_v46_Mirror__7.stl" scale="0.001 0.001 0.001"/>
      </geometry>
    </collision>
  </link>
  <link name="L_Mirror__3">
    <inertial>
      <origin rpy="0 0 0" xyz="-0.042580019575540445 0.015023915902644375 -0.010819051242127342"/>
      <mass value="0.045500552100246464"/>
      <inertia ixx="4.6e-05" ixy="-0.0" ixz="-1.8e-05" iyy="6.7e-05" iyz="-0.0" izz="4.1e-05"/>
    </inertial>
    <visual>
      <origin rpy="0 0 0" xyz="0.016099 0.073451 0.30372"/>
      <geometry>
        <mesh filename="package://hip-rejoint_description/meshes/L_Mirror__3.stl" scale="0.001 0.001 0.001"/>
      </geometry>
      <material name="abs_white"/>
    </visual>
    <collision>
      <origin rpy="0 0 0" xyz="0.016099 0.073451 0.30372"/>
      <geometry>
        <mesh filename="package://hip-rejoint_description/meshes/L_Mirror__3.stl" scale="0.001 0.001 0.001"/>
      </geometry>
    </collision>
  </link>
  <link name="JX_servo_v46_Mirror__8">
    <inertial>
      <origin rpy="0 0 0" xyz="-0.011241755983362356 -0.008786419775988014 0.03500212369387967"/>
      <mass value="0.2114"/>
      <inertia ixx="0.00038" ixy="6e-06" ixz="4.4e-05" iyy="0.000552" iyz="0.0" izz="0.000359"/>
    </inertial>
    <visual>
      <origin rpy="0 0 0" xyz="0.083099 0.049951 0.37892"/>
      <geometry>
        <mesh filename="package://hip-rejoint_description/meshes/JX_servo_v46_Mirror__8.stl" scale="0.001 0.001 0.001"/>
      </geometry>
      <material name="polystyrene"/>
    </visual>
    <collision>
      <origin rpy="0 0 0" xyz="0.083099 0.049951 0.37892"/>
      <geometry>
        <mesh filename="package://hip-rejoint_description/meshes/JX_servo_v46_Mirror__8.stl" scale="0.001 0.001 0.001"/>
      </geometry>
    </collision>
  </link>
  <link name="right_foot">
    <inertial>
      <origin rpy="0 0 0" xyz="0.05767574370347767 -0.008228774425991459 -0.036208099196046395"/>
      <mass value="0.1854930080519705"/>
      <inertia ixx="0.000167" ixy="8e-06" ixz="2.3e-05" iyy="0.000496" iyz="-8e-06" izz="0.000598"/>
    </inertial>
    <visual>
      <origin rpy="0 0 0" xyz="0.057499 0.058451 0.35932"/>
      <geometry>
        <mesh filename="package://hip-rejoint_description/meshes/right_foot_1.stl" scale="0.001 0.001 0.001"/>
      </geometry>
      <material name="abs_white"/>
    </visual>
    <collision>
      <origin rpy="0 0 0" xyz="0.057499 0.058451 0.35932"/>
      <geometry>
        <mesh filename="package://hip-rejoint_description/meshes/right_foot_1.stl" scale="0.001 0.001 0.001"/>
      </geometry>
    </collision>
  </link>
  <link name="Component65_1">
    <inertial>
      <origin rpy="0 0 0" xyz="-0.057027622259124396 -0.005184392153188431 -0.031750299999999634"/>
      <mass value="0.550045164280725"/>
      <inertia ixx="0.002078" ixy="-0.0" ixz="0.0" iyy="0.000783" iyz="0.0" izz="0.002491"/>
    </inertial>
    <visual>
      <origin rpy="0 0 0" xyz="0.04015 -0.0102 -0.103234"/>
      <geometry>
        <mesh filename="package://hip-rejoint_description/meshes/Component65_1.stl" scale="0.001 0.001 0.001"/>
      </geometry>
      <material name="abs_white"/>
    </visual>
    <collision>
      <origin rpy="0 0 0" xyz="0.04015 -0.0102 -0.103234"/>
      <geometry>
        <mesh filename="package://hip-rejoint_description/meshes/Component65_1.stl" scale="0.001 0.001 0.001"/>
      </geometry>
    </collision>
  </link>
  <link name="Component66_1">
    <inertial>
      <origin rpy="0 0 0" xyz="0.023575000000000013 1.7780915628762273e-16 -0.022700299999999646"/>
      <mass value="0.3199209891539211"/>
      <inertia ixx="0.000447" ixy="-0.0" ixz="0.0" iyy="0.000104" iyz="0.0" izz="0.000517"/>
    </inertial>
    <visual>
      <origin rpy="0 0 0" xyz="0.1543 -0.005 -0.103234"/>
      <geometry>
        <mesh filename="package://hip-rejoint_description/meshes/Component66_1.stl" scale="0.001 0.001 0.001"/>
      </geometry>
      <material name="brass_polished"/>
    </visual>
    <collision>
      <origin rpy="0 0 0" xyz="0.1543 -0.005 -0.103234"/>
      <geometry>
        <mesh filename="package://hip-rejoint_description/meshes/Component66_1.stl" scale="0.001 0.001 0.001"/>
      </geometry>
    </collision>
  </link>
  <link name="JX_servo_v46_Mirror__10">
    <inertial>
      <origin rpy="0 0 0" xyz="-0.00028652686259981325 -0.036841555983361404 -0.015402523693878463"/>
      <mass value="0.2114"/>
      <inertia ixx="0.000552" ixy="6e-06" ixz="-0.0" iyy="0.00038" iyz="-4.4e-05" izz="0.000359"/>
    </inertial>
    <visual>
      <origin rpy="0 0 0" xyz="0.04 0.0966 -0.071484"/>
      <geometry>
        <mesh filename="package://hip-rejoint_description/meshes/JX_servo_v46_Mirror__10.stl" scale="0.001 0.001 0.001"/>
      </geometry>
      <material name="polystyrene"/>
    </visual>
    <collision>
      <origin rpy="0 0 0" xyz="0.04 0.0966 -0.071484"/>
      <geometry>
        <mesh filename="package://hip-rejoint_description/meshes/JX_servo_v46_Mirror__10.stl" scale="0.001 0.001 0.001"/>
      </geometry>
    </collision>
  </link>
  <link name="JX_servo_v46_Mirror__11">
    <inertial>
      <origin rpy="0 0 0" xyz="0.008213473137395816 0.015141555983359672 -0.04019807630612032"/>
      <mass value="0.2114"/>
      <inertia ixx="0.000552" ixy="-6e-06" ixz="0.0" iyy="0.00038" iyz="-4.4e-05" izz="0.000359"/>
    </inertial>
    <visual>
      <origin rpy="0 0 0" xyz="0.0485 0.1542 -0.015784"/>
      <geometry>
        <mesh filename="package://hip-rejoint_description/meshes/JX_servo_v46_Mirror__11.stl" scale="0.001 0.001 0.001"/>
      </geometry>
      <material name="polystyrene"/>
    </visual>
    <collision>
      <origin rpy="0 0 0" xyz="0.0485 0.1542 -0.015784"/>
      <geometry>
        <mesh filename="package://hip-rejoint_description/meshes/JX_servo_v46_Mirror__11.stl" scale="0.001 0.001 0.001"/>
      </geometry>
    </collision>
  </link>
  <link name="JX_servo_v46_Mirror__12">
    <inertial>
      <origin rpy="0 0 0" xyz="0.00028652686259972304 0.03684155598336175 -0.015402523693878518"/>
      <mass value="0.2114"/>
      <inertia ixx="0.000552" ixy="6e-06" ixz="0.0" iyy="0.00038" iyz="4.4e-05" izz="0.000359"/>
    </inertial>
    <visual>
      <origin rpy="0 0 0" xyz="0.04 -0.1066 -0.071484"/>
      <geometry>
        <mesh filename="package://hip-rejoint_description/meshes/JX_servo_v46_Mirror__12.stl" scale="0.001 0.001 0.001"/>
      </geometry>
      <material name="polystyrene"/>
    </visual>
    <collision>
      <origin rpy="0 0 0" xyz="0.04 -0.1066 -0.071484"/>
      <geometry>
        <mesh filename="package://hip-rejoint_description/meshes/JX_servo_v46_Mirror__12.stl" scale="0.001 0.001 0.001"/>
      </geometry>
    </collision>
  </link>
  <link name="JX_servo_v46_Mirror__13">
    <inertial>
      <origin rpy="0 0 0" xyz="0.008786526862586554 -0.015141555983359062 -0.04019807630612043"/>
      <mass value="0.2114"/>
      <inertia ixx="0.000552" ixy="-6e-06" ixz="-0.0" iyy="0.00038" iyz="4.4e-05" izz="0.000359"/>
    </inertial>
    <visual>
      <origin rpy="0 0 0" xyz="0.0485 -0.1642 -0.015784"/>
      <geometry>
        <mesh filename="package://hip-rejoint_description/meshes/JX_servo_v46_Mirror__13.stl" scale="0.001 0.001 0.001"/>
      </geometry>
      <material name="polystyrene"/>
    </visual>
    <collision>
      <origin rpy="0 0 0" xyz="0.0485 -0.1642 -0.015784"/>
      <geometry>
        <mesh filename="package://hip-rejoint_description/meshes/JX_servo_v46_Mirror__13.stl" scale="0.001 0.001 0.001"/>
      </geometry>
    </collision>
  </link>
  <link name="Component11_Mirror__2">
    <inertial>
      <origin rpy="0 0 0" xyz="1.174060848541103e-14 -0.0015000000000024716 -2.9999999917595943e-07"/>
      <mass value="0.003775795544427548"/>
      <inertia ixx="1E-06" ixy="-0.0" ixz="-0.0" iyy="1e-06" iyz="-0.0" izz="1E-06"/>
    </inertial>
    <visual>
      <origin rpy="0 0 0" xyz="0.04 0.1759 0.039816"/>
      <geometry>
        <mesh filename="package://hip-rejoint_description/meshes/Component11_Mirror__2.stl" scale="0.001 0.001 0.001"/>
      </geometry>
      <material name="plastic_matte_black"/>
    </visual>
    <collision>
      <origin rpy="0 0 0" xyz="0.04 0.1759 0.039816"/>
      <geometry>
        <mesh filename="package://hip-rejoint_description/meshes/Component11_Mirror__2.stl" scale="0.001 0.001 0.001"/>
      </geometry>
    </collision>
  </link>
  <link name="Component11_Mirror__3">
    <inertial>
      <origin rpy="0 0 0" xyz="-6.654399253847032e-15 0.0015000000000029712 -2.999999990996316e-07"/>
      <mass value="0.003775795544427548"/>
      <inertia ixx="1E-06" ixy="-0.0" ixz="0.0" iyy="1e-06" iyz="-0.0" izz="1E-06"/>
    </inertial>
    <visual>
      <origin rpy="0 0 0" xyz="0.04 -0.1859 0.039816"/>
      <geometry>
        <mesh filename="package://hip-rejoint_description/meshes/Component11_Mirror__3.stl" scale="0.001 0.001 0.001"/>
      </geometry>
      <material name="plastic_matte_black"/>
    </visual>
    <collision>
      <origin rpy="0 0 0" xyz="0.04 -0.1859 0.039816"/>
      <geometry>
        <mesh filename="package://hip-rejoint_description/meshes/Component11_Mirror__3.stl" scale="0.001 0.001 0.001"/>
      </geometry>
    </collision>
  </link>
  <link name="trunk">
    <inertial>
      <origin rpy="0 0 0" xyz="-0.024999999999999932 2.511766836188478e-13 -4.075620637523491e-05"/>
      <mass value="0.19337373769234342"/>
      <inertia ixx="0.000494" ixy="0.0" ixz="-0.0" iyy="4.6e-05" iyz="0.0" izz="0.000538"/>
    </inertial>
    <visual>
      <origin rpy="0 0 0" xyz="0.0 -0.005 -0.005"/>
      <geometry>
        <mesh filename="package://hip-rejoint_description/meshes/trunk_1.stl" scale="0.001 0.001 0.001"/>
      </geometry>
      <material name="acrylic_red"/>
    </visual>
    <collision>
      <origin rpy="0 0 0" xyz="0.0 -0.005 -0.005"/>
      <geometry>
        <mesh filename="package://hip-rejoint_description/meshes/trunk_1.stl" scale="0.001 0.001 0.001"/>
      </geometry>
    </collision>
  </link>
  <link name="custom_servo_support__lower_neck__v2_1">
    <inertial>
      <origin rpy="0 0 0" xyz="-0.0001873462042440155 1.1439633962329054e-14 0.001965903992148993"/>
      <mass value="0.0030444171650099846"/>
      <inertia ixx="1E-06" ixy="-0.0" ixz="0.0" iyy="1E-06" iyz="-0.0" izz="1e-06"/>
    </inertial>
    <visual>
      <origin rpy="0 0 0" xyz="0.09715 -0.005 -0.103234"/>
      <geometry>
        <mesh filename="package://hip-rejoint_description/meshes/custom_servo_support__lower_neck__v2_1.stl" scale="0.001 0.001 0.001"/>
      </geometry>
      <material name="plastic_glossy_black"/>
    </visual>
    <collision>
      <origin rpy="0 0 0" xyz="0.09715 -0.005 -0.103234"/>
      <geometry>
        <mesh filename="package://hip-rejoint_description/meshes/custom_servo_support__lower_neck__v2_1.stl" scale="0.001 0.001 0.001"/>
      </geometry>
    </collision>
  </link>
  <link name="gobilda-servo_1">
    <inertial>
      <origin rpy="0 0 0" xyz="-0.021069107694159497 -1.343324230497489e-09 0.019801967478668275"/>
      <mass value="0.06058731126055281"/>
      <inertia ixx="7e-06" ixy="0.0" ixz="-0.0" iyy="1.4e-05" iyz="0.0" izz="1e-05"/>
    </inertial>
    <visual>
      <origin rpy="0 0 0" xyz="0.077 -0.005 -0.106214"/>
      <geometry>
        <mesh filename="package://hip-rejoint_description/meshes/gobilda-servo_1.stl" scale="0.001 0.001 0.001"/>
      </geometry>
      <material name="plastic_glossy_grey"/>
    </visual>
    <collision>
      <origin rpy="0 0 0" xyz="0.077 -0.005 -0.106214"/>
      <geometry>
        <mesh filename="package://hip-rejoint_description/meshes/gobilda-servo_1.stl" scale="0.001 0.001 0.001"/>
      </geometry>
    </collision>
  </link>
  <link name="25t-servo-hub_1">
    <inertial>
      <origin rpy="0 0 0" xyz="-4.778934504928722e-07 1.6215494579117223e-07 -0.0003424918529943699"/>
      <mass value="0.005584850212079893"/>
      <inertia ixx="1E-06" ixy="-0.0" ixz="-0.0" iyy="1E-06" iyz="0.0" izz="1E-06"/>
    </inertial>
    <visual>
      <origin rpy="0 0 0" xyz="0.0883 -0.005 -0.147134"/>
      <geometry>
        <mesh filename="package://hip-rejoint_description/meshes/25t-servo-hub_1.stl" scale="0.001 0.001 0.001"/>
      </geometry>
      <material name="aluminum_satin"/>
    </visual>
    <collision>
      <origin rpy="0 0 0" xyz="0.0883 -0.005 -0.147134"/>
      <geometry>
        <mesh filename="package://hip-rejoint_description/meshes/25t-servo-hub_1.stl" scale="0.001 0.001 0.001"/>
      </geometry>
    </collision>
  </link>
  <link name="neck_1">
    <inertial>
      <origin rpy="0 0 0" xyz="2.761679773755077e-15 -0.001757162936255714 0.016322497824422827"/>
      <mass value="0.015465374363363156"/>
      <inertia ixx="1.1e-05" ixy="-0.0" ixz="-0.0" iyy="5e-06" iyz="0.0" izz="9e-06"/>
    </inertial>
    <visual>
      <origin rpy="0 0 0" xyz="0.0883 -0.005 -0.149928"/>
      <geometry>
        <mesh filename="package://hip-rejoint_description/meshes/neck_1.stl" scale="0.001 0.001 0.001"/>
      </geometry>
      <material name="abs_white"/>
    </visual>
    <collision>
      <origin rpy="0 0 0" xyz="0.0883 -0.005 -0.149928"/>
      <geometry>
        <mesh filename="package://hip-rejoint_description/meshes/neck_1.stl" scale="0.001 0.001 0.001"/>
      </geometry>
    </collision>
  </link>
  <link name="25t-servo-hub_2">
    <inertial>
      <origin rpy="0 0 0" xyz="-4.778934504928722e-07 -0.0031361918529911464 7.907080462610239e-09"/>
      <mass value="0.005584850212079893"/>
      <inertia ixx="1E-06" ixy="-0.0" ixz="0.0" iyy="1E-06" iyz="-0.0" izz="1E-06"/>
    </inertial>
    <visual>
      <origin rpy="0 0 0" xyz="0.0883 -0.031187 -0.183745"/>
      <geometry>
        <mesh filename="package://hip-rejoint_description/meshes/25t-servo-hub_2.stl" scale="0.001 0.001 0.001"/>
      </geometry>
      <material name="aluminum_satin"/>
    </visual>
    <collision>
      <origin rpy="0 0 0" xyz="0.0883 -0.031187 -0.183745"/>
      <geometry>
        <mesh filename="package://hip-rejoint_description/meshes/25t-servo-hub_2.stl" scale="0.001 0.001 0.001"/>
      </geometry>
    </collision>
  </link>
  <link name="gobilda-servo_2">
    <inertial>
      <origin rpy="0 0 0" xyz="0.009769107694159326 -0.021117732521328484 1.6871870181511817e-07"/>
      <mass value="0.06058731126055281"/>
      <inertia ixx="7e-06" ixy="0.0" ixz="-0.0" iyy="1e-05" iyz="0.0" izz="1.4e-05"/>
    </inertial>
    <visual>
      <origin rpy="0 0 0" xyz="0.0883 -0.028393 -0.183745"/>
      <geometry>
        <mesh filename="package://hip-rejoint_description/meshes/gobilda-servo_2.stl" scale="0.001 0.001 0.001"/>
      </geometry>
      <material name="plastic_glossy_grey"/>
    </visual>
    <collision>
      <origin rpy="0 0 0" xyz="0.0883 -0.028393 -0.183745"/>
      <geometry>
        <mesh filename="package://hip-rejoint_description/meshes/gobilda-servo_2.stl" scale="0.001 0.001 0.001"/>
      </geometry>
    </collision>
  </link>
  <link name="head_1">
    <inertial>
      <origin rpy="0 0 0" xyz="0.019537949594635937 0.009180173124962852 0.00755420273403995"/>
      <mass value="0.007653734054253099"/>
      <inertia ixx="2e-06" ixy="0.0" ixz="0.0" iyy="3e-06" iyz="-0.0" izz="3e-06"/>
    </inertial>
    <visual>
      <origin rpy="0 0 0" xyz="0.0996 0.012527 -0.183745"/>
      <geometry>
        <mesh filename="package://hip-rejoint_description/meshes/head_1.stl" scale="0.001 0.001 0.001"/>
      </geometry>
      <material name="abs_white"/>
    </visual>
    <collision>
      <origin rpy="0 0 0" xyz="0.0996 0.012527 -0.183745"/>
      <geometry>
        <mesh filename="package://hip-rejoint_description/meshes/head_1.stl" scale="0.001 0.001 0.001"/>
      </geometry>
    </collision>
  </link>
  <link name="camera_1">
    <inertial>
      <origin rpy="0 0 0" xyz="0.014184397326867326 -1.0758781820467342e-05 0.01921531813692287"/>
      <mass value="0.094257141411043"/>
      <inertia ixx="5.2e-05" ixy="0.0" ixz="-1.1e-05" iyy="4.3e-05" iyz="-0.0" izz="6.9e-05"/>
    </inertial>
    <visual>
      <origin rpy="0 0 0" xyz="0.0863 -0.005493 -0.204745"/>
      <geometry>
        <mesh filename="package://hip-rejoint_description/meshes/camera_1.stl" scale="0.001 0.001 0.001"/>
      </geometry>
      <material name="plastic_glossy_black"/>
    </visual>
    <collision>
      <origin rpy="0 0 0" xyz="0.0863 -0.005493 -0.204745"/>
      <geometry>
        <mesh filename="package://hip-rejoint_description/meshes/camera_1.stl" scale="0.001 0.001 0.001"/>
      </geometry>
    </collision>
  </link>
  <joint name="Rigid 2" type="fixed">
    <origin rpy="0 0 0" xyz="-0.025 0.0542 0.004763"/>
    <parent link="trunk"/>
    <child link="R8-2RS_Bearing_1"/>
  </joint>
  <joint name="Rigid 3" type="fixed">
    <origin rpy="0 0 0" xyz="-0.025 0.0542 0.004763"/>
    <parent link="trunk"/>
    <child link="R8-2RS_Bearing_2"/>
  </joint>
  <joint name="Rigid 4" type="fixed">
    <origin rpy="0 0 0" xyz="-0.025 -0.0542 0.004762"/>
    <parent link="trunk"/>
    <child link="R8-2RS_Bearing_3"/>
  </joint>
  <joint name="Rigid 5" type="fixed">
    <origin rpy="0 0 0" xyz="0.0 0.0 1e-06"/>
    <parent link="R8-2RS_Bearing_3"/>
    <child link="R8-2RS_Bearing_4"/>
  </joint>
  <joint name="Rigid 6" type="fixed">
    <origin rpy="0 0 0" xyz="-0.025 0.0542 0.004763"/>
    <parent link="trunk"/>
    <child link="Component2_2"/>
  </joint>
  <joint name="Rigid 7" type="fixed">
    <origin rpy="0 0 0" xyz="-0.025 -0.0542 0.004762"/>
    <parent link="trunk"/>
    <child link="Component2_1"/>
  </joint>
  <joint name="Rigid 8" type="fixed">
    <origin rpy="0 0 0" xyz="0.0 0.0 0.010956"/>
    <parent link="Component2_1"/>
    <child link="91590A121_External_Retaining_Ring_v1_2"/>
  </joint>
  <joint name="right_hip_yaw" type="continuous">
    <origin rpy="0 0 0" xyz="0.0 0.0 0.000635"/>
    <parent link="91590A121_External_Retaining_Ring_v1_2"/>
    <child link="2025K9_303_Stainless_Steel_Rotary_Shaft_with_Retaining_Ring_Grooves_v1_1"/>
    <axis xyz="0.0 0.0 -1.0"/>
  </joint>
  <joint name="Rigid 10" type="fixed">
    <origin rpy="0 0 0" xyz="0.0 0.0 -0.022251"/>
    <parent link="2025K9_303_Stainless_Steel_Rotary_Shaft_with_Retaining_Ring_Grooves_v1_1"/>
    <child link="91590A121_External_Retaining_Ring_v1_3"/>
  </joint>
  <joint name="Rigid 11" type="fixed">
    <origin rpy="0 0 0" xyz="0.0 0.0 -0.033376"/>
    <parent link="2025K9_303_Stainless_Steel_Rotary_Shaft_with_Retaining_Ring_Grooves_v1_1"/>
    <child link="91590A121_External_Retaining_Ring_v1_1"/>
  </joint>
  <joint name="Rigid 12" type="fixed">
    <origin rpy="0 0 0" xyz="-0.03165 -7.6e-05 -0.04215"/>
    <parent link="Component32_1"/>
    <child link="Component39_1"/>
  </joint>
  <joint name="right_hip_roll" type="continuous">
    <origin rpy="0 0 0" xyz="-0.0127 0.0 0.0"/>
    <parent link="Component39_1"/>
    <child link="JX_servo_v80_3"/>
    <axis xyz="1.0 0.0 0.0"/>
  </joint>
  <joint name="Rigid 15" type="fixed">
    <origin rpy="0 0 0" xyz="-0.0125 0.00835 -0.0556"/>
    <parent link="JX_servo_v80_3"/>
    <child link="Component9__1__1"/>
  </joint>
  <joint name="Rigid 16" type="fixed">
    <origin rpy="0 0 0" xyz="0.0 0.0 -0.000635"/>
    <parent link="91590A121_External_Retaining_Ring_v1_1"/>
    <child link="Component4_1"/>
  </joint>
  <joint name="Rigid 17" type="fixed">
    <origin rpy="0 0 0" xyz="0.0 0.0 -0.005312"/>
    <parent link="Component4_1"/>
    <child link="Component32_1"/>
  </joint>
  <joint name="Rigid 18" type="fixed">
    <origin rpy="0 0 0" xyz="0.0 0.0 0.014681"/>
    <parent link="2025K9_303_Stainless_Steel_Rotary_Shaft_with_Retaining_Ring_Grooves_v1_1"/>
    <child link="15T-horn_v13_1"/>
  </joint>
  <joint name="Rigid 19" type="fixed">
    <origin rpy="0 0 0" xyz="0.0 0.0 0.0001"/>
    <parent link="15T-horn_v13_1"/>
    <child link="JX_servo_v80_1"/>
  </joint>
  <joint name="Rigid 20" type="fixed">
    <origin rpy="0 0 0" xyz="0.048601 0.00435 0.0"/>
    <parent link="Component9__1__1"/>
    <child link="JX_servo_v80_2"/>
  </joint>
  <joint name="Rigid 21" type="fixed">
    <origin rpy="0 0 0" xyz="0.0 0.0 -0.033376"/>
    <parent link="2025K9_303_Stainless_Steel_Rotary_Shaft_with_Retaining_Ring_Grooves_v1_2"/>
    <child link="91590A121_External_Retaining_Ring_v1_4"/>
  </joint>
  <joint name="Rigid 22" type="fixed">
    <origin rpy="0 0 0" xyz="0.0 0.0 -0.000635"/>
    <parent link="91590A121_External_Retaining_Ring_v1_4"/>
    <child link="Component4_2"/>
  </joint>
  <joint name="Rigid 23" type="fixed">
    <origin rpy="0 0 0" xyz="0.0 0.0 -0.005312"/>
    <parent link="Component4_2"/>
    <child link="Component32_2"/>
  </joint>
  <joint name="Rigid 24" type="fixed">
    <origin rpy="0 0 0" xyz="-0.03165 -7.6e-05 -0.04215"/>
    <parent link="Component32_2"/>
    <child link="Component39_2"/>
  </joint>
  <joint name="left_hip_roll" type="continuous">
    <origin rpy="0 0 0" xyz="-0.0127 0.0 0.0"/>
    <parent link="Component39_2"/>
    <child link="JX_servo_v80_5"/>
    <axis xyz="1.0 0.0 0.0"/>
  </joint>
  <joint name="Rigid 26" type="fixed">
    <origin rpy="0 0 0" xyz="0.065601 0.00435 0.0"/>
    <parent link="Component9__1__2"/>
    <child link="JX_servo_v80_7"/>
  </joint>
  <joint name="Rigid 27" type="fixed">
    <origin rpy="0 0 0" xyz="-0.0125 0.00835 -0.0556"/>
    <parent link="JX_servo_v80_5"/>
    <child link="Component9__1__2"/>
  </joint>
  <joint name="Rigid 28" type="fixed">
    <origin rpy="0 0 0" xyz="0.0 0.0 -0.022251"/>
    <parent link="2025K9_303_Stainless_Steel_Rotary_Shaft_with_Retaining_Ring_Grooves_v1_2"/>
    <child link="91590A121_External_Retaining_Ring_v1_5"/>
  </joint>
  <joint name="Rigid 29" type="fixed">
    <origin rpy="0 0 0" xyz="0.0 0.0 0.010954"/>
    <parent link="Component2_2"/>
    <child link="91590A121_External_Retaining_Ring_v1_6"/>
  </joint>
  <joint name="left_hip_yaw" type="continuous">
    <origin rpy="0 0 0" xyz="0.0 0.0 0.000636"/>
    <parent link="91590A121_External_Retaining_Ring_v1_6"/>
    <child link="2025K9_303_Stainless_Steel_Rotary_Shaft_with_Retaining_Ring_Grooves_v1_2"/>
    <axis xyz="0.0 0.0 -1.0"/>
  </joint>
  <joint name="Rigid 31" type="fixed">
    <origin rpy="0 0 0" xyz="0.0 0.0 0.014681"/>
    <parent link="2025K9_303_Stainless_Steel_Rotary_Shaft_with_Retaining_Ring_Grooves_v1_2"/>
    <child link="Component6_2"/>
  </joint>
  <joint name="Rigid 32" type="fixed">
    <origin rpy="0 0 0" xyz="0.0 0.0 0.0001"/>
    <parent link="Component6_2"/>
    <child link="JX_servo_v80_4"/>
  </joint>
  <joint name="Rigid 35" type="fixed">
    <origin rpy="0 0 0" xyz="-0.0085 -0.0217 -0.0556"/>
    <parent link="JX_servo_v46_Mirror__1"/>
    <child link="Component5_Mirror__1"/>
  </joint>
  <joint name="left_ankle_pitch" type="continuous">
    <origin rpy="0 0 0" xyz="0.0085 0.0224 -0.0836"/>
    <parent link="Component5_Mirror__1"/>
    <child link="JX_servo_v46_Mirror__2"/>
    <axis xyz="-0.0 1.0 -0.0"/>
  </joint>
  <joint name="Rigid 37" type="fixed">
    <origin rpy="0 0 0" xyz="0.0085 -0.0217 0.0556"/>
    <parent link="JX_servo_v46_Mirror__2"/>
    <child link="L_Mirror__1"/>
  </joint>
  <joint name="Rigid 38" type="fixed">
    <origin rpy="0 0 0" xyz="-0.067 -0.0065 -0.0001"/>
    <parent link="L_Mirror__1"/>
    <child link="JX_servo_v46_Mirror__3"/>
  </joint>
  <joint name="left_ankle_roll" type="continuous">
    <origin rpy="0 0 0" xyz="0.0256 -0.0085 -0.0556"/>
    <parent link="JX_servo_v46_Mirror__3"/>
    <child link="left_foot"/>
    <axis xyz="1.0 0.0 -0.0"/>
  </joint>
  <joint name="left_hip_pitch" type="continuous">
    <origin rpy="0 0 0" xyz="-0.00865 0.032475 0.0556"/>
    <parent link="JX_servo_v80_7"/>
    <child link="Component4__2__1"/>
    <axis xyz="-0.0 -1.0 0.0"/>
  </joint>
  <joint name="left_knee" type="continuous">
    <origin rpy="0 0 0" xyz="0.0 0.0 -0.16"/>
    <parent link="Component4__2__1"/>
    <child link="JX_servo_v46_Mirror__1"/>
    <axis xyz="-0.0 1.0 -0.0"/>
  </joint>
  <joint name="right_hip_pitch" type="continuous">
    <origin rpy="0 0 0" xyz="0.00865 -0.057875 0.0556"/>
    <parent link="JX_servo_v80_2"/>
    <child link="Component4_Mirror___1__1"/>
    <axis xyz="0.0 1.0 -0.0"/>
  </joint>
  <joint name="right_knee" type="continuous">
    <origin rpy="0 0 0" xyz="0.0 0.0 -0.16"/>
    <parent link="Component4_Mirror___1__1"/>
    <child link="JX_servo_v46_Mirror__9"/>
    <axis xyz="0.0 1.0 -0.0"/>
  </joint>
  <joint name="Rigid 44" type="fixed">
    <origin rpy="0 0 0" xyz="-0.0085 0.0217 -0.0556"/>
    <parent link="JX_servo_v46_Mirror__9"/>
    <child link="Component5_Mirror__Mirror__1"/>
  </joint>
  <joint name="right_ankle_pitch" type="continuous">
    <origin rpy="0 0 0" xyz="0.0085 -0.0224 -0.0836"/>
    <parent link="Component5_Mirror__Mirror__1"/>
    <child link="JX_servo_v46_Mirror__7"/>
    <axis xyz="-0.0 1.0 -0.0"/>
  </joint>
  <joint name="Rigid 46" type="fixed">
    <origin rpy="0 0 0" xyz="0.0085 0.0217 0.0556"/>
    <parent link="JX_servo_v46_Mirror__7"/>
    <child link="L_Mirror__3"/>
  </joint>
  <joint name="Rigid 47" type="fixed">
    <origin rpy="0 0 0" xyz="-0.067 0.0235 -0.0752"/>
    <parent link="L_Mirror__3"/>
    <child link="JX_servo_v46_Mirror__8"/>
  </joint>
  <joint name="right_ankle_roll" type="continuous">
    <origin rpy="0 0 0" xyz="0.0256 -0.0085 0.0196"/>
    <parent link="JX_servo_v46_Mirror__8"/>
    <child link="right_foot"/>
    <axis xyz="1.0 0.0 -0.0"/>
  </joint>
  <joint name="Rigid 50" type="fixed">
    <origin rpy="0 0 0" xyz="-0.01515 0.0594 0.0671"/>
    <parent link="JX_servo_v80_1"/>
    <child link="Component65_1"/>
  </joint>
  <joint name="Rigid 51" type="fixed">
    <origin rpy="0 0 0" xyz="-0.11415 -0.0052 0.0"/>
    <parent link="Component65_1"/>
    <child link="Component66_1"/>
  </joint>
  <joint name="right_shoulder_pitch" type="continuous">
    <origin rpy="0 0 0" xyz="0.00015 -0.1068 -0.03175"/>
    <parent link="Component65_1"/>
    <child link="JX_servo_v46_Mirror__10"/>
    <axis xyz="0.0 -1.0 -0.0"/>
  </joint>
  <joint name="Rigid 53" type="fixed">
    <origin rpy="0 0 0" xyz="-0.0085 -0.0576 -0.0557"/>
    <parent link="JX_servo_v46_Mirror__10"/>
    <child link="JX_servo_v46_Mirror__11"/>
  </joint>
  <joint name="left_shoulder_pitch" type="continuous">
    <origin rpy="0 0 0" xyz="0.00015 0.0964 -0.03175"/>
    <parent link="Component65_1"/>
    <child link="JX_servo_v46_Mirror__12"/>
    <axis xyz="-0.0 1.0 0.0"/>
  </joint>
  <joint name="Rigid 55" type="fixed">
    <origin rpy="0 0 0" xyz="-0.0085 0.0576 -0.0557"/>
    <parent link="JX_servo_v46_Mirror__12"/>
    <child link="JX_servo_v46_Mirror__13"/>
  </joint>
  <joint name="right_elbow" type="continuous">
    <origin rpy="0 0 0" xyz="0.0085 -0.0217 -0.0556"/>
    <parent link="JX_servo_v46_Mirror__11"/>
    <child link="Component11_Mirror__2"/>
    <axis xyz="0.0 -1.0 0.0"/>
  </joint>
  <joint name="left_elbow" type="continuous">
    <origin rpy="0 0 0" xyz="0.0085 0.0217 -0.0556"/>
    <parent link="JX_servo_v46_Mirror__13"/>
    <child link="Component11_Mirror__3"/>
    <axis xyz="-0.0 1.0 0.0"/>
  </joint>
  <joint name="Rigid 58" type="fixed">
    <origin rpy="0 0 0" xyz="0.0 0.005 0.005"/>
    <parent link="base_link"/>
    <child link="trunk"/>
  </joint>
  <joint name="Rigid 59" type="fixed">
    <origin rpy="0 0 0" xyz="-0.057 -0.0052 0.0"/>
    <parent link="Component65_1"/>
    <child link="custom_servo_support__lower_neck__v2_1"/>
  </joint>
  <joint name="Rigid 60" type="fixed">
    <origin rpy="0 0 0" xyz="0.02015 0.0 0.00298"/>
    <parent link="custom_servo_support__lower_neck__v2_1"/>
    <child link="gobilda-servo_1"/>
  </joint>
  <joint name="Rigid 61" type="fixed">
    <origin rpy="0 0 0" xyz="-0.0113 0.0 0.04092"/>
    <parent link="gobilda-servo_1"/>
    <child link="25t-servo-hub_1"/>
  </joint>
  <joint name="head_yaw" type="continuous">
    <origin rpy="0 0 0" xyz="0.0 0.0 0.002794"/>
    <parent link="25t-servo-hub_1"/>
    <child link="neck_1"/>
    <axis xyz="-0.0 0.0 1.0"/>
  </joint>
  <joint name="head_pitch" type="continuous">
    <origin rpy="0 0 0" xyz="0.0 0.026187 0.033817"/>
    <parent link="neck_1"/>
    <child link="25t-servo-hub_2"/>
    <axis xyz="-0.0 1.0 -0.0"/>
  </joint>
  <joint name="Rigid 64" type="fixed">
    <origin rpy="0 0 0" xyz="0.0 -0.002794 0.0"/>
    <parent link="25t-servo-hub_2"/>
    <child link="gobilda-servo_2"/>
  </joint>
  <joint name="Rigid 65" type="fixed">
    <origin rpy="0 0 0" xyz="-0.0113 -0.04092 0.0"/>
    <parent link="gobilda-servo_2"/>
    <child link="head_1"/>
  </joint>
  <joint name="Rigid 66" type="fixed">
    <origin rpy="0 0 0" xyz="0.0133 0.01802 0.021"/>
    <parent link="head_1"/>
    <child link="camera_1"/>
  </joint>
</robot>

