<?xml version="1.0" ?>
<robot name="hip-rejoint" xmlns:xacro="http://www.ros.org/wiki/xacro">
  <!-- 
    Steps to generate model:

    - Joint and export in Fusion
    - Generate URDF from xacro via:
      - `conda activate py2; rosrun xacro xacro '/path/to/model.xacro' > '/path/to/model.urdf';`
    - Fix inertias in the URDF with `%s/i\(\w\)\1="\-*0.0"/i\1\1="1E-06"/g`
    - Rename `base_link` to `torso` in the URDF to accomodate placo
    - Rejoint `torso` to a new root link with a `floating` joint in URDF (i.e. `<link name="root" /><joint name="root-float" type="floating"><child link="torso" /><parent link="root" /></joint>`
    - Import to mujoco and save as XML
    - Ensure left and right foot links exist

    Further model fixes:
    - Reorient body to match world frame
    - Add sites to all servos via `%s/<body\(.*\)pos="\([^"]*\)">\(\_.\{-}\)<joint\(.*\)name="\([^"]*\)"/<site name="site_\5" pos="\2" \/><body\1pos="\2">\3<joint\4name="\5"/gi`
    - Add accelerometers and gyros to all sites with `sed` to generate the tag lists:
      - sed 's/<site name="site_\([^"]*\)".*>/\n<accelerometer name="xl_\1" site="site_\1" \/>\n/g' mjmodel.xml | grep '<accelerometer'
    - Disable collision geoms

    - Servo inertias are wrong because they are extracted with all options, including invisible ones. Since they're small, only fix masses depending on the servo enclosure option that is used.
  -->

  <mujoco>
    <compiler meshdir="../meshes" balanceinertia="true" discardvisual="false"/>
  </mujoco>

<xacro:include filename="$(find hip-rejoint_description)/urdf/materials.xacro" />
<xacro:include filename="$(find hip-rejoint_description)/urdf/hip-rejoint.trans" />
<xacro:include filename="$(find hip-rejoint_description)/urdf/hip-rejoint.gazebo" />
<link name="root" />
<link name="torso">
  <inertial>
    <origin xyz="-0.17198470578696426 -0.024251867789563585 -0.021093953275271887" rpy="0 0 0"/>
    <mass value="0.19337373769234342"/>
    <inertia ixx="4.6e-05" iyy="0.000538" izz="0.000494" ixy="0.0" iyz="-0.0" ixz="0.0"/>
  </inertial>
  <visual>
    <origin xyz="0 0 0" rpy="0 0 0"/>
    <geometry>
      <mesh filename="package://hip-rejoint_description/meshes/base_link.stl" scale="0.001 0.001 0.001"/>
    </geometry>
    <material name="acrylic_red"/>
  </visual>
  <collision>
    <origin xyz="0 0 0" rpy="0 0 0"/>
    <geometry>
      <mesh filename="package://hip-rejoint_description/meshes/base_link.stl" scale="0.001 0.001 0.001"/>
    </geometry>
  </collision>
</link>

<link name="R8-2RS_Bearing_1">
  <inertial>
    <origin xyz="2.942129484623246e-07 -0.003968361583188348 4.67247281074612e-08" rpy="0 0 0"/>
    <mass value="0.03206594861680248"/>
    <inertia ixx="2e-06" iyy="4e-06" izz="2e-06" ixy="-0.0" iyz="-0.0" ixz="0.0"/>
  </inertial>
  <visual>
    <origin xyz="0.117785 0.019449 0.021094" rpy="0 0 0"/>
    <geometry>
      <mesh filename="package://hip-rejoint_description/meshes/R8-2RS_Bearing_1.stl" scale="0.001 0.001 0.001"/>
    </geometry>
    <material name="steel_satin"/>
  </visual>
  <collision>
    <origin xyz="0.117785 0.019449 0.021094" rpy="0 0 0"/>
    <geometry>
      <mesh filename="package://hip-rejoint_description/meshes/R8-2RS_Bearing_1.stl" scale="0.001 0.001 0.001"/>
    </geometry>
  </collision>
</link>

<link name="R8-2RS_Bearing_2">
  <inertial>
    <origin xyz="2.9421294850395796e-07 0.003969138416811653 4.672472811093065e-08" rpy="0 0 0"/>
    <mass value="0.03206594861680248"/>
    <inertia ixx="2e-06" iyy="4e-06" izz="2e-06" ixy="-0.0" iyz="0.0" ixz="-0.0"/>
  </inertial>
  <visual>
    <origin xyz="0.117785 0.019449 0.021094" rpy="0 0 0"/>
    <geometry>
      <mesh filename="package://hip-rejoint_description/meshes/R8-2RS_Bearing_2.stl" scale="0.001 0.001 0.001"/>
    </geometry>
    <material name="steel_satin"/>
  </visual>
  <collision>
    <origin xyz="0.117785 0.019449 0.021094" rpy="0 0 0"/>
    <geometry>
      <mesh filename="package://hip-rejoint_description/meshes/R8-2RS_Bearing_2.stl" scale="0.001 0.001 0.001"/>
    </geometry>
  </collision>
</link>

<link name="R8-2RS_Bearing_3">
  <inertial>
    <origin xyz="2.9421294739373494e-07 -0.0039683615831883345 4.6724728045011155e-08" rpy="0 0 0"/>
    <mass value="0.03206594861680248"/>
    <inertia ixx="2e-06" iyy="4e-06" izz="2e-06" ixy="0.0" iyz="-0.0" ixz="0.0"/>
  </inertial>
  <visual>
    <origin xyz="0.226185 0.019449 0.021094" rpy="0 0 0"/>
    <geometry>
      <mesh filename="package://hip-rejoint_description/meshes/R8-2RS_Bearing_3.stl" scale="0.001 0.001 0.001"/>
    </geometry>
    <material name="steel_satin"/>
  </visual>
  <collision>
    <origin xyz="0.226185 0.019449 0.021094" rpy="0 0 0"/>
    <geometry>
      <mesh filename="package://hip-rejoint_description/meshes/R8-2RS_Bearing_3.stl" scale="0.001 0.001 0.001"/>
    </geometry>
  </collision>
</link>

<link name="R8-2RS_Bearing_4">
  <inertial>
    <origin xyz="2.9421294750475724e-07 0.003969138416811662 4.6724728045011155e-08" rpy="0 0 0"/>
    <mass value="0.03206594861680248"/>
    <inertia ixx="2e-06" iyy="4e-06" izz="2e-06" ixy="0.0" iyz="-0.0" ixz="0.0"/>
  </inertial>
  <visual>
    <origin xyz="0.226185 0.019449 0.021094" rpy="0 0 0"/>
    <geometry>
      <mesh filename="package://hip-rejoint_description/meshes/R8-2RS_Bearing_4.stl" scale="0.001 0.001 0.001"/>
    </geometry>
    <material name="steel_satin"/>
  </visual>
  <collision>
    <origin xyz="0.226185 0.019449 0.021094" rpy="0 0 0"/>
    <geometry>
      <mesh filename="package://hip-rejoint_description/meshes/R8-2RS_Bearing_4.stl" scale="0.001 0.001 0.001"/>
    </geometry>
  </collision>
</link>

<link name="Component2_2">
  <inertial>
    <origin xyz="2.942126966776204e-07 0.006598864666209372 4.672472816297235e-08" rpy="0 0 0"/>
    <mass value="0.043046314847355716"/>
    <inertia ixx="9e-06" iyy="1.6e-05" izz="9e-06" ixy="0.0" iyz="0.0" ixz="0.0"/>
  </inertial>
  <visual>
    <origin xyz="0.117785 0.019449 0.021094" rpy="0 0 0"/>
    <geometry>
      <mesh filename="package://hip-rejoint_description/meshes/Component2_2.stl" scale="0.001 0.001 0.001"/>
    </geometry>
    <material name="aluminum_satin"/>
  </visual>
  <collision>
    <origin xyz="0.117785 0.019449 0.021094" rpy="0 0 0"/>
    <geometry>
      <mesh filename="package://hip-rejoint_description/meshes/Component2_2.stl" scale="0.001 0.001 0.001"/>
    </geometry>
  </collision>
</link>

<link name="Component2_1">
  <inertial>
    <origin xyz="2.9421269573393083e-07 0.006598864666209387 4.672472808317507e-08" rpy="0 0 0"/>
    <mass value="0.043046314847355716"/>
    <inertia ixx="9e-06" iyy="1.6e-05" izz="9e-06" ixy="0.0" iyz="0.0" ixz="0.0"/>
  </inertial>
  <visual>
    <origin xyz="0.226185 0.019449 0.021094" rpy="0 0 0"/>
    <geometry>
      <mesh filename="package://hip-rejoint_description/meshes/Component2_1.stl" scale="0.001 0.001 0.001"/>
    </geometry>
    <material name="aluminum_satin"/>
  </visual>
  <collision>
    <origin xyz="0.226185 0.019449 0.021094" rpy="0 0 0"/>
    <geometry>
      <mesh filename="package://hip-rejoint_description/meshes/Component2_1.stl" scale="0.001 0.001 0.001"/>
    </geometry>
  </collision>
</link>

<link name="91590A121_External_Retaining_Ring_v1_2">
  <inertial>
    <origin xyz="0.00028649178236625494 0.0003178884168116656 4.6724729946268084e-08" rpy="0 0 0"/>
    <mass value="0.00024760918611349786"/>
    <inertia ixx="1E-06" iyy="1E-06" izz="1E-06" ixy="-0.0" iyz="-0.0" ixz="0.0"/>
  </inertial>
  <visual>
    <origin xyz="0.226185 0.008494 0.021094" rpy="0 0 0"/>
    <geometry>
      <mesh filename="package://hip-rejoint_description/meshes/91590A121_External_Retaining_Ring_v1_2.stl" scale="0.001 0.001 0.001"/>
    </geometry>
    <material name="steel_satin"/>
  </visual>
  <collision>
    <origin xyz="0.226185 0.008494 0.021094" rpy="0 0 0"/>
    <geometry>
      <mesh filename="package://hip-rejoint_description/meshes/91590A121_External_Retaining_Ring_v1_2.stl" scale="0.001 0.001 0.001"/>
    </geometry>
  </collision>
</link>

<link name="2025K9_303_Stainless_Steel_Rotary_Shaft_with_Retaining_Ring_Grooves_v1_1">
  <inertial>
    <origin xyz="2.9421339503565846e-07 -0.02344973289915206 4.672469118213729e-08" rpy="0 0 0"/>
    <mass value="0.07269824555688346"/>
    <inertia ixx="3.6e-05" iyy="1e-06" izz="3.6e-05" ixy="0.0" iyz="0.0" ixz="-0.0"/>
  </inertial>
  <visual>
    <origin xyz="0.226185 0.007859 0.021094" rpy="0 0 0"/>
    <geometry>
      <mesh filename="package://hip-rejoint_description/meshes/2025K9_303_Stainless_Steel_Rotary_Shaft_with_Retaining_Ring_Grooves_v1_1.stl" scale="0.001 0.001 0.001"/>
    </geometry>
    <material name="steel_satin"/>
  </visual>
  <collision>
    <origin xyz="0.226185 0.007859 0.021094" rpy="0 0 0"/>
    <geometry>
      <mesh filename="package://hip-rejoint_description/meshes/2025K9_303_Stainless_Steel_Rotary_Shaft_with_Retaining_Ring_Grooves_v1_1.stl" scale="0.001 0.001 0.001"/>
    </geometry>
  </collision>
</link>

<link name="91590A121_External_Retaining_Ring_v1_3">
  <inertial>
    <origin xyz="-0.0002859033567979563 0.00031748841681164194 4.672472619232648e-08" rpy="0 0 0"/>
    <mass value="0.00024760918611349786"/>
    <inertia ixx="1E-06" iyy="1E-06" izz="1E-06" ixy="0.0" iyz="0.0" ixz="0.0"/>
  </inertial>
  <visual>
    <origin xyz="0.226185 0.030109 0.021094" rpy="0 0 0"/>
    <geometry>
      <mesh filename="package://hip-rejoint_description/meshes/91590A121_External_Retaining_Ring_v1_3.stl" scale="0.001 0.001 0.001"/>
    </geometry>
    <material name="steel_satin"/>
  </visual>
  <collision>
    <origin xyz="0.226185 0.030109 0.021094" rpy="0 0 0"/>
    <geometry>
      <mesh filename="package://hip-rejoint_description/meshes/91590A121_External_Retaining_Ring_v1_3.stl" scale="0.001 0.001 0.001"/>
    </geometry>
  </collision>
</link>

<link name="91590A121_External_Retaining_Ring_v1_1">
  <inertial>
    <origin xyz="-0.0002859033567979563 -0.00031771158318838477 4.672472619232648e-08" rpy="0 0 0"/>
    <mass value="0.00024760918611349786"/>
    <inertia ixx="1E-06" iyy="1E-06" izz="1E-06" ixy="0.0" iyz="0.0" ixz="0.0"/>
  </inertial>
  <visual>
    <origin xyz="0.226185 0.041234 0.021094" rpy="0 0 0"/>
    <geometry>
      <mesh filename="package://hip-rejoint_description/meshes/91590A121_External_Retaining_Ring_v1_1.stl" scale="0.001 0.001 0.001"/>
    </geometry>
    <material name="steel_satin"/>
  </visual>
  <collision>
    <origin xyz="0.226185 0.041234 0.021094" rpy="0 0 0"/>
    <geometry>
      <mesh filename="package://hip-rejoint_description/meshes/91590A121_External_Retaining_Ring_v1_1.stl" scale="0.001 0.001 0.001"/>
    </geometry>
  </collision>
</link>

<link name="Component39_1">
  <inertial>
    <origin xyz="4.012993808366616e-07 0.007256391231184128 -0.004453611325866483" rpy="0 0 0"/>
    <mass value="0.015364690334044086"/>
    <inertia ixx="1e-06" iyy="1e-06" izz="2e-06" ixy="0.0" iyz="-0.0" ixz="-0.0"/>
  </inertial>
  <visual>
    <origin xyz="0.226261 0.089331 0.052744" rpy="0 0 0"/>
    <geometry>
      <mesh filename="package://hip-rejoint_description/meshes/Component39_1.stl" scale="0.001 0.001 0.001"/>
    </geometry>
    <material name="aluminum_satin"/>
  </visual>
  <collision>
    <origin xyz="0.226261 0.089331 0.052744" rpy="0 0 0"/>
    <geometry>
      <mesh filename="package://hip-rejoint_description/meshes/Component39_1.stl" scale="0.001 0.001 0.001"/>
    </geometry>
  </collision>
</link>

<link name="JX_servo_v80_3">
  <inertial>
    <origin xyz="-0.00014277640071522213 -0.01667057760210608 -0.032810682562249185" rpy="0 0 0"/>
    <mass value="0.2114"/>
    <inertia ixx="0.001903" iyy="0.001012" izz="0.001692" ixy="-0.0" iyz="-4.9e-05" ixz="-1e-06"/>
  </inertial>
  <visual>
    <origin xyz="0.226261 0.089331 0.065444" rpy="0 0 0"/>
    <geometry>
      <mesh filename="package://hip-rejoint_description/meshes/JX_servo_v80_3.stl" scale="0.001 0.001 0.001"/>
    </geometry>
    <material name="polystyrene"/>
  </visual>
  <collision>
    <origin xyz="0.226261 0.089331 0.065444" rpy="0 0 0"/>
    <geometry>
      <mesh filename="package://hip-rejoint_description/meshes/JX_servo_v80_3.stl" scale="0.001 0.001 0.001"/>
    </geometry>
  </collision>
</link>

<link name="Component9__1__1">
  <inertial>
    <origin xyz="-0.00843870704729241 -0.0002762815006513153 0.03333634353861456" rpy="0 0 0"/>
    <mass value="0.13759034791983457"/>
    <inertia ixx="5.4e-05" iyy="6.2e-05" izz="1e-05" ixy="0.0" iyz="0.0" ixz="-0.0"/>
  </inertial>
  <visual>
    <origin xyz="0.217911 0.144931 0.077944" rpy="0 0 0"/>
    <geometry>
      <mesh filename="package://hip-rejoint_description/meshes/Component9__1__1.stl" scale="0.001 0.001 0.001"/>
    </geometry>
    <material name="steel_satin"/>
  </visual>
  <collision>
    <origin xyz="0.217911 0.144931 0.077944" rpy="0 0 0"/>
    <geometry>
      <mesh filename="package://hip-rejoint_description/meshes/Component9__1__1.stl" scale="0.001 0.001 0.001"/>
    </geometry>
  </collision>
</link>

<link name="Component4_1">
  <inertial>
    <origin xyz="2.9421258293527153e-07 -0.0027447847308813556 4.672472811093065e-08" rpy="0 0 0"/>
    <mass value="0.011955695388392617"/>
    <inertia ixx="1e-06" iyy="2e-06" izz="1e-06" ixy="0.0" iyz="-0.0" ixz="0.0"/>
  </inertial>
  <visual>
    <origin xyz="0.226185 0.041869 0.021094" rpy="0 0 0"/>
    <geometry>
      <mesh filename="package://hip-rejoint_description/meshes/Component4_1.stl" scale="0.001 0.001 0.001"/>
    </geometry>
    <material name="aluminum_satin"/>
  </visual>
  <collision>
    <origin xyz="0.226185 0.041869 0.021094" rpy="0 0 0"/>
    <geometry>
      <mesh filename="package://hip-rejoint_description/meshes/Component4_1.stl" scale="0.001 0.001 0.001"/>
    </geometry>
  </collision>
</link>

<link name="Component32_1">
  <inertial>
    <origin xyz="-7.76893528999234e-05 -0.016749806336665382 0.00046218653518774466" rpy="0 0 0"/>
    <mass value="0.11550269835963742"/>
    <inertia ixx="9.9e-05" iyy="9.4e-05" izz="4.9e-05" ixy="0.0" iyz="-0.0" ixz="-0.0"/>
  </inertial>
  <visual>
    <origin xyz="0.226185 0.047181 0.021094" rpy="0 0 0"/>
    <geometry>
      <mesh filename="package://hip-rejoint_description/meshes/Component32_1.stl" scale="0.001 0.001 0.001"/>
    </geometry>
    <material name="aluminum_satin"/>
  </visual>
  <collision>
    <origin xyz="0.226185 0.047181 0.021094" rpy="0 0 0"/>
    <geometry>
      <mesh filename="package://hip-rejoint_description/meshes/Component32_1.stl" scale="0.001 0.001 0.001"/>
    </geometry>
  </collision>
</link>

<link name="15T-horn_v13_1">
  <inertial>
    <origin xyz="6.445217540576587e-05 -0.0012005190897811545 4.672472825317797e-08" rpy="0 0 0"/>
    <mass value="0.004179712167666874"/>
    <inertia ixx="1E-06" iyy="1E-06" izz="1E-06" ixy="0.0" iyz="-0.0" ixz="0.0"/>
  </inertial>
  <visual>
    <origin xyz="0.226185 -0.006823 0.021094" rpy="0 0 0"/>
    <geometry>
      <mesh filename="package://hip-rejoint_description/meshes/15T-horn_v13_1.stl" scale="0.001 0.001 0.001"/>
    </geometry>
    <material name="aluminum_satin"/>
  </visual>
  <collision>
    <origin xyz="0.226185 -0.006823 0.021094" rpy="0 0 0"/>
    <geometry>
      <mesh filename="package://hip-rejoint_description/meshes/15T-horn_v13_1.stl" scale="0.001 0.001 0.001"/>
    </geometry>
  </collision>
</link>

<link name="JX_servo_v80_1">
  <inertial>
    <origin xyz="0.0166706602317018 0.03901071770378921 -0.00014313097538535408" rpy="0 0 0"/>
    <mass value="0.2114"/>
    <inertia ixx="0.001012" iyy="0.001692" izz="0.001903" ixy="-4.9e-05" iyz="1e-06" ixz="0.0"/>
  </inertial>
  <visual>
    <origin xyz="0.226185 -0.006923 0.021094" rpy="0 0 0"/>
    <geometry>
      <mesh filename="package://hip-rejoint_description/meshes/JX_servo_v80_1.stl" scale="0.001 0.001 0.001"/>
    </geometry>
    <material name="polystyrene"/>
  </visual>
  <collision>
    <origin xyz="0.226185 -0.006923 0.021094" rpy="0 0 0"/>
    <geometry>
      <mesh filename="package://hip-rejoint_description/meshes/JX_servo_v80_1.stl" scale="0.001 0.001 0.001"/>
    </geometry>
  </collision>
</link>

<link name="JX_servo_v80_2">
  <inertial>
    <origin xyz="-0.015338469413624434 0.03892942239789397 0.008506669024614683" rpy="0 0 0"/>
    <mass value="0.379197"/>
    <inertia ixx="0.001692" iyy="0.001012" izz="0.001903" ixy="4.9e-05" iyz="-0.0" ixz="1e-06"/>
  </inertial>
  <visual>
    <origin xyz="0.213561 0.144931 0.029343" rpy="0 0 0"/>
    <geometry>
      <mesh filename="package://hip-rejoint_description/meshes/JX_servo_v80_2.stl" scale="0.001 0.001 0.001"/>
    </geometry>
    <material name="polystyrene"/>
  </visual>
  <collision>
    <origin xyz="0.213561 0.144931 0.029343" rpy="0 0 0"/>
    <geometry>
      <mesh filename="package://hip-rejoint_description/meshes/JX_servo_v80_2.stl" scale="0.001 0.001 0.001"/>
    </geometry>
  </collision>
</link>

<link name="91590A121_External_Retaining_Ring_v1_4">
  <inertial>
    <origin xyz="-0.0002859033567972208 -0.00031771158318838477 4.672472627212376e-08" rpy="0 0 0"/>
    <mass value="0.00024760918611349786"/>
    <inertia ixx="1E-06" iyy="1E-06" izz="1E-06" ixy="0.0" iyz="0.0" ixz="0.0"/>
  </inertial>
  <visual>
    <origin xyz="0.117785 0.041234 0.021094" rpy="0 0 0"/>
    <geometry>
      <mesh filename="package://hip-rejoint_description/meshes/91590A121_External_Retaining_Ring_v1_4.stl" scale="0.001 0.001 0.001"/>
    </geometry>
    <material name="steel_satin"/>
  </visual>
  <collision>
    <origin xyz="0.117785 0.041234 0.021094" rpy="0 0 0"/>
    <geometry>
      <mesh filename="package://hip-rejoint_description/meshes/91590A121_External_Retaining_Ring_v1_4.stl" scale="0.001 0.001 0.001"/>
    </geometry>
  </collision>
</link>

<link name="Component4_2">
  <inertial>
    <origin xyz="2.9421258371242764e-07 -0.0027447847308813625 4.6724728190727927e-08" rpy="0 0 0"/>
    <mass value="0.011955695388392617"/>
    <inertia ixx="1e-06" iyy="2e-06" izz="1e-06" ixy="0.0" iyz="0.0" ixz="0.0"/>
  </inertial>
  <visual>
    <origin xyz="0.117785 0.041869 0.021094" rpy="0 0 0"/>
    <geometry>
      <mesh filename="package://hip-rejoint_description/meshes/Component4_2.stl" scale="0.001 0.001 0.001"/>
    </geometry>
    <material name="aluminum_satin"/>
  </visual>
  <collision>
    <origin xyz="0.117785 0.041869 0.021094" rpy="0 0 0"/>
    <geometry>
      <mesh filename="package://hip-rejoint_description/meshes/Component4_2.stl" scale="0.001 0.001 0.001"/>
    </geometry>
  </collision>
</link>

<link name="Component32_2">
  <inertial>
    <origin xyz="-7.768935289907686e-05 -0.016749806336665243 0.00046218653518772385" rpy="0 0 0"/>
    <mass value="0.11550269835963742"/>
    <inertia ixx="9.9e-05" iyy="9.4e-05" izz="4.9e-05" ixy="0.0" iyz="-0.0" ixz="-0.0"/>
  </inertial>
  <visual>
    <origin xyz="0.117785 0.047181 0.021094" rpy="0 0 0"/>
    <geometry>
      <mesh filename="package://hip-rejoint_description/meshes/Component32_2.stl" scale="0.001 0.001 0.001"/>
    </geometry>
    <material name="aluminum_satin"/>
  </visual>
  <collision>
    <origin xyz="0.117785 0.047181 0.021094" rpy="0 0 0"/>
    <geometry>
      <mesh filename="package://hip-rejoint_description/meshes/Component32_2.stl" scale="0.001 0.001 0.001"/>
    </geometry>
  </collision>
</link>

<link name="Component39_2">
  <inertial>
    <origin xyz="4.012993817387178e-07 0.007256391231184323 -0.004453611325866379" rpy="0 0 0"/>
    <mass value="0.015364690334044086"/>
    <inertia ixx="1e-06" iyy="1e-06" izz="2e-06" ixy="0.0" iyz="-0.0" ixz="-0.0"/>
  </inertial>
  <visual>
    <origin xyz="0.117861 0.089331 0.052744" rpy="0 0 0"/>
    <geometry>
      <mesh filename="package://hip-rejoint_description/meshes/Component39_2.stl" scale="0.001 0.001 0.001"/>
    </geometry>
    <material name="aluminum_satin"/>
  </visual>
  <collision>
    <origin xyz="0.117861 0.089331 0.052744" rpy="0 0 0"/>
    <geometry>
      <mesh filename="package://hip-rejoint_description/meshes/Component39_2.stl" scale="0.001 0.001 0.001"/>
    </geometry>
  </collision>
</link>

<link name="JX_servo_v80_5">
  <inertial>
    <origin xyz="-0.00014277640071438946 -0.016670577602105885 -0.03281068256224917" rpy="0 0 0"/>
    <mass value="0.2114"/>
    <inertia ixx="0.001903" iyy="0.001012" izz="0.001692" ixy="-0.0" iyz="-4.9e-05" ixz="-1e-06"/>
  </inertial>
  <visual>
    <origin xyz="0.117861 0.089331 0.065444" rpy="0 0 0"/>
    <geometry>
      <mesh filename="package://hip-rejoint_description/meshes/JX_servo_v80_5.stl" scale="0.001 0.001 0.001"/>
    </geometry>
    <material name="polystyrene"/>
  </visual>
  <collision>
    <origin xyz="0.117861 0.089331 0.065444" rpy="0 0 0"/>
    <geometry>
      <mesh filename="package://hip-rejoint_description/meshes/JX_servo_v80_5.stl" scale="0.001 0.001 0.001"/>
    </geometry>
  </collision>
</link>

<link name="JX_servo_v80_7">
  <inertial>
    <origin xyz="-0.010060727987577997 0.03892942239789415 -0.008506975575158279" rpy="0 0 0"/>
    <mass value="0.379197"/>
    <inertia ixx="0.001692" iyy="0.001012" izz="0.001903" ixy="-4.9e-05" iyz="0.0" ixz="1e-06"/>
  </inertial>
  <visual>
    <origin xyz="0.105161 0.144931 0.012343" rpy="0 0 0"/>
    <geometry>
      <mesh filename="package://hip-rejoint_description/meshes/JX_servo_v80_7.stl" scale="0.001 0.001 0.001"/>
    </geometry>
    <material name="polystyrene"/>
  </visual>
  <collision>
    <origin xyz="0.105161 0.144931 0.012343" rpy="0 0 0"/>
    <geometry>
      <mesh filename="package://hip-rejoint_description/meshes/JX_servo_v80_7.stl" scale="0.001 0.001 0.001"/>
    </geometry>
  </collision>
</link>

<link name="Component9__1__2">
  <inertial>
    <origin xyz="-0.008438707047291494 -0.00027628150065114876 0.0333363435386146" rpy="0 0 0"/>
    <mass value="0.13759034791983457"/>
    <inertia ixx="5.4e-05" iyy="6.2e-05" izz="1e-05" ixy="0.0" iyz="0.0" ixz="-0.0"/>
  </inertial>
  <visual>
    <origin xyz="0.109511 0.144931 0.077944" rpy="0 0 0"/>
    <geometry>
      <mesh filename="package://hip-rejoint_description/meshes/Component9__1__2.stl" scale="0.001 0.001 0.001"/>
    </geometry>
    <material name="steel_satin"/>
  </visual>
  <collision>
    <origin xyz="0.109511 0.144931 0.077944" rpy="0 0 0"/>
    <geometry>
      <mesh filename="package://hip-rejoint_description/meshes/Component9__1__2.stl" scale="0.001 0.001 0.001"/>
    </geometry>
  </collision>
</link>

<link name="91590A121_External_Retaining_Ring_v1_5">
  <inertial>
    <origin xyz="-0.000285903356797082 0.00031748841681159337 4.672472627559321e-08" rpy="0 0 0"/>
    <mass value="0.00024760918611349786"/>
    <inertia ixx="1E-06" iyy="1E-06" izz="1E-06" ixy="0.0" iyz="0.0" ixz="0.0"/>
  </inertial>
  <visual>
    <origin xyz="0.117785 0.030109 0.021094" rpy="0 0 0"/>
    <geometry>
      <mesh filename="package://hip-rejoint_description/meshes/91590A121_External_Retaining_Ring_v1_5.stl" scale="0.001 0.001 0.001"/>
    </geometry>
    <material name="steel_satin"/>
  </visual>
  <collision>
    <origin xyz="0.117785 0.030109 0.021094" rpy="0 0 0"/>
    <geometry>
      <mesh filename="package://hip-rejoint_description/meshes/91590A121_External_Retaining_Ring_v1_5.stl" scale="0.001 0.001 0.001"/>
    </geometry>
  </collision>
</link>

<link name="91590A121_External_Retaining_Ring_v1_6">
  <inertial>
    <origin xyz="0.0002864917823671709 0.00031788841681165 4.6724730026065364e-08" rpy="0 0 0"/>
    <mass value="0.00024760918611349786"/>
    <inertia ixx="1E-06" iyy="1E-06" izz="1E-06" ixy="0.0" iyz="0.0" ixz="0.0"/>
  </inertial>
  <visual>
    <origin xyz="0.117785 0.008494 0.021094" rpy="0 0 0"/>
    <geometry>
      <mesh filename="package://hip-rejoint_description/meshes/91590A121_External_Retaining_Ring_v1_6.stl" scale="0.001 0.001 0.001"/>
    </geometry>
    <material name="steel_satin"/>
  </visual>
  <collision>
    <origin xyz="0.117785 0.008494 0.021094" rpy="0 0 0"/>
    <geometry>
      <mesh filename="package://hip-rejoint_description/meshes/91590A121_External_Retaining_Ring_v1_6.stl" scale="0.001 0.001 0.001"/>
    </geometry>
  </collision>
</link>

<link name="2025K9_303_Stainless_Steel_Rotary_Shaft_with_Retaining_Ring_Grooves_v1_2">
  <inertial>
    <origin xyz="2.9421339585444795e-07 -0.02344973289915206 4.672469127234291e-08" rpy="0 0 0"/>
    <mass value="0.07269824555688346"/>
    <inertia ixx="3.6e-05" iyy="1e-06" izz="3.6e-05" ixy="0.0" iyz="0.0" ixz="0.0"/>
  </inertial>
  <visual>
    <origin xyz="0.117785 0.007859 0.021094" rpy="0 0 0"/>
    <geometry>
      <mesh filename="package://hip-rejoint_description/meshes/2025K9_303_Stainless_Steel_Rotary_Shaft_with_Retaining_Ring_Grooves_v1_2.stl" scale="0.001 0.001 0.001"/>
    </geometry>
    <material name="steel_satin"/>
  </visual>
  <collision>
    <origin xyz="0.117785 0.007859 0.021094" rpy="0 0 0"/>
    <geometry>
      <mesh filename="package://hip-rejoint_description/meshes/2025K9_303_Stainless_Steel_Rotary_Shaft_with_Retaining_Ring_Grooves_v1_2.stl" scale="0.001 0.001 0.001"/>
    </geometry>
  </collision>
</link>

<link name="Component6_2">
  <inertial>
    <origin xyz="6.445217540662629e-05 -0.0012005190897811926 4.672472834685304e-08" rpy="0 0 0"/>
    <mass value="0.004179712167666874"/>
    <inertia ixx="1E-06" iyy="1E-06" izz="1E-06" ixy="0.0" iyz="-0.0" ixz="-0.0"/>
  </inertial>
  <visual>
    <origin xyz="0.117785 -0.006823 0.021094" rpy="0 0 0"/>
    <geometry>
      <mesh filename="package://hip-rejoint_description/meshes/Component6_2.stl" scale="0.001 0.001 0.001"/>
    </geometry>
    <material name="aluminum_satin"/>
  </visual>
  <collision>
    <origin xyz="0.117785 -0.006823 0.021094" rpy="0 0 0"/>
    <geometry>
      <mesh filename="package://hip-rejoint_description/meshes/Component6_2.stl" scale="0.001 0.001 0.001"/>
    </geometry>
  </collision>
</link>

<link name="JX_servo_v80_4">
  <inertial>
    <origin xyz="-0.01667007180613264 0.03901071770378893 0.00014322442484144063" rpy="0 0 0"/>
    <mass value="0.2114"/>
    <inertia ixx="0.001012" iyy="0.001692" izz="0.001903" ixy="4.9e-05" iyz="-1e-06" ixz="0.0"/>
  </inertial>
  <visual>
    <origin xyz="0.117785 -0.006923 0.021094" rpy="0 0 0"/>
    <geometry>
      <mesh filename="package://hip-rejoint_description/meshes/JX_servo_v80_4.stl" scale="0.001 0.001 0.001"/>
    </geometry>
    <material name="polystyrene"/>
  </visual>
  <collision>
    <origin xyz="0.117785 -0.006923 0.021094" rpy="0 0 0"/>
    <geometry>
      <mesh filename="package://hip-rejoint_description/meshes/JX_servo_v80_4.stl" scale="0.001 0.001 0.001"/>
    </geometry>
  </collision>
</link>

<link name="Component5_Mirror__1">
  <inertial>
    <origin xyz="-0.01579035602938142 -0.037242488618799974 0.008499846724729292" rpy="0 0 0"/>
    <mass value="0.09281870151638756"/>
    <inertia ixx="0.000101" iyy="0.000141" izz="0.000217" ixy="1e-06" iyz="0.0" ixz="0.0"/>
  </inertial>
  <visual>
    <origin xyz="0.094386 0.304931 0.029493" rpy="0 0 0"/>
    <geometry>
      <mesh filename="package://hip-rejoint_description/meshes/Component5_Mirror__1.stl" scale="0.001 0.001 0.001"/>
    </geometry>
    <material name="abs_white"/>
  </visual>
  <collision>
    <origin xyz="0.094386 0.304931 0.029493" rpy="0 0 0"/>
    <geometry>
      <mesh filename="package://hip-rejoint_description/meshes/Component5_Mirror__1.stl" scale="0.001 0.001 0.001"/>
    </geometry>
  </collision>
</link>

<link name="JX_servo_v46_Mirror__2">
  <inertial>
    <origin xyz="-0.03684115468396337 0.015402012110690366 0.00028637358733015275" rpy="0 0 0"/>
    <mass value="0.2114"/>
    <inertia ixx="0.00038" iyy="0.000359" izz="0.000552" ixy="4.4e-05" iyz="-0.0" ixz="-6e-06"/>
  </inertial>
  <visual>
    <origin xyz="0.071986 0.388531 0.020993" rpy="0 0 0"/>
    <geometry>
      <mesh filename="package://hip-rejoint_description/meshes/JX_servo_v46_Mirror__2.stl" scale="0.001 0.001 0.001"/>
    </geometry>
    <material name="polystyrene"/>
  </visual>
  <collision>
    <origin xyz="0.071986 0.388531 0.020993" rpy="0 0 0"/>
    <geometry>
      <mesh filename="package://hip-rejoint_description/meshes/JX_servo_v46_Mirror__2.stl" scale="0.001 0.001 0.001"/>
    </geometry>
  </collision>
</link>

<link name="L_Mirror__1">
  <inertial>
    <origin xyz="-0.014975789884571725 -0.01091916282531652 -0.04257997285080964" rpy="0 0 0"/>
    <mass value="0.045500552100246464"/>
    <inertia ixx="6.7e-05" iyy="4.1e-05" izz="4.6e-05" ixy="-0.0" iyz="-1.8e-05" ixz="-0.0"/>
  </inertial>
  <visual>
    <origin xyz="0.093686 0.332931 0.012493" rpy="0 0 0"/>
    <geometry>
      <mesh filename="package://hip-rejoint_description/meshes/L_Mirror__1.stl" scale="0.001 0.001 0.001"/>
    </geometry>
    <material name="abs_white"/>
  </visual>
  <collision>
    <origin xyz="0.093686 0.332931 0.012493" rpy="0 0 0"/>
    <geometry>
      <mesh filename="package://hip-rejoint_description/meshes/L_Mirror__1.stl" scale="0.001 0.001 0.001"/>
    </geometry>
  </collision>
</link>

<link name="JX_servo_v46_Mirror__3">
  <inertial>
    <origin xyz="-0.00878612556320428 -0.04019798788930984 -0.011241709258631494" rpy="0 0 0"/>
    <mass value="0.2114"/>
    <inertia ixx="0.000552" iyy="0.000359" izz="0.00038" ixy="0.0" iyz="4.4e-05" ixz="6e-06"/>
  </inertial>
  <visual>
    <origin xyz="0.100186 0.333031 0.079493" rpy="0 0 0"/>
    <geometry>
      <mesh filename="package://hip-rejoint_description/meshes/JX_servo_v46_Mirror__3.stl" scale="0.001 0.001 0.001"/>
    </geometry>
    <material name="polystyrene"/>
  </visual>
  <collision>
    <origin xyz="0.100186 0.333031 0.079493" rpy="0 0 0"/>
    <geometry>
      <mesh filename="package://hip-rejoint_description/meshes/JX_servo_v46_Mirror__3.stl" scale="0.001 0.001 0.001"/>
    </geometry>
  </collision>
</link>

<link name="left_foot">
  <inertial>
    <origin xyz="0.008229282597750645 -0.03620820883926851 0.05767577474512388" rpy="0 0 0"/>
    <mass value="0.18549302395679304"/>
    <inertia ixx="0.000496" iyy="0.000598" izz="0.000167" ixy="8e-06" iyz="2.3e-05" ixz="-8e-06"/>
  </inertial>
  <visual>
    <origin xyz="0.108686 0.388631 0.053893" rpy="0 0 0"/>
    <geometry>
      <mesh filename="package://hip-rejoint_description/meshes/Component8_Mirror__1.stl" scale="0.001 0.001 0.001"/>
    </geometry>
    <material name="abs_white"/>
  </visual>
  <collision>
    <origin xyz="0.108686 0.388631 0.053893" rpy="0 0 0"/>
    <geometry>
      <mesh filename="package://hip-rejoint_description/meshes/Component8_Mirror__1.stl" scale="0.001 0.001 0.001"/>
    </geometry>
  </collision>
</link>

<link name="Component4__2__1">
  <inertial>
    <origin xyz="-0.03836236384092319 -0.08477226287354095 0.003159966075554216" rpy="0 0 0"/>
    <mass value="0.15906974524164488"/>
    <inertia ixx="0.000427" iyy="0.000271" izz="0.000652" ixy="1e-06" iyz="9e-06" ixz="0.0"/>
  </inertial>
  <visual>
    <origin xyz="0.072686 0.089331 0.020993" rpy="0 0 0"/>
    <geometry>
      <mesh filename="package://hip-rejoint_description/meshes/Component4__2__1.stl" scale="0.001 0.001 0.001"/>
    </geometry>
    <material name="abs_white"/>
  </visual>
  <collision>
    <origin xyz="0.072686 0.089331 0.020993" rpy="0 0 0"/>
    <geometry>
      <mesh filename="package://hip-rejoint_description/meshes/Component4__2__1.stl" scale="0.001 0.001 0.001"/>
    </geometry>
  </collision>
</link>

<link name="JX_servo_v46_Mirror__1">
  <inertial>
    <origin xyz="-0.0368411546839629 -0.015402435277067389 -0.0002866801378715554" rpy="0 0 0"/>
    <mass value="0.2114"/>
    <inertia ixx="0.00038" iyy="0.000359" izz="0.000552" ixy="-4.4e-05" iyz="-0.0" ixz="6e-06"/>
  </inertial>
  <visual>
    <origin xyz="0.072686 0.249331 0.020993" rpy="0 0 0"/>
    <geometry>
      <mesh filename="package://hip-rejoint_description/meshes/JX_servo_v46_Mirror__1.stl" scale="0.001 0.001 0.001"/>
    </geometry>
    <material name="polystyrene"/>
  </visual>
  <collision>
    <origin xyz="0.072686 0.249331 0.020993" rpy="0 0 0"/>
    <geometry>
      <mesh filename="package://hip-rejoint_description/meshes/JX_servo_v46_Mirror__1.stl" scale="0.001 0.001 0.001"/>
    </geometry>
  </collision>
</link>

<link name="Component4_Mirror___1__1">
  <inertial>
    <origin xyz="0.038363166439720375 -0.08477226287354125 0.0031599660755537856" rpy="0 0 0"/>
    <mass value="0.15906974524164494"/>
    <inertia ixx="0.000427" iyy="0.000271" izz="0.000652" ixy="-1e-06" iyz="9e-06" ixz="-0.0"/>
  </inertial>
  <visual>
    <origin xyz="0.271436 0.089331 0.020693" rpy="0 0 0"/>
    <geometry>
      <mesh filename="package://hip-rejoint_description/meshes/Component4_Mirror___1__1.stl" scale="0.001 0.001 0.001"/>
    </geometry>
    <material name="abs_white"/>
  </visual>
  <collision>
    <origin xyz="0.271436 0.089331 0.020693" rpy="0 0 0"/>
    <geometry>
      <mesh filename="package://hip-rejoint_description/meshes/Component4_Mirror___1__1.stl" scale="0.001 0.001 0.001"/>
    </geometry>
  </collision>
</link>

<link name="JX_servo_v46_Mirror__9">
  <inertial>
    <origin xyz="0.03684195728275985 -0.015402435277067333 0.00028637358732558696" rpy="0 0 0"/>
    <mass value="0.2114"/>
    <inertia ixx="0.00038" iyy="0.000359" izz="0.000552" ixy="4.4e-05" iyz="0.0" ixz="6e-06"/>
  </inertial>
  <visual>
    <origin xyz="0.271436 0.249331 0.020693" rpy="0 0 0"/>
    <geometry>
      <mesh filename="package://hip-rejoint_description/meshes/JX_servo_v46_Mirror__9.stl" scale="0.001 0.001 0.001"/>
    </geometry>
    <material name="polystyrene"/>
  </visual>
  <collision>
    <origin xyz="0.271436 0.249331 0.020693" rpy="0 0 0"/>
    <geometry>
      <mesh filename="package://hip-rejoint_description/meshes/JX_servo_v46_Mirror__9.stl" scale="0.001 0.001 0.001"/>
    </geometry>
  </collision>
</link>

<link name="Component5_Mirror__Mirror__1">
  <inertial>
    <origin xyz="0.015791158628178203 -0.03724248861880003 0.008499846724724949" rpy="0 0 0"/>
    <mass value="0.09281870151638758"/>
    <inertia ixx="0.000101" iyy="0.000141" izz="0.000217" ixy="-1e-06" iyz="0.0" ixz="0.0"/>
  </inertial>
  <visual>
    <origin xyz="0.249736 0.304931 0.029193" rpy="0 0 0"/>
    <geometry>
      <mesh filename="package://hip-rejoint_description/meshes/Component5_Mirror__Mirror__1.stl" scale="0.001 0.001 0.001"/>
    </geometry>
    <material name="abs_white"/>
  </visual>
  <collision>
    <origin xyz="0.249736 0.304931 0.029193" rpy="0 0 0"/>
    <geometry>
      <mesh filename="package://hip-rejoint_description/meshes/Component5_Mirror__Mirror__1.stl" scale="0.001 0.001 0.001"/>
    </geometry>
  </collision>
</link>

<link name="JX_servo_v46_Mirror__7">
  <inertial>
    <origin xyz="0.03684195728276016 0.015402012110691143 -0.00028668013787922636" rpy="0 0 0"/>
    <mass value="0.2114"/>
    <inertia ixx="0.00038" iyy="0.000359" izz="0.000552" ixy="-4.4e-05" iyz="0.0" ixz="-6e-06"/>
  </inertial>
  <visual>
    <origin xyz="0.272136 0.388531 0.020693" rpy="0 0 0"/>
    <geometry>
      <mesh filename="package://hip-rejoint_description/meshes/JX_servo_v46_Mirror__7.stl" scale="0.001 0.001 0.001"/>
    </geometry>
    <material name="polystyrene"/>
  </visual>
  <collision>
    <origin xyz="0.272136 0.388531 0.020693" rpy="0 0 0"/>
    <geometry>
      <mesh filename="package://hip-rejoint_description/meshes/JX_servo_v46_Mirror__7.stl" scale="0.001 0.001 0.001"/>
    </geometry>
  </collision>
</link>

<link name="L_Mirror__3">
  <inertial>
    <origin xyz="0.015024210115428732 -0.010819162825315864 -0.04257997285081784" rpy="0 0 0"/>
    <mass value="0.045500552100246464"/>
    <inertia ixx="6.7e-05" iyy="4.1e-05" izz="4.6e-05" ixy="-0.0" iyz="-1.8e-05" ixz="-0.0"/>
  </inertial>
  <visual>
    <origin xyz="0.250436 0.332931 0.012193" rpy="0 0 0"/>
    <geometry>
      <mesh filename="package://hip-rejoint_description/meshes/L_Mirror__3.stl" scale="0.001 0.001 0.001"/>
    </geometry>
    <material name="abs_white"/>
  </visual>
  <collision>
    <origin xyz="0.250436 0.332931 0.012193" rpy="0 0 0"/>
    <geometry>
      <mesh filename="package://hip-rejoint_description/meshes/L_Mirror__3.stl" scale="0.001 0.001 0.001"/>
    </geometry>
  </collision>
</link>

<link name="JX_servo_v46_Mirror__8">
  <inertial>
    <origin xyz="-0.008786125563203712 0.035002012110691316 -0.011241709258639696" rpy="0 0 0"/>
    <mass value="0.2114"/>
    <inertia ixx="0.000552" iyy="0.000359" izz="0.00038" ixy="0.0" iyz="4.4e-05" ixz="6e-06"/>
  </inertial>
  <visual>
    <origin xyz="0.226936 0.408131 0.079193" rpy="0 0 0"/>
    <geometry>
      <mesh filename="package://hip-rejoint_description/meshes/JX_servo_v46_Mirror__8.stl" scale="0.001 0.001 0.001"/>
    </geometry>
    <material name="polystyrene"/>
  </visual>
  <collision>
    <origin xyz="0.226936 0.408131 0.079193" rpy="0 0 0"/>
    <geometry>
      <mesh filename="package://hip-rejoint_description/meshes/JX_servo_v46_Mirror__8.stl" scale="0.001 0.001 0.001"/>
    </geometry>
  </collision>
</link>

<link name="right_foot">
  <inertial>
    <origin xyz="-0.008228480213207129 -0.03620821077923492 0.05767579042820024" rpy="0 0 0"/>
    <mass value="0.1854930080519705"/>
    <inertia ixx="0.000496" iyy="0.000598" izz="0.000167" ixy="-8e-06" iyz="2.3e-05" ixz="8e-06"/>
  </inertial>
  <visual>
    <origin xyz="0.235436 0.388531 0.053593" rpy="0 0 0"/>
    <geometry>
      <mesh filename="package://hip-rejoint_description/meshes/Component8_Mirror__Mirror__1.stl" scale="0.001 0.001 0.001"/>
    </geometry>
    <material name="abs_white"/>
  </visual>
  <collision>
    <origin xyz="0.235436 0.388531 0.053593" rpy="0 0 0"/>
    <geometry>
      <mesh filename="package://hip-rejoint_description/meshes/Component8_Mirror__Mirror__1.stl" scale="0.001 0.001 0.001"/>
    </geometry>
  </collision>
</link>

<link name="Component65_1">
  <inertial>
    <origin xyz="-0.005184097940403948 -0.031750411583187976 -0.05702757553439637" rpy="0 0 0"/>
    <mass value="0.550045164280725"/>
    <inertia ixx="0.000783" iyy="0.002491" izz="0.002078" ixy="0.0" iyz="0.0" ixz="-0.0"/>
  </inertial>
  <visual>
    <origin xyz="0.166785 -0.074023 0.036244" rpy="0 0 0"/>
    <geometry>
      <mesh filename="package://hip-rejoint_description/meshes/Component65_1.stl" scale="0.001 0.001 0.001"/>
    </geometry>
    <material name="abs_white"/>
  </visual>
  <collision>
    <origin xyz="0.166785 -0.074023 0.036244" rpy="0 0 0"/>
    <geometry>
      <mesh filename="package://hip-rejoint_description/meshes/Component65_1.stl" scale="0.001 0.001 0.001"/>
    </geometry>
  </collision>
</link>

<link name="Component66_1">
  <inertial>
    <origin xyz="2.9421278460728395e-07 -0.022700411583187953 0.023575046724728044" rpy="0 0 0"/>
    <mass value="0.3199209891539212"/>
    <inertia ixx="0.000104" iyy="0.000517" izz="0.000447" ixy="-0.0" iyz="-0.0" ixz="0.0"/>
  </inertial>
  <visual>
    <origin xyz="0.171985 -0.074023 0.150394" rpy="0 0 0"/>
    <geometry>
      <mesh filename="package://hip-rejoint_description/meshes/Component66_1.stl" scale="0.001 0.001 0.001"/>
    </geometry>
    <material name="brass_polished"/>
  </visual>
  <collision>
    <origin xyz="0.171985 -0.074023 0.150394" rpy="0 0 0"/>
    <geometry>
      <mesh filename="package://hip-rejoint_description/meshes/Component66_1.stl" scale="0.001 0.001 0.001"/>
    </geometry>
  </collision>
</link>

<link name="JX_servo_v46_Mirror__10">
  <inertial>
    <origin xyz="-0.03684126177057695 -0.0154026352770667 -0.0002864801378689441" rpy="0 0 0"/>
    <mass value="0.2114"/>
    <inertia ixx="0.00038" iyy="0.000359" izz="0.000552" ixy="-4.4e-05" iyz="-0.0" ixz="6e-06"/>
  </inertial>
  <visual>
    <origin xyz="0.273585 -0.042273 0.036094" rpy="0 0 0"/>
    <geometry>
      <mesh filename="package://hip-rejoint_description/meshes/JX_servo_v46_Mirror__10.stl" scale="0.001 0.001 0.001"/>
    </geometry>
    <material name="polystyrene"/>
  </visual>
  <collision>
    <origin xyz="0.273585 -0.042273 0.036094" rpy="0 0 0"/>
    <geometry>
      <mesh filename="package://hip-rejoint_description/meshes/JX_servo_v46_Mirror__10.stl" scale="0.001 0.001 0.001"/>
    </geometry>
  </collision>
</link>

<link name="JX_servo_v46_Mirror__11">
  <inertial>
    <origin xyz="0.015141850196143947 -0.04019818788930868 0.008213519862116048" rpy="0 0 0"/>
    <mass value="0.2114"/>
    <inertia ixx="0.00038" iyy="0.000359" izz="0.000552" ixy="-4.4e-05" iyz="0.0" ixz="-6e-06"/>
  </inertial>
  <visual>
    <origin xyz="0.331185 0.013427 0.044594" rpy="0 0 0"/>
    <geometry>
      <mesh filename="package://hip-rejoint_description/meshes/JX_servo_v46_Mirror__11.stl" scale="0.001 0.001 0.001"/>
    </geometry>
    <material name="polystyrene"/>
  </visual>
  <collision>
    <origin xyz="0.331185 0.013427 0.044594" rpy="0 0 0"/>
    <geometry>
      <mesh filename="package://hip-rejoint_description/meshes/JX_servo_v46_Mirror__11.stl" scale="0.001 0.001 0.001"/>
    </geometry>
  </collision>
</link>

<link name="JX_servo_v46_Mirror__12">
  <inertial>
    <origin xyz="0.036841850196146324 -0.015402635277066846 0.00028657358732495086" rpy="0 0 0"/>
    <mass value="0.2114"/>
    <inertia ixx="0.00038" iyy="0.000359" izz="0.000552" ixy="4.4e-05" iyz="0.0" ixz="6e-06"/>
  </inertial>
  <visual>
    <origin xyz="0.070385 -0.042273 0.036094" rpy="0 0 0"/>
    <geometry>
      <mesh filename="package://hip-rejoint_description/meshes/JX_servo_v46_Mirror__12.stl" scale="0.001 0.001 0.001"/>
    </geometry>
    <material name="polystyrene"/>
  </visual>
  <collision>
    <origin xyz="0.070385 -0.042273 0.036094" rpy="0 0 0"/>
    <geometry>
      <mesh filename="package://hip-rejoint_description/meshes/JX_servo_v46_Mirror__12.stl" scale="0.001 0.001 0.001"/>
    </geometry>
  </collision>
</link>

<link name="JX_servo_v46_Mirror__13">
  <inertial>
    <origin xyz="-0.015141261770573568 -0.0401981878893089 0.00878657358732133" rpy="0 0 0"/>
    <mass value="0.2114"/>
    <inertia ixx="0.00038" iyy="0.000359" izz="0.000552" ixy="4.4e-05" iyz="-0.0" ixz="-6e-06"/>
  </inertial>
  <visual>
    <origin xyz="0.012785 0.013427 0.044594" rpy="0 0 0"/>
    <geometry>
      <mesh filename="package://hip-rejoint_description/meshes/JX_servo_v46_Mirror__13.stl" scale="0.001 0.001 0.001"/>
    </geometry>
    <material name="polystyrene"/>
  </visual>
  <collision>
    <origin xyz="0.012785 0.013427 0.044594" rpy="0 0 0"/>
    <geometry>
      <mesh filename="package://hip-rejoint_description/meshes/JX_servo_v46_Mirror__13.stl" scale="0.001 0.001 0.001"/>
    </geometry>
  </collision>
</link>

<link name="Component11_Mirror__2">
  <inertial>
    <origin xyz="-0.0014997057872181974 -4.1158318753176104e-07 4.672472387473592e-08" rpy="0 0 0"/>
    <mass value="0.003775795544427548"/>
    <inertia ixx="1e-06" iyy="1E-06" izz="1E-06" ixy="0.0" iyz="-0.0" ixz="-0.0"/>
  </inertial>
  <visual>
    <origin xyz="0.352885 0.069027 0.036094" rpy="0 0 0"/>
    <geometry>
      <mesh filename="package://hip-rejoint_description/meshes/Component11_Mirror__2.stl" scale="0.001 0.001 0.001"/>
    </geometry>
    <material name="plastic_matte_black"/>
  </visual>
  <collision>
    <origin xyz="0.352885 0.069027 0.036094" rpy="0 0 0"/>
    <geometry>
      <mesh filename="package://hip-rejoint_description/meshes/Component11_Mirror__2.stl" scale="0.001 0.001 0.001"/>
    </geometry>
  </collision>
</link>

<link name="Component11_Mirror__3">
  <inertial>
    <origin xyz="0.0015002942127881787 -4.115831874901277e-07 4.672473739170124e-08" rpy="0 0 0"/>
    <mass value="0.003775795544427548"/>
    <inertia ixx="1e-06" iyy="1E-06" izz="1E-06" ixy="-0.0" iyz="0.0" ixz="-0.0"/>
  </inertial>
  <visual>
    <origin xyz="-0.008915 0.069027 0.036094" rpy="0 0 0"/>
    <geometry>
      <mesh filename="package://hip-rejoint_description/meshes/Component11_Mirror__3.stl" scale="0.001 0.001 0.001"/>
    </geometry>
    <material name="plastic_matte_black"/>
  </visual>
  <collision>
    <origin xyz="-0.008915 0.069027 0.036094" rpy="0 0 0"/>
    <geometry>
      <mesh filename="package://hip-rejoint_description/meshes/Component11_Mirror__3.stl" scale="0.001 0.001 0.001"/>
    </geometry>
  </collision>
</link>

<joint name="rootfloat" type="fixed">
  <origin xyz="0 0 0" rpy="1.57 0 1.57" />
  <parent link="root" />
  <child link="torso" />
</joint>
<joint name="Rigid 2" type="fixed">
  <origin xyz="-0.117785 -0.019449 -0.021094" rpy="0 0 0"/>
  <parent link="torso"/>
  <child link="R8-2RS_Bearing_1"/>
</joint>

<joint name="Rigid 3" type="fixed">
  <origin xyz="-0.117785 -0.019449 -0.021094" rpy="0 0 0"/>
  <parent link="torso"/>
  <child link="R8-2RS_Bearing_2"/>
</joint>

<joint name="Rigid 4" type="fixed">
  <origin xyz="-0.226185 -0.019449 -0.021094" rpy="0 0 0"/>
  <parent link="torso"/>
  <child link="R8-2RS_Bearing_3"/>
</joint>

<joint name="Rigid 5" type="fixed">
  <origin xyz="0.0 0.0 0.0" rpy="0 0 0"/>
  <parent link="R8-2RS_Bearing_3"/>
  <child link="R8-2RS_Bearing_4"/>
</joint>

<joint name="Rigid 6" type="fixed">
  <origin xyz="-0.117785 -0.019449 -0.021094" rpy="0 0 0"/>
  <parent link="torso"/>
  <child link="Component2_2"/>
</joint>

<joint name="Rigid 7" type="fixed">
  <origin xyz="-0.226185 -0.019449 -0.021094" rpy="0 0 0"/>
  <parent link="torso"/>
  <child link="Component2_1"/>
</joint>

<joint name="Rigid 8" type="fixed">
  <origin xyz="0.0 0.010955 0.0" rpy="0 0 0"/>
  <parent link="Component2_1"/>
  <child link="91590A121_External_Retaining_Ring_v1_2"/>
</joint>

<joint name="right_hip_yaw" type="continuous">
  <origin xyz="0.0 0.000635 0.0" rpy="0 0 0"/>
  <parent link="91590A121_External_Retaining_Ring_v1_2"/>
  <child link="2025K9_303_Stainless_Steel_Rotary_Shaft_with_Retaining_Ring_Grooves_v1_1"/>
  <axis xyz="-0.0 -1.0 0.0"/>
</joint>

<joint name="Rigid 10" type="fixed">
  <origin xyz="0.0 -0.02225 0.0" rpy="0 0 0"/>
  <parent link="2025K9_303_Stainless_Steel_Rotary_Shaft_with_Retaining_Ring_Grooves_v1_1"/>
  <child link="91590A121_External_Retaining_Ring_v1_3"/>
</joint>

<joint name="Rigid 11" type="fixed">
  <origin xyz="0.0 -0.033375 0.0" rpy="0 0 0"/>
  <parent link="2025K9_303_Stainless_Steel_Rotary_Shaft_with_Retaining_Ring_Grooves_v1_1"/>
  <child link="91590A121_External_Retaining_Ring_v1_1"/>
</joint>

<joint name="Rigid 12" type="fixed">
  <origin xyz="-7.6e-05 -0.04215 -0.03165" rpy="0 0 0"/>
  <parent link="Component32_1"/>
  <child link="Component39_1"/>
</joint>

<joint name="right_hip_roll" type="continuous">
  <origin xyz="0.0 0.0 -0.0127" rpy="0 0 0"/>
  <parent link="Component39_1"/>
  <child link="JX_servo_v80_3"/>
  <axis xyz="0.0 0.0 1.0"/>
</joint>

<joint name="Rigid 15" type="fixed">
  <origin xyz="0.00835 -0.0556 -0.0125" rpy="0 0 0"/>
  <parent link="JX_servo_v80_3"/>
  <child link="Component9__1__1"/>
</joint>

<joint name="Rigid 16" type="fixed">
  <origin xyz="0.0 -0.000635 0.0" rpy="0 0 0"/>
  <parent link="91590A121_External_Retaining_Ring_v1_1"/>
  <child link="Component4_1"/>
</joint>

<joint name="Rigid 17" type="fixed">
  <origin xyz="0.0 -0.005312 0.0" rpy="0 0 0"/>
  <parent link="Component4_1"/>
  <child link="Component32_1"/>
</joint>

<joint name="Rigid 18" type="fixed">
  <origin xyz="0.0 0.014682 0.0" rpy="0 0 0"/>
  <parent link="2025K9_303_Stainless_Steel_Rotary_Shaft_with_Retaining_Ring_Grooves_v1_1"/>
  <child link="15T-horn_v13_1"/>
</joint>

<joint name="Rigid 19" type="fixed">
  <origin xyz="0.0 0.0001 0.0" rpy="0 0 0"/>
  <parent link="15T-horn_v13_1"/>
  <child link="JX_servo_v80_1"/>
</joint>

<joint name="Rigid 20" type="fixed">
  <origin xyz="0.00435 0.0 0.048601" rpy="0 0 0"/>
  <parent link="Component9__1__1"/>
  <child link="JX_servo_v80_2"/>
</joint>

<joint name="Rigid 21" type="fixed">
  <origin xyz="0.0 -0.033375 0.0" rpy="0 0 0"/>
  <parent link="2025K9_303_Stainless_Steel_Rotary_Shaft_with_Retaining_Ring_Grooves_v1_2"/>
  <child link="91590A121_External_Retaining_Ring_v1_4"/>
</joint>

<joint name="Rigid 22" type="fixed">
  <origin xyz="0.0 -0.000635 0.0" rpy="0 0 0"/>
  <parent link="91590A121_External_Retaining_Ring_v1_4"/>
  <child link="Component4_2"/>
</joint>

<joint name="Rigid 23" type="fixed">
  <origin xyz="0.0 -0.005312 0.0" rpy="0 0 0"/>
  <parent link="Component4_2"/>
  <child link="Component32_2"/>
</joint>

<joint name="Rigid 24" type="fixed">
  <origin xyz="-7.6e-05 -0.04215 -0.03165" rpy="0 0 0"/>
  <parent link="Component32_2"/>
  <child link="Component39_2"/>
</joint>

<joint name="left_hip_roll" type="continuous">
  <origin xyz="0.0 0.0 -0.0127" rpy="0 0 0"/>
  <parent link="Component39_2"/>
  <child link="JX_servo_v80_5"/>
  <axis xyz="0.0 0.0 1.0"/>
</joint>

<joint name="Rigid 26" type="fixed">
  <origin xyz="0.00435 0.0 0.065601" rpy="0 0 0"/>
  <parent link="Component9__1__2"/>
  <child link="JX_servo_v80_7"/>
</joint>

<joint name="Rigid 27" type="fixed">
  <origin xyz="0.00835 -0.0556 -0.0125" rpy="0 0 0"/>
  <parent link="JX_servo_v80_5"/>
  <child link="Component9__1__2"/>
</joint>

<joint name="Rigid 28" type="fixed">
  <origin xyz="0.0 -0.02225 0.0" rpy="0 0 0"/>
  <parent link="2025K9_303_Stainless_Steel_Rotary_Shaft_with_Retaining_Ring_Grooves_v1_2"/>
  <child link="91590A121_External_Retaining_Ring_v1_5"/>
</joint>

<joint name="Rigid 29" type="fixed">
  <origin xyz="0.0 0.010955 0.0" rpy="0 0 0"/>
  <parent link="Component2_2"/>
  <child link="91590A121_External_Retaining_Ring_v1_6"/>
</joint>

<joint name="left_hip_yaw" type="continuous">
  <origin xyz="0.0 0.000635 0.0" rpy="0 0 0"/>
  <parent link="91590A121_External_Retaining_Ring_v1_6"/>
  <child link="2025K9_303_Stainless_Steel_Rotary_Shaft_with_Retaining_Ring_Grooves_v1_2"/>
  <axis xyz="-0.0 -1.0 0.0"/>
</joint>

<joint name="Rigid 31" type="fixed">
  <origin xyz="0.0 0.014682 0.0" rpy="0 0 0"/>
  <parent link="2025K9_303_Stainless_Steel_Rotary_Shaft_with_Retaining_Ring_Grooves_v1_2"/>
  <child link="Component6_2"/>
</joint>

<joint name="Rigid 32" type="fixed">
  <origin xyz="0.0 0.0001 0.0" rpy="0 0 0"/>
  <parent link="Component6_2"/>
  <child link="JX_servo_v80_4"/>
</joint>

<joint name="Rigid 35" type="fixed">
  <origin xyz="-0.0217 -0.0556 -0.0085" rpy="0 0 0"/>
  <parent link="JX_servo_v46_Mirror__1"/>
  <child link="Component5_Mirror__1"/>
</joint>

<joint name="left_ankle_pitch" type="continuous">
  <origin xyz="0.0224 -0.0836 0.0085" rpy="0 0 0"/>
  <parent link="Component5_Mirror__1"/>
  <child link="JX_servo_v46_Mirror__2"/>
  <axis xyz="1.0 -0.0 -0.0"/>
</joint>

<joint name="Rigid 37" type="fixed">
  <origin xyz="-0.0217 0.0556 0.0085" rpy="0 0 0"/>
  <parent link="JX_servo_v46_Mirror__2"/>
  <child link="L_Mirror__1"/>
</joint>

<joint name="Rigid 38" type="fixed">
  <origin xyz="-0.0065 -0.0001 -0.067" rpy="0 0 0"/>
  <parent link="L_Mirror__1"/>
  <child link="JX_servo_v46_Mirror__3"/>
</joint>

<joint name="left_ankle_roll" type="continuous">
  <origin xyz="-0.0085 -0.0556 0.0256" rpy="0 0 0"/>
  <parent link="JX_servo_v46_Mirror__3"/>
  <child link="left_foot"/>
  <axis xyz="0.0 -0.0 1.0"/>
</joint>

<joint name="left_hip_pitch" type="continuous">
  <origin xyz="0.032475 0.0556 -0.00865" rpy="0 0 0"/>
  <parent link="JX_servo_v80_7"/>
  <child link="Component4__2__1"/>
  <axis xyz="-1.0 0.0 -0.0"/>
</joint>

<joint name="left_knee" type="continuous">
  <origin xyz="0.0 -0.16 0.0" rpy="0 0 0"/>
  <parent link="Component4__2__1"/>
  <child link="JX_servo_v46_Mirror__1"/>
  <axis xyz="1.0 -0.0 -0.0"/>
</joint>

<joint name="right_hip_pitch" type="continuous">
  <origin xyz="-0.057875 0.0556 0.00865" rpy="0 0 0"/>
  <parent link="JX_servo_v80_2"/>
  <child link="Component4_Mirror___1__1"/>
  <axis xyz="1.0 -0.0 0.0"/>
</joint>

<joint name="right_knee" type="continuous">
  <origin xyz="0.0 -0.16 0.0" rpy="0 0 0"/>
  <parent link="Component4_Mirror___1__1"/>
  <child link="JX_servo_v46_Mirror__9"/>
  <axis xyz="1.0 -0.0 0.0"/>
</joint>

<joint name="Rigid 44" type="fixed">
  <origin xyz="0.0217 -0.0556 -0.0085" rpy="0 0 0"/>
  <parent link="JX_servo_v46_Mirror__9"/>
  <child link="Component5_Mirror__Mirror__1"/>
</joint>

<joint name="right_ankle_pitch" type="continuous">
  <origin xyz="-0.0224 -0.0836 0.0085" rpy="0 0 0"/>
  <parent link="Component5_Mirror__Mirror__1"/>
  <child link="JX_servo_v46_Mirror__7"/>
  <axis xyz="1.0 -0.0 -0.0"/>
</joint>

<joint name="Rigid 46" type="fixed">
  <origin xyz="0.0217 0.0556 0.0085" rpy="0 0 0"/>
  <parent link="JX_servo_v46_Mirror__7"/>
  <child link="L_Mirror__3"/>
</joint>

<joint name="Rigid 47" type="fixed">
  <origin xyz="0.0235 -0.0752 -0.067" rpy="0 0 0"/>
  <parent link="L_Mirror__3"/>
  <child link="JX_servo_v46_Mirror__8"/>
</joint>

<joint name="right_ankle_roll" type="continuous">
  <origin xyz="-0.0085 0.0196 0.0256" rpy="0 0 0"/>
  <parent link="JX_servo_v46_Mirror__8"/>
  <child link="right_foot"/>
  <axis xyz="0.0 -0.0 1.0"/>
</joint>

<joint name="Rigid 50" type="fixed">
  <origin xyz="0.0594 0.0671 -0.01515" rpy="0 0 0"/>
  <parent link="JX_servo_v80_1"/>
  <child link="Component65_1"/>
</joint>

<joint name="Rigid 51" type="fixed">
  <origin xyz="-0.0052 0.0 -0.11415" rpy="0 0 0"/>
  <parent link="Component65_1"/>
  <child link="Component66_1"/>
</joint>

<joint name="right_shoulder" type="continuous">
  <origin xyz="-0.1068 -0.03175 0.00015" rpy="0 0 0"/>
  <parent link="Component65_1"/>
  <child link="JX_servo_v46_Mirror__10"/>
  <axis xyz="-1.0 0.0 0.0"/>
</joint>

<joint name="Rigid 53" type="fixed">
  <origin xyz="-0.0576 -0.0557 -0.0085" rpy="0 0 0"/>
  <parent link="JX_servo_v46_Mirror__10"/>
  <child link="JX_servo_v46_Mirror__11"/>
</joint>

<joint name="left_shoulder" type="continuous">
  <origin xyz="0.0964 -0.03175 0.00015" rpy="0 0 0"/>
  <parent link="Component65_1"/>
  <child link="JX_servo_v46_Mirror__12"/>
  <axis xyz="1.0 0.0 0.0"/>
</joint>

<joint name="Rigid 55" type="fixed">
  <origin xyz="0.0576 -0.0557 -0.0085" rpy="0 0 0"/>
  <parent link="JX_servo_v46_Mirror__12"/>
  <child link="JX_servo_v46_Mirror__13"/>
</joint>

<joint name="right_elbow" type="continuous">
  <origin xyz="-0.0217 -0.0556 0.0085" rpy="0 0 0"/>
  <parent link="JX_servo_v46_Mirror__11"/>
  <child link="Component11_Mirror__2"/>
  <axis xyz="-1.0 0.0 0.0"/>
</joint>

<joint name="left_elbow" type="continuous">
  <origin xyz="0.0217 -0.0556 0.0085" rpy="0 0 0"/>
  <parent link="JX_servo_v46_Mirror__13"/>
  <child link="Component11_Mirror__3"/>
  <axis xyz="1.0 0.0 -0.0"/>
</joint>

</robot>
