<?xml version="1.0" ?>
<!-- =================================================================================== -->
<!-- |    This document was autogenerated by xacro from bez2_urdf.xacro                | -->
<!-- |    EDITING THIS FILE BY HAND IS NOT RECOMMENDED                                 | -->
<!-- =================================================================================== -->
<robot name="bez2_urdf">
  <material name="white">
    <color rgba="1.0 1.0 1.0 1.0"/>
  </material>
  <material name="black">
    <color rgba="0.0 0.0 0.0 1.0"/>
  </material>
  <material name="silver">
    <color rgba="0.7 0.7 0.7 1.0"/>
  </material>
  <material name="yellow">
    <color rgba="0.9 0.9 0.0 1.0"/>
  </material>
  <material name="red">
    <color rgba="0.7 0.0 0.0 1.0"/>
  </material>
  <material name="green">
    <color rgba="0.0 0.7 0.0 1.0"/>
  </material>
  <material name="blue">
    <color rgba="0.0 0.0 0.7 1.0"/>
  </material>
  <material name="purple">
    <color rgba="0.7 0.0 0.7 1.0"/>
  </material>
  <material name="cyan">
    <color rgba="0.0 0.7 0.7 1.0"/>
  </material>
  <material name="silver_default">
    <color rgba="0.700 0.700 0.700 1.000"/>
  </material>
  <material name="steel_satin">
    <color rgba="0.6274509803921569 0.6274509803921569 0.6274509803921569 1.0"/>
  </material>
  <material name="plastic_matte_yellow">
    <color rgba="0.9098039215686274 0.6784313725490196 0.13725490196078433 1.0"/>
  </material>
  <transmission name="right_leg_motor_0_tran">
    <type>transmission_interface/SimpleTransmission</type>
    <joint name="right_leg_motor_0">
      <hardwareInterface>hardware_interface/EffortJointInterface</hardwareInterface>
    </joint>
    <actuator name="right_leg_motor_0_actr">
      <hardwareInterface>hardware_interface/EffortJointInterface</hardwareInterface>
      <mechanicalReduction>1</mechanicalReduction>
    </actuator>
  </transmission>
  <transmission name="left_leg_motor_0_tran">
    <type>transmission_interface/SimpleTransmission</type>
    <joint name="left_leg_motor_0">
      <hardwareInterface>hardware_interface/EffortJointInterface</hardwareInterface>
    </joint>
    <actuator name="left_leg_motor_0_actr">
      <hardwareInterface>hardware_interface/EffortJointInterface</hardwareInterface>
      <mechanicalReduction>1</mechanicalReduction>
    </actuator>
  </transmission>
  <transmission name="left_leg_motor_1_tran">
    <type>transmission_interface/SimpleTransmission</type>
    <joint name="left_leg_motor_1">
      <hardwareInterface>hardware_interface/EffortJointInterface</hardwareInterface>
    </joint>
    <actuator name="left_leg_motor_1_actr">
      <hardwareInterface>hardware_interface/EffortJointInterface</hardwareInterface>
      <mechanicalReduction>1</mechanicalReduction>
    </actuator>
  </transmission>
  <transmission name="right_leg_motor_1_tran">
    <type>transmission_interface/SimpleTransmission</type>
    <joint name="right_leg_motor_1">
      <hardwareInterface>hardware_interface/EffortJointInterface</hardwareInterface>
    </joint>
    <actuator name="right_leg_motor_1_actr">
      <hardwareInterface>hardware_interface/EffortJointInterface</hardwareInterface>
      <mechanicalReduction>1</mechanicalReduction>
    </actuator>
  </transmission>
  <transmission name="left_leg_motor_2_tran">
    <type>transmission_interface/SimpleTransmission</type>
    <joint name="left_leg_motor_2">
      <hardwareInterface>hardware_interface/EffortJointInterface</hardwareInterface>
    </joint>
    <actuator name="left_leg_motor_2_actr">
      <hardwareInterface>hardware_interface/EffortJointInterface</hardwareInterface>
      <mechanicalReduction>1</mechanicalReduction>
    </actuator>
  </transmission>
  <transmission name="right_leg_motor_2_tran">
    <type>transmission_interface/SimpleTransmission</type>
    <joint name="right_leg_motor_2">
      <hardwareInterface>hardware_interface/EffortJointInterface</hardwareInterface>
    </joint>
    <actuator name="right_leg_motor_2_actr">
      <hardwareInterface>hardware_interface/EffortJointInterface</hardwareInterface>
      <mechanicalReduction>1</mechanicalReduction>
    </actuator>
  </transmission>
  <transmission name="left_leg_motor_3_tran">
    <type>transmission_interface/SimpleTransmission</type>
    <joint name="left_leg_motor_3">
      <hardwareInterface>hardware_interface/EffortJointInterface</hardwareInterface>
    </joint>
    <actuator name="left_leg_motor_3_actr">
      <hardwareInterface>hardware_interface/EffortJointInterface</hardwareInterface>
      <mechanicalReduction>1</mechanicalReduction>
    </actuator>
  </transmission>
  <transmission name="right_leg_motor_3_tran">
    <type>transmission_interface/SimpleTransmission</type>
    <joint name="right_leg_motor_3">
      <hardwareInterface>hardware_interface/EffortJointInterface</hardwareInterface>
    </joint>
    <actuator name="right_leg_motor_3_actr">
      <hardwareInterface>hardware_interface/EffortJointInterface</hardwareInterface>
      <mechanicalReduction>1</mechanicalReduction>
    </actuator>
  </transmission>
  <transmission name="left_leg_motor_4_tran">
    <type>transmission_interface/SimpleTransmission</type>
    <joint name="left_leg_motor_4">
      <hardwareInterface>hardware_interface/EffortJointInterface</hardwareInterface>
    </joint>
    <actuator name="left_leg_motor_4_actr">
      <hardwareInterface>hardware_interface/EffortJointInterface</hardwareInterface>
      <mechanicalReduction>1</mechanicalReduction>
    </actuator>
  </transmission>
  <transmission name="right_leg_motor_4_tran">
    <type>transmission_interface/SimpleTransmission</type>
    <joint name="right_leg_motor_4">
      <hardwareInterface>hardware_interface/EffortJointInterface</hardwareInterface>
    </joint>
    <actuator name="right_leg_motor_4_actr">
      <hardwareInterface>hardware_interface/EffortJointInterface</hardwareInterface>
      <mechanicalReduction>1</mechanicalReduction>
    </actuator>
  </transmission>
  <transmission name="right_leg_motor_5_tran">
    <type>transmission_interface/SimpleTransmission</type>
    <joint name="right_leg_motor_5">
      <hardwareInterface>hardware_interface/EffortJointInterface</hardwareInterface>
    </joint>
    <actuator name="right_leg_motor_5_actr">
      <hardwareInterface>hardware_interface/EffortJointInterface</hardwareInterface>
      <mechanicalReduction>1</mechanicalReduction>
    </actuator>
  </transmission>
  <transmission name="left_leg_motor_5_tran">
    <type>transmission_interface/SimpleTransmission</type>
    <joint name="left_leg_motor_5">
      <hardwareInterface>hardware_interface/EffortJointInterface</hardwareInterface>
    </joint>
    <actuator name="left_leg_motor_5_actr">
      <hardwareInterface>hardware_interface/EffortJointInterface</hardwareInterface>
      <mechanicalReduction>1</mechanicalReduction>
    </actuator>
  </transmission>
  <transmission name="head_motor_0_tran">
    <type>transmission_interface/SimpleTransmission</type>
    <joint name="head_motor_0">
      <hardwareInterface>hardware_interface/EffortJointInterface</hardwareInterface>
    </joint>
    <actuator name="head_motor_0_actr">
      <hardwareInterface>hardware_interface/EffortJointInterface</hardwareInterface>
      <mechanicalReduction>1</mechanicalReduction>
    </actuator>
  </transmission>
  <transmission name="head_motor_1_tran">
    <type>transmission_interface/SimpleTransmission</type>
    <joint name="head_motor_1">
      <hardwareInterface>hardware_interface/EffortJointInterface</hardwareInterface>
    </joint>
    <actuator name="head_motor_1_actr">
      <hardwareInterface>hardware_interface/EffortJointInterface</hardwareInterface>
      <mechanicalReduction>1</mechanicalReduction>
    </actuator>
  </transmission>
  <transmission name="right_arm_motor_0_tran">
    <type>transmission_interface/SimpleTransmission</type>
    <joint name="right_arm_motor_0">
      <hardwareInterface>hardware_interface/EffortJointInterface</hardwareInterface>
    </joint>
    <actuator name="right_arm_motor_0_actr">
      <hardwareInterface>hardware_interface/EffortJointInterface</hardwareInterface>
      <mechanicalReduction>1</mechanicalReduction>
    </actuator>
  </transmission>
  <transmission name="left_arm_motor_0_tran">
    <type>transmission_interface/SimpleTransmission</type>
    <joint name="left_arm_motor_0">
      <hardwareInterface>hardware_interface/EffortJointInterface</hardwareInterface>
    </joint>
    <actuator name="left_arm_motor_0_actr">
      <hardwareInterface>hardware_interface/EffortJointInterface</hardwareInterface>
      <mechanicalReduction>1</mechanicalReduction>
    </actuator>
  </transmission>
  <transmission name="left_arm_motor_1_tran">
    <type>transmission_interface/SimpleTransmission</type>
    <joint name="left_arm_motor_1">
      <hardwareInterface>hardware_interface/EffortJointInterface</hardwareInterface>
    </joint>
    <actuator name="left_arm_motor_1_actr">
      <hardwareInterface>hardware_interface/EffortJointInterface</hardwareInterface>
      <mechanicalReduction>1</mechanicalReduction>
    </actuator>
  </transmission>
  <transmission name="right_arm_motor_1_tran">
    <type>transmission_interface/SimpleTransmission</type>
    <joint name="right_arm_motor_1">
      <hardwareInterface>hardware_interface/EffortJointInterface</hardwareInterface>
    </joint>
    <actuator name="right_arm_motor_1_actr">
      <hardwareInterface>hardware_interface/EffortJointInterface</hardwareInterface>
      <mechanicalReduction>1</mechanicalReduction>
    </actuator>
  </transmission>
  <transmission name="left_arm_motor_2_tran">
    <type>transmission_interface/SimpleTransmission</type>
    <joint name="left_arm_motor_2">
      <hardwareInterface>hardware_interface/EffortJointInterface</hardwareInterface>
    </joint>
    <actuator name="left_arm_motor_2_actr">
      <hardwareInterface>hardware_interface/EffortJointInterface</hardwareInterface>
      <mechanicalReduction>1</mechanicalReduction>
    </actuator>
  </transmission>
  <transmission name="right_arm_motor_2_tran">
    <type>transmission_interface/SimpleTransmission</type>
    <joint name="right_arm_motor_2">
      <hardwareInterface>hardware_interface/EffortJointInterface</hardwareInterface>
    </joint>
    <actuator name="right_arm_motor_2_actr">
      <hardwareInterface>hardware_interface/EffortJointInterface</hardwareInterface>
      <mechanicalReduction>1</mechanicalReduction>
    </actuator>
  </transmission>
  <gazebo>
    <plugin filename="libgazebo_ros_control.so" name="control"/>
  </gazebo>
  <gazebo reference="torso">
    <material>Gazebo/Silver</material>
    <mu1>0.2</mu1>
    <mu2>0.2</mu2>
    <selfCollide>true</selfCollide>
    <gravity>true</gravity>
  </gazebo>
  <gazebo reference="right_hip_side">
    <material>Gazebo/Silver</material>
    <mu1>0.2</mu1>
    <mu2>0.2</mu2>
    <selfCollide>true</selfCollide>
  </gazebo>
  <gazebo reference="left_hip_side">
    <material>Gazebo/Silver</material>
    <mu1>0.2</mu1>
    <mu2>0.2</mu2>
    <selfCollide>true</selfCollide>
  </gazebo>
  <gazebo reference="left_hip_front">
    <material>Gazebo/Silver</material>
    <mu1>0.2</mu1>
    <mu2>0.2</mu2>
    <selfCollide>true</selfCollide>
  </gazebo>
  <gazebo reference="right_hip_front">
    <material>Gazebo/Silver</material>
    <mu1>0.2</mu1>
    <mu2>0.2</mu2>
    <selfCollide>true</selfCollide>
  </gazebo>
  <gazebo reference="left_thigh">
    <material>Gazebo/Silver</material>
    <mu1>0.2</mu1>
    <mu2>0.2</mu2>
    <selfCollide>true</selfCollide>
  </gazebo>
  <gazebo reference="right_thigh">
    <material>Gazebo/Silver</material>
    <mu1>0.2</mu1>
    <mu2>0.2</mu2>
    <selfCollide>true</selfCollide>
  </gazebo>
  <gazebo reference="left_calve">
    <material>Gazebo/Silver</material>
    <mu1>0.2</mu1>
    <mu2>0.2</mu2>
    <selfCollide>true</selfCollide>
  </gazebo>
  <gazebo reference="right_calve">
    <material>Gazebo/Silver</material>
    <mu1>0.2</mu1>
    <mu2>0.2</mu2>
    <selfCollide>true</selfCollide>
  </gazebo>
  <gazebo reference="left_ankle">
    <material>Gazebo/Silver</material>
    <mu1>0.2</mu1>
    <mu2>0.2</mu2>
    <selfCollide>true</selfCollide>
  </gazebo>
  <gazebo reference="right_ankle">
    <material>Gazebo/Silver</material>
    <mu1>0.2</mu1>
    <mu2>0.2</mu2>
    <selfCollide>true</selfCollide>
  </gazebo>
  <gazebo reference="right_foot">
    <material>Gazebo/Silver</material>
    <mu1>0.2</mu1>
    <mu2>0.2</mu2>
    <selfCollide>true</selfCollide>
  </gazebo>
  <gazebo reference="left_foot">
    <material>Gazebo/Silver</material>
    <mu1>0.2</mu1>
    <mu2>0.2</mu2>
    <selfCollide>true</selfCollide>
  </gazebo>
  <gazebo reference="neck">
    <material>Gazebo/Silver</material>
    <mu1>0.2</mu1>
    <mu2>0.2</mu2>
    <selfCollide>true</selfCollide>
  </gazebo>
  <gazebo reference="head">
    <material>Gazebo/Silver</material>
    <mu1>0.2</mu1>
    <mu2>0.2</mu2>
    <selfCollide>true</selfCollide>
  </gazebo>
  <gazebo reference="right_shoulder">
    <material>Gazebo/Silver</material>
    <mu1>0.2</mu1>
    <mu2>0.2</mu2>
    <selfCollide>true</selfCollide>
  </gazebo>
  <gazebo reference="left_shoulder">
    <material>Gazebo/Silver</material>
    <mu1>0.2</mu1>
    <mu2>0.2</mu2>
    <selfCollide>true</selfCollide>
  </gazebo>
  <gazebo reference="left_bicep">
    <material>Gazebo/Silver</material>
    <mu1>0.2</mu1>
    <mu2>0.2</mu2>
    <selfCollide>true</selfCollide>
  </gazebo>
  <gazebo reference="right_bicep">
    <material>Gazebo/Silver</material>
    <mu1>0.2</mu1>
    <mu2>0.2</mu2>
    <selfCollide>true</selfCollide>
  </gazebo>
  <gazebo reference="left_forearm">
    <material>Gazebo/Silver</material>
    <mu1>0.2</mu1>
    <mu2>0.2</mu2>
    <selfCollide>true</selfCollide>
  </gazebo>
  <gazebo reference="right_forearm">
    <material>Gazebo/Silver</material>
    <mu1>0.2</mu1>
    <mu2>0.2</mu2>
    <selfCollide>true</selfCollide>
  </gazebo>
  <link name="torso">
    <inertial>
      <origin rpy="0 0 0" xyz="-0.21571129429326383 -0.09056097822952673 -0.0036209032704476486"/>
      <mass value="1.642579698459482"/>
      <inertia ixx="0.126743" ixy="0.000954" ixz="0.000457" iyy="0.127173" iyz="0.001886" izz="0.175491"/>
    </inertial>
    <visual>
      <origin rpy="0 0 0" xyz="0 0 0"/>
      <geometry>
        <mesh filename="/home/jonathan/catkin_ws/src/soccerbot/soccer_description/bez2_urdf_description_4/meshes/torso.stl" scale="0.001 0.001 0.001"/>
      </geometry>
      <material name="steel_satin"/>
    </visual>
    <collision>
      <origin rpy="0 0 0" xyz="0 0 0"/>
      <geometry>
        <mesh filename="/home/jonathan/catkin_ws/src/soccerbot/soccer_description/bez2_urdf_description_4/meshes/torso.stl" scale="0.001 0.001 0.001"/>
      </geometry>
    </collision>
  </link>
  <link name="neck">
    <inertial>
      <origin rpy="0 0 0" xyz="-0.005416578381325948 0.014255007146555454 1.3884111705209784e-07"/>
      <mass value="0.015549664333897642"/>
      <inertia ixx="3e-06" ixy="1e-06" ixz="0.0" iyy="6e-06" iyz="-0.0" izz="8e-06"/>
    </inertial>
    <visual>
      <origin rpy="0 0 0" xyz="0.216834 -0.013799 -0.005989"/>
      <geometry>
        <mesh filename="/home/jonathan/catkin_ws/src/soccerbot/soccer_description/bez2_urdf_description_4/meshes/neck.stl" scale="0.001 0.001 0.001"/>
      </geometry>
      <material name="plastic_matte_yellow"/>
    </visual>
    <collision>
      <origin rpy="0 0 0" xyz="0.216834 -0.013799 -0.005989"/>
      <geometry>
        <mesh filename="/home/jonathan/catkin_ws/src/soccerbot/soccer_description/bez2_urdf_description_4/meshes/neck.stl" scale="0.001 0.001 0.001"/>
      </geometry>
    </collision>
  </link>
  <link name="head">
    <inertial>
      <origin rpy="0 0 0" xyz="0.018592918200100034 0.012723544328102049 -0.0067684921493538636"/>
      <mass value="0.5407373847724953"/>
      <inertia ixx="0.000378" ixy="-4e-06" ixz="-0.0" iyy="0.000259" iyz="-8.1e-05" izz="0.000349"/>
    </inertial>
    <visual>
      <origin rpy="0 0 0" xyz="0.236334 -0.038799 -0.005989"/>
      <geometry>
        <mesh filename="/home/jonathan/catkin_ws/src/soccerbot/soccer_description/bez2_urdf_description_4/meshes/head.stl" scale="0.001 0.001 0.001"/>
      </geometry>
      <material name="plastic_matte_yellow"/>
    </visual>
    <collision>
      <origin rpy="0 0 0" xyz="0.236334 -0.038799 -0.005989"/>
      <geometry>
        <mesh filename="/home/jonathan/catkin_ws/src/soccerbot/soccer_description/bez2_urdf_description_4/meshes/head.stl" scale="0.001 0.001 0.001"/>
      </geometry>
    </collision>
  </link>
  <link name="left_shoulder">
    <inertial>
      <origin rpy="0 0 0" xyz="0.025390972668247483 -0.007099586291917492 9.508611288259246e-05"/>
      <mass value="0.42869731083494267"/>
      <inertia ixx="0.000137" ixy="1.8e-05" ixz="0.0" iyy="0.000116" iyz="3e-06" izz="0.000136"/>
    </inertial>
    <visual>
      <origin rpy="0 0 0" xyz="0.107134 0.018201 -0.002989"/>
      <geometry>
        <mesh filename="/home/jonathan/catkin_ws/src/soccerbot/soccer_description/bez2_urdf_description_4/meshes/left_shoulder.stl" scale="0.001 0.001 0.001"/>
      </geometry>
      <material name="steel_satin"/>
    </visual>
    <collision>
      <origin rpy="0 0 0" xyz="0.107134 0.018201 -0.002989"/>
      <geometry>
        <mesh filename="/home/jonathan/catkin_ws/src/soccerbot/soccer_description/bez2_urdf_description_4/meshes/left_shoulder.stl" scale="0.001 0.001 0.001"/>
      </geometry>
    </collision>
  </link>
  <link name="left_forearm">
    <inertial>
      <origin rpy="0 0 0" xyz="-0.020541961481344233 -0.07127024597337608 -0.026300695669579106"/>
      <mass value="0.06415483406403591"/>
      <inertia ixx="0.00026" ixy="-0.0" ixz="-0.0" iyy="2e-05" iyz="-7e-06" izz="0.000265"/>
    </inertial>
    <visual>
      <origin rpy="0 0 0" xyz="0.055696 0.125951 -0.004802"/>
      <geometry>
        <mesh filename="/home/jonathan/catkin_ws/src/soccerbot/soccer_description/bez2_urdf_description_4/meshes/left_forearm.stl" scale="0.001 0.001 0.001"/>
      </geometry>
      <material name="plastic_matte_yellow"/>
    </visual>
    <collision>
      <origin rpy="0 0 0" xyz="0.055696 0.125951 -0.004802"/>
      <geometry>
        <mesh filename="/home/jonathan/catkin_ws/src/soccerbot/soccer_description/bez2_urdf_description_4/meshes/left_forearm.stl" scale="0.001 0.001 0.001"/>
      </geometry>
    </collision>
  </link>
  <link name="left_bicep">
    <inertial>
      <origin rpy="0 0 0" xyz="0.000837422641322888 -0.05229647165113617 -0.019316083690244838"/>
      <mass value="0.7365391814909177"/>
      <inertia ixx="0.000616" ixy="1.3e-05" ixz="-0.0" iyy="0.000236" iyz="9e-06" izz="0.000601"/>
    </inertial>
    <visual>
      <origin rpy="0 0 0" xyz="0.077634 0.039201 -0.023489"/>
      <geometry>
        <mesh filename="/home/jonathan/catkin_ws/src/soccerbot/soccer_description/bez2_urdf_description_4/meshes/left_bicep.stl" scale="0.001 0.001 0.001"/>
      </geometry>
      <material name="steel_satin"/>
    </visual>
    <collision>
      <origin rpy="0 0 0" xyz="0.077634 0.039201 -0.023489"/>
      <geometry>
        <mesh filename="/home/jonathan/catkin_ws/src/soccerbot/soccer_description/bez2_urdf_description_4/meshes/left_bicep.stl" scale="0.001 0.001 0.001"/>
      </geometry>
    </collision>
  </link>
  <link name="left_hip_side">
    <inertial>
      <origin rpy="0 0 0" xyz="1.9172787252275114e-07 -0.007745738686026682 1.3828988840516865e-07"/>
      <mass value="0.023116469719045966"/>
      <inertia ixx="8e-06" ixy="-0.0" ixz="-0.0" iyy="7e-06" iyz="0.0" izz="3e-06"/>
    </inertial>
    <visual>
      <origin rpy="0 0 0" xyz="0.151634 0.224201 -0.015289"/>
      <geometry>
        <mesh filename="/home/jonathan/catkin_ws/src/soccerbot/soccer_description/bez2_urdf_description_4/meshes/left_hip_side.stl" scale="0.001 0.001 0.001"/>
      </geometry>
      <material name="steel_satin"/>
    </visual>
    <collision>
      <origin rpy="0 0 0" xyz="0.151634 0.224201 -0.015289"/>
      <geometry>
        <mesh filename="/home/jonathan/catkin_ws/src/soccerbot/soccer_description/bez2_urdf_description_4/meshes/left_hip_side.stl" scale="0.001 0.001 0.001"/>
      </geometry>
    </collision>
  </link>
  <link name="left_hip_front">
    <inertial>
      <origin rpy="0 0 0" xyz="0.00054199420852305 -0.012130624367135301 0.0004997464984967115"/>
      <mass value="0.7328385746044006"/>
      <inertia ixx="0.000458" ixy="-1e-06" ixz="-8e-06" iyy="0.000394" iyz="-2e-06" izz="0.000195"/>
    </inertial>
    <visual>
      <origin rpy="0 0 0" xyz="0.151634 0.252201 0.005211"/>
      <geometry>
        <mesh filename="/home/jonathan/catkin_ws/src/soccerbot/soccer_description/bez2_urdf_description_4/meshes/left_hip_front.stl" scale="0.001 0.001 0.001"/>
      </geometry>
      <material name="steel_satin"/>
    </visual>
    <collision>
      <origin rpy="0 0 0" xyz="0.151634 0.252201 0.005211"/>
      <geometry>
        <mesh filename="/home/jonathan/catkin_ws/src/soccerbot/soccer_description/bez2_urdf_description_4/meshes/left_hip_front.stl" scale="0.001 0.001 0.001"/>
      </geometry>
    </collision>
  </link>
  <link name="left_thigh">
    <inertial>
      <origin rpy="0 0 0" xyz="-0.018793854860002318 -0.06540844430287307 1.382897246455378e-07"/>
      <mass value="0.191955361852033"/>
      <inertia ixx="0.000121" ixy="1e-06" ixz="-0.0" iyy="6.9e-05" iyz="0.0" izz="0.000159"/>
    </inertial>
    <visual>
      <origin rpy="0 0 0" xyz="0.131334 0.252201 -0.01556"/>
      <geometry>
        <mesh filename="/home/jonathan/catkin_ws/src/soccerbot/soccer_description/bez2_urdf_description_4/meshes/left_thigh.stl" scale="0.001 0.001 0.001"/>
      </geometry>
      <material name="steel_satin"/>
    </visual>
    <collision>
      <origin rpy="0 0 0" xyz="0.131334 0.252201 -0.01556"/>
      <geometry>
        <mesh filename="/home/jonathan/catkin_ws/src/soccerbot/soccer_description/bez2_urdf_description_4/meshes/left_thigh.stl" scale="0.001 0.001 0.001"/>
      </geometry>
    </collision>
  </link>
  <link name="left_calve">
    <inertial>
      <origin rpy="0 0 0" xyz="-0.023267641569652553 -0.03085299717338086 0.0003497080567835976"/>
      <mass value="0.20304073544640247"/>
      <inertia ixx="0.00015" ixy="-2e-06" ixz="0.0" iyy="6.2e-05" iyz="2e-06" izz="0.000176"/>
    </inertial>
    <visual>
      <origin rpy="0 0 0" xyz="0.126066 0.368201 -0.01556"/>
      <geometry>
        <mesh filename="/home/jonathan/catkin_ws/src/soccerbot/soccer_description/bez2_urdf_description_4/meshes/left_calve.stl" scale="0.001 0.001 0.001"/>
      </geometry>
      <material name="steel_satin"/>
    </visual>
    <collision>
      <origin rpy="0 0 0" xyz="0.126066 0.368201 -0.01556"/>
      <geometry>
        <mesh filename="/home/jonathan/catkin_ws/src/soccerbot/soccer_description/bez2_urdf_description_4/meshes/left_calve.stl" scale="0.001 0.001 0.001"/>
      </geometry>
    </collision>
  </link>
  <link name="left_ankle">
    <inertial>
      <origin rpy="0 0 0" xyz="-0.02305678575314518 -0.017837916213576277 -0.020655013251792347"/>
      <mass value="0.26345509510176346"/>
      <inertia ixx="0.000212" ixy="-2e-06" ixz="-1e-06" iyy="0.000173" iyz="-1.7e-05" izz="0.000102"/>
    </inertial>
    <visual>
      <origin rpy="0 0 0" xyz="0.126066 0.456201 -0.01686"/>
      <geometry>
        <mesh filename="/home/jonathan/catkin_ws/src/soccerbot/soccer_description/bez2_urdf_description_4/meshes/left_ankle.stl" scale="0.001 0.001 0.001"/>
      </geometry>
      <material name="steel_satin"/>
    </visual>
    <collision>
      <origin rpy="0 0 0" xyz="0.126066 0.456201 -0.01686"/>
      <geometry>
        <mesh filename="/home/jonathan/catkin_ws/src/soccerbot/soccer_description/bez2_urdf_description_4/meshes/left_ankle.stl" scale="0.001 0.001 0.001"/>
      </geometry>
    </collision>
  </link>
  <link name="left_foot">
    <inertial>
      <origin rpy="0 0 0" xyz="0.01810728287499444 -0.01978149677877339 0.0476420980971338"/>
      <mass value="0.37785469138016164"/>
      <inertia ixx="0.000905" ixy="5e-06" ixz="-2.6e-05" iyy="0.001142" iyz="1.4e-05" izz="0.000247"/>
    </inertial>
    <visual>
      <origin rpy="0 0 0" xyz="0.149566 0.492201 0.04764"/>
      <geometry>
        <mesh filename="/home/jonathan/catkin_ws/src/soccerbot/soccer_description/bez2_urdf_description_4/meshes/left_foot.stl" scale="0.001 0.001 0.001"/>
      </geometry>
      <material name="steel_satin"/>
    </visual>
    <collision>
      <origin rpy="0 0 0" xyz="0.149566 0.492201 0.04764"/>
      <geometry>
        <mesh filename="/home/jonathan/catkin_ws/src/soccerbot/soccer_description/bez2_urdf_description_4/meshes/left_foot.stl" scale="0.001 0.001 0.001"/>
      </geometry>
    </collision>
  </link>
  <link name="right_shoulder">
    <inertial>
      <origin rpy="0 0 0" xyz="-0.025390584258132287 -0.007099586291917228 0.00042726293639836236"/>
      <mass value="0.42869731083494267"/>
      <inertia ixx="0.000137" ixy="-1.8e-05" ixz="1e-06" iyy="0.000116" iyz="4e-06" izz="0.000136"/>
    </inertial>
    <visual>
      <origin rpy="0 0 0" xyz="0.326534 0.018201 -0.002989"/>
      <geometry>
        <mesh filename="/home/jonathan/catkin_ws/src/soccerbot/soccer_description/bez2_urdf_description_4/meshes/right_shoulder.stl" scale="0.001 0.001 0.001"/>
      </geometry>
      <material name="steel_satin"/>
    </visual>
    <collision>
      <origin rpy="0 0 0" xyz="0.326534 0.018201 -0.002989"/>
      <geometry>
        <mesh filename="/home/jonathan/catkin_ws/src/soccerbot/soccer_description/bez2_urdf_description_4/meshes/right_shoulder.stl" scale="0.001 0.001 0.001"/>
      </geometry>
    </collision>
  </link>
  <link name="right_bicep">
    <inertial>
      <origin rpy="0 0 0" xyz="-0.0008370391854580772 -0.052296471651135726 -0.020683638627620245"/>
      <mass value="0.7365391814909177"/>
      <inertia ixx="0.000616" ixy="-1.3e-05" ixz="-0.0" iyy="0.000236" iyz="-9e-06" izz="0.000601"/>
    </inertial>
    <visual>
      <origin rpy="0 0 0" xyz="0.356034 0.039201 -0.023989"/>
      <geometry>
        <mesh filename="/home/jonathan/catkin_ws/src/soccerbot/soccer_description/bez2_urdf_description_4/meshes/right_bicep.stl" scale="0.001 0.001 0.001"/>
      </geometry>
      <material name="steel_satin"/>
    </visual>
    <collision>
      <origin rpy="0 0 0" xyz="0.356034 0.039201 -0.023989"/>
      <geometry>
        <mesh filename="/home/jonathan/catkin_ws/src/soccerbot/soccer_description/bez2_urdf_description_4/meshes/right_bicep.stl" scale="0.001 0.001 0.001"/>
      </geometry>
    </collision>
  </link>
  <link name="right_forearm">
    <inertial>
      <origin rpy="0 0 0" xyz="0.020457813945959913 -0.07127024597337553 -0.026300482702023342"/>
      <mass value="0.06415483406403591"/>
      <inertia ixx="0.00026" ixy="-0.0" ixz="-0.0" iyy="2e-05" iyz="-7e-06" izz="0.000265"/>
    </inertial>
    <visual>
      <origin rpy="0 0 0" xyz="0.377971 0.125951 -0.002677"/>
      <geometry>
        <mesh filename="/home/jonathan/catkin_ws/src/soccerbot/soccer_description/bez2_urdf_description_4/meshes/right_forearm.stl" scale="0.001 0.001 0.001"/>
      </geometry>
      <material name="plastic_matte_yellow"/>
    </visual>
    <collision>
      <origin rpy="0 0 0" xyz="0.377971 0.125951 -0.002677"/>
      <geometry>
        <mesh filename="/home/jonathan/catkin_ws/src/soccerbot/soccer_description/bez2_urdf_description_4/meshes/right_forearm.stl" scale="0.001 0.001 0.001"/>
      </geometry>
    </collision>
  </link>
  <link name="right_hip_side">
    <inertial>
      <origin rpy="0 0 0" xyz="1.9172787457666374e-07 -0.0077457386860268485 1.3828988838782141e-07"/>
      <mass value="0.023116469719045966"/>
      <inertia ixx="8e-06" ixy="-0.0" ixz="-0.0" iyy="7e-06" iyz="0.0" izz="3e-06"/>
    </inertial>
    <visual>
      <origin rpy="0 0 0" xyz="0.282034 0.224201 -0.015289"/>
      <geometry>
        <mesh filename="/home/jonathan/catkin_ws/src/soccerbot/soccer_description/bez2_urdf_description_4/meshes/right_hip_side.stl" scale="0.001 0.001 0.001"/>
      </geometry>
      <material name="steel_satin"/>
    </visual>
    <collision>
      <origin rpy="0 0 0" xyz="0.282034 0.224201 -0.015289"/>
      <geometry>
        <mesh filename="/home/jonathan/catkin_ws/src/soccerbot/soccer_description/bez2_urdf_description_4/meshes/right_hip_side.stl" scale="0.001 0.001 0.001"/>
      </geometry>
    </collision>
  </link>
  <link name="right_hip_front">
    <inertial>
      <origin rpy="0 0 0" xyz="0.0005419942085249652 -0.012130624367135412 0.0004997464984966967"/>
      <mass value="0.7328385746044006"/>
      <inertia ixx="0.000458" ixy="-1e-06" ixz="-8e-06" iyy="0.000394" iyz="-2e-06" izz="0.000195"/>
    </inertial>
    <visual>
      <origin rpy="0 0 0" xyz="0.282034 0.252201 0.005211"/>
      <geometry>
        <mesh filename="/home/jonathan/catkin_ws/src/soccerbot/soccer_description/bez2_urdf_description_4/meshes/right_hip_front.stl" scale="0.001 0.001 0.001"/>
      </geometry>
      <material name="steel_satin"/>
    </visual>
    <collision>
      <origin rpy="0 0 0" xyz="0.282034 0.252201 0.005211"/>
      <geometry>
        <mesh filename="/home/jonathan/catkin_ws/src/soccerbot/soccer_description/bez2_urdf_description_4/meshes/right_hip_front.stl" scale="0.001 0.001 0.001"/>
      </geometry>
    </collision>
  </link>
  <link name="right_thigh">
    <inertial>
      <origin rpy="0 0 0" xyz="-0.01879385486000179 -0.06540844430287324 1.3828972466982392e-07"/>
      <mass value="0.191955361852033"/>
      <inertia ixx="0.000121" ixy="1e-06" ixz="-0.0" iyy="6.9e-05" iyz="-0.0" izz="0.000159"/>
    </inertial>
    <visual>
      <origin rpy="0 0 0" xyz="0.261734 0.252201 -0.01556"/>
      <geometry>
        <mesh filename="/home/jonathan/catkin_ws/src/soccerbot/soccer_description/bez2_urdf_description_4/meshes/right_thigh.stl" scale="0.001 0.001 0.001"/>
      </geometry>
      <material name="steel_satin"/>
    </visual>
    <collision>
      <origin rpy="0 0 0" xyz="0.261734 0.252201 -0.01556"/>
      <geometry>
        <mesh filename="/home/jonathan/catkin_ws/src/soccerbot/soccer_description/bez2_urdf_description_4/meshes/right_thigh.stl" scale="0.001 0.001 0.001"/>
      </geometry>
    </collision>
  </link>
  <link name="right_calve">
    <inertial>
      <origin rpy="0 0 0" xyz="-0.023267641569651998 -0.030852997173381136 0.00034970805678362187"/>
      <mass value="0.20304073544640247"/>
      <inertia ixx="0.00015" ixy="-2e-06" ixz="0.0" iyy="6.2e-05" iyz="2e-06" izz="0.000176"/>
    </inertial>
    <visual>
      <origin rpy="0 0 0" xyz="0.256466 0.368201 -0.01556"/>
      <geometry>
        <mesh filename="/home/jonathan/catkin_ws/src/soccerbot/soccer_description/bez2_urdf_description_4/meshes/right_calve.stl" scale="0.001 0.001 0.001"/>
      </geometry>
      <material name="steel_satin"/>
    </visual>
    <collision>
      <origin rpy="0 0 0" xyz="0.256466 0.368201 -0.01556"/>
      <geometry>
        <mesh filename="/home/jonathan/catkin_ws/src/soccerbot/soccer_description/bez2_urdf_description_4/meshes/right_calve.stl" scale="0.001 0.001 0.001"/>
      </geometry>
    </collision>
  </link>
  <link name="right_ankle">
    <inertial>
      <origin rpy="0 0 0" xyz="-0.023056785753144626 -0.017837916213576444 -0.02065501325179228"/>
      <mass value="0.26345509510176346"/>
      <inertia ixx="0.000212" ixy="-2e-06" ixz="-1e-06" iyy="0.000173" iyz="-1.7e-05" izz="0.000102"/>
    </inertial>
    <visual>
      <origin rpy="0 0 0" xyz="0.256466 0.456201 -0.01686"/>
      <geometry>
        <mesh filename="/home/jonathan/catkin_ws/src/soccerbot/soccer_description/bez2_urdf_description_4/meshes/right_ankle.stl" scale="0.001 0.001 0.001"/>
      </geometry>
      <material name="steel_satin"/>
    </visual>
    <collision>
      <origin rpy="0 0 0" xyz="0.256466 0.456201 -0.01686"/>
      <geometry>
        <mesh filename="/home/jonathan/catkin_ws/src/soccerbot/soccer_description/bez2_urdf_description_4/meshes/right_ankle.stl" scale="0.001 0.001 0.001"/>
      </geometry>
    </collision>
  </link>
  <link name="right_foot">
    <inertial>
      <origin rpy="0 0 0" xyz="-0.018106380779456643 -0.01978149677877372 0.04764209809713378"/>
      <mass value="0.37785469138016164"/>
      <inertia ixx="0.000905" ixy="-5e-06" ixz="2.6e-05" iyy="0.001142" iyz="1.4e-05" izz="0.000247"/>
    </inertial>
    <visual>
      <origin rpy="0 0 0" xyz="0.279966 0.492201 0.04764"/>
      <geometry>
        <mesh filename="/home/jonathan/catkin_ws/src/soccerbot/soccer_description/bez2_urdf_description_4/meshes/right_foot.stl" scale="0.001 0.001 0.001"/>
      </geometry>
      <material name="steel_satin"/>
    </visual>
    <collision>
      <origin rpy="0 0 0" xyz="0.279966 0.492201 0.04764"/>
      <geometry>
        <mesh filename="/home/jonathan/catkin_ws/src/soccerbot/soccer_description/bez2_urdf_description_4/meshes/right_foot.stl" scale="0.001 0.001 0.001"/>
      </geometry>
    </collision>
  </link>
  <joint name="head_motor_0" type="revolute">
    <origin rpy="0 0 0" xyz="-0.216834 0.013799 0.005989"/>
    <parent link="torso"/>
    <child link="neck"/>
    <axis xyz="-0.0 -1.0 -0.0"/>
    <dynamics damping="0.16" friction="0.6"/>
    <limit effort="1.5" lower="-1.5707963267948966" upper="1.5707963267948966" velocity="6.39"/>
  </joint>
  <joint name="head_motor_1" type="revolute">
    <origin rpy="0 0 0" xyz="0 0 0.0"/>
    <parent link="neck"/>
    <child link="head"/>
    <axis xyz="1.0 -0.0 0.0"/>
    <dynamics damping="0.16" friction="0.6"/>
    <limit effort="1.5" lower="0" upper="1.5707963267948966" velocity="6.39"/>
  </joint>
  <joint name="left_arm_motor_0" type="revolute">
    <origin rpy="0 0 0" xyz="-0.107134 -0.018201 0.002989"/>
    <parent link="torso"/>
    <child link="left_shoulder"/>
    <axis xyz="-1.0 0.0 0.0"/>
    <dynamics damping="0.3" friction="0.83"/>
    <limit effort="2.5" lower="-1.5707963267948966" upper="3.9269908169872414" velocity="5.76"/>
  </joint>
  <joint name="left_arm_motor_1" type="revolute">
    <origin rpy="0 0 0" xyz="0.0295 -0.021 0.0205"/>
    <parent link="left_shoulder"/>
    <child link="left_bicep"/>
    <axis xyz="-0.0 0.0 1.0"/>
    <dynamics damping="0.3" friction="0.83"/>
    <limit effort="2.5" lower="0" upper="1.5707963267948966" velocity="5.76"/>
  </joint>
  <joint name="left_arm_motor_2" type="revolute">
    <origin rpy="0 0 0" xyz="0.021938 -0.08675 -0.018687"/>
    <parent link="left_bicep"/>
    <child link="left_forearm"/>
    <axis xyz="-1.0 -0.0 0.0"/>
    <dynamics damping="0.3" friction="0.83"/>
    <limit effort="2.5" lower="0" upper="3.141592653589793" velocity="5.76"/>
  </joint>
  <joint name="left_leg_motor_0" type="revolute">
    <origin rpy="0 0 0" xyz="-0.151634 -0.224201 0.015289"/>
    <parent link="torso"/>
    <child link="left_hip_side"/>
    <axis xyz="-0.0 -1.0 0.0"/>
    <dynamics damping="0.721165" friction="0.721165"/>
    <limit effort="4.1" lower="-1.309" upper="0.524" velocity="4.82"/>
  </joint>
  <joint name="left_leg_motor_1" type="revolute">
    <origin rpy="0 0 0" xyz="0.0 -0.028 -0.0205"/>
    <parent link="left_hip_side"/>
    <child link="left_hip_front"/>
    <axis xyz="0.0 0.0 1.0"/>
    <dynamics damping="0.721165" friction="0.721165"/>
    <limit effort="4.1" lower="-0.7853981633974483" upper="1.5707963267948966" velocity="4.82"/>
  </joint>
  <joint name="left_leg_motor_2" type="revolute">
    <origin rpy="0 0 0" xyz="0.0203 0.0 0.020771"/>
    <parent link="left_hip_front"/>
    <child link="left_thigh"/>
    <axis xyz="-1.0 -0.0 -0.0"/>
    <dynamics damping="0.721165" friction="0.721165"/>
    <limit effort="4.1" lower="-0.7853981633974483" upper="2.356194490192345" velocity="4.82"/>
  </joint>
  <joint name="left_leg_motor_3" type="revolute">
    <origin rpy="0 0 0" xyz="0.005268 -0.116 0.0"/>
    <parent link="left_thigh"/>
    <child link="left_calve"/>
    <axis xyz="-1.0 0.0 -0.0"/>
    <dynamics damping="0.66" friction="1.42"/>
    <limit effort="6.0" lower="-2.793" upper="0" velocity="6.6"/>
  </joint>
  <joint name="left_leg_motor_4" type="revolute">
    <origin rpy="0 0 0" xyz="0.0 -0.088 0.0013"/>
    <parent link="left_calve"/>
    <child link="left_ankle"/>
    <axis xyz="-1.0 -0.0 -0.0"/>
    <dynamics damping="0.66" friction="1.42"/>
    <limit effort="6.0" lower="-0.7853981633974483" upper="1.5707963267948966" velocity="6.6"/>
  </joint>
  <joint name="left_leg_motor_5" type="revolute">
    <origin rpy="0 0 0" xyz="-0.0235 -0.036 -0.0645"/>
    <parent link="left_ankle"/>
    <child link="left_foot"/>
    <axis xyz="0.0 0.0 -1.0"/>
    <dynamics damping="0.66" friction="1.42"/>
    <limit effort="6.0" lower="-0.7853981633974483" upper="0.7853981633974483" velocity="6.6"/>
  </joint>
  <joint name="right_arm_motor_0" type="revolute">
    <origin rpy="0 0 0" xyz="-0.326534 -0.018201 0.002989"/>
    <parent link="torso"/>
    <child link="right_shoulder"/>
    <axis xyz="-1.0 -0.0 0.0"/>
    <dynamics damping="0.3" friction="0.83"/>
    <limit effort="2.5" lower="-1.5707963267948966" upper="3.9269908169872414" velocity="5.76"/>
  </joint>
  <joint name="right_arm_motor_1" type="revolute">
    <origin rpy="0 0 0" xyz="-0.0295 -0.021 0.021"/>
    <parent link="right_shoulder"/>
    <child link="right_bicep"/>
    <axis xyz="0.0 0.0 -1.0"/>
    <dynamics damping="0.3" friction="0.83"/>
    <limit effort="2.5" lower="0" upper="1.5707963267948966" velocity="5.76"/>
  </joint>
  <joint name="right_arm_motor_2" type="revolute">
    <origin rpy="0 0 0" xyz="-0.021937 -0.08675 -0.021312"/>
    <parent link="right_bicep"/>
    <child link="right_forearm"/>
    <axis xyz="-1.0 0.0 -0.0"/>
    <dynamics damping="0.3" friction="0.83"/>
    <limit effort="2.5" lower="0" upper="3.141592653589793" velocity="5.76"/>
  </joint>
  <joint name="right_leg_motor_0" type="revolute">
    <origin rpy="0 0 0" xyz="-0.282034 -0.224201 0.015289"/>
    <parent link="torso"/>
    <child link="right_hip_side"/>
    <axis xyz="0.0 1.0 -0.0"/>
    <dynamics damping="0.721165" friction="0.721165"/>
    <limit effort="4.1" lower="-1.309" upper="0.524" velocity="4.82"/>
  </joint>
  <joint name="right_leg_motor_1" type="revolute">
    <origin rpy="0 0 0" xyz="0.0 -0.028 -0.0205"/>
    <parent link="right_hip_side"/>
    <child link="right_hip_front"/>
    <axis xyz="-0.0 0.0 -1.0"/>
    <dynamics damping="0.721165" friction="0.721165"/>
    <limit effort="4.1" lower="-0.7853981633974483" upper="1.5707963267948966" velocity="4.82"/>
  </joint>
  <joint name="right_leg_motor_2" type="revolute">
    <origin rpy="0 0 0" xyz="0.0203 0.0 0.020771"/>
    <parent link="right_hip_front"/>
    <child link="right_thigh"/>
    <axis xyz="-1.0 -0.0 -0.0"/>
    <dynamics damping="0.721165" friction="0.721165"/>
    <limit effort="4.1" lower="-0.7853981633974483" upper="2.356194490192345" velocity="4.82"/>
  </joint>
  <joint name="right_leg_motor_3" type="revolute">
    <origin rpy="0 0 0" xyz="0.005268 -0.116 0.0"/>
    <parent link="right_thigh"/>
    <child link="right_calve"/>
    <axis xyz="-1.0 0.0 -0.0"/>
    <dynamics damping="0.66" friction="1.42"/>
    <limit effort="6.0" lower="-2.793" upper="0" velocity="6.6"/>
  </joint>
  <joint name="right_leg_motor_4" type="revolute">
    <origin rpy="0 0 0" xyz="0.0 -0.088 0.0013"/>
    <parent link="right_calve"/>
    <child link="right_ankle"/>
    <axis xyz="-1.0 -0.0 -0.0"/>
    <dynamics damping="0.66" friction="1.42"/>
    <limit effort="6.0" lower="-0.7853981633974483" upper="1.5707963267948966" velocity="6.6"/>
  </joint>
  <joint name="right_leg_motor_5" type="revolute">
    <origin rpy="0 0 0" xyz="-0.0235 -0.036 -0.0645"/>
    <parent link="right_ankle"/>
    <child link="right_foot"/>
    <axis xyz="0.0 0.0 1.0"/>
    <dynamics damping="0.66" friction="1.42"/>
    <limit effort="6.0" lower="-0.7853981633974483" upper="0.7853981633974483" velocity="6.6"/>
  </joint>
  <link name="imu_link">
    <inertial>
      <mass value="0.01"/>
      <origin rpy="0  0  0" xyz="0 0 0"/>
      <inertia ixx="1e-9" ixy="0" ixz="0" iyy="1e-9" iyz="0" izz="1e-9"/>
    </inertial>
  </link>
  <joint name="torso_imu" type="fixed">
    <parent link="torso"/>
    <child link="imu_link"/>
    <origin rpy="0 0 0" xyz="0.0 0 0.000"/>
    <axis xyz="0 0 0"/>
  </joint>
  <gazebo reference="imu_link">
    <gravity>true</gravity>
    <sensor name="imu_sensor" type="imu">
      <always_on>true</always_on>
      <update_rate>100</update_rate>
      <visualize>true</visualize>
      <topic>__default_topic__</topic>
      <plugin filename="libgazebo_ros_imu_sensor.so" name="imu_plugin">
        <topicName>imu_raw</topicName>
        <bodyName>imu_link</bodyName>
        <updateRateHZ>50.0</updateRateHZ>
        <gaussianNoise>0.0</gaussianNoise>
        <xyzOffset>0 0 0</xyzOffset>
        <rpyOffset>0 0 0</rpyOffset>
        <frameName>imu_link</frameName>
      </plugin>
      <pose>0 0 0 0 0 0</pose>
    </sensor>
  </gazebo>
  <gazebo reference="imu_link">
    <kp>1000000000000000.0</kp>
    <kd>10000000000000.0</kd>
    <mu1>0.2</mu1>
    <mu2>0.2</mu2>
  </gazebo>
</robot>
