<robot name="onshape">
<link name="torso_2023">
<!-- Shapes for x_plate_23_front -->
<collision>
<origin xyz="0.060389204868665502524 1.4717405120971200828e-07 0.068082300000000012252" rpy="-1.570796326794896558 6.895308295167207679e-17 -1.570796326794896558" />
<geometry>
<box size="0.14499999999999999001 0.1155920000000000003 0.0060000000000000001249" />
</geometry>
</collision>
<!-- Shapes for mx-64at_ar -->
<collision>
<origin xyz="0.020939204868665975412 0.046400147174051414867 0.02200000000001074707" rpy="3.1415926535897691352 -1.3138215008622163751e-14 -1.570796326794896336" />
<geometry>
<box size="0.040199999999999999623 0.061100000000000001532 0.041000000000000001721" />
</geometry>
</collision>
<!-- Shapes for mx-64at_ar -->
<collision>
<origin xyz="0.020939204868666350112 -0.046399852825948745272 0.02200000000001099687" rpy="3.1415926535897495953 -1.2771348726224209355e-14 -1.5707963267949036634" />
<geometry>
<box size="0.040199999999999999623 0.061100000000000001532 0.041000000000000001721" />
</geometry>
</collision>
<!-- Shapes for mx-64at_ar -->
<collision>
<origin xyz="0.01583920486865465771 1.471740505627167706e-07 0.15700000000000038924" rpy="-2.0985643641962011544e-15 -2.5607325653630936744e-16 -1.570796326794896558" />
<geometry>
<box size="0.040199999999999999623 0.061100000000000001532 0.041000000000000001721" />
</geometry>
</collision>
<!-- Shapes for x_plate_23_front -->
<collision>
<origin xyz="-0.059610795131336914709 1.4717404883173641263e-07 0.071917699999998543903" rpy="1.5707963267948952257 7.9211561423418466212e-15 1.570796326794896558" />
<geometry>
<box size="0.14499999999999999001 0.1155920000000000003 0.0060000000000000001249" />
</geometry>
</collision>
<!-- Shapes for mx-64at_ar -->
<collision>
<origin xyz="0.010839204868674762183 0.056000147174040608433 0.16400000000000933276" rpy="-1.5707963267948805708 -1.5707963267948898967 0" />
<geometry>
<box size="0.040199999999999999623 0.061100000000000001532 0.041000000000000001721" />
</geometry>
</collision>
<!-- Shapes for mx-64at_ar -->
<collision>
<origin xyz="0.010839204868674713611 -0.055999852825940207857 0.16400000000001024869" rpy="1.5707963267948803487 1.5707963267948898967 0" />
<geometry>
<box size="0.040199999999999999623 0.061100000000000001532 0.041000000000000001721" />
</geometry>
</collision>
<visual>
<origin xyz="0 0 0" rpy="0 -0 0" />
<geometry>
<mesh filename="torso_2023_visual.stl"/>
</geometry>
<material name="torso_2023_material">
<color rgba="0.19899150351318967145 0.20531734779085583642 0.21164319206852200139 1.0"/>
</material>
</visual>
<inertial>
<origin xyz="0.002404191551789617437 0.00058179701409666133814 0.069312406945558138749" rpy="0 0 0"/>
<mass value="3.209475452296372211" />
<inertia ixx="0.018197261163386959509" ixy="3.9679899281069150514e-05"  ixz="0.00040820634538382894645" iyy="0.016253016131205444417" iyz="-0.0001554682564299787826" izz="0.010276323694102498102" />
</inertial>
</link>

<link name="head_base">
<inertial>
<origin xyz="0 0 0" rpy="0 0 0" />
<mass value="1e-9" />
<inertia ixx="0" ixy="0" ixz="0" iyy="0" iyz="0" izz="0" />
</inertial>
</link>
<joint name="head_base_frame" type="fixed">
<origin xyz="0.033389204868654910607 1.4717405055631460442e-07 0.18300000000001087619" rpy="-1.2246467991473633145e-16 -2.2088105346187814874e-29 1.4393641492882479269e-28" />
<parent link="torso_2023" />
<child link="head_base" />
<axis xyz="0 0 0"/>
</joint>

<link name="trunk">
<inertial>
<origin xyz="0 0 0" rpy="0 0 0" />
<mass value="1e-9" />
<inertia ixx="0" ixy="0" ixz="0" iyy="0" iyz="0" izz="0" />
</inertial>
</link>
<joint name="trunk_frame" type="fixed">
<origin xyz="0.060889204868665502968 1.4717405119935517762e-07 0.0024999999999999996184" rpy="-8.2672622867162037207e-28 -0 -2.2402855000300105724e-59" />
<parent link="torso_2023" />
<child link="trunk" />
<axis xyz="0 0 0"/>
</joint>

<link name="u_neck">
<!-- Shapes for u_side_neck -->
<collision>
<origin xyz="0.024999999999999980571 1.9733087385364363632e-16 0.032901041851021092799" rpy="1.5707963267948976682 3.8654184355828463032e-29 -1.5707963267948958919" />
<geometry>
<box size="0.02999999999999999889 0.065802000000000013258 0.0030000000000000000625" />
</geometry>
</collision>
<!-- Shapes for u_side_neck -->
<collision>
<origin xyz="-0.024999999999999966693 -6.3823946217424702993e-18 0.032901041851021231577" rpy="1.570796326794896558 -1.1832913578314774909e-29 1.5707963267948970021" />
<geometry>
<box size="0.02999999999999999889 0.065802000000000013258 0.0030000000000000000625" />
</geometry>
</collision>
<!-- Shapes for u_base_64 -->
<collision>
<origin xyz="0 6.9388939039072299184e-18 0.0031250000000000001735" rpy="-3.141592653589793116 -0 6.6680722587749828369e-32" />
<geometry>
<box size="0.049000000000000001887 0.02999999999999999889 0.0062500000000000003469" />
</geometry>
</collision>
<visual>
<origin xyz="0 0 0" rpy="0 -0 0" />
<geometry>
<mesh filename="u_neck_visual.stl"/>
</geometry>
<material name="u_neck_material">
<color rgba="0.30196078431372541662 0.30196078431372541662 0.30196078431372541662 1.0"/>
</material>
</visual>
<inertial>
<origin xyz="6.2190491371535006904e-18 5.9578490733930535427e-17 0.020633402679855899348" rpy="0 0 0"/>
<mass value="0.054479900613359222294" />
<inertia ixx="3.0578702573708491281e-05" ixy="-1.35944226682749599e-11"  ixz="8.6291481501531847043e-20" iyy="5.16951967684507277e-05" iyz="-1.3658406274475592967e-20" izz="2.9852490907290876406e-05" />
</inertial>
</link>

<link name="head_2023__field_of_view_false">
<!-- Shapes for head_plate_g_2023 -->
<collision>
<origin xyz="-0.023800000000009986778 0.03650000000001005912 -0.0049999999999899985559" rpy="-3.141592653589793116 8.3007013600425831728e-32 3.141592653589793116" />
<geometry>
<cylinder length="0.0030000000000000000625" radius="0.023500000000000000056" />
</geometry>
</collision>
<collision>
<origin xyz="0.0099999999999900099357 0.03650000000001005912 -0.0049999999999899985559" rpy="-3.141592653589793116 8.3007013600425831728e-32 3.141592653589793116" />
<geometry>
<box size="0.061600000000000001976 0.047000000000000000111 0.0030000000000000000625" />
</geometry>
</collision>
<!-- Shapes for head_plate_d_2023 -->
<collision>
<origin xyz="-0.023799999999999980893 0.036500000000000011602 -0.049000000000000001887" rpy="-3.141592653589793116 8.3007013600425831728e-32 3.141592653589793116" />
<geometry>
<cylinder length="0.0030000000000000000625" radius="0.023500000000000000056" />
</geometry>
</collision>
<collision>
<origin xyz="0.010000000000000015821 0.036500000000000011602 -0.049000000000000001887" rpy="-3.141592653589793116 8.3007013600425831728e-32 3.141592653589793116" />
<geometry>
<box size="0.061600000000000001976 0.047000000000000000111 0.0030000000000000000625" />
</geometry>
</collision>
<!-- Shapes for mx-64at_ar -->
<collision>
<origin xyz="6.9222544433143798142e-33 -0.017549999999999975342 -0.023500000000000000056" rpy="-4.9303806576313237838e-32 -8.3007013600425831728e-32 0" />
<geometry>
<box size="0.040199999999999999623 0.061100000000000001532 0.041000000000000001721" />
</geometry>
</collision>
<visual>
<origin xyz="0 0 0" rpy="0 -0 0" />
<geometry>
<mesh filename="head_2023__field_of_view_false_visual.stl"/>
</geometry>
<material name="head_2023__field_of_view_false_material">
<color rgba="0.32045575682762955649 0.3148738338185399499 0.29812806479127113013 1.0"/>
</material>
</visual>
<inertial>
<origin xyz="-0.00014727358172439604118 0.004188973710585135353 -0.022194668178046370044" rpy="0 0 0"/>
<mass value="0.2442753572452601718" />
<inertia ixx="0.00024412764562559184991" ixy="5.0115087234599496772e-06"  ixz="5.8509375179164991778e-07" iyy="9.8460636778300379798e-05" iyz="4.8564002640062205055e-06" izz="0.00024462482752841290846" />
</inertial>
</link>

<link name="camera">
<inertial>
<origin xyz="0 0 0" rpy="0 0 0" />
<mass value="1e-9" />
<inertia ixx="0" ixy="0" ixz="0" iyy="0" iyz="0" izz="0" />
</inertial>
</link>
<joint name="camera_frame" type="fixed">
<origin xyz="-0.024933000004024159779 0.033500000000055651928 -0.023500000000000031281" rpy="3.1415926535897926719 1.5707963267948934494 0" />
<parent link="head_2023__field_of_view_false" />
<child link="camera" />
<axis xyz="0 0 0"/>
</joint>

<joint name="head_pitch" type="revolute">
<origin xyz="-0.023500000000000478839 0 0.058302041851021751961" rpy="1.570796326794896558 1.0090503962456224389e-14 -1.5707963267949012209" />
<parent link="u_neck" />
<child link="head_2023__field_of_view_false" />
<axis xyz="0 0 1"/>
<limit effort="10" velocity="6" lower="-0.785398163397448279" upper="1.570796326794896558"/>
<joint_properties friction="0.0"/>
</joint>

<joint name="head_yaw" type="revolute">
<origin xyz="0.033389204868654723257 1.4717405055870088152e-07 0.18050000000001087397" rpy="-2.0985643641961916881e-15 -2.5607325488194789582e-16 -1.5707963267948958919" />
<parent link="torso_2023" />
<child link="u_neck" />
<axis xyz="0 0 1"/>
<limit effort="10" velocity="6" lower="-2.0943951023931952626" upper="2.0943951023931952626"/>
<joint_properties friction="0.0"/>
</joint>

<link name="u_shoulder_2023">
<!-- Shapes for u_base_64 -->
<collision>
<origin xyz="6.9388939039072260665e-18 -2.7755575615628913511e-17 0.0071249999999999898484" rpy="3.141592653589793116 -7.6522649634278952728e-31 0" />
<geometry>
<box size="0.049000000000000001887 0.02999999999999999889 0.0062500000000000003469" />
</geometry>
</collision>
<visual>
<origin xyz="0 0 0" rpy="0 -0 0" />
<geometry>
<mesh filename="u_shoulder_2023_visual.stl"/>
</geometry>
<material name="u_shoulder_2023_material">
<color rgba="0.30196078431372547213 0.30196078431372547213 0.30196078431372547213 1.0"/>
</material>
</visual>
<inertial>
<origin xyz="2.4424894614099603073e-18 0.0049396691582913390683 0.016218911071912058691" rpy="0 0 0"/>
<mass value="0.063115931035088973511" />
<inertia ixx="1.953710958907587769e-05" ixy="8.0865176683183985495e-21"  ixz="2.9910850949917480723e-21" iyy="3.797873232270680368e-05" iyz="-4.2793411691716059055e-06" izz="3.8321411352794628792e-05" />
</inertial>
</link>

<link name="left_humerus">
<!-- Shapes for mx-64at_ar -->
<collision>
<origin xyz="-2.7268465263574627341e-17 -0.017549999999999201655 -0.023500000000009992063" rpy="1.1349789930213770448e-16 4.141519752410504657e-30 5.5511151231260415471e-17" />
<geometry>
<box size="0.040199999999999999623 0.061100000000000001532 0.041000000000000001721" />
</geometry>
</collision>
<!-- Shapes for humerus_plate -->
<collision>
<origin xyz="-9.7404723176097718351e-15 -0.10450000000001578859 -0.040000000000000236755" rpy="-3.141592653589793116 9.9803458132119541838e-16 -1.5707963267948958919" />
<geometry>
<box size="0.10499999999999999611 0.02999999999999999889 0.0030000000000000000625" />
</geometry>
</collision>
<visual>
<origin xyz="0 0 0" rpy="0 -0 0" />
<geometry>
<mesh filename="left_humerus_visual.stl"/>
</geometry>
<material name="left_humerus_material">
<color rgba="0.26470081700903547173 0.26470081700903547173 0.26470081700903547173 1.0"/>
</material>
</visual>
<inertial>
<origin xyz="5.6943617024147799295e-05 -0.048319510719950012345 -0.024575881071813601014" rpy="0 0 0"/>
<mass value="0.21354801913329538032" />
<inertia ixx="0.00058096798203317672436" ixy="-6.2560841153511995456e-07"  ixz="5.9950522391738340977e-07" iyy="6.2506691086893211452e-05" iyz="-4.7119123519259538857e-05" izz="0.00056596906011033081777" />
</inertial>
</link>

<link name="radius_v2">
<!-- Shapes for hand_2023 -->
<collision>
<origin xyz="2.3314683517128287349e-15 -0.14960000000000389653 -0.04200000000000708722" rpy="8.5789493427639171835e-16 -1.4349632593279760165e-14 -1.5707963267948807928" />
<geometry>
<cylinder length="0.0030000000000000000625" radius="0.040000000000000000833" />
</geometry>
</collision>
<collision>
<origin xyz="9.950017590433736978e-16 -0.064975600000001590417 -0.042000000000008301526" rpy="8.5789493427639171835e-16 -1.4349632593279760165e-14 -1.5707963267948807928" />
<geometry>
<box size="0.099551199999999992474 0.041200000000000000511 0.0030000000000000000625" />
</geometry>
</collision>
<!-- Shapes for mx-64at_ar -->
<collision>
<origin xyz="2.7716579020276322994e-16 -0.017550000000000353512 -0.023500000000009339807" rpy="-1.4627188349436689856e-14 -1.7291397324641162744e-15 -3.3085993879108190798e-24" />
<geometry>
<box size="0.040199999999999999623 0.061100000000000001532 0.041000000000000001721" />
</geometry>
</collision>
<!-- Shapes for hand_2023 -->
<collision>
<origin xyz="2.2620794126737568455e-15 -0.14960000000000434062 -0.0050000000000077768694" rpy="1.5801403290851799135e-15 -1.4099832412738820687e-14 -1.5707963267948807928" />
<geometry>
<cylinder length="0.0030000000000000000625" radius="0.040000000000000000833" />
</geometry>
</collision>
<collision>
<origin xyz="9.2561282028426519106e-16 -0.064975600000000327539 -0.0050000000000089694918" rpy="1.5801403290851799135e-15 -1.4099832412738820687e-14 -1.5707963267948807928" />
<geometry>
<box size="0.099551199999999992474 0.041200000000000000511 0.0030000000000000000625" />
</geometry>
</collision>
<visual>
<origin xyz="0 0 0" rpy="0 -0 0" />
<geometry>
<mesh filename="radius_v2_visual.stl"/>
</geometry>
<material name="radius_v2_material">
<color rgba="0.21421337674205653823 0.21421337674205653823 0.21421337674205653823 1.0"/>
</material>
</visual>
<inertial>
<origin xyz="8.4068843436831345163e-05 -0.058656980732179446469 -0.022253253402805699135" rpy="0 0 0"/>
<mass value="0.24385614723354964717" />
<inertia ixx="0.00088750206453679482757" ixy="-8.5350141283946978968e-07"  ixz="6.3814753118080238269e-07" iyy="0.00012329082294249270888" iyz="-1.4900103353591719914e-05" izz="0.00090346747116607385025" />
</inertial>
</link>

<joint name="left_elbow" type="revolute">
<origin xyz="0.023499999999999215961 -0.14200000000002438449 -0.0024999999999901836856" rpy="-2.0539125955565735208e-15 1.5707963267948905628 0" />
<parent link="left_humerus" />
<child link="radius_v2" />
<axis xyz="0 0 1"/>
<limit effort="10" velocity="6" lower="-2.7925268031909271649" upper="0.26179938779914940783"/>
<joint_properties friction="0.0"/>
</joint>

<joint name="left_shoulder_roll" type="revolute">
<origin xyz="0.023500000000000003525 0.030000000000000026645 0.030000000000000040523" rpy="-1.570796326794896558 -1.3089969389957472057 -1.5707963267948776842" />
<parent link="u_shoulder_2023" />
<child link="left_humerus" />
<axis xyz="0 0 1"/>
<limit effort="10" velocity="6" lower="-0.26179938779914940783" upper="1.3089969389957472057"/>
<joint_properties friction="0.0"/>
</joint>

<joint name="left_shoulder_pitch" type="revolute">
<origin xyz="0.028389204868674390581 0.079500147174040886044 0.16400000000000944378" rpy="-1.5707963267948972241 -6.7723604502158080687e-15 1.5994042028286861822e-14" />
<parent link="torso_2023" />
<child link="u_shoulder_2023" />
<axis xyz="0 0 1"/>
<limit effort="10" velocity="6" lower="-2.1816615649929120835" upper="2.1816615649929120835"/>
<joint_properties friction="0.0"/>
</joint>

<link name="u_shoulder_2023_2">
<!-- Shapes for u_base_64 -->
<collision>
<origin xyz="3.2699529172686476008e-33 0 -0.0071250000000000037262" rpy="0 3.7607829462383170689e-31 0" />
<geometry>
<box size="0.049000000000000001887 0.02999999999999999889 0.0062500000000000003469" />
</geometry>
</collision>
<visual>
<origin xyz="0 0 0" rpy="0 -0 0" />
<geometry>
<mesh filename="u_shoulder_2023_2_visual.stl"/>
</geometry>
<material name="u_shoulder_2023_2_material">
<color rgba="0.30196078431372547213 0.30196078431372547213 0.30196078431372547213 1.0"/>
</material>
</visual>
<inertial>
<origin xyz="1.0467811977471260936e-18 -0.004939669158291338201 -0.016218911071912076038" rpy="0 0 0"/>
<mass value="0.063115931035088959633" />
<inertia ixx="1.9537109589075860749e-05" ixy="9.4894159872083334861e-21"  ixz="-1.1249656330721176378e-22" iyy="3.7978732322706796904e-05" iyz="-4.2793411691715999763e-06" izz="3.8321411352794601687e-05" />
</inertial>
</link>

<link name="right_humerus">
<!-- Shapes for humerus_plate -->
<collision>
<origin xyz="1.7347234759768070944e-18 -0.10450000000000948808 -0.040000000000000042466" rpy="-3.1415926535897922278 9.6043344093044080964e-16 -1.5707963267948972241" />
<geometry>
<box size="0.10499999999999999611 0.02999999999999999889 0.0030000000000000000625" />
</geometry>
</collision>
<!-- Shapes for mx-64at_ar -->
<collision>
<origin xyz="0 -0.017549999999999999628 -0.023499999999999996586" rpy="-7.8886090522101180541e-31 -3.9443045261050590271e-31 5.5511151231257827021e-17" />
<geometry>
<box size="0.040199999999999999623 0.061100000000000001532 0.041000000000000001721" />
</geometry>
</collision>
<visual>
<origin xyz="0 0 0" rpy="0 -0 0" />
<geometry>
<mesh filename="right_humerus_visual.stl"/>
</geometry>
<material name="right_humerus_material">
<color rgba="0.26470081700903547173 0.26470081700903547173 0.26470081700903547173 1.0"/>
</material>
</visual>
<inertial>
<origin xyz="0.00013505725925222261327 -0.04831951073071154984 -0.024558474479375511784" rpy="0 0 0"/>
<mass value="0.21354801913329532481" />
<inertia ixx="0.00058097591616929793786" ixy="-6.5754355948998949182e-07"  ixz="5.8206046435963933794e-07" iyy="6.2511422023192716926e-05" iyz="-4.7130347402953834315e-05" izz="0.0005659658577717034721" />
</inertial>
</link>

<link name="radius_v2_2">
<!-- Shapes for hand_2023 -->
<collision>
<origin xyz="-1.0120376758848704027e-15 0.14960000000000850395 0.0050000000000103329845" rpy="3.1415926535897917837 1.6098233857063850813e-15 1.5707963267949021091" />
<geometry>
<cylinder length="0.0030000000000000000625" radius="0.040000000000000000833" />
</geometry>
</collision>
<collision>
<origin xyz="-5.5402188392501099437e-16 0.064975600000003658208 0.0050000000000104691603" rpy="3.1415926535897917837 1.6098233857063850813e-15 1.5707963267949021091" />
<geometry>
<box size="0.099551199999999992474 0.041200000000000000511 0.0030000000000000000625" />
</geometry>
</collision>
<!-- Shapes for hand_2023 -->
<collision>
<origin xyz="-8.5942364336233482337e-16 0.14960000000000839293 0.042000000000012124857" rpy="3.1415926535897922278 1.9984014443251693601e-15 1.5707963267949023312" />
<geometry>
<cylinder length="0.0030000000000000000625" radius="0.040000000000000000833" />
</geometry>
</collision>
<collision>
<origin xyz="-3.8496625887058528284e-16 0.064975600000003616574 0.042000000000012298329" rpy="3.1415926535897922278 1.9984014443251693601e-15 1.5707963267949023312" />
<geometry>
<box size="0.099551199999999992474 0.041200000000000000511 0.0030000000000000000625" />
</geometry>
</collision>
<!-- Shapes for mx-64at_ar -->
<collision>
<origin xyz="-1.1276118927484529748e-16 0.017550000000001019645 0.023500000000011341678" rpy="3.1415926535897913396 1.1729299448981592607e-17 3.1428563154283590482e-18" />
<geometry>
<box size="0.040199999999999999623 0.061100000000000001532 0.041000000000000001721" />
</geometry>
</collision>
<visual>
<origin xyz="0 0 0" rpy="0 -0 0" />
<geometry>
<mesh filename="radius_v2_2_visual.stl"/>
</geometry>
<material name="radius_v2_2_material">
<color rgba="0.21421337674205653823 0.21421337674205653823 0.21421337674205653823 1.0"/>
</material>
</visual>
<inertial>
<origin xyz="8.4068843435550400954e-05 0.058656980732181396299 0.022253253402808172851" rpy="0 0 0"/>
<mass value="0.2438561472335495639" />
<inertia ixx="0.00088750206453684437561" ixy="8.5350141285283766365e-07"  ixz="-6.381475311803566316e-07" iyy="0.00012329082294250184328" iyz="-1.4900103353600539221e-05" izz="0.00090346747116614323919" />
</inertial>
</link>

<joint name="right_elbow" type="revolute">
<origin xyz="-0.023500000000009346746 -0.1420000000000189444 -0.0024999999999904057302" rpy="-3.141592653589793116 -1.5707963267948925612 0" />
<parent link="right_humerus" />
<child link="radius_v2_2" />
<axis xyz="0 0 1"/>
<limit effort="10" velocity="6" lower="-2.7925268031909271649" upper="0.26179938779914940783"/>
<joint_properties friction="0.0"/>
</joint>

<joint name="right_shoulder_roll" type="revolute">
<origin xyz="-0.02349999999998999764 -0.029999999999999971134 -0.030000000000000026645" rpy="1.570796326794896558 -1.3089969389957472057 -1.5707963267948921171" />
<parent link="u_shoulder_2023_2" />
<child link="right_humerus" />
<axis xyz="0 0 1"/>
<limit effort="10" velocity="6" lower="-1.3089969389957472057" upper="0.26179938779914940783"/>
<joint_properties friction="0.0"/>
</joint>

<joint name="right_shoulder_pitch" type="revolute">
<origin xyz="0.028389204868675101817 -0.079499852825939937295 0.16400000000001035971" rpy="1.5707963268037437032 6.7723604502158104352e-15 -3.1415926535897766847" />
<parent link="torso_2023" />
<child link="u_shoulder_2023_2" />
<axis xyz="0 0 1"/>
<limit effort="10" velocity="6" lower="-2.1816615649929120835" upper="2.1816615649929120835"/>
<joint_properties friction="0.0"/>
</joint>

<link name="u_block_2023">
<!-- Shapes for u_side_small_2023 -->
<collision>
<origin xyz="-0.031440000000000009606 3.4694469519536141888e-18 -0.023750000000000003747" rpy="1.570796326794896558 6.310887241768093042e-30 1.570796326794896558" />
<geometry>
<box size="0.037499999999999998612 0.047500000000000000555 0.0030000000000000000625" />
</geometry>
</collision>
<!-- Shapes for u_side_small_with_trace_2023 -->
<collision>
<origin xyz="0.02189999999999998892 6.9388939039072283776e-18 -0.023750000000000000278" rpy="-1.570796326794896558 -1.2621774483536186084e-29 -1.57079632679489678" />
<geometry>
<box size="0.037499999999999998612 0.047500000000000000555 0.0030000000000000000625" />
</geometry>
</collision>
<visual>
<origin xyz="0 0 0" rpy="0 -0 0" />
<geometry>
<mesh filename="u_block_2023_visual.stl"/>
</geometry>
<material name="u_block_2023_material">
<color rgba="0.30196078431372547213 0.30196078431372547213 0.30196078431372547213 1.0"/>
</material>
</visual>
<inertial>
<origin xyz="-0.0050952800776957766701 9.7644663469321402356e-06 -0.0098513101413465718748" rpy="0 0 0"/>
<mass value="0.063013635376408735911" />
<inertia ixx="2.0269572434619567789e-05" ixy="1.8445701181431763189e-08"  ixz="-2.0238661272364778972e-06" iyy="4.242644375039842286e-05" iyz="1.5885140541300664519e-08" izz="3.5257525466159230149e-05" />
</inertial>
</link>

<link name="mx106_block_hip__list_0bj1pweadmbeeq_hip">
<!-- Shapes for mx106 -->
<collision>
<origin xyz="-1.3877787807814228725e-17 -0.018050000000000003542 -0.025999999999999995337" rpy="0 8.6736173924775835263e-19 -6.3108872417680944433e-30" />
<geometry>
<box size="0.040199999999999999623 0.065099999999999991207 0.045999999999999999223" />
</geometry>
</collision>
<!-- Shapes for mx106 -->
<collision>
<origin xyz="-5.3096416152698375025e-16 -0.018050000000003157269 0.023400000000023329222" rpy="4.5186077102243625071e-14 1.5707963267948559238 0" />
<geometry>
<box size="0.040199999999999999623 0.065099999999999991207 0.045999999999999999223" />
</geometry>
</collision>
<visual>
<origin xyz="0 0 0" rpy="0 -0 0" />
<geometry>
<mesh filename="mx106_block_hip__list_0bj1pweadmbeeq_hip_visual.stl"/>
</geometry>
<material name="mx106_block_hip__list_0bj1pweadmbeeq_hip_material">
<color rgba="0.30196078431372547213 0.30196078431372547213 0.30196078431372547213 1.0"/>
</material>
</visual>
<inertial>
<origin xyz="-0.00052517765759452336629 -0.015396401985203247639 0.0038303184852019494556" rpy="0 0 0"/>
<mass value="0.39709667579512258895" />
<inertia ixx="0.00042862260505794458733" ixy="2.0806166038692639799e-06"  ixz="4.0772710547725568797e-06" iyy="0.00037083252140591576066" iyz="-3.1158102365651866282e-05" izz="0.00018178857406348238024" />
</inertial>
</link>

<link name="left_knee_2023">
<!-- Shapes for mx106 -->
<collision>
<origin xyz="1.6171271352083070381e-16 0.1219500000000218326 -0.029500000000001719291" rpy="-1.2212453270869655723e-15 3.6419652016395373155e-14 8.8149932579980409148e-15" />
<geometry>
<box size="0.040199999999999999623 0.065099999999999991207 0.045999999999999999223" />
</geometry>
</collision>
<!-- Shapes for u_side_femur_mir_2023 -->
<collision>
<origin xyz="7.3155695846210832323e-16 0.03724999999999987349 -0.056999999999998170186" rpy="3.1415926535897678029 8.0177184336170216939e-14 4.6345982414074152745e-14" />
<geometry>
<box size="0.02999999999999999889 0.096500000000000002442 0.0030000000000000000625" />
</geometry>
</collision>
<!-- Shapes for u_side_femur_2023 -->
<collision>
<origin xyz="1.0857104619941809451e-30 0.037249999999999991451 0.0015000000000000303889" rpy="-6.3108872417680944433e-30 -8.6736173726459660735e-19 -3.1554436208840472216e-30" />
<geometry>
<box size="0.02999999999999999889 0.096500000000000002442 0.0030000000000000000625" />
</geometry>
</collision>
<visual>
<origin xyz="0 0 0" rpy="0 -0 0" />
<geometry>
<mesh filename="left_knee_2023_visual.stl"/>
</geometry>
<material name="left_knee_2023_material">
<color rgba="0.30196078431372547213 0.30196078431372547213 0.30196078431372547213 1.0"/>
</material>
</visual>
<inertial>
<origin xyz="-3.0553573383180897976e-05 0.10076603301830913684 -0.029713754998557023734" rpy="0 0 0"/>
<mass value="0.2677691867359469069" />
<inertia ixx="0.00053571701931061236138" ixy="-1.3722075397623253609e-07"  ixz="6.3727683447587735337e-09" iyy="0.00012197186231223949165" iyz="1.3660400579921389087e-05" izz="0.0004590485175473826493" />
</inertial>
</link>

<link name="tibia_2023">
<!-- Shapes for tibia_plate_2023 -->
<collision>
<origin xyz="-0.0062131000000000009137 0.068950999999999970647 0.0015000000000000021996" rpy="3.141592653589793116 -7.5508931389136273186e-28 3.141592653589793116" />
<geometry>
<box size="0.04042620000000000241 0.1700990000000000002 0.0030000000000000000625" />
</geometry>
</collision>
<!-- Shapes for tibia_plate_2023 -->
<collision>
<origin xyz="-0.0062131000000000703026 0.068951000000002218848 -0.055939999999999809321" rpy="3.141592653589793116 6.9388939031522946543e-18 -3.141592653589793116" />
<geometry>
<box size="0.04042620000000000241 0.1700990000000000002 0.0030000000000000000625" />
</geometry>
</collision>
<visual>
<origin xyz="0 0 0" rpy="0 -0 0" />
<geometry>
<mesh filename="tibia_2023_visual.stl"/>
</geometry>
<material name="tibia_2023_material">
<color rgba="0.30196078431372547213 0.30196078431372547213 0.30196078431372547213 1.0"/>
</material>
</visual>
<inertial>
<origin xyz="-0.0028913753365941005299 0.065442665826062410006 -0.027705371350447639128" rpy="0 0 0"/>
<mass value="0.10514218166037306301" />
<inertia ixx="0.00034688180105246974646" ixy="-6.3819851304368827632e-06"  ixz="1.4756104806406160047e-07" iyy="9.8374305485239240711e-05" iyz="2.3259862708943979779e-07" izz="0.00026979716953320361612" />
</inertial>
</link>

<link name="mx106_block_mir_ankle">
<!-- Shapes for mx106 -->
<collision>
<origin xyz="-2.4709714430828168791e-15 0.018050000000000336609 -0.028500000000006901757" rpy="-1.0530465392209239822e-13 -2.3732751874837530345e-14 3.1415926535897851224" />
<geometry>
<box size="0.040199999999999999623 0.065099999999999991207 0.045999999999999999223" />
</geometry>
</collision>
<!-- Shapes for mx106 -->
<collision>
<origin xyz="0.049400000000019546331 0.018050000000001946432 -0.028500000000009739765" rpy="-3.1415926535897917837 1.5707963267948961139 0" />
<geometry>
<box size="0.040199999999999999623 0.065099999999999991207 0.045999999999999999223" />
</geometry>
</collision>
<visual>
<origin xyz="0 0 0" rpy="0 -0 0" />
<geometry>
<mesh filename="mx106_block_mir_ankle_visual.stl"/>
</geometry>
<material name="mx106_block_mir_ankle_material">
<color rgba="0.30196078431372547213 0.30196078431372547213 0.30196078431372547213 1.0"/>
</material>
</visual>
<inertial>
<origin xyz="0.019569546325788403363 0.015396401985194207995 -0.029027444726314407392" rpy="0 0 0"/>
<mass value="0.39709667579512253344" />
<inertia ixx="0.0001817878523649805306" ixy="-3.1147027124168910053e-05"  ixz="-4.0741771018149208064e-06" iyy="0.00037083367389992484163" iyz="-2.0892224411081371265e-06" izz="0.00042862447925065669165" />
</inertial>
</link>

<link name="left_foot_cleat_front_right">
<!-- Shapes for cleat -->
<collision>
<origin xyz="0.043500000000002633782 -0.053500000000002607969 -0.032129999999995377535" rpy="-1.5707963267948874542 -0.79995698224465738857 3.1415926535897478189" />
<geometry>
<cylinder length="0.016000000000000000333" radius="0.0080000000000000001665" />
</geometry>
</collision>
<!-- Shapes for u_base_motors_blocs -->
<collision>
<origin xyz="1.4762496780562628373e-15 -0.036875000000000462963 0.028170000000003303509" rpy="1.5707963267949351938 1.5707963267948670261 0" />
<geometry>
<box size="0.052340000000000004576 0.02999999999999999889 0.0062500000000000003469" />
</geometry>
</collision>
<!-- Shapes for cleat -->
<collision>
<origin xyz="-0.032499999999997530864 -0.053499999999999610367 -0.032129999999997535531" rpy="-1.5707963267948901187 -0.086503880229796090151 3.1415926535897540361" />
<geometry>
<cylinder length="0.016000000000000000333" radius="0.0080000000000000001665" />
</geometry>
</collision>
<!-- Shapes for cleat -->
<collision>
<origin xyz="0.043499999999998512079 -0.053500000000001719791 0.10947000000000467468" rpy="-1.5707963267947662178 -1.5212200824455746062 3.1415926535896221417" />
<geometry>
<cylinder length="0.016000000000000000333" radius="0.0080000000000000001665" />
</geometry>
</collision>
<!-- Shapes for foot_plate -->
<collision>
<origin xyz="0.0055000000000009789322 -0.041500000000000647482 0.038670000000003500185" rpy="-1.5707963267949029973 -2.8955136899265411491e-14 -3.8626551064056153461e-14" />
<geometry>
<box size="0.091999999999999998446 0.1575999999999999901 0.0030000000000000000625" />
</geometry>
</collision>
<!-- Shapes for cleat -->
<collision>
<origin xyz="-0.032500000000001534606 -0.0534999999999987777 0.1094700000000025375" rpy="-1.5707963267948901187 0.019369496889519402516 3.1415926535897549243" />
<geometry>
<cylinder length="0.016000000000000000333" radius="0.0080000000000000001665" />
</geometry>
</collision>
<visual>
<origin xyz="0 0 0" rpy="0 -0 0" />
<geometry>
<mesh filename="left_foot_cleat_front_right_visual.stl"/>
</geometry>
<material name="left_foot_cleat_front_right_material">
<color rgba="0.30196078431372547213 0.30093481115542580762 0.2985408737860601458 1.0"/>
</material>
</visual>
<inertial>
<origin xyz="0.0045444467896919703981 -0.036554210534013545364 0.046646141434125924785" rpy="0 0 0"/>
<mass value="0.28185582496698080579" />
<inertia ixx="0.00071822426056174150811" ixy="2.509109339611377301e-06"  ixz="-4.6415033481460829217e-06" iyy="0.00092244501368009225103" iyz="-1.4353691871045213082e-05" izz="0.00026531274718818520855" />
</inertial>
</link>

<link name="left_foot">
<inertial>
<origin xyz="0 0 0" rpy="0 0 0" />
<mass value="1e-9" />
<inertia ixx="0" ixy="0" ixz="0" iyy="0" iyz="0" izz="0" />
</inertial>
</link>
<joint name="left_foot_frame" type="fixed">
<origin xyz="0.0029999999999995585753 -0.061499999999999499511 0.036170000000003685314" rpy="-1.5707963267949351938 -1.5707963267948670261 0" />
<parent link="left_foot_cleat_front_right" />
<child link="left_foot" />
<axis xyz="0 0 0"/>
</joint>

<joint name="left_ankle_roll" type="revolute">
<origin xyz="0.023400000000019932633 1.9984014443252817728e-15 -0.028500000000009760581" rpy="-1.373109095316520288e-15 -1.5707963267948961139 0" />
<parent link="mx106_block_mir_ankle" />
<child link="left_foot_cleat_front_right" />
<axis xyz="0 0 1"/>
<limit effort="10" velocity="6" lower="-0.785398163397448279" upper="0.785398163397448279"/>
<joint_properties friction="0.0"/>
</joint>

<joint name="left_ankle_pitch" type="revolute">
<origin xyz="-4.6447221069279009953e-16 0.13999999999999993006 1.3877787807814456755e-17" rpy="-3.3306690738665106266e-16 1.238592561846688481e-15 -3.141592653589793116" />
<parent link="tibia_2023" />
<child link="mx106_block_mir_ankle" />
<axis xyz="0 0 1"/>
<limit effort="10" velocity="6" lower="-1.570796326794896558" upper="1.570796326794896558"/>
<joint_properties friction="0.0"/>
</joint>

<joint name="left_knee" type="revolute">
<origin xyz="7.6674777638174873573e-16 0.14000000000002160716 -0.0009999999999908693038" rpy="-2.0988219545715784156e-15 -1.1804793254014940395e-15 2.839899258795644181e-29" />
<parent link="left_knee_2023" />
<child link="tibia_2023" />
<axis xyz="0 0 1"/>
<limit effort="10" velocity="6" lower="-0" upper="3.141592653589793116"/>
<joint_properties friction="0.0"/>
</joint>

<joint name="left_hip_pitch" type="revolute">
<origin xyz="0.029500000000009907186 1.5751289161869408417e-15 0.023400000000018298524" rpy="3.1415926535897926719 -1.5707963267948925612 0" />
<parent link="mx106_block_hip__list_0bj1pweadmbeeq_hip" />
<child link="left_knee_2023" />
<axis xyz="0 0 1"/>
<limit effort="10" velocity="6" lower="-1.570796326794896558" upper="1.570796326794896558"/>
<joint_properties friction="0.0"/>
</joint>

<joint name="left_hip_roll" type="revolute">
<origin xyz="0.023399999999999993722 0 -0.04000000000000001471" rpy="1.570796326794896558 4.9856009209967390067e-28 -1.57079632679489678" />
<parent link="u_block_2023" />
<child link="mx106_block_hip__list_0bj1pweadmbeeq_hip" />
<axis xyz="0 0 1"/>
<limit effort="10" velocity="6" lower="-0.52359877559829881566" upper="0.61086523819801530344"/>
<joint_properties friction="0.0"/>
</joint>

<joint name="left_hip_yaw" type="revolute">
<origin xyz="0.0033892048686650008693 0.04640014717406074074 -0.021000000000001701334" rpy="4.811819888172199206e-14 1.4904713170580737495e-14 -3.1342126022195269108" />
<parent link="torso_2023" />
<child link="u_block_2023" />
<axis xyz="0 0 1"/>
<limit effort="10" velocity="6" lower="-1.0471975511965976313" upper="1.0471975511965976313"/>
<joint_properties friction="0.0"/>
</joint>

<link name="u_block_2023_2">
<!-- Shapes for u_side_small_2023 -->
<collision>
<origin xyz="-0.031439999999999995728 2.9143354396410359186e-16 -0.023750000000000003747" rpy="1.570796326794896558 -1.0499738648491914655e-27 1.57079632679489678" />
<geometry>
<box size="0.037499999999999998612 0.047500000000000000555 0.0030000000000000000625" />
</geometry>
</collision>
<!-- Shapes for u_side_small_with_trace_2023 -->
<collision>
<origin xyz="0.021899999999999995859 -9.7144514654701197287e-17 -0.023750000000000010686" rpy="-1.570796326794896558 -2.4612460242895433804e-28 -1.5707963267948954478" />
<geometry>
<box size="0.037499999999999998612 0.047500000000000000555 0.0030000000000000000625" />
</geometry>
</collision>
<visual>
<origin xyz="0 0 0" rpy="0 -0 0" />
<geometry>
<mesh filename="u_block_2023_2_visual.stl"/>
</geometry>
<material name="u_block_2023_2_material">
<color rgba="0.30196078431372547213 0.30196078431372547213 0.30196078431372547213 1.0"/>
</material>
</visual>
<inertial>
<origin xyz="-0.0050949059968970842466 3.3621005712157433804e-05 -0.0098513101413465788136" rpy="0 0 0"/>
<mass value="0.063013635376408722033" />
<inertia ixx="2.0270940898426988554e-05" ixy="5.6491314096496230294e-08"  ixz="-2.0232353087303246486e-06" iyy="4.2425250270775865667e-05" iyz="5.6114809043106517712e-08" izz="3.5257700450344276681e-05" />
</inertial>
</link>

<link name="mx106_block_mir_hip__list_mr67plvazplf9a_hip">
<!-- Shapes for mx106 -->
<collision>
<origin xyz="6.9388939039071998739e-18 -0.018050000000000003542 -0.025999999999999995337" rpy="3.9443045261050581512e-31 1.6865018419759483207e-29 0" />
<geometry>
<box size="0.040199999999999999623 0.065099999999999991207 0.045999999999999999223" />
</geometry>
</collision>
<!-- Shapes for mx106 -->
<collision>
<origin xyz="2.2656388159760541343e-15 -0.018049999999999899458 0.023400000000012265156" rpy="1.5720758028692191369e-13 -1.5707963267948590325 0" />
<geometry>
<box size="0.040199999999999999623 0.065099999999999991207 0.045999999999999999223" />
</geometry>
</collision>
<visual>
<origin xyz="0 0 0" rpy="0 -0 0" />
<geometry>
<mesh filename="mx106_block_mir_hip__list_mr67plvazplf9a_hip_visual.stl"/>
</geometry>
<material name="mx106_block_mir_hip__list_mr67plvazplf9a_hip_material">
<color rgba="0.30196078431372541662 0.30196078431372541662 0.30196078431372541662 1.0"/>
</material>
</visual>
<inertial>
<origin xyz="0.00052753870022482270835 -0.015396401985192931239 0.0038224253330314708448" rpy="0 0 0"/>
<mass value="0.39709667579512247793" />
<inertia ixx="0.00042850163757161960007" ixy="-2.089796984351987033e-06"  ixz="-4.1603634636162852188e-06" iyy="0.00037070883372999875131" iyz="-3.1097942980207547291e-05" izz="0.00018178585387409359185" />
</inertial>
</link>

<link name="right_knee_2023">
<!-- Shapes for u_side_femur_2023 -->
<collision>
<origin xyz="4.3368086899451021128e-19 -0.037249999999999991451 -0.0015000000000000026333" rpy="3.141592653589793116 -1.8608358460305281247e-28 -7.8886090522101180541e-31" />
<geometry>
<box size="0.02999999999999999889 0.096500000000000002442 0.0030000000000000000625" />
</geometry>
</collision>
<!-- Shapes for u_side_femur_mir_2023 -->
<collision>
<origin xyz="2.3605107741876429032e-15 -0.037249999999998263667 0.057000000000000793088" rpy="-1.5521415202872842641e-14 4.3218900680485566105e-14 -2.7929047963232088636e-15" />
<geometry>
<box size="0.02999999999999999889 0.096500000000000002442 0.0030000000000000000625" />
</geometry>
</collision>
<!-- Shapes for mx106 -->
<collision>
<origin xyz="3.2163304136956578056e-16 -0.12195000000002537144 0.029499999999993191391" rpy="-3.1415926535897722438 3.1374208786515176269e-14 3.4635488921353921256e-14" />
<geometry>
<box size="0.040199999999999999623 0.065099999999999991207 0.045999999999999999223" />
</geometry>
</collision>
<visual>
<origin xyz="0 0 0" rpy="0 -0 0" />
<geometry>
<mesh filename="right_knee_2023_visual.stl"/>
</geometry>
<material name="right_knee_2023_material">
<color rgba="0.30196078431372547213 0.30196078431372547213 0.30196078431372547213 1.0"/>
</material>
</visual>
<inertial>
<origin xyz="-3.0553573382522570417e-05 -0.10076603301831110748 0.029699873205946827198" rpy="0 0 0"/>
<mass value="0.26776918673594685139" />
<inertia ixx="0.00053571855681478614247" ixy="1.3722075397588938187e-07"  ixz="-6.2591971620997953175e-09" iyy="0.00012197339981637886287" iyz="1.3692241520979617968e-05" izz="0.00045904851754741680166" />
</inertial>
</link>

<link name="tibia_2023_2">
<!-- Shapes for tibia_plate_2023 -->
<collision>
<origin xyz="-0.006213099999990981219 0.068950999999995751799 0.055939999999998685221" rpy="3.1415926535897873428 -3.8004321911697914517e-14 -3.1415926535897829019" />
<geometry>
<box size="0.04042620000000000241 0.1700990000000000002 0.0030000000000000000625" />
</geometry>
</collision>
<!-- Shapes for tibia_plate_2023 -->
<collision>
<origin xyz="-0.0062131000000000009137 0.068950999999999998402 -0.0014999999999999861534" rpy="3.141592653589793116 -3.4694469517341198049e-18 3.141592653589793116" />
<geometry>
<box size="0.04042620000000000241 0.1700990000000000002 0.0030000000000000000625" />
</geometry>
</collision>
<visual>
<origin xyz="0 0 0" rpy="0 -0 0" />
<geometry>
<mesh filename="tibia_2023_2_visual.stl"/>
</geometry>
<material name="tibia_2023_2_material">
<color rgba="0.30196078431372547213 0.30196078431372547213 0.30196078431372547213 1.0"/>
</material>
</visual>
<inertial>
<origin xyz="-0.0028913753365892125129 0.065442665826058801781 0.026734628649552116819" rpy="0 0 0"/>
<mass value="0.10514218166037306301" />
<inertia ixx="0.00034688180105246226546" ixy="-6.3819851304390528616e-06"  ixz="1.4756104805157776419e-07" iyy="9.8374305485233941673e-05" iyz="2.3259862708960571037e-07" izz="0.00026979716953318675678" />
</inertial>
</link>

<link name="mx106_block_ankle__list_0bj1pweadmbeeq_default">
<!-- Shapes for mx106 -->
<collision>
<origin xyz="3.0357660829594136478e-17 -0.018050000000000170075 0.028500000000010003443" rpy="3.141592653589793116 2.5373944181513879921e-28 -3.141592653589793116" />
<geometry>
<box size="0.040199999999999999623 0.065099999999999991207 0.045999999999999999223" />
</geometry>
</collision>
<!-- Shapes for mx106 -->
<collision>
<origin xyz="-0.049400000000020004298 -0.018049999999999954969 0.028500000000010072831" rpy="-9.2644242016574441323e-23 1.570796326794896558 0" />
<geometry>
<box size="0.040199999999999999623 0.065099999999999991207 0.045999999999999999223" />
</geometry>
</collision>
<visual>
<origin xyz="0 0 0" rpy="0 -0 0" />
<geometry>
<mesh filename="mx106_block_ankle__list_0bj1pweadmbeeq_default_visual.stl"/>
</geometry>
<material name="mx106_block_ankle__list_0bj1pweadmbeeq_default_material">
<color rgba="0.30196078431372541662 0.30196078431372541662 0.30196078431372541662 1.0"/>
</material>
</visual>
<inertial>
<origin xyz="-0.019572401009989238291 -0.015396401985201089643 0.029025166915077751234" rpy="0 0 0"/>
<mass value="0.39709667579512247793" />
<inertia ixx="0.00018178880446396869465" ixy="-3.114147575544874805e-05"  ixz="-4.1062666594564375136e-06" iyy="0.00037079025525090506714" iyz="-2.0805509255757983854e-06" izz="0.00042858010850244083025" />
</inertial>
</link>

<link name="right_foot_cleat_back_left">
<!-- Shapes for u_base_motors_blocs -->
<collision>
<origin xyz="3.417405247674309976e-16 -0.036875000000001302569 0.028170000000003227181" rpy="1.5707963267949054398 1.570796326794841713 0" />
<geometry>
<box size="0.052340000000000004576 0.02999999999999999889 0.0062500000000000003469" />
</geometry>
</collision>
<!-- Shapes for cleat -->
<collision>
<origin xyz="-0.043499999999999428013 -0.053499999999997369104 -0.032129999999998326565" rpy="1.5707963267950397768 -1.1719174185838625579 -1.4562743463413491521e-13" />
<geometry>
<cylinder length="0.016000000000000000333" radius="0.0080000000000000001665" />
</geometry>
</collision>
<!-- Shapes for foot_plate -->
<collision>
<origin xyz="-0.0054999999999997637584 -0.041500000000001868727 0.038670000000002924256" rpy="-1.5707963267948399366 -7.8582973461754015656e-15 -8.9151391897941728726e-15" />
<geometry>
<box size="0.091999999999999998446 0.1575999999999999901 0.0030000000000000000625" />
</geometry>
</collision>
<!-- Shapes for cleat -->
<collision>
<origin xyz="0.032500000000000708877 -0.053499999999998049116 -0.032129999999997785332" rpy="-1.5707963267950937336 1.2836470252590890251 3.141592653589579065" />
<geometry>
<cylinder length="0.016000000000000000333" radius="0.0080000000000000001665" />
</geometry>
</collision>
<!-- Shapes for cleat -->
<collision>
<origin xyz="-0.043500000000000357825 -0.053500000000005716594 0.10947000000000232933" rpy="1.5707963267954050401 -1.4586817975653372237 -5.3885283641449396517e-13" />
<geometry>
<cylinder length="0.016000000000000000333" radius="0.0080000000000000001665" />
</geometry>
</collision>
<!-- Shapes for cleat -->
<collision>
<origin xyz="0.032499999999999612532 -0.0535000000000060566 0.1094700000000029122" rpy="-1.5707963267950568742 -1.2146438330590096921 -3.1415926535896381289" />
<geometry>
<cylinder length="0.016000000000000000333" radius="0.0080000000000000001665" />
</geometry>
</collision>
<visual>
<origin xyz="0 0 0" rpy="0 -0 0" />
<geometry>
<mesh filename="right_foot_cleat_back_left_visual.stl"/>
</geometry>
<material name="right_foot_cleat_back_left_material">
<color rgba="0.30196078431372541662 0.30093481115542580762 0.29854087378606020131 1.0"/>
</material>
</visual>
<inertial>
<origin xyz="-0.0045443948701719095659 -0.036554210534015252332 0.046646141434125570902" rpy="0 0 0"/>
<mass value="0.2818558249669808613" />
<inertia ixx="0.00071822426056174367651" ixy="-2.5093325733322183397e-06"  ixz="4.6417350201811620762e-06" iyy="0.0009224449850517641358" iyz="-1.4353691871003549225e-05" izz="0.00026531271855985053389" />
</inertial>
</link>

<link name="right_foot">
<inertial>
<origin xyz="0 0 0" rpy="0 0 0" />
<mass value="1e-9" />
<inertia ixx="0" ixy="0" ixz="0" iyy="0" iyz="0" izz="0" />
</inertial>
</link>
<joint name="right_foot_frame" type="fixed">
<origin xyz="-0.0029999999999998708256 -0.061500000000001275868 0.036170000000001908957" rpy="-1.5707963267949054398 -1.5707963267948401587 0" />
<parent link="right_foot_cleat_back_left" />
<child link="right_foot" />
<axis xyz="0 0 0"/>
</joint>

<joint name="right_ankle_roll" type="revolute">
<origin xyz="-0.023400000000020335089 1.1102230246251565404e-16 0.02850000000001007977" rpy="-3.141592653589793116 -1.5707963267948872321 0" />
<parent link="mx106_block_ankle__list_0bj1pweadmbeeq_default" />
<child link="right_foot_cleat_back_left" />
<axis xyz="0 0 1"/>
<limit effort="10" velocity="6" lower="-0.785398163397448279" upper="0.785398163397448279"/>
<joint_properties friction="0.0"/>
</joint>

<joint name="right_ankle_pitch" type="revolute">
<origin xyz="3.7903707950093235013e-16 0.13999999999999998557 2.7755575615628913511e-17" rpy="-2.2999513674697388823e-15 1.3912482277331527707e-15 4.9436401737054287372e-16" />
<parent link="tibia_2023_2" />
<child link="mx106_block_ankle__list_0bj1pweadmbeeq_default" />
<axis xyz="0 0 1"/>
<limit effort="10" velocity="6" lower="-1.570796326794896558" upper="1.570796326794896558"/>
<joint_properties friction="0.0"/>
</joint>

<joint name="right_knee" type="revolute">
<origin xyz="3.3089850304257595326e-16 -0.14000000000002205125 0.00099999999998860722439" rpy="-7.7073639491941966807e-14 -1.4675760606762180715e-15 3.1415926535897926719" />
<parent link="right_knee_2023" />
<child link="tibia_2023_2" />
<axis xyz="0 0 1"/>
<limit effort="10" velocity="6" lower="0" upper="3.141592653589793116"/>
<joint_properties friction="0.0"/>
</joint>

<joint name="right_hip_pitch" type="revolute">
<origin xyz="-0.029500000000008623491 -6.9388939039072283776e-16 0.023400000000012088214" rpy="-2.4835167061004709567e-14 1.5707963267948934494 0" />
<parent link="mx106_block_mir_hip__list_mr67plvazplf9a_hip" />
<child link="right_knee_2023" />
<axis xyz="0 0 1"/>
<limit effort="10" velocity="6" lower="-1.570796326794896558" upper="1.570796326794896558"/>
<joint_properties friction="0.0"/>
</joint>

<joint name="right_hip_roll" type="revolute">
<origin xyz="0.023400000000000000661 1.8041124150158793782e-15 -0.040000000000000021649" rpy="1.5707963267948936714 -6.8695049648709969792e-16 -1.5707963267948972241" />
<parent link="u_block_2023_2" />
<child link="mx106_block_mir_hip__list_mr67plvazplf9a_hip" />
<axis xyz="0 0 1"/>
<limit effort="10" velocity="6" lower="-0.61086523819801530344" upper="0.52359877559829881566"/>
<joint_properties friction="0.0"/>
</joint>

<joint name="right_hip_yaw" type="revolute">
<origin xyz="0.0033892048686646053524 -0.046399852825939190415 -0.021000000000002322365" rpy="-6.8332004219422605546e-15 -5.4790940367335168281e-15 -3.1176144146104105559" />
<parent link="torso_2023" />
<child link="u_block_2023_2" />
<axis xyz="0 0 1"/>
<limit effort="10" velocity="6" lower="-1.0471975511965976313" upper="1.0471975511965976313"/>
<joint_properties friction="0.0"/>
</joint>


</robot>
