  
<?xml version="1.0"?>

<robot name="omnibot" xmlns:xacro="http://www.ros.org/wiki/xacro">

      <!--static>false</static-->
   <link name="body">
	<pose>0 0 0.5 0 0 0</pose>
        <visual name="visual">
          <geometry>
            
	<mesh><uri>file://bodycentre2v6.stl</uri>
		<scale>0.001 0.001 0.001</scale></mesh>           
	</geometry>
        </visual>
   	<collision name='collision'>
            <geometry>
              <mesh><uri>file://bodycentre2v6.stl</uri>
		<scale>0.001 0.001 0.001</scale></mesh> 
            </geometry>
          </collision>
      </link>

  <link name="left_front_wheel">
      <pose>-0.15 -0.15 0.5 0 0 0.785398</pose>
	<collision name="collision">
          <geometry>
            <mesh><uri>file://wheelCentrev1.stl</uri>
		<scale>0.001 0.001 0.001</scale></mesh>   
          </geometry>
        </collision>
        <visual name="visual">
          <geometry>
            <mesh><uri>file://wheelCentrev1.stl</uri>
		<scale>0.001 0.001 0.001</scale></mesh>     
	</geometry>
        </visual>
    </link>

  <link name="left_back_wheel">
      <pose>0.15 -0.15 0.5 0 0 2.35619</pose>
	<collision name="collision">
          <geometry>
            <mesh><uri>file://wheelCentrev1.stl</uri>
		<scale>0.001 0.001 0.001</scale></mesh>   
          </geometry>
        </collision>
        <visual name="visual">
          <geometry>
            <mesh><uri>file://wheelCentrev1.stl</uri>
		<scale>0.001 0.001 0.001</scale></mesh>     
	</geometry>
        </visual>
  </link>

  <link name="right_front_wheel">
      <pose>0.15 0.15 0.5 0 0 3.92699</pose>
	<collision name="collision">
          <geometry>
            <mesh><uri>file://wheelCentrev1.stl</uri>
		<scale>0.001 0.001 0.001</scale></mesh>   
          </geometry>
        </collision>
        <visual name="visual">
          <geometry>
            <mesh><uri>file://wheelCentrev1.stl</uri>
		<scale>0.001 0.001 0.001</scale></mesh>     
	</geometry>
        </visual>
     </link>

  <link name="right_back_wheel">
      <pose>-0.15 0.15 0.5 0 0 5.49779</pose>
	<collision name="collision">
          <geometry>
            <mesh><uri>file://wheelCentrev1.stl</uri>
		<scale>0.001 0.001 0.001</scale></mesh>   
          </geometry>
        </collision>
        <visual name="visual">
          <geometry>
            <mesh><uri>file://wheelCentrev1.stl</uri>
		<scale>0.001 0.001 0.001</scale></mesh>     
	</geometry>
        </visual>
      </link>

<link name="camera_link">
      <pose>0 0 0.93 0 0 0</pose>
	<inertial>
        <mass>0.1</mass>
        <inertia>
          <ixx>0.000166667</ixx>
          <iyy>0.000166667</iyy>
          <izz>0.000166667</izz>
        </inertia>
      </inertial>
      <collision name="collision">
        <geometry>
          <box>
            <size>0.03 0.03 0.03</size>
          </box>
        </geometry>
      </collision>
      <visual name="visual">
        <geometry>
          <box>
            <size>0.03 0.03 0.03</size>
          </box>
        </geometry>
      </visual>

      <!--sensor name="camera1" type="camera">
	<always_on>1</always_on>
        <update_rate>30</update_rate>
        <visualize>true</visualize>
        <camera>
         <horizontal_fov>1.3962634</horizontal_fov>
         <image>
          <width>800</width>
          <height>800</height>
          <format>R8G8B8</format>
         </image>
         <clip>
          <near>0.02</near>
          <far>300</far>
         </clip>
         <noise>
          <type>gaussian</type-->
          <!-- Noise is sampled independently per pixel on each frame.
               That pixel's noise value is added to each of its color
               channels, which at that point lie in the range [0,1]. -->
          <!--mean>0.0</mean>
          <stddev>0.007</stddev>
        </noise>
      </camera>
      <plugin name="camera_controller" filename="libgazebo_ros_camera.so">
        <alwaysOn>true</alwaysOn>
        <updateRate>0.0</updateRate>
        <cameraName>omnibot/camera1</cameraName>
        <imageTopicName>omnibot/camera1/image_raw</imageTopicName>
        <cameraInfoTopicName>omnibot/camera1/camera_info</cameraInfoTopicName>
        <frameName>camera_link</frameName>
        <hackBaseline>0.07</hackBaseline>
        <distortionK1>0.0</distortionK1>
        <distortionK2>0.0</distortionK2>
        <distortionK3>0.0</distortionK3>
        <distortionT1>0.0</distortionT1>
        <distortionT2>0.0</distortionT2>
      </plugin>
    </sensor-->
     </link>


	<joint type="revolute" name="left_front_wheel_hinge">
        <pose>0 0 0 0 0 0</pose>
        <child>left_front_wheel</child>
        <parent>body</parent>
        <axis>
          <xyz>1 0 0</xyz>
        </axis>
      </joint>

      <joint type="revolute" name="right_front_wheel_hinge">
        <pose>0 0 0 0 0 0</pose>
        <child>right_front_wheel</child>
        <parent>body</parent>
        <axis>
          <xyz>1 0 0</xyz>
        </axis>
      </joint>

	<joint type="revolute" name="left_back_wheel_hinge">
        <pose>0 0 0 0 0 0</pose>
        <child>left_back_wheel</child>
        <parent>body</parent>
        <axis>
          <xyz>1 0 0</xyz>
        </axis>
      </joint>

      <joint type="revolute" name="right_back_wheel_hinge">
        <pose>0 0 0 0 0 0</pose>
        <child>right_back_wheel</child>
        <parent>body</parent>
        <axis>
          <xyz>1 0 0</xyz>
        </axis>
      </joint>

	<joint name="camera_joint" type="fixed">
    		<parent>body</parent>
    		<child>camera_link</child>
  	</joint>
    </robot>

