    <robot name="soccerbot" xmlns:xacro="http://www.ros.org/wiki/xacro">
        <xacro:macro name="arm" params="name origin direction">
            <link name="$(arg tf_prefix)/${name}_bicep">
                <inertial>
                    <mass value="0.213e-3"/>
                    <origin rpy="0  0  0" xyz="0.000 ${direction * 0.02579} -0.04955"/>
                    <inertia ixx="2.824e-4" ixy="0.000" ixz="${direction * 0.000}"
                             iyy="2.744e-4" iyz="${direction * 1.165e-5}"
                             izz="2.433e-5" />
                </inertial>
                <collision name="collision">
                    <origin rpy="0  0  0" xyz="0 ${direction * 0.0225} -0.05001"/>
                    <geometry>
                        <box size="0.04 0.04776 0.123"/>
                    </geometry>
                </collision>
                <visual name="visual">
                    <origin rpy="0  0  0" xyz="0  0  0"/>
                    <geometry>
                        <mesh filename="${FILE_PATH}/meshes/${name}_bicep.${MODEL_TYPE}" scale="1 1 1"/>
                    </geometry>
                    <material name="black" />
                </visual>
            </link>
            <link name="$(arg tf_prefix)/${name}_forearm">
                <inertial>
                    <mass value="45.7e-3"/>
                    <origin rpy="0  0  0" xyz="0 0.0245 -0.0546097" />
                    <inertia ixx="0.113e-3" ixy="0.000" ixz="${direction * 0.001e-3}"
                             iyy="0.107e-3" iyz="${direction * 0.000}"
                             izz="0.012e-3" />
                </inertial>
                <collision name="collision">
                    <origin rpy="0  0  0" xyz="-0.0055 0.01750 -0.0600"/>
                    <geometry>
                        <box size="0.035 0.049 0.144"/>
                    </geometry>
                </collision>
                <visual name="visual">
                    <origin rpy="0  0  0" xyz="0  0  0"/>
                    <geometry>
                        <mesh filename="${FILE_PATH}/meshes/${name}_forearm.${MODEL_TYPE}" scale="0.001 0.001 0.001"/>
                    </geometry>
                    <material name="black" />
                </visual>
            </link>

            <joint name="${name}_arm_motor_0" type="revolute">
                <parent link="${origin}"/>
                <child link="$(arg tf_prefix)/${name}_bicep"/>
                <origin rpy="0 0 0" xyz="-0.0157 ${direction * 0.0725} 0"/>
                <axis xyz="0 -1 0"/>
                <dynamics damping="${JOINT_DAMPING}" friction="${JOINT_FRICTION}" />
                <limit effort="${AX12_TORQUE}" lower="-${PI/2}" upper="${PI*5/4}" velocity="${AX12_VELOCITY}"/>
            </joint>
            <joint name="${name}_arm_motor_1" type="revolute">
                <parent link="$(arg tf_prefix)/${name}_bicep"/>
                <child link="$(arg tf_prefix)/${name}_forearm"/>
                <origin rpy="0 0 0" xyz="0 0 -0.10"/>
                <axis xyz="0 -1 0"/>
                <dynamics damping="${JOINT_DAMPING}" friction="${JOINT_FRICTION}" />
                <limit effort="${AX12_TORQUE}" lower="0" upper="${PI}" velocity="${AX12_VELOCITY}"/>
            </joint>

            <gazebo reference="$(arg tf_prefix)/${name}_forearm">
                <mu1>${FOREARM_MU1}</mu1>
                <mu2>${FOREARM_MU2}</mu2>
            </gazebo>

            <transmission name="${name}_arm_motor_0">
                <type>transmission_interface/SimpleTransmission</type>
                <joint name="${name}_arm_motor_0">
                    <hardwareInterface>hardware_interface/EffortJointInterface</hardwareInterface>
                </joint>
                <actuator name="${name}_arm_motor_0">
                    <hardwareInterface>hardware_interface/EffortJointInterface</hardwareInterface>
                    <mechanicalReduction>1</mechanicalReduction>
                </actuator>
            </transmission>
            <transmission name="${name}_arm_motor_1">
                <type>transmission_interface/SimpleTransmission</type>
                <joint name="${name}_arm_motor_1">
                    <hardwareInterface>hardware_interface/EffortJointInterface</hardwareInterface>
                </joint>
                <actuator name="${name}_arm_motor_1">
                    <hardwareInterface>hardware_interface/EffortJointInterface</hardwareInterface>
                    <mechanicalReduction>1</mechanicalReduction>
                </actuator>
            </transmission>

            <gazebo reference="$(arg tf_prefix)/${name}_bicep">
                <kp>${JOINT_KP}</kp>
                <kd>${JOINT_KD}</kd>
                <mu1>${JOINT_MU1}</mu1>
                <mu2>${JOINT_MU2}</mu2>
            </gazebo>
            <gazebo reference="$(arg tf_prefix)/${name}_forearm">
                <kp>${JOINT_KP}</kp>
                <kd>${JOINT_KD}</kd>
                <mu1>${JOINT_MU1}</mu1>
                <mu2>${JOINT_MU2}</mu2>
            </gazebo>
        </xacro:macro>
    </robot>