<robot name="soccerbot" xmlns:xacro="http://www.ros.org/wiki/xacro">
    <xacro:macro name="head" params="origin">
        <link name="neck">
            <inertial>
                <mass value="0.011294"/>
                <origin rpy="0  0  0" xyz="0 -0.0006476 0.0092453"/>
                <inertia ixx="5.489e-6" ixy="0" ixz="0"
                         iyy="1.433e-6" iyz="0"
                         izz="4.955e-6"/>
            </inertial>
            <collision name="collision">
                <origin rpy="0  0  0" xyz="0 0 0.0165"/>
                <geometry>
                    <box size="0.022 0.0523 0.033"/>
                </geometry>
            </collision>
            <visual name="visual">
                <origin rpy="0  0  0" xyz="0  0  0"/>
                <geometry>
                    <mesh filename="${FILE_PATH}/meshes/neck.${MODEL_TYPE}" scale="1 1 1"/>
                </geometry>
                <material name="black" />
            </visual>
        </link>
        <link name="head">
            <inertial>
                <mass value="0.282"/>
                <origin rpy="0  0  0" xyz="0.0237166 0.0018096 0.0255966"/>
                <inertia ixx="2.06e-4" ixy="1.06e-6" ixz="-5.73e-5"
                         iyy="2.057e-4" iyz="2.534e-6"
                         izz="1.603e-4"/>
            </inertial>
            <collision name="collision">
                <origin rpy="0  0  0" xyz="-0.013 0 0.025"/>
                <geometry>
                    <box size="0.0712 0.094 0.0779"/>
                </geometry>
            </collision>
            <visual name="visual">
                <origin rpy="0  0  0" xyz="0  0  0"/>
                <geometry>
                    <mesh filename="${FILE_PATH}/meshes/head.${MODEL_TYPE}" scale="1 1 1"/>
                </geometry>
                <material name="black" />
            </visual>
        </link>

        <joint name="head_motor_0" type="revolute">
            <parent link="${origin}"/>
            <child link="neck"/>
            <origin rpy="0 0 0" xyz="0.024 0 0.05875"/>
            <axis xyz="0 0 1"/>
            <dynamics damping="${JOINT_DAMPING}" friction="${JOINT_FRICTION}" />
            <limit effort="${AX12_TORQUE}" lower="-${PI/2}" upper="${PI/2}" velocity="${AX12_VELOCITY}"/>
        </joint>
        <joint name="head_motor_1" type="revolute">
            <parent link="neck"/>
            <child link="head"/>
            <origin rpy="0 0 0" xyz="0 0 0.024"/>
            <axis xyz="0 1 0"/>
            <dynamics damping="${JOINT_DAMPING}" friction="${JOINT_FRICTION}" />
            <limit effort="${AX12_TORQUE}" lower="-${PI*3/4}" upper="${PI*3/4}" velocity="${AX12_VELOCITY}"/>
        </joint>

        <transmission name="head_motor_0">
            <type>transmission_interface/SimpleTransmission</type>
            <joint name="head_motor_0">
                <hardwareInterface>hardware_interface/EffortJointInterface</hardwareInterface>
            </joint>
            <actuator name="head_motor_0">
                <hardwareInterface>hardware_interface/EffortJointInterface</hardwareInterface>
                <mechanicalReduction>1</mechanicalReduction>
            </actuator>
        </transmission>
        <transmission name="head_motor_1">
            <type>transmission_interface/SimpleTransmission</type>
            <joint name="head_motor_1">
                <hardwareInterface>hardware_interface/EffortJointInterface</hardwareInterface>
            </joint>
            <actuator name="head_motor_1">
                <hardwareInterface>hardware_interface/EffortJointInterface</hardwareInterface>
                <mechanicalReduction>1</mechanicalReduction>
            </actuator>
        </transmission>

        <gazebo reference="neck">
            <kp>${JOINT_KP}</kp>
            <kd>${JOINT_KD}</kd>
            <mu1>${JOINT_MU1}</mu1>
            <mu2>${JOINT_MU2}</mu2>
        </gazebo>
        <gazebo reference="head">
            <kp>${JOINT_KP}</kp>
            <kd>${JOINT_KD}</kd>
            <mu1>${JOINT_MU1}</mu1>
            <mu2>${JOINT_MU2}</mu2>
        </gazebo>
    </xacro:macro>
</robot>
