<?xml version="1.0" encoding="utf-8"?>
<!-- =================================================================================== -->
<!-- |    This document was autogenerated by xacro from models/soccerbot.xacro         | -->
<!-- |    EDITING THIS FILE BY HAND IS NOT RECOMMENDED                                 | -->
<!-- =================================================================================== -->
<robot name="soccerbot">
  <link name="torso">
    <inertial>
      <mass value="1.529"/>
      <origin rpy="0 0 0" xyz="0.0082498 -0.0017440 -0.0522479"/>
      <inertia ixx="4.323e-3" ixy="5.549e-6" ixz="3.960e-5" iyy="5.198e-3" iyz="-1.509e-5" izz="3.567e-3"/>
    </inertial>
    <collision name="collision">
      <origin rpy="0 0 0" xyz="0 0 -0.052"/>
      <geometry>
        <box size="0.130 0.145 0.152"/>
      </geometry>
    </collision>
    <visual name="visual">
      <origin rpy="0 0 0" xyz="0 0 0"/>
      <geometry>
        <mesh filename="../soccer_description/meshes/torso.stl" scale="1 1 1"/>
      </geometry>
    </visual>
  </link>
  <link name="left_bicep">
    <inertial>
      <mass value="0.213e-3"/>
      <origin rpy="0  0  0" xyz="0.000 0.02579 -0.04955"/>
      <inertia ixx="2.824e-4" ixy="0.000" ixz="0.0" iyy="2.744e-4" iyz="1.165e-05" izz="2.433e-5"/>
    </inertial>
    <collision name="collision">
      <origin rpy="0  0  0" xyz="0 0.0225 -0.05001"/>
      <geometry>
        <box size="0.04 0.04776 0.123"/>
      </geometry>
    </collision>
    <visual name="visual">
      <origin rpy="0  0  0" xyz="0  0  0"/>
      <geometry>
        <mesh filename="../soccer_description/meshes/left_bicep.stl" scale="1 1 1"/>
      </geometry>
      <material name="black"/>
    </visual>
  </link>
  <link name="left_forearm">
    <inertial>
      <mass value="45.7e-3"/>
      <origin rpy="0  0  0" xyz="0 0.0245 -0.0546097"/>
      <inertia ixx="0.113e-3" ixy="0.000" ixz="1e-06" iyy="0.107e-3" iyz="0.0" izz="0.012e-3"/>
    </inertial>
    <collision name="collision">
      <origin rpy="0  0  0" xyz="-0.0055 0.01750 -0.0600"/>
      <geometry>
        <box size="0.035 0.049 0.144"/>
      </geometry>
    </collision>
    <visual name="visual">
      <origin rpy="0  0  0" xyz="0  0  0"/>
      <geometry>
        <mesh filename="../soccer_description/meshes/left_forearm.stl" scale="1 1 1"/>
      </geometry>
      <material name="black"/>
    </visual>
  </link>
  <joint name="left_arm_motor_0" type="revolute">
    <parent link="torso"/>
    <child link="left_bicep"/>
    <origin rpy="0 0 0" xyz="-0.0157 0.0725 0"/>
    <axis xyz="0 -1 0"/>
    <dynamics damping="0.01" friction="0.1"/>
    <limit effort="1.5" lower="-1.57079632679" upper="3.92699081699" velocity="1"/>
  </joint>
  <joint name="left_arm_motor_1" type="revolute">
    <parent link="left_bicep"/>
    <child link="left_forearm"/>
    <origin rpy="0 0 0" xyz="0 0 -0.10"/>
    <axis xyz="0 -1 0"/>
    <dynamics damping="0.01" friction="0.1"/>
    <limit effort="1.5" lower="0" upper="3.14159265359" velocity="1"/>
  </joint>
  <gazebo reference="left_forearm">
    <mu1>0.2</mu1>
    <mu2>0.2</mu2>
  </gazebo>
  <transmission name="left_arm_motor_0">
    <type>transmission_interface/SimpleTransmission</type>
    <joint name="left_arm_motor_0">
      <hardwareInterface>hardware_interface/EffortJointInterface</hardwareInterface>
    </joint>
    <actuator name="left_arm_motor_0">
      <hardwareInterface>hardware_interface/EffortJointInterface</hardwareInterface>
      <mechanicalReduction>1</mechanicalReduction>
    </actuator>
  </transmission>
  <transmission name="left_arm_motor_1">
    <type>transmission_interface/SimpleTransmission</type>
    <joint name="left_arm_motor_1">
      <hardwareInterface>hardware_interface/EffortJointInterface</hardwareInterface>
    </joint>
    <actuator name="left_arm_motor_1">
      <hardwareInterface>hardware_interface/EffortJointInterface</hardwareInterface>
      <mechanicalReduction>1</mechanicalReduction>
    </actuator>
  </transmission>
  <gazebo reference="left_bicep">
    <kp>1e+15</kp>
    <kd>1e+13</kd>
    <mu1>0.2</mu1>
    <mu2>0.2</mu2>
  </gazebo>
  <gazebo reference="left_forearm">
    <kp>1e+15</kp>
    <kd>1e+13</kd>
    <mu1>0.2</mu1>
    <mu2>0.2</mu2>
  </gazebo>
  <link name="right_bicep">
    <inertial>
      <mass value="0.213e-3"/>
      <origin rpy="0  0  0" xyz="0.000 -0.02579 -0.04955"/>
      <inertia ixx="2.824e-4" ixy="0.000" ixz="-0.0" iyy="2.744e-4" iyz="-1.165e-05" izz="2.433e-5"/>
    </inertial>
    <collision name="collision">
      <origin rpy="0  0  0" xyz="0 -0.0225 -0.05001"/>
      <geometry>
        <box size="0.04 0.04776 0.123"/>
      </geometry>
    </collision>
    <visual name="visual">
      <origin rpy="0  0  0" xyz="0  0  0"/>
      <geometry>
        <mesh filename="../soccer_description/meshes/right_bicep.stl" scale="1 1 1"/>
      </geometry>
      <material name="black"/>
    </visual>
  </link>
  <link name="right_forearm">
    <inertial>
      <mass value="45.7e-3"/>
      <origin rpy="0  0  0" xyz="0 0.0245 -0.0546097"/>
      <inertia ixx="0.113e-3" ixy="0.000" ixz="-1e-06" iyy="0.107e-3" iyz="-0.0" izz="0.012e-3"/>
    </inertial>
    <collision name="collision">
      <origin rpy="0  0  0" xyz="-0.0055 0.01750 -0.0600"/>
      <geometry>
        <box size="0.035 0.049 0.144"/>
      </geometry>
    </collision>
    <visual name="visual">
      <origin rpy="0  0  0" xyz="0  0  0"/>
      <geometry>
        <mesh filename="../soccer_description/meshes/right_forearm.stl" scale="1 1 1"/>
      </geometry>
      <material name="black"/>
    </visual>
  </link>
  <joint name="right_arm_motor_0" type="revolute">
    <parent link="torso"/>
    <child link="right_bicep"/>
    <origin rpy="0 0 0" xyz="-0.0157 -0.0725 0"/>
    <axis xyz="0 -1 0"/>
    <dynamics damping="0.01" friction="0.1"/>
    <limit effort="1.5" lower="-1.57079632679" upper="3.92699081699" velocity="1"/>
  </joint>
  <joint name="right_arm_motor_1" type="revolute">
    <parent link="right_bicep"/>
    <child link="right_forearm"/>
    <origin rpy="0 0 0" xyz="0 0 -0.10"/>
    <axis xyz="0 -1 0"/>
    <dynamics damping="0.01" friction="0.1"/>
    <limit effort="1.5" lower="0" upper="3.14159265359" velocity="1"/>
  </joint>
  <gazebo reference="right_forearm">
    <mu1>0.2</mu1>
    <mu2>0.2</mu2>
  </gazebo>
  <transmission name="right_arm_motor_0">
    <type>transmission_interface/SimpleTransmission</type>
    <joint name="right_arm_motor_0">
      <hardwareInterface>hardware_interface/EffortJointInterface</hardwareInterface>
    </joint>
    <actuator name="right_arm_motor_0">
      <hardwareInterface>hardware_interface/EffortJointInterface</hardwareInterface>
      <mechanicalReduction>1</mechanicalReduction>
    </actuator>
  </transmission>
  <transmission name="right_arm_motor_1">
    <type>transmission_interface/SimpleTransmission</type>
    <joint name="right_arm_motor_1">
      <hardwareInterface>hardware_interface/EffortJointInterface</hardwareInterface>
    </joint>
    <actuator name="right_arm_motor_1">
      <hardwareInterface>hardware_interface/EffortJointInterface</hardwareInterface>
      <mechanicalReduction>1</mechanicalReduction>
    </actuator>
  </transmission>
  <gazebo reference="right_bicep">
    <kp>1e+15</kp>
    <kd>1e+13</kd>
    <mu1>0.2</mu1>
    <mu2>0.2</mu2>
  </gazebo>
  <gazebo reference="right_forearm">
    <kp>1e+15</kp>
    <kd>1e+13</kd>
    <mu1>0.2</mu1>
    <mu2>0.2</mu2>
  </gazebo>
  <link name="left_hip_side">
    <inertial>
      <mass value="9.364e-3"/>
      <origin rpy="0  0  0" xyz="0.0003695 0.0000 0.01689"/>
      <inertia ixx="0.002e-3" ixy="0.000" ixz="0.000" iyy="0.005e-3" iyz="0.000" izz="0.004e-3"/>
    </inertial>
    <collision name="collision">
      <origin rpy="0  0  0" xyz="0 0 0.00899"/>
      <geometry>
        <box size="0.0485 0.022 0.0039"/>
      </geometry>
    </collision>
    <visual name="visual">
      <origin rpy="0  0  0" xyz="0  0  0"/>
      <geometry>
        <mesh filename="../soccer_description/meshes/left_hip_side.stl" scale="1 1 1"/>
      </geometry>
      <material name="black"/>
    </visual>
  </link>
  <link name="left_hip_front">
    <inertial>
      <mass value="153.186e-3"/>
      <origin rpy="0 0 0" xyz="-0.02093 0 -0.011313"/>
      <inertia ixx="0.041e-3" ixy="0.000" ixz="-0.002e-3" iyy="0.118e-3" iyz="0.000" izz="0.106e-3"/>
    </inertial>
    <collision name="collision">
      <origin rpy="0 0 0" xyz="-0.02187 0 -0.01332"/>
      <geometry>
        <box size="0.083747 0.04885 0.0506"/>
      </geometry>
    </collision>
    <visual name="visual">
      <origin rpy="0  0  0" xyz="0  0  0"/>
      <geometry>
        <mesh filename="../soccer_description/meshes/left_hip_front.stl" scale="1 1 1"/>
      </geometry>
      <material name="black"/>
    </visual>
  </link>
  <link name="left_thigh">
    <inertial>
      <mass value="21.438e-3"/>
      <origin rpy="0 0 0" xyz="0.0019422 0.0001419 -0.0469409"/>
      <inertia ixx="0.025e-3" ixy="2e-06" ixz="0.000" iyy="0.016e-3" iyz="0.000" izz="0.010e-3"/>
    </inertial>
    <collision name="collision">
      <origin rpy="0 0 0" xyz="0 0 -0.0445"/>
      <geometry>
        <box size="0.022 0.048 0.111"/>
      </geometry>
    </collision>
    <visual name="visual">
      <origin rpy="0  0  0" xyz="0  0  0"/>
      <geometry>
        <mesh filename="../soccer_description/meshes/left_thigh.stl" scale="1 1 1"/>
      </geometry>
      <material name="black"/>
    </visual>
  </link>
  <link name="left_calve">
    <inertial>
      <mass value="86.547e-3"/>
      <origin rpy="0  0  0" xyz="0 -3.259e-07 -0.0150123e-3"/>
      <inertia ixx="0.054e-3" ixy="0.000" ixz="0.000" iyy="0.046e-3" iyz="-0.001e-3" izz="0.019e-3"/>
    </inertial>
    <collision name="collision">
      <origin rpy="0 0 0" xyz="0 0 -0.03385"/>
      <geometry>
        <box size="0.031883 0.048 0.105683"/>
      </geometry>
    </collision>
    <visual name="visual">
      <origin rpy="0 0 0" xyz="0 0 -0.0827"/>
      <geometry>
        <mesh filename="../soccer_description/meshes/left_calve.stl" scale="1 1 1"/>
      </geometry>
      <material name="black"/>
    </visual>
  </link>
  <link name="left_ankle">
    <inertial>
      <mass value="153.186e-3"/>
      <origin rpy="0 0 0" xyz="-0.020939e-3 0.000 0.011313e-3"/>
      <inertia ixx="0.041e-3" ixy="0.000" ixz="0.002e-3" iyy="0.118e-3" iyz="0.000" izz="0.106e-3"/>
    </inertial>
    <collision name="collision">
      <origin rpy="0 0 0" xyz="-0.02014 0 0.01031"/>
      <geometry>
        <box size="0.090769 0.042 0.0506"/>
      </geometry>
    </collision>
    <visual name="visual">
      <origin rpy="0 0 0" xyz="0  0  0"/>
      <geometry>
        <mesh filename="../soccer_description/meshes/left_ankle.stl" scale="1 1 1"/>
      </geometry>
      <material name="black"/>
    </visual>
  </link>
  <link name="left_foot">
    <inertial>
      <mass value="23.216e-3"/>
      <origin rpy="0 0 0" xyz="-0.020939 0.0 0.011313"/>
      <inertia ixx="0.006e-3" ixy="0.000" ixz="0.000" iyy="0.018e-3" iyz="0.000" izz="0.022e-3"/>
    </inertial>
    <collision name="collision">
      <origin rpy="0 0 0" xyz="0.00385 -0.00401 -0.00737 "/>
      <geometry>
        <box size="0.09 0.07 0.03674"/>
      </geometry>
      <contact_coefficients mu="100.0"/>
    </collision>
    <visual name="visual">
      <origin rpy="0  0  0" xyz="0  0  0"/>
      <geometry>
        <mesh filename="../soccer_description/meshes/left_foot.stl" scale="1 1 1"/>
      </geometry>
      <material name="black"/>
    </visual>
  </link>
  <joint name="left_leg_motor_0" type="revolute">
    <parent link="torso"/>
    <child link="left_hip_side"/>
    <origin rpy="0 0 0" xyz="0.0135 0.035 -0.156"/>
    <axis xyz="0 0 -1"/>
    <dynamics damping="0.01" friction="0.1"/>
    <limit effort="2.5" lower="-1.309" upper="0.524" velocity="1"/>
  </joint>
  <joint name="left_leg_motor_1" type="revolute">
    <parent link="left_hip_side"/>
    <child link="left_hip_front"/>
    <origin rpy="0 0 0" xyz="0 0 0"/>
    <axis xyz="1 0 0"/>
    <dynamics damping="0.01" friction="0.1"/>
    <limit effort="2.5" lower="-0.785398163397" upper="1.57079632679" velocity="1"/>
  </joint>
  <joint name="left_leg_motor_2" type="revolute">
    <parent link="left_hip_front"/>
    <child link="left_thigh"/>
    <origin rpy="0 0 0" xyz="0 0 0"/>
    <axis xyz="0 -1 0"/>
    <dynamics damping="0.01" friction="0.1"/>
    <limit effort="2.5" lower="-0.785398163397" upper="2.35619449019" velocity="1"/>
  </joint>
  <joint name="left_leg_motor_3" type="revolute">
    <parent link="left_thigh"/>
    <child link="left_calve"/>
    <origin rpy="0 0 0" xyz="0 0 -0.09290"/>
    <axis xyz="0 -1 0"/>
    <dynamics damping="0.01" friction="0.1"/>
    <limit effort="2.5" lower="-2.793" upper="0" velocity="1"/>
  </joint>
  <joint name="left_leg_motor_4" type="revolute">
    <parent link="left_calve"/>
    <child link="left_ankle"/>
    <origin rpy="0 0 0" xyz="0 0 -0.0827"/>
    <axis xyz="0 -1 0"/>
    <dynamics damping="0.01" friction="0.1"/>
    <limit effort="2.5" lower="-0.785398163397" upper="1.57079632679" velocity="1"/>
  </joint>
  <joint name="left_leg_motor_5" type="revolute">
    <parent link="left_ankle"/>
    <child link="left_foot"/>
    <origin rpy="0 0 0" xyz="0 0 0"/>
    <axis xyz="1 0 0"/>
    <dynamics damping="0.01" friction="0.1"/>
    <limit effort="2.5" lower="-0.785398163397" upper="0.785398163397" velocity="1"/>
  </joint>
  <transmission name="left_leg_motor_0">
    <type>transmission_interface/SimpleTransmission</type>
    <joint name="left_leg_motor_0">
      <hardwareInterface>hardware_interface/EffortJointInterface</hardwareInterface>
    </joint>
    <actuator name="left_leg_motor_0">
      <hardwareInterface>hardware_interface/EffortJointInterface</hardwareInterface>
      <mechanicalReduction>1</mechanicalReduction>
    </actuator>
  </transmission>
  <transmission name="left_leg_motor_1">
    <type>transmission_interface/SimpleTransmission</type>
    <joint name="left_leg_motor_1">
      <hardwareInterface>hardware_interface/EffortJointInterface</hardwareInterface>
    </joint>
    <actuator name="left_leg_motor_1">
      <hardwareInterface>hardware_interface/EffortJointInterface</hardwareInterface>
      <mechanicalReduction>1</mechanicalReduction>
    </actuator>
  </transmission>
  <transmission name="left_leg_motor_2">
    <type>transmission_interface/SimpleTransmission</type>
    <joint name="left_leg_motor_2">
      <hardwareInterface>hardware_interface/EffortJointInterface</hardwareInterface>
    </joint>
    <actuator name="left_leg_motor_2">
      <hardwareInterface>hardware_interface/EffortJointInterface</hardwareInterface>
      <mechanicalReduction>1</mechanicalReduction>
    </actuator>
  </transmission>
  <transmission name="left_leg_motor_3">
    <type>transmission_interface/SimpleTransmission</type>
    <joint name="left_leg_motor_3">
      <hardwareInterface>hardware_interface/EffortJointInterface</hardwareInterface>
    </joint>
    <actuator name="left_leg_motor_3">
      <hardwareInterface>hardware_interface/EffortJointInterface</hardwareInterface>
      <mechanicalReduction>1</mechanicalReduction>
    </actuator>
  </transmission>
  <transmission name="left_leg_motor_4">
    <type>transmission_interface/SimpleTransmission</type>
    <joint name="left_leg_motor_4">
      <hardwareInterface>hardware_interface/EffortJointInterface</hardwareInterface>
    </joint>
    <actuator name="left_leg_motor_4">
      <hardwareInterface>hardware_interface/EffortJointInterface</hardwareInterface>
      <mechanicalReduction>1</mechanicalReduction>
    </actuator>
  </transmission>
  <transmission name="left_leg_motor_5">
    <type>transmission_interface/SimpleTransmission</type>
    <joint name="left_leg_motor_5">
      <hardwareInterface>hardware_interface/EffortJointInterface</hardwareInterface>
    </joint>
    <actuator name="left_leg_motor_5">
      <hardwareInterface>hardware_interface/EffortJointInterface</hardwareInterface>
      <mechanicalReduction>1</mechanicalReduction>
    </actuator>
  </transmission>
  <gazebo reference="left_hip_side">
    <kp>1e+15</kp>
    <kd>1e+13</kd>
    <mu1>0.2</mu1>
    <mu2>0.2</mu2>
  </gazebo>
  <gazebo reference="left_hip_front">
    <kp>1e+15</kp>
    <kd>1e+13</kd>
    <mu1>0.2</mu1>
    <mu2>0.2</mu2>
  </gazebo>
  <gazebo reference="left_thigh">
    <kp>1e+15</kp>
    <kd>1e+13</kd>
    <mu1>0.2</mu1>
    <mu2>0.2</mu2>
  </gazebo>
  <gazebo reference="left_calve">
    <kp>1e+15</kp>
    <kd>1e+13</kd>
    <mu1>0.2</mu1>
    <mu2>0.2</mu2>
  </gazebo>
  <gazebo reference="left_ankle">
    <kp>1e+15</kp>
    <kd>1e+13</kd>
    <mu1>0.2</mu1>
    <mu2>0.2</mu2>
  </gazebo>
  <gazebo reference="left_foot">
    <mu1>0.2</mu1>
    <mu2>0.2</mu2>
  </gazebo>
  <link name="right_hip_side">
    <inertial>
      <mass value="9.364e-3"/>
      <origin rpy="0  0  0" xyz="0.0003695 0.0000 0.01689"/>
      <inertia ixx="0.002e-3" ixy="0.000" ixz="0.000" iyy="0.005e-3" iyz="0.000" izz="0.004e-3"/>
    </inertial>
    <collision name="collision">
      <origin rpy="0  0  0" xyz="0 0 0.00899"/>
      <geometry>
        <box size="0.0485 0.022 0.0039"/>
      </geometry>
    </collision>
    <visual name="visual">
      <origin rpy="0  0  0" xyz="0  0  0"/>
      <geometry>
        <mesh filename="../soccer_description/meshes/right_hip_side.stl" scale="1 1 1"/>
      </geometry>
      <material name="black"/>
    </visual>
  </link>
  <link name="right_hip_front">
    <inertial>
      <mass value="153.186e-3"/>
      <origin rpy="0 0 0" xyz="-0.02093 0 -0.011313"/>
      <inertia ixx="0.041e-3" ixy="0.000" ixz="-0.002e-3" iyy="0.118e-3" iyz="0.000" izz="0.106e-3"/>
    </inertial>
    <collision name="collision">
      <origin rpy="0 0 0" xyz="-0.02187 0 -0.01332"/>
      <geometry>
        <box size="0.083747 0.04885 0.0506"/>
      </geometry>
    </collision>
    <visual name="visual">
      <origin rpy="0  0  0" xyz="0  0  0"/>
      <geometry>
        <mesh filename="../soccer_description/meshes/right_hip_front.stl" scale="1 1 1"/>
      </geometry>
      <material name="black"/>
    </visual>
  </link>
  <link name="right_thigh">
    <inertial>
      <mass value="21.438e-3"/>
      <origin rpy="0 0 0" xyz="0.0019422 -0.0001419 -0.0469409"/>
      <inertia ixx="0.025e-3" ixy="-2e-06" ixz="0.000" iyy="0.016e-3" iyz="0.000" izz="0.010e-3"/>
    </inertial>
    <collision name="collision">
      <origin rpy="0 0 0" xyz="0 0 -0.0445"/>
      <geometry>
        <box size="0.022 0.048 0.111"/>
      </geometry>
    </collision>
    <visual name="visual">
      <origin rpy="0  0  0" xyz="0  0  0"/>
      <geometry>
        <mesh filename="../soccer_description/meshes/right_thigh.stl" scale="1 1 1"/>
      </geometry>
      <material name="black"/>
    </visual>
  </link>
  <link name="right_calve">
    <inertial>
      <mass value="86.547e-3"/>
      <origin rpy="0  0  0" xyz="0 3.259e-07 -0.0150123e-3"/>
      <inertia ixx="0.054e-3" ixy="0.000" ixz="0.000" iyy="0.046e-3" iyz="-0.001e-3" izz="0.019e-3"/>
    </inertial>
    <collision name="collision">
      <origin rpy="0 0 0" xyz="0 0 -0.03385"/>
      <geometry>
        <box size="0.031883 0.048 0.105683"/>
      </geometry>
    </collision>
    <visual name="visual">
      <origin rpy="0 0 0" xyz="0 0 -0.0827"/>
      <geometry>
        <mesh filename="../soccer_description/meshes/right_calve.stl" scale="1 1 1"/>
      </geometry>
      <material name="black"/>
    </visual>
  </link>
  <link name="right_ankle">
    <inertial>
      <mass value="153.186e-3"/>
      <origin rpy="0 0 0" xyz="-0.020939e-3 0.000 0.011313e-3"/>
      <inertia ixx="0.041e-3" ixy="0.000" ixz="0.002e-3" iyy="0.118e-3" iyz="0.000" izz="0.106e-3"/>
    </inertial>
    <collision name="collision">
      <origin rpy="0 0 0" xyz="-0.02014 0 0.01031"/>
      <geometry>
        <box size="0.090769 0.042 0.0506"/>
      </geometry>
    </collision>
    <visual name="visual">
      <origin rpy="0 0 0" xyz="0  0  0"/>
      <geometry>
        <mesh filename="../soccer_description/meshes/right_ankle.stl" scale="1 1 1"/>
      </geometry>
      <material name="black"/>
    </visual>
  </link>
  <link name="right_foot">
    <inertial>
      <mass value="23.216e-3"/>
      <origin rpy="0 0 0" xyz="-0.020939 0.0 0.011313"/>
      <inertia ixx="0.006e-3" ixy="0.000" ixz="0.000" iyy="0.018e-3" iyz="0.000" izz="0.022e-3"/>
    </inertial>
    <collision name="collision">
      <origin rpy="0 0 0" xyz="0.00385 0.00401 -0.00737 "/>
      <geometry>
        <box size="0.09 0.07 0.03674"/>
      </geometry>
      <contact_coefficients mu="100.0"/>
    </collision>
    <visual name="visual">
      <origin rpy="0  0  0" xyz="0  0  0"/>
      <geometry>
        <mesh filename="../soccer_description/meshes/right_foot.stl" scale="1 1 1"/>
      </geometry>
      <material name="black"/>
    </visual>
  </link>
  <joint name="right_leg_motor_0" type="revolute">
    <parent link="torso"/>
    <child link="right_hip_side"/>
    <origin rpy="0 0 0" xyz="0.0135 -0.035 -0.156"/>
    <axis xyz="0 0 1"/>
    <dynamics damping="0.01" friction="0.1"/>
    <limit effort="2.5" lower="-1.309" upper="0.524" velocity="1"/>
  </joint>
  <joint name="right_leg_motor_1" type="revolute">
    <parent link="right_hip_side"/>
    <child link="right_hip_front"/>
    <origin rpy="0 0 0" xyz="0 0 0"/>
    <axis xyz="-1 0 0"/>
    <dynamics damping="0.01" friction="0.1"/>
    <limit effort="2.5" lower="-0.785398163397" upper="1.57079632679" velocity="1"/>
  </joint>
  <joint name="right_leg_motor_2" type="revolute">
    <parent link="right_hip_front"/>
    <child link="right_thigh"/>
    <origin rpy="0 0 0" xyz="0 0 0"/>
    <axis xyz="0 -1 0"/>
    <dynamics damping="0.01" friction="0.1"/>
    <limit effort="2.5" lower="-0.785398163397" upper="2.35619449019" velocity="1"/>
  </joint>
  <joint name="right_leg_motor_3" type="revolute">
    <parent link="right_thigh"/>
    <child link="right_calve"/>
    <origin rpy="0 0 0" xyz="0 0 -0.09290"/>
    <axis xyz="0 -1 0"/>
    <dynamics damping="0.01" friction="0.1"/>
    <limit effort="2.5" lower="-2.793" upper="0" velocity="1"/>
  </joint>
  <joint name="right_leg_motor_4" type="revolute">
    <parent link="right_calve"/>
    <child link="right_ankle"/>
    <origin rpy="0 0 0" xyz="0 0 -0.0827"/>
    <axis xyz="0 -1 0"/>
    <dynamics damping="0.01" friction="0.1"/>
    <limit effort="2.5" lower="-0.785398163397" upper="1.57079632679" velocity="1"/>
  </joint>
  <joint name="right_leg_motor_5" type="revolute">
    <parent link="right_ankle"/>
    <child link="right_foot"/>
    <origin rpy="0 0 0" xyz="0 0 0"/>
    <axis xyz="-1 0 0"/>
    <dynamics damping="0.01" friction="0.1"/>
    <limit effort="2.5" lower="-0.785398163397" upper="0.785398163397" velocity="1"/>
  </joint>
  <transmission name="right_leg_motor_0">
    <type>transmission_interface/SimpleTransmission</type>
    <joint name="right_leg_motor_0">
      <hardwareInterface>hardware_interface/EffortJointInterface</hardwareInterface>
    </joint>
    <actuator name="right_leg_motor_0">
      <hardwareInterface>hardware_interface/EffortJointInterface</hardwareInterface>
      <mechanicalReduction>1</mechanicalReduction>
    </actuator>
  </transmission>
  <transmission name="right_leg_motor_1">
    <type>transmission_interface/SimpleTransmission</type>
    <joint name="right_leg_motor_1">
      <hardwareInterface>hardware_interface/EffortJointInterface</hardwareInterface>
    </joint>
    <actuator name="right_leg_motor_1">
      <hardwareInterface>hardware_interface/EffortJointInterface</hardwareInterface>
      <mechanicalReduction>1</mechanicalReduction>
    </actuator>
  </transmission>
  <transmission name="right_leg_motor_2">
    <type>transmission_interface/SimpleTransmission</type>
    <joint name="right_leg_motor_2">
      <hardwareInterface>hardware_interface/EffortJointInterface</hardwareInterface>
    </joint>
    <actuator name="right_leg_motor_2">
      <hardwareInterface>hardware_interface/EffortJointInterface</hardwareInterface>
      <mechanicalReduction>1</mechanicalReduction>
    </actuator>
  </transmission>
  <transmission name="right_leg_motor_3">
    <type>transmission_interface/SimpleTransmission</type>
    <joint name="right_leg_motor_3">
      <hardwareInterface>hardware_interface/EffortJointInterface</hardwareInterface>
    </joint>
    <actuator name="right_leg_motor_3">
      <hardwareInterface>hardware_interface/EffortJointInterface</hardwareInterface>
      <mechanicalReduction>1</mechanicalReduction>
    </actuator>
  </transmission>
  <transmission name="right_leg_motor_4">
    <type>transmission_interface/SimpleTransmission</type>
    <joint name="right_leg_motor_4">
      <hardwareInterface>hardware_interface/EffortJointInterface</hardwareInterface>
    </joint>
    <actuator name="right_leg_motor_4">
      <hardwareInterface>hardware_interface/EffortJointInterface</hardwareInterface>
      <mechanicalReduction>1</mechanicalReduction>
    </actuator>
  </transmission>
  <transmission name="right_leg_motor_5">
    <type>transmission_interface/SimpleTransmission</type>
    <joint name="right_leg_motor_5">
      <hardwareInterface>hardware_interface/EffortJointInterface</hardwareInterface>
    </joint>
    <actuator name="right_leg_motor_5">
      <hardwareInterface>hardware_interface/EffortJointInterface</hardwareInterface>
      <mechanicalReduction>1</mechanicalReduction>
    </actuator>
  </transmission>
  <gazebo reference="right_hip_side">
    <kp>1e+15</kp>
    <kd>1e+13</kd>
    <mu1>0.2</mu1>
    <mu2>0.2</mu2>
  </gazebo>
  <gazebo reference="right_hip_front">
    <kp>1e+15</kp>
    <kd>1e+13</kd>
    <mu1>0.2</mu1>
    <mu2>0.2</mu2>
  </gazebo>
  <gazebo reference="right_thigh">
    <kp>1e+15</kp>
    <kd>1e+13</kd>
    <mu1>0.2</mu1>
    <mu2>0.2</mu2>
  </gazebo>
  <gazebo reference="right_calve">
    <kp>1e+15</kp>
    <kd>1e+13</kd>
    <mu1>0.2</mu1>
    <mu2>0.2</mu2>
  </gazebo>
  <gazebo reference="right_ankle">
    <kp>1e+15</kp>
    <kd>1e+13</kd>
    <mu1>0.2</mu1>
    <mu2>0.2</mu2>
  </gazebo>
  <gazebo reference="right_foot">
    <mu1>0.2</mu1>
    <mu2>0.2</mu2>
  </gazebo>
  <link name="neck">
    <inertial>
      <mass value="0.011294"/>
      <origin rpy="0  0  0" xyz="0 -0.0006476 0.0092453"/>
      <inertia ixx="5.489e-6" ixy="0" ixz="0" iyy="1.433e-6" iyz="0" izz="4.955e-6"/>
    </inertial>
    <collision name="collision">
      <origin rpy="0  0  0" xyz="0 0 0.0165"/>
      <geometry>
        <box size="0.022 0.0523 0.033"/>
      </geometry>
    </collision>
    <visual name="visual">
      <origin rpy="0  0  0" xyz="0  0  0"/>
      <geometry>
        <mesh filename="../soccer_description/meshes/neck.stl" scale="1 1 1"/>
      </geometry>
      <material name="black"/>
    </visual>
  </link>
  <link name="head">
    <inertial>
      <mass value="0.282"/>
      <origin rpy="0  0  0" xyz="0.0237166 0.0018096 0.0255966"/>
      <inertia ixx="2.06e-4" ixy="1.06e-6" ixz="-5.73e-5" iyy="2.057e-4" iyz="2.534e-6" izz="1.603e-4"/>
    </inertial>
    <collision name="collision">
      <origin rpy="0  0  0" xyz="-0.013 0 0.025"/>
      <geometry>
        <box size="0.0712 0.094 0.0779"/>
      </geometry>
    </collision>
    <visual name="visual">
      <origin rpy="0  0  0" xyz="0  0  0"/>
      <geometry>
        <mesh filename="../soccer_description/meshes/head.stl" scale="1 1 1"/>
      </geometry>
      <material name="black"/>
    </visual>
  </link>
  <joint name="head_motor_0" type="revolute">
    <parent link="torso"/>
    <child link="neck"/>
    <origin rpy="0 0 0" xyz="0.024 0 0.05875"/>
    <axis xyz="0 0 1"/>
    <dynamics damping="0.01" friction="0.1"/>
    <limit effort="1.5" lower="-1.57079632679" upper="1.57079632679" velocity="1"/>
  </joint>
  <joint name="head_motor_1" type="revolute">
    <parent link="neck"/>
    <child link="head"/>
    <origin rpy="0 0 0" xyz="0 0 0.024"/>
    <axis xyz="0 1 0"/>
    <dynamics damping="0.01" friction="0.1"/>
    <limit effort="1.5" lower="-2.35619449019" upper="2.35619449019" velocity="1"/>
  </joint>
  <transmission name="head_motor_0">
    <type>transmission_interface/SimpleTransmission</type>
    <joint name="head_motor_0">
      <hardwareInterface>hardware_interface/EffortJointInterface</hardwareInterface>
    </joint>
    <actuator name="head_motor_0">
      <hardwareInterface>hardware_interface/EffortJointInterface</hardwareInterface>
      <mechanicalReduction>1</mechanicalReduction>
    </actuator>
  </transmission>
  <transmission name="head_motor_1">
    <type>transmission_interface/SimpleTransmission</type>
    <joint name="head_motor_1">
      <hardwareInterface>hardware_interface/EffortJointInterface</hardwareInterface>
    </joint>
    <actuator name="head_motor_1">
      <hardwareInterface>hardware_interface/EffortJointInterface</hardwareInterface>
      <mechanicalReduction>1</mechanicalReduction>
    </actuator>
  </transmission>
  <gazebo reference="neck">
    <kp>1e+15</kp>
    <kd>1e+13</kd>
    <mu1>0.2</mu1>
    <mu2>0.2</mu2>
  </gazebo>
  <gazebo reference="head">
    <kp>1e+15</kp>
    <kd>1e+13</kd>
    <mu1>0.2</mu1>
    <mu2>0.2</mu2>
  </gazebo>
  <link name="imu_link"/>
  <joint name="torso_imu" type="fixed">
    <parent link="torso"/>
    <child link="imu_link"/>
    <origin rpy="0 0 0" xyz="0.1 0 0.0075"/>
    <axis xyz="0 0 0"/>
  </joint>
  <gazebo reference="imu_link">
    <gravity>true</gravity>
    <sensor name="imu_sensor" type="imu">
      <always_on>true</always_on>
      <update_rate>100</update_rate>
      <visualize>true</visualize>
      <topic>__default_topic__</topic>
      <plugin filename="libgazebo_ros_imu_sensor.so" name="imu_plugin">
        <topicName>imu_raw</topicName>
        <bodyName>imu_link</bodyName>
        <updateRateHZ>50.0</updateRateHZ>
        <gaussianNoise>0.0</gaussianNoise>
        <xyzOffset>0 0 0</xyzOffset>
        <rpyOffset>0 0 0</rpyOffset>
        <frameName>imu_link</frameName>
      </plugin>
      <pose>0 0 0 0 0 0</pose>
    </sensor>
  </gazebo>
  <gazebo reference="imu_link">
    <kp>1e+15</kp>
    <kd>1e+13</kd>
    <mu1>0.2</mu1>
    <mu2>0.2</mu2>
  </gazebo>
  <link name="camera"/>
  <joint name="head_camera" type="fixed">
    <parent link="head"/>
    <child link="camera"/>
    <origin rpy="0 0 0" xyz="0.015 0.00145 0.04740"/>
    <axis xyz="0  0  0"/>
    <dynamics damping="0.01" friction="0.1"/>
    <limit effort="0" lower="0" upper="0" velocity="0"/>
  </joint>
  <gazebo reference="camera">
    <sensor name="main_camera" type="camera">
      <always_on>1</always_on>
      <visualize>1</visualize>
      <update_rate>30</update_rate>
      <camera>
        <horizontal_fov>1.39626</horizontal_fov>
        <image>
          <width>640</width>
          <height>480</height>
          <format>R8G8B8</format>
        </image>
        <clip>
          <near>0.2</near>
          <far>10</far>
        </clip>
        <noise>
          <type>gaussian</type>
          <mean>0</mean>
          <stddev>0.007</stddev>
        </noise>
      </camera>
      <plugin filename="libgazebo_ros_camera.so" name="camera_controller">
        <alwaysOn>true</alwaysOn>
        <updateRate>0.0</updateRate>
        <cameraName>camera</cameraName>
        <imageTopicName>image_raw</imageTopicName>
        <cameraInfoTopicName>camera_info</cameraInfoTopicName>
        <frameName>camera_link</frameName>
        <hackBaseline>0.07</hackBaseline>
        <distortionK1>0.0</distortionK1>
        <distortionK2>0.0</distortionK2>
        <distortionK3>0.0</distortionK3>
        <distortionT1>0.0</distortionT1>
        <distortionT2>0.0</distortionT2>
      </plugin>
    </sensor>
  </gazebo>
  <gazebo reference="camera">
    <kp>1e+15</kp>
    <kd>1e+13</kd>
    <mu1>0.2</mu1>
    <mu2>0.2</mu2>
  </gazebo>
  <gazebo>
    <plugin filename="libgazebo_ros_control.so" name="gazebo_ros_control">
      <robotNamespace>/</robotNamespace>
      <robotSimType>gazebo_ros_control/DefaultRobotHWSim</robotSimType>
    </plugin>
  </gazebo>
  <gazebo reference="torso">
    <kp>1e+15</kp>
    <kd>1e+13</kd>
    <mu1>0.2</mu1>
    <mu2>0.2</mu2>
  </gazebo>
</robot>
