<?xml version="1.0" ?>
<robot name="assembly" version="1.0">
  <material name="silver_default">
    <color rgba="0.7 0.7 0.7 1.0"/>
  </material>
  <material name="aluminum_satin">
    <color rgba="0.9607843137254902 0.9607843137254902 0.9647058823529412 1.0"/>
  </material>
  <material name="steel_satin">
    <color rgba="0.6274509803921569 0.6274509803921569 0.6274509803921569 1.0"/>
  </material>
  <material name="abs_white">
    <color rgba="0.36470588235294116 0.4392156862745098 0.5098039215686274 1.0"/>
  </material>
  <transmission name="left_hip_yaw_tran">
    <type>transmission_interface/SimpleTransmission</type>
    <joint name="left_hip_yaw">
      <hardwareInterface>hardware_interface/EffortJointInterface</hardwareInterface>
    </joint>
    <actuator name="left_hip_yaw_actr">
      <mechanicalReduction>1.0</mechanicalReduction>
    </actuator>
  </transmission>
  <transmission name="left_ankle_roll_tran">
    <type>transmission_interface/SimpleTransmission</type>
    <joint name="left_ankle_roll">
      <hardwareInterface>hardware_interface/EffortJointInterface</hardwareInterface>
    </joint>
    <actuator name="left_ankle_roll_actr">
      <mechanicalReduction>1.0</mechanicalReduction>
    </actuator>
  </transmission>
  <transmission name="left_shoulder_pitch_tran">
    <type>transmission_interface/SimpleTransmission</type>
    <joint name="left_shoulder_pitch">
      <hardwareInterface>hardware_interface/EffortJointInterface</hardwareInterface>
    </joint>
    <actuator name="left_shoulder_pitch_actr">
      <mechanicalReduction>1.0</mechanicalReduction>
    </actuator>
  </transmission>
  <transmission name="left_shoulder_roll_tran">
    <type>transmission_interface/SimpleTransmission</type>
    <joint name="left_shoulder_roll">
      <hardwareInterface>hardware_interface/EffortJointInterface</hardwareInterface>
    </joint>
    <actuator name="left_shoulder_roll_actr">
      <mechanicalReduction>1.0</mechanicalReduction>
    </actuator>
  </transmission>
  <transmission name="left_elbow_tran">
    <type>transmission_interface/SimpleTransmission</type>
    <joint name="left_elbow">
      <hardwareInterface>hardware_interface/EffortJointInterface</hardwareInterface>
    </joint>
    <actuator name="left_elbow_actr">
      <mechanicalReduction>1.0</mechanicalReduction>
    </actuator>
  </transmission>
  <transmission name="head_yaw_tran">
    <type>transmission_interface/SimpleTransmission</type>
    <joint name="head_yaw">
      <hardwareInterface>hardware_interface/EffortJointInterface</hardwareInterface>
    </joint>
    <actuator name="head_yaw_actr">
      <mechanicalReduction>1.0</mechanicalReduction>
    </actuator>
  </transmission>
  <transmission name="head_pitch_tran">
    <type>transmission_interface/SimpleTransmission</type>
    <joint name="head_pitch">
      <hardwareInterface>hardware_interface/EffortJointInterface</hardwareInterface>
    </joint>
    <actuator name="head_pitch_actr">
      <mechanicalReduction>1.0</mechanicalReduction>
    </actuator>
  </transmission>
  <transmission name="right_hip_yaw_tran">
    <type>transmission_interface/SimpleTransmission</type>
    <joint name="right_hip_yaw">
      <hardwareInterface>hardware_interface/EffortJointInterface</hardwareInterface>
    </joint>
    <actuator name="right_hip_yaw_actr">
      <mechanicalReduction>1.0</mechanicalReduction>
    </actuator>
  </transmission>
  <transmission name="right_ankle_pitch_tran">
    <type>transmission_interface/SimpleTransmission</type>
    <joint name="right_ankle_pitch">
      <hardwareInterface>hardware_interface/EffortJointInterface</hardwareInterface>
    </joint>
    <actuator name="right_ankle_pitch_actr">
      <mechanicalReduction>1.0</mechanicalReduction>
    </actuator>
  </transmission>
  <transmission name="right_ankle_roll_tran">
    <type>transmission_interface/SimpleTransmission</type>
    <joint name="right_ankle_roll">
      <hardwareInterface>hardware_interface/EffortJointInterface</hardwareInterface>
    </joint>
    <actuator name="right_ankle_roll_actr">
      <mechanicalReduction>1.0</mechanicalReduction>
    </actuator>
  </transmission>
  <transmission name="right_shoulder_pitch_tran">
    <type>transmission_interface/SimpleTransmission</type>
    <joint name="right_shoulder_pitch">
      <hardwareInterface>hardware_interface/EffortJointInterface</hardwareInterface>
    </joint>
    <actuator name="right_shoulder_pitch_actr">
      <mechanicalReduction>1.0</mechanicalReduction>
    </actuator>
  </transmission>
  <transmission name="right_shoulder_roll_tran">
    <type>transmission_interface/SimpleTransmission</type>
    <joint name="right_shoulder_roll">
      <hardwareInterface>hardware_interface/EffortJointInterface</hardwareInterface>
    </joint>
    <actuator name="right_shoulder_roll_actr">
      <mechanicalReduction>1.0</mechanicalReduction>
    </actuator>
  </transmission>
  <transmission name="right_elbow_tran">
    <type>transmission_interface/SimpleTransmission</type>
    <joint name="right_elbow">
      <hardwareInterface>hardware_interface/EffortJointInterface</hardwareInterface>
    </joint>
    <actuator name="right_elbow_actr">
      <mechanicalReduction>1.0</mechanicalReduction>
    </actuator>
  </transmission>
  <transmission name="left_hip_pitch_tran">
    <type>transmission_interface/SimpleTransmission</type>
    <joint name="left_hip_pitch">
      <hardwareInterface>hardware_interface/EffortJointInterface</hardwareInterface>
    </joint>
    <actuator name="left_hip_pitch_actr">
      <mechanicalReduction>1.0</mechanicalReduction>
    </actuator>
  </transmission>
  <transmission name="right_hip_pitch_tran">
    <type>transmission_interface/SimpleTransmission</type>
    <joint name="right_hip_pitch">
      <hardwareInterface>hardware_interface/EffortJointInterface</hardwareInterface>
    </joint>
    <actuator name="right_hip_pitch_actr">
      <mechanicalReduction>1.0</mechanicalReduction>
    </actuator>
  </transmission>
  <transmission name="left_hip_roll_tran">
    <type>transmission_interface/SimpleTransmission</type>
    <joint name="left_hip_roll">
      <hardwareInterface>hardware_interface/EffortJointInterface</hardwareInterface>
    </joint>
    <actuator name="left_hip_roll_actr">
      <mechanicalReduction>1.0</mechanicalReduction>
    </actuator>
  </transmission>
  <transmission name="left_knee_tran">
    <type>transmission_interface/SimpleTransmission</type>
    <joint name="left_knee">
      <hardwareInterface>hardware_interface/EffortJointInterface</hardwareInterface>
    </joint>
    <actuator name="left_knee_actr">
      <mechanicalReduction>1.0</mechanicalReduction>
    </actuator>
  </transmission>
  <transmission name="left_ankle_pitch_tran">
    <type>transmission_interface/SimpleTransmission</type>
    <joint name="left_ankle_pitch">
      <hardwareInterface>hardware_interface/EffortJointInterface</hardwareInterface>
    </joint>
    <actuator name="left_ankle_pitch_actr">
      <mechanicalReduction>1.0</mechanicalReduction>
    </actuator>
  </transmission>
  <transmission name="right_hip_roll_tran">
    <type>transmission_interface/SimpleTransmission</type>
    <joint name="right_hip_roll">
      <hardwareInterface>hardware_interface/EffortJointInterface</hardwareInterface>
    </joint>
    <actuator name="right_hip_roll_actr">
      <mechanicalReduction>1.0</mechanicalReduction>
    </actuator>
  </transmission>
  <transmission name="right_knee_tran">
    <type>transmission_interface/SimpleTransmission</type>
    <joint name="right_knee">
      <hardwareInterface>hardware_interface/EffortJointInterface</hardwareInterface>
    </joint>
    <actuator name="right_knee_actr">
      <mechanicalReduction>1.0</mechanicalReduction>
    </actuator>
  </transmission>
  <gazebo>
    <plugin filename="libgazebo_ros_control.so" name="control"/>
  </gazebo>
  <gazebo reference="base_link">
    <material>Gazebo/Silver</material>
    <mu1>0.2</mu1>
    <mu2>0.2</mu2>
    <selfCollide>true</selfCollide>
    <gravity>true</gravity>
  </gazebo>
  <gazebo reference="left_hip_side_v5_1">
    <material>Gazebo/Silver</material>
    <mu1>0.2</mu1>
    <mu2>0.2</mu2>
    <selfCollide>true</selfCollide>
  </gazebo>
  <gazebo reference="left_foot_v10_1">
    <material>Gazebo/Silver</material>
    <mu1>0.2</mu1>
    <mu2>0.2</mu2>
    <selfCollide>true</selfCollide>
  </gazebo>
  <gazebo reference="left_shoulder_v5_1">
    <material>Gazebo/Silver</material>
    <mu1>0.2</mu1>
    <mu2>0.2</mu2>
    <selfCollide>true</selfCollide>
  </gazebo>
  <gazebo reference="left_bicep_v6_1">
    <material>Gazebo/Silver</material>
    <mu1>0.2</mu1>
    <mu2>0.2</mu2>
    <selfCollide>true</selfCollide>
  </gazebo>
  <gazebo reference="left_forearm_v4_1">
    <material>Gazebo/Silver</material>
    <mu1>0.2</mu1>
    <mu2>0.2</mu2>
    <selfCollide>true</selfCollide>
  </gazebo>
  <gazebo reference="neck_v6_1">
    <material>Gazebo/Silver</material>
    <mu1>0.2</mu1>
    <mu2>0.2</mu2>
    <selfCollide>true</selfCollide>
  </gazebo>
  <gazebo reference="head_v4_1">
    <material>Gazebo/Silver</material>
    <mu1>0.2</mu1>
    <mu2>0.2</mu2>
    <selfCollide>true</selfCollide>
  </gazebo>
  <gazebo reference="right_hip_side_v1_1">
    <material>Gazebo/Silver</material>
    <mu1>0.2</mu1>
    <mu2>0.2</mu2>
    <selfCollide>true</selfCollide>
  </gazebo>
  <gazebo reference="right_ankle_v2_1">
    <material>Gazebo/Silver</material>
    <mu1>0.2</mu1>
    <mu2>0.2</mu2>
    <selfCollide>true</selfCollide>
  </gazebo>
  <gazebo reference="right_foot_v2_1">
    <material>Gazebo/Silver</material>
    <mu1>0.2</mu1>
    <mu2>0.2</mu2>
    <selfCollide>true</selfCollide>
  </gazebo>
  <gazebo reference="right_shoulder_v1_1">
    <material>Gazebo/Silver</material>
    <mu1>0.2</mu1>
    <mu2>0.2</mu2>
    <selfCollide>true</selfCollide>
  </gazebo>
  <gazebo reference="right_bicep_v2_1">
    <material>Gazebo/Silver</material>
    <mu1>0.2</mu1>
    <mu2>0.2</mu2>
    <selfCollide>true</selfCollide>
  </gazebo>
  <gazebo reference="right_forearm_v1_1">
    <material>Gazebo/Silver</material>
    <mu1>0.2</mu1>
    <mu2>0.2</mu2>
    <selfCollide>true</selfCollide>
  </gazebo>
  <gazebo reference="left_thigh_v1_1">
    <material>Gazebo/Silver</material>
    <mu1>0.2</mu1>
    <mu2>0.2</mu2>
    <selfCollide>true</selfCollide>
  </gazebo>
  <gazebo reference="right_thigh_v1_1">
    <material>Gazebo/Silver</material>
    <mu1>0.2</mu1>
    <mu2>0.2</mu2>
    <selfCollide>true</selfCollide>
  </gazebo>
  <gazebo reference="left_hip_front_v5_1">
    <material>Gazebo/Silver</material>
    <mu1>0.2</mu1>
    <mu2>0.2</mu2>
    <selfCollide>true</selfCollide>
  </gazebo>
  <gazebo reference="left_calve_v5_1">
    <material>Gazebo/Silver</material>
    <mu1>0.2</mu1>
    <mu2>0.2</mu2>
    <selfCollide>true</selfCollide>
  </gazebo>
  <gazebo reference="left_ankle_v7_1">
    <material>Gazebo/Silver</material>
    <mu1>0.2</mu1>
    <mu2>0.2</mu2>
    <selfCollide>true</selfCollide>
  </gazebo>
  <gazebo reference="right_hip_front_v5_1">
    <material>Gazebo/Silver</material>
    <mu1>0.2</mu1>
    <mu2>0.2</mu2>
    <selfCollide>true</selfCollide>
  </gazebo>
  <gazebo reference="right_calve_v1_1">
    <material>Gazebo/Silver</material>
    <mu1>0.2</mu1>
    <mu2>0.2</mu2>
    <selfCollide>true</selfCollide>
  </gazebo>
  <link name="base_link">
    <inertial>
      <origin xyz="-0.02024929347181477 0.00329389202927954 -0.02671963219571571" rpy="0.0 0.0 0.0"/>
      <mass value="3.0429325287174738"/>
      <inertia ixx="0.009761" ixy="7.9e-05" ixz="-0.000195" iyy="0.006663" iyz="8.1e-05" izz="0.008082"/>
    </inertial>
    <visual>
      <origin xyz="0.0 0.0 0.0" rpy="0.0 0.0 0.0"/>
      <geometry>
        <mesh filename="package://assembly_description/meshes/base_link.stl" scale="0.001 0.001 0.001"/>
      </geometry>
      <material name="silver_default"/>
    </visual>
    <collision>
      <origin xyz="-20.115992033740344 4.664365111821573e-15 -17.900023462380794" rpy="0.0035558452482774066 -1.2246390569167522e-16 1.5707963267948966"/>
      <geometry>
        <box size="172.0 182.18887294249834 184.9703420076188"/>
      </geometry>
    </collision>
  </link>
  <link name="left_hip_side_v5_1">
    <inertial>
      <origin xyz="-0.0176303342104258 -2.8796409701214998e-15 -0.007188418776152797" rpy="0.0 0.0 0.0"/>
      <mass value="0.03929574358294283"/>
      <inertia ixx="7e-06" ixy="0.0" ixz="4e-06" iyy="9.2e-05" iyz="0.0" izz="9e-05"/>
    </inertial>
    <visual>
      <origin xyz="-0.016 -0.04125 0.1085" rpy="0.0 0.0 0.0"/>
      <geometry>
        <mesh filename="package://assembly_description/meshes/left_hip_side_v5_1.stl" scale="0.001 0.001 0.001"/>
      </geometry>
      <material name="aluminum_satin"/>
    </visual>
    <collision>
      <origin xyz="-6.215996948242194 41.20875 -129.38945532226563" rpy="1.5707963267948968 -0.0 -1.5707963267948966"/>
      <geometry>
        <box size="32.0 41.995910644531264 147.99999999999997"/>
      </geometry>
    </collision>
  </link>
  <link name="left_foot_v10_1">
    <inertial>
      <origin xyz="0.05312327716355333 0.01311710007932914 -0.017187548637288774" rpy="0.0 0.0 0.0"/>
      <mass value="0.03929273129474386"/>
      <inertia ixx="2.6e-05" ixy="2e-06" ixz="-3e-06" iyy="0.000124" iyz="2e-06" izz="0.000144"/>
    </inertial>
    <visual>
      <origin xyz="0.054731 -0.04125 0.3685" rpy="0.0 0.0 0.0"/>
      <geometry>
        <mesh filename="package://assembly_description/meshes/left_foot_v10_1.stl" scale="0.001 0.001 0.001"/>
      </geometry>
      <material name="abs_white"/>
    </visual>
    <collision>
      <origin xyz="-5.646021258300785 58.08637969394898 -390.6517665508918" rpy="1.5707963267948968 1.0636978224025597 -1.5707963267948966"/>
      <geometry>
        <box size="50.95253945537241 80.13108364447424 184.0"/>
      </geometry>
    </collision>
  </link>
  <link name="left_shoulder_v5_1">
    <inertial>
      <origin xyz="8.922688803092438e-11 0.007844026821939576 2.0192181260370035e-14" rpy="0.0 0.0 0.0"/>
      <mass value="0.010592862408759271"/>
      <inertia ixx="1e-06" ixy="0.0" ixz="0.0" iyy="3e-06" iyz="-0.0" izz="3e-06"/>
    </inertial>
    <visual>
      <origin xyz="-0.003 -0.084 -0.04475" rpy="0.0 0.0 0.0"/>
      <geometry>
        <mesh filename="package://assembly_description/meshes/left_shoulder_v5_1.stl" scale="0.001 0.001 0.001"/>
      </geometry>
      <material name="aluminum_satin"/>
    </visual>
    <collision>
      <origin xyz="2.9970000000000008 100.0660015258789 44.70524904632568" rpy="-3.141592653589793 1.5707963267948966 0.0"/>
      <geometry>
        <box size="26.99842262268067 33.30000305175781 41.0"/>
      </geometry>
    </collision>
  </link>
  <link name="left_bicep_v6_1">
    <inertial>
      <origin xyz="-0.019420473733666368 0.00010477857835172744 -0.06051458521988624" rpy="0.0 0.0 0.0"/>
      <mass value="0.18636400760544294"/>
      <inertia ixx="0.000442" ixy="0.0" ixz="-1e-05" iyy="0.000444" iyz="3e-06" izz="3.5e-05"/>
    </inertial>
    <visual>
      <origin xyz="-0.022 -0.1143 -0.04475" rpy="0.0 0.0 0.0"/>
      <geometry>
        <mesh filename="package://assembly_description/meshes/left_bicep_v6_1.stl" scale="0.001 0.001 0.001"/>
      </geometry>
      <material name="silver_default"/>
    </visual>
    <collision>
      <origin xyz="3.478 114.48634315795898 -14.865005279541016" rpy="3.141592653589793 -0.0 -3.141592653589793"/>
      <geometry>
        <box size="41.0 41.00000762939453 141.64051055908203"/>
      </geometry>
    </collision>
  </link>
  <link name="left_forearm_v4_1">
    <inertial>
      <origin xyz="0.0004904443113911659 -0.01970036030468776 -0.0814474917977369" rpy="0.0 0.0 0.0"/>
      <mass value="0.05984540204112203"/>
      <inertia ixx="0.000124" ixy="-0.0" ixz="-0.0" iyy="0.000119" iyz="-0.0" izz="2.1e-05"/>
    </inertial>
    <visual>
      <origin xyz="-0.001597 -0.133101 0.074391" rpy="0.0 0.0 0.0"/>
      <geometry>
        <mesh filename="package://assembly_description/meshes/left_forearm_v4_1.stl" scale="0.001 0.001 0.001"/>
      </geometry>
      <material name="abs_white"/>
    </visual>
    <collision>
      <origin xyz="2.082179473999023 113.26753758032227 -136.3161233737793" rpy="3.141592653589793 -0.0 3.141592653589793"/>
      <geometry>
        <box size="42.50000000000001 48.999992370605476 150.00000762939453"/>
      </geometry>
    </collision>
  </link>
  <link name="neck_v6_1">
    <inertial>
      <origin xyz="8.936969206796164e-11 0.0012409815706136025 0.012040454865583" rpy="0.0 0.0 0.0"/>
      <mass value="0.004247113386163016"/>
      <inertia ixx="2e-06" ixy="-0.0" ixz="0.0" iyy="1e-06" iyz="-0.0" izz="2e-06"/>
    </inertial>
    <visual>
      <origin xyz="-0.0 -0.00025 -0.0725" rpy="0.0 0.0 0.0"/>
      <geometry>
        <mesh filename="package://assembly_description/meshes/neck_v6_1.stl" scale="0.001 0.001 0.001"/>
      </geometry>
      <material name="abs_white"/>
    </visual>
    <collision>
      <origin xyz="-1.5308084989341915e-17 0.24975 91.42254470825195" rpy="1.5707963267948966 -0.0 6.123233995736766e-17"/>
      <geometry>
        <box size="22.000000000000007 37.990089416503906 45.0"/>
      </geometry>
    </collision>
  </link>
  <link name="head_v4_1">
    <inertial>
      <origin xyz="-0.0025761957912120003 0.01899177474904292 0.03300593624682499" rpy="0.0 0.0 0.0"/>
      <mass value="0.26433915470596575"/>
      <inertia ixx="0.000237" ixy="-0.0" ixz="-5.6e-05" iyy="0.000239" iyz="-2e-06" izz="0.000166"/>
    </inertial>
    <visual>
      <origin xyz="-0.0 0.01825 -0.0975" rpy="0.0 0.0 0.0"/>
      <geometry>
        <mesh filename="package://assembly_description/meshes/head_v4_1.stl" scale="0.001 0.001 0.001"/>
      </geometry>
      <material name="steel_satin"/>
    </visual>
    <collision>
      <origin xyz="-9.89999961853027 0.9682507629394537 125.30250152587891" rpy="1.5707963267948966 -0.0 3.141592653589793"/>
      <geometry>
        <box size="71.20000076293945 84.30000305175781 94.0"/>
      </geometry>
    </collision>
  </link>
  <link name="right_hip_side_v1_1">
    <inertial>
      <origin xyz="-0.017630334210425074 -2.7131075164277263e-15 -0.007188418776152866" rpy="0.0 0.0 0.0"/>
      <mass value="0.03929574358294283"/>
      <inertia ixx="7e-06" ixy="0.0" ixz="4e-06" iyy="9.2e-05" iyz="0.0" izz="9e-05"/>
    </inertial>
    <visual>
      <origin xyz="-0.016 0.04125 0.1085" rpy="0.0 0.0 0.0"/>
      <geometry>
        <mesh filename="package://assembly_description/meshes/right_hip_side_v1_1.stl" scale="0.001 0.001 0.001"/>
      </geometry>
      <material name="aluminum_satin"/>
    </visual>
    <collision>
      <origin xyz="-6.215996948242194 -41.20875 -129.38945532226563" rpy="1.5707963267948968 -0.0 -1.5707963267948966"/>
      <geometry>
        <box size="32.0 41.995910644531264 147.99999999999997"/>
      </geometry>
    </collision>
  </link>
  <link name="right_ankle_v2_1">
    <inertial>
      <origin xyz="-0.019332548462524354 0.02355722240141854 -0.018170467896408804" rpy="0.0 0.0 0.0"/>
      <mass value="0.2722002973016189"/>
      <inertia ixx="0.000108" ixy="-0.0" ixz="-1.3e-05" iyy="0.000229" iyz="1e-06" izz="0.000189"/>
    </inertial>
    <visual>
      <origin xyz="-0.0116 0.06475 0.3325" rpy="0.0 0.0 0.0"/>
      <geometry>
        <mesh filename="package://assembly_description/meshes/right_ankle_v2_1.stl" scale="0.001 0.001 0.001"/>
      </geometry>
      <material name="steel_satin"/>
    </visual>
    <collision>
      <origin xyz="-10.762400568342853 -41.685249999999996 -350.22797197209337" rpy="1.564531285334775 6.123233995736767e-17 -1.5707963267948968"/>
      <geometry>
        <box size="55.000000000000014 64.38847622564403 93.10624610455508"/>
      </geometry>
    </collision>
  </link>
  <link name="right_foot_v2_1">
    <inertial>
      <origin xyz="0.053123527163554944 -0.01311710007932746 -0.017187548637289052" rpy="0.0 0.0 0.0"/>
      <mass value="0.03929273129474384"/>
      <inertia ixx="2.6e-05" ixy="-2e-06" ixz="-3e-06" iyy="0.000124" iyz="-2e-06" izz="0.000144"/>
    </inertial>
    <visual>
      <origin xyz="0.0547 0.04125 0.3685" rpy="0.0 0.0 0.0"/>
      <geometry>
        <mesh filename="package://assembly_description/meshes/right_foot_v2_1.stl" scale="0.001 0.001 0.001"/>
      </geometry>
      <material name="abs_white"/>
    </visual>
    <collision>
      <origin xyz="-5.614802258300785 -58.086379693949006 -390.65176655089186" rpy="-1.5707963267948968 1.0636978224025597 1.5707963267948966"/>
      <geometry>
        <box size="50.95253945537252 80.1310836444743 184.0"/>
      </geometry>
    </collision>
  </link>
  <link name="right_shoulder_v1_1">
    <inertial>
      <origin xyz="8.958533047331851e-11 -0.007844026821937675 2.015054789694659e-14" rpy="0.0 0.0 0.0"/>
      <mass value="0.010592862408759271"/>
      <inertia ixx="1e-06" ixy="0.0" ixz="-0.0" iyy="3e-06" iyz="0.0" izz="3e-06"/>
    </inertial>
    <visual>
      <origin xyz="-0.003 0.084 -0.04475" rpy="0.0 0.0 0.0"/>
      <geometry>
        <mesh filename="package://assembly_description/meshes/right_shoulder_v1_1.stl" scale="0.001 0.001 0.001"/>
      </geometry>
      <material name="aluminum_satin"/>
    </visual>
    <collision>
      <origin xyz="2.9970000000000008 -100.0660015258789 44.70524904632568" rpy="-3.141592653589793 1.5707963267948966 0.0"/>
      <geometry>
        <box size="26.998422622680668 33.30000305175781 41.0"/>
      </geometry>
    </collision>
  </link>
  <link name="right_bicep_v2_1">
    <inertial>
      <origin xyz="-0.01907144993358056 -0.0012317079698353356 -0.06051458521988612" rpy="0.0 0.0 0.0"/>
      <mass value="0.18636400760544294"/>
      <inertia ixx="0.000443" ixy="-0.0" ixz="-6e-06" iyy="0.000444" iyz="-1.1e-05" izz="3.5e-05"/>
    </inertial>
    <visual>
      <origin xyz="-0.022 0.1143 -0.04475" rpy="0.0 0.0 0.0"/>
      <geometry>
        <mesh filename="package://assembly_description/meshes/right_bicep_v2_1.stl" scale="0.001 0.001 0.001"/>
      </geometry>
      <material name="silver_default"/>
    </visual>
    <collision>
      <origin xyz="3.4544928817749025 -116.48634315795898 -14.865005279541016" rpy="3.141592653589793 -0.0 -1.5707963267948966"/>
      <geometry>
        <box size="41.00000762939453 41.04701423645021 141.64051055908203"/>
      </geometry>
    </collision>
  </link>
  <link name="right_forearm_v1_1">
    <inertial>
      <origin xyz="0.0004903254970113039 0.019700355234835765 -0.08144749179773612" rpy="0.0 0.0 0.0"/>
      <mass value="0.05984540204112203"/>
      <inertia ixx="0.000124" ixy="-0.0" ixz="-0.0" iyy="0.000119" iyz="-0.0" izz="2.1e-05"/>
    </inertial>
    <visual>
      <origin xyz="-0.002403 0.135101 0.074391" rpy="0.0 0.0 0.0"/>
      <geometry>
        <mesh filename="package://assembly_description/meshes/right_forearm_v1_1.stl" scale="0.001 0.001 0.001"/>
      </geometry>
      <material name="abs_white"/>
    </visual>
    <collision>
      <origin xyz="2.887254974243164 -115.26553758032226 -136.3161233737793" rpy="3.141592653589793 -0.0 3.141592653589793"/>
      <geometry>
        <box size="42.50000000000001 48.99999237060547 150.00000762939453"/>
      </geometry>
    </collision>
  </link>
  <link name="left_thigh_v1_1">
    <inertial>
      <origin xyz="-3.483251756527389e-07 -0.028961129249142487 -0.036619318233349435" rpy="0.0 0.0 0.0"/>
      <mass value="0.02898284927838432"/>
      <inertia ixx="3.5e-05" ixy="0.0" ixz="0.0" iyy="2.1e-05" iyz="-0.0" izz="1.7e-05"/>
    </inertial>
    <visual>
      <origin xyz="-0.011569 -0.06475 0.1725" rpy="0.0 0.0 0.0"/>
      <geometry>
        <mesh filename="package://assembly_description/meshes/left_thigh_v1_1.stl" scale="0.001 0.001 0.001"/>
      </geometry>
      <material name="aluminum_satin"/>
    </visual>
    <collision>
      <origin xyz="11.557181500679016 41.43525 -208.3275" rpy="3.141592653589793 -0.0 3.141592653589793"/>
      <geometry>
        <box size="27.99999976158142 50.5 100.0"/>
      </geometry>
    </collision>
  </link>
  <link name="right_thigh_v1_1">
    <inertial>
      <origin xyz="9.832517461512424e-08 0.028961129249143854 -0.03661931823334971" rpy="0.0 0.0 0.0"/>
      <mass value="0.02898284927838432"/>
      <inertia ixx="3.5e-05" ixy="0.0" ixz="-0.0" iyy="2.1e-05" iyz="0.0" izz="1.7e-05"/>
    </inertial>
    <visual>
      <origin xyz="-0.0116 0.06475 0.1725" rpy="0.0 0.0 0.0"/>
      <geometry>
        <mesh filename="package://assembly_description/meshes/right_thigh_v1_1.stl" scale="0.001 0.001 0.001"/>
      </geometry>
      <material name="aluminum_satin"/>
    </visual>
    <collision>
      <origin xyz="11.588399904632569 -41.43525 -208.3275" rpy="3.141592653589793 -0.0 3.141592653589793"/>
      <geometry>
        <box size="28.00000095367433 50.5 100.0"/>
      </geometry>
    </collision>
  </link>
  <link name="left_hip_front_v5_1">
    <inertial>
      <origin xyz="0.04719163872713075 0.0001729815107887056 -0.01748011628225432" rpy="0.0 0.0 0.0"/>
      <mass value="0.2722002973016189"/>
      <inertia ixx="0.000107" ixy="-1e-06" ixz="1e-05" iyy="0.000233" iyz="2e-06" izz="0.000192"/>
    </inertial>
    <visual>
      <origin xyz="0.0547 -0.04125 0.1365" rpy="0.0 0.0 0.0"/>
      <geometry>
        <mesh filename="package://assembly_description/meshes/left_hip_front_v5_1.stl" scale="0.001 0.001 0.001"/>
      </geometry>
      <material name="aluminum_satin"/>
    </visual>
    <collision>
      <origin xyz="-9.492122115994706 44.208749999999995 -154.29535804541985" rpy="1.5770636862446759 6.123233995736766e-17 -1.5707963267948968"/>
      <geometry>
        <box size="49.99999999999999 65.46226440380707 96.10633227373287"/>
      </geometry>
    </collision>
  </link>
  <link name="left_calve_v5_1">
    <inertial>
      <origin xyz="-5.272168187817235e-05 -0.023766836658218507 -0.023901439852959505" rpy="0.0 0.0 0.0"/>
      <mass value="0.15898038946070936"/>
      <inertia ixx="0.000124" ixy="0.0" ixz="-0.0" iyy="0.000107" iyz="-8e-06" izz="4.4e-05"/>
    </inertial>
    <visual>
      <origin xyz="-0.011569 -0.06475 0.2445" rpy="0.0 0.0 0.0"/>
      <geometry>
        <mesh filename="package://assembly_description/meshes/left_calve_v5_1.stl" scale="0.001 0.001 0.001"/>
      </geometry>
      <material name="aluminum_satin"/>
    </visual>
    <collision>
      <origin xyz="10.85718157220459 41.99208854351798 -288.2740994138152" rpy="0.028321037544288875 6.123233995736766e-17 3.141592653589793"/>
      <geometry>
        <box size="41.600000381469734 52.02728661144463 117.27588224325463"/>
      </geometry>
    </collision>
  </link>
  <link name="left_ankle_v7_1">
    <inertial>
      <origin xyz="-0.01908804310535514 -0.023327010944413494 -0.018519883717742103" rpy="0.0 0.0 0.0"/>
      <mass value="0.2722002973016189"/>
      <inertia ixx="0.000107" ixy="-1e-06" ixz="-1e-05" iyy="0.000233" iyz="-2e-06" izz="0.000192"/>
    </inertial>
    <visual>
      <origin xyz="-0.011569 -0.06475 0.3325" rpy="0.0 0.0 0.0"/>
      <geometry>
        <mesh filename="package://assembly_description/meshes/left_ankle_v7_1.stl" scale="0.001 0.001 0.001"/>
      </geometry>
      <material name="steel_satin"/>
    </visual>
    <collision>
      <origin xyz="-8.577231610365262 44.18525000000001 -350.24185791622017" rpy="1.564531285334775 6.123233995736767e-17 -1.5707963267948968"/>
      <geometry>
        <box size="50.00000000000002 64.7393903991729 98.13104219956234"/>
      </geometry>
    </collision>
  </link>
  <link name="right_hip_front_v5_1">
    <inertial>
      <origin xyz="0.04721220689744356 -0.0001729890555860411 -0.01748011628225596" rpy="0.0 0.0 0.0"/>
      <mass value="0.2722002973016189"/>
      <inertia ixx="0.000107" ixy="1e-06" ixz="1e-05" iyy="0.000233" iyz="-2e-06" izz="0.000192"/>
    </inertial>
    <visual>
      <origin xyz="0.0547 0.04125 0.1365" rpy="0.0 0.0 0.0"/>
      <geometry>
        <mesh filename="package://assembly_description/meshes/right_hip_front_v5_1.stl" scale="0.001 0.001 0.001"/>
      </geometry>
      <material name="aluminum_satin"/>
    </visual>
    <collision>
      <origin xyz="-8.595301525878904 -44.20875000000001 -154.1091359863281" rpy="-1.5707963267948968 1.2246467991473532e-16 1.5707963267948966"/>
      <geometry>
        <box size="50.00000000000002 65.35829439495298 97.70940774550232"/>
      </geometry>
    </collision>
  </link>
  <link name="right_calve_v1_1">
    <inertial>
      <origin xyz="5.247168187765515e-05 0.02376683665821997 -0.023901439852960005" rpy="0.0 0.0 0.0"/>
      <mass value="0.15898038946070936"/>
      <inertia ixx="0.000124" ixy="0.0" ixz="0.0" iyy="0.000107" iyz="8e-06" izz="4.4e-05"/>
    </inertial>
    <visual>
      <origin xyz="-0.0116 0.06475 0.2445" rpy="0.0 0.0 0.0"/>
      <geometry>
        <mesh filename="package://assembly_description/meshes/right_calve_v1_1.stl" scale="0.001 0.001 0.001"/>
      </geometry>
      <material name="aluminum_satin"/>
    </visual>
    <collision>
      <origin xyz="12.288399237060547 -41.99208854351799 -288.2740994138152" rpy="-0.028321037544288875 6.123233995736766e-17 3.141592653589793"/>
      <geometry>
        <box size="41.599998474121094 52.02728661144462 117.27588224325463"/>
      </geometry>
    </collision>
  </link>
  <joint name="left_hip_yaw" type="continuous">
    <origin xyz="0.016 0.04125 -0.1085" rpy="0.0 0.0 0.0"/>
    <axis xyz="-0.0 -0.0 -1.0"/>
    <parent link="base_link"/>
    <child link="left_hip_side_v5_1"/>
  </joint>
  <joint name="left_ankle_roll" type="continuous">
    <origin xyz="-0.0663 -0.0235 -0.036" rpy="0.0 0.0 0.0"/>
    <axis xyz="1.0 -0.0 0.0"/>
    <parent link="left_ankle_v7_1"/>
    <child link="left_foot_v10_1"/>
  </joint>
  <joint name="left_shoulder_pitch" type="continuous">
    <origin xyz="0.003 0.084 0.04475" rpy="0.0 0.0 0.0"/>
    <axis xyz="-0.0 1.0 -0.0"/>
    <parent link="base_link"/>
    <child link="left_shoulder_v5_1"/>
  </joint>
  <joint name="left_shoulder_roll" type="continuous">
    <origin xyz="0.019 0.0303 0.0" rpy="0.0 0.0 0.0"/>
    <axis xyz="-1.0 -0.0 0.0"/>
    <parent link="left_shoulder_v5_1"/>
    <child link="left_bicep_v6_1"/>
  </joint>
  <joint name="left_elbow" type="continuous">
    <origin xyz="-0.020403 0.018801 -0.119141" rpy="0.0 0.0 0.0"/>
    <axis xyz="-0.0 1.0 -0.0"/>
    <parent link="left_bicep_v6_1"/>
    <child link="left_forearm_v4_1"/>
  </joint>
  <joint name="head_yaw" type="continuous">
    <origin xyz="0.0 0.00025 0.0725" rpy="0.0 0.0 0.0"/>
    <axis xyz="-0.0 0.0 1.0"/>
    <parent link="base_link"/>
    <child link="neck_v6_1"/>
  </joint>
  <joint name="head_pitch" type="continuous">
    <origin xyz="0.0 -0.0185 0.025" rpy="0.0 0.0 0.0"/>
    <axis xyz="0.0 -1.0 0.0"/>
    <parent link="neck_v6_1"/>
    <child link="head_v4_1"/>
  </joint>
  <joint name="right_hip_yaw" type="continuous">
    <origin xyz="0.016 -0.04125 -0.1085" rpy="0.0 0.0 0.0"/>
    <axis xyz="-0.0 0.0 -1.0"/>
    <parent link="base_link"/>
    <child link="right_hip_side_v1_1"/>
  </joint>
  <joint name="right_ankle_pitch" type="continuous">
    <origin xyz="0.0 0.0 -0.088" rpy="0.0 0.0 0.0"/>
    <axis xyz="-0.0 1.0 0.0"/>
    <parent link="right_calve_v1_1"/>
    <child link="right_ankle_v2_1"/>
  </joint>
  <joint name="right_ankle_roll" type="continuous">
    <origin xyz="-0.0663 0.0235 -0.036" rpy="0.0 0.0 0.0"/>
    <axis xyz="1.0 -0.0 0.0"/>
    <parent link="right_ankle_v2_1"/>
    <child link="right_foot_v2_1"/>
  </joint>
  <joint name="right_shoulder_pitch" type="continuous">
    <origin xyz="0.003 -0.084 0.04475" rpy="0.0 0.0 0.0"/>
    <axis xyz="-0.0 1.0 -0.0"/>
    <parent link="base_link"/>
    <child link="right_shoulder_v1_1"/>
  </joint>
  <joint name="right_shoulder_roll" type="continuous">
    <origin xyz="0.019 -0.0303 0.0" rpy="0.0 0.0 0.0"/>
    <axis xyz="1.0 0.0 -0.0"/>
    <parent link="right_shoulder_v1_1"/>
    <child link="right_bicep_v2_1"/>
  </joint>
  <joint name="right_elbow" type="continuous">
    <origin xyz="-0.019597 -0.020801 -0.119141" rpy="0.0 0.0 0.0"/>
    <axis xyz="-0.0 -1.0 0.0"/>
    <parent link="right_bicep_v2_1"/>
    <child link="right_forearm_v1_1"/>
  </joint>
  <joint name="left_hip_pitch" type="continuous">
    <origin xyz="0.066269 0.0235 -0.036" rpy="0.0 0.0 0.0"/>
    <axis xyz="-0.0 -1.0 0.0"/>
    <parent link="left_hip_front_v5_1"/>
    <child link="left_thigh_v1_1"/>
  </joint>
  <joint name="right_hip_pitch" type="continuous">
    <origin xyz="0.0663 -0.0235 -0.036" rpy="0.0 0.0 0.0"/>
    <axis xyz="-0.0 1.0 0.0"/>
    <parent link="right_hip_front_v5_1"/>
    <child link="right_thigh_v1_1"/>
  </joint>
  <joint name="left_hip_roll" type="continuous">
    <origin xyz="-0.0707 0.0 -0.028" rpy="0.0 0.0 0.0"/>
    <axis xyz="1.0 -0.0 0.0"/>
    <parent link="left_hip_side_v5_1"/>
    <child link="left_hip_front_v5_1"/>
  </joint>
  <joint name="left_knee" type="continuous">
    <origin xyz="0.0 0.0 -0.072" rpy="0.0 0.0 0.0"/>
    <axis xyz="0.0 1.0 -0.0"/>
    <parent link="left_thigh_v1_1"/>
    <child link="left_calve_v5_1"/>
  </joint>
  <joint name="left_ankle_pitch" type="continuous">
    <origin xyz="0.0 0.0 -0.088" rpy="0.0 0.0 0.0"/>
    <axis xyz="0.0 -1.0 0.0"/>
    <parent link="left_calve_v5_1"/>
    <child link="left_ankle_v7_1"/>
  </joint>
  <joint name="right_hip_roll" type="continuous">
    <origin xyz="-0.0707 0.0 -0.028" rpy="0.0 0.0 0.0"/>
    <axis xyz="1.0 -0.0 -0.0"/>
    <parent link="right_hip_side_v1_1"/>
    <child link="right_hip_front_v5_1"/>
  </joint>
  <joint name="right_knee" type="continuous">
    <origin xyz="0.0 0.0 -0.072" rpy="0.0 0.0 0.0"/>
    <axis xyz="0.0 -1.0 -0.0"/>
    <parent link="right_thigh_v1_1"/>
    <child link="right_calve_v1_1"/>
  </joint>
</robot>