<?xml version="1.0" ?>
<robot name="bez1" version="1.0">
  <material name="white">
    <color rgba="1.0 1.0 1.0 1.0"/>
  </material>
  <material name="black">
    <color rgba="0.0 0.0 0.0 1.0"/>
  </material>
  <material name="silver">
    <color rgba="0.7 0.7 0.7 1.0"/>
  </material>
  <material name="yellow">
    <color rgba="0.9 0.9 0.0 1.0"/>
  </material>
  <material name="red">
    <color rgba="0.7 0.0 0.0 1.0"/>
  </material>
  <material name="green">
    <color rgba="0.0 0.7 0.0 1.0"/>
  </material>
  <material name="blue">
    <color rgba="0.0 0.0 0.7 1.0"/>
  </material>
  <material name="purple">
    <color rgba="0.7 0.0 0.7 1.0"/>
  </material>
  <material name="cyan">
    <color rgba="0.0 0.7 0.7 1.0"/>
  </material>
  <link name="/torso">
    <inertial>
      <origin xyz="0.0082498 -0.001744 -0.0522479" rpy="0.0 0.0 0.0"/>
      <mass value="1.529"/>
      <inertia ixx="0.004323" ixy="5.549e-06" ixz="3.96e-05" iyy="0.005198" iyz="-1.509e-05" izz="0.003567"/>
    </inertial>
    <collision name="collision">
      <origin xyz="0.0 0.0 -0.052" rpy="0.0 0.0 0.0"/>
      <geometry>
        <box size="0.13 0.145 0.152"/>
      </geometry>
    </collision>
    <visual name="visual">
      <origin xyz="0.0 0.0 0.0" rpy="0.0 0.0 0.0"/>
      <geometry>
        <mesh filename="../bez1_description/meshes/torso.stl" scale="1.0 1.0 1.0"/>
      </geometry>
      <material name="black"/>
    </visual>
  </link>
  <link name="/left_bicep">
    <inertial>
      <origin xyz="0.0 0.02579 -0.04955" rpy="0.0 0.0 0.0"/>
      <mass value="0.000213"/>
      <inertia ixx="0.0002824" ixy="0.0" ixz="0.0" iyy="0.0002744" iyz="1.165e-05" izz="2.433e-05"/>
    </inertial>
    <collision name="collision">
      <origin xyz="0.0 0.0225 -0.05001" rpy="0.0 0.0 0.0"/>
      <geometry>
        <box size="0.04 0.04776 0.123"/>
      </geometry>
    </collision>
    <visual name="visual">
      <origin xyz="0.0 0.0 0.0" rpy="0.0 0.0 0.0"/>
      <geometry>
        <mesh filename="../bez1_description/meshes/left_bicep.stl" scale="1.0 1.0 1.0"/>
      </geometry>
      <material name="white"/>
    </visual>
  </link>
  <link name="/left_forearm">
    <inertial>
      <origin xyz="0.0 0.0245 -0.0546097" rpy="0.0 0.0 0.0"/>
      <mass value="0.0457"/>
      <inertia ixx="0.000113" ixy="0.0" ixz="1e-06" iyy="0.000107" iyz="0.0" izz="1.2e-05"/>
    </inertial>
    <collision name="collision">
      <origin xyz="-0.0055 0.0175 -0.06" rpy="0.0 0.0 0.0"/>
      <geometry>
        <box size="0.035 0.049 0.144"/>
      </geometry>
    </collision>
    <visual name="visual">
      <origin xyz="0.0 0.0 0.0" rpy="0.0 0.0 0.0"/>
      <geometry>
        <mesh filename="../bez1_description/meshes/left_forearm.stl" scale="1.0 1.0 1.0"/>
      </geometry>
      <material name="purple"/>
    </visual>
  </link>
  <joint name="left_arm_motor_0" type="revolute">
    <origin xyz="-0.0157 0.0725 0.0" rpy="0.0 0.0 0.0"/>
    <axis xyz="0.0 -1.0 0.0"/>
    <parent link="/torso"/>
    <child link="/left_bicep"/>
    <limit effort="1.5" lower="-1.5707963267948966" upper="3.9269908169872414" velocity="1.0"/>
    <dynamics damping="0.01" friction="0.1"/>
  </joint>
  <joint name="left_arm_motor_1" type="revolute">
    <origin xyz="0.0 0.0 -0.1" rpy="0.0 0.0 0.0"/>
    <axis xyz="0.0 -1.0 0.0"/>
    <parent link="/left_bicep"/>
    <child link="/left_forearm"/>
    <limit effort="1.5" lower="0.0" upper="3.141592653589793" velocity="1.0"/>
    <dynamics damping="0.01" friction="0.1"/>
  </joint>
  <gazebo reference="/left_forearm">
    <mu1>0.2</mu1>
    <mu2>0.2</mu2>
  </gazebo>
  <transmission name="left_arm_motor_0">
    <type>transmission_interface/SimpleTransmission</type>
    <joint name="left_arm_motor_0">
      <hardwareInterface>hardware_interface/EffortJointInterface</hardwareInterface>
    </joint>
    <actuator name="left_arm_motor_0">
      <mechanicalReduction>1.0</mechanicalReduction>
    </actuator>
  </transmission>
  <transmission name="left_arm_motor_1">
    <type>transmission_interface/SimpleTransmission</type>
    <joint name="left_arm_motor_1">
      <hardwareInterface>hardware_interface/EffortJointInterface</hardwareInterface>
    </joint>
    <actuator name="left_arm_motor_1">
      <mechanicalReduction>1.0</mechanicalReduction>
    </actuator>
  </transmission>
  <gazebo reference="/left_bicep">
    <kp>1000000000000000.0</kp>
    <kd>10000000000000.0</kd>
    <mu1>0.2</mu1>
    <mu2>0.2</mu2>
  </gazebo>
  <gazebo reference="/left_forearm">
    <kp>1000000000000000.0</kp>
    <kd>10000000000000.0</kd>
    <mu1>0.2</mu1>
    <mu2>0.2</mu2>
  </gazebo>
  <link name="/right_bicep">
    <inertial>
      <origin xyz="0.0 -0.02579 -0.04955" rpy="0.0 0.0 0.0"/>
      <mass value="0.000213"/>
      <inertia ixx="0.0002824" ixy="0.0" ixz="-0.0" iyy="0.0002744" iyz="-1.165e-05" izz="2.433e-05"/>
    </inertial>
    <collision name="collision">
      <origin xyz="0.0 -0.0225 -0.05001" rpy="0.0 0.0 0.0"/>
      <geometry>
        <box size="0.04 0.04776 0.123"/>
      </geometry>
    </collision>
    <visual name="visual">
      <origin xyz="0.0 0.0 0.0" rpy="0.0 0.0 0.0"/>
      <geometry>
        <mesh filename="../bez1_description/meshes/right_bicep.stl" scale="1.0 1.0 1.0"/>
      </geometry>
      <material name="white"/>
    </visual>
  </link>
  <link name="/right_forearm">
    <inertial>
      <origin xyz="0.0 -0.0245 -0.0546097" rpy="0.0 0.0 0.0"/>
      <mass value="0.0457"/>
      <inertia ixx="0.000113" ixy="0.0" ixz="-1e-06" iyy="0.000107" iyz="-0.0" izz="1.2e-05"/>
    </inertial>
    <collision name="collision">
      <origin xyz="-0.0055 -0.0175 -0.06" rpy="0.0 0.0 0.0"/>
      <geometry>
        <box size="0.035 0.049 0.144"/>
      </geometry>
    </collision>
    <visual name="visual">
      <origin xyz="0.0 0.0 0.0" rpy="0.0 0.0 0.0"/>
      <geometry>
        <mesh filename="../bez1_description/meshes/right_forearm.stl" scale="1.0 1.0 1.0"/>
      </geometry>
      <material name="purple"/>
    </visual>
  </link>
  <joint name="right_arm_motor_0" type="revolute">
    <origin xyz="-0.0157 -0.0725 0.0" rpy="0.0 0.0 0.0"/>
    <axis xyz="0.0 -1.0 0.0"/>
    <parent link="/torso"/>
    <child link="/right_bicep"/>
    <limit effort="1.5" lower="-1.5707963267948966" upper="3.9269908169872414" velocity="1.0"/>
    <dynamics damping="0.01" friction="0.1"/>
  </joint>
  <joint name="right_arm_motor_1" type="revolute">
    <origin xyz="0.0 0.0 -0.1" rpy="0.0 0.0 0.0"/>
    <axis xyz="0.0 -1.0 0.0"/>
    <parent link="/right_bicep"/>
    <child link="/right_forearm"/>
    <limit effort="1.5" lower="0.0" upper="3.141592653589793" velocity="1.0"/>
    <dynamics damping="0.01" friction="0.1"/>
  </joint>
  <gazebo reference="/right_forearm">
    <mu1>0.2</mu1>
    <mu2>0.2</mu2>
  </gazebo>
  <transmission name="right_arm_motor_0">
    <type>transmission_interface/SimpleTransmission</type>
    <joint name="right_arm_motor_0">
      <hardwareInterface>hardware_interface/EffortJointInterface</hardwareInterface>
    </joint>
    <actuator name="right_arm_motor_0">
      <mechanicalReduction>1.0</mechanicalReduction>
    </actuator>
  </transmission>
  <transmission name="right_arm_motor_1">
    <type>transmission_interface/SimpleTransmission</type>
    <joint name="right_arm_motor_1">
      <hardwareInterface>hardware_interface/EffortJointInterface</hardwareInterface>
    </joint>
    <actuator name="right_arm_motor_1">
      <mechanicalReduction>1.0</mechanicalReduction>
    </actuator>
  </transmission>
  <gazebo reference="/right_bicep">
    <kp>1000000000000000.0</kp>
    <kd>10000000000000.0</kd>
    <mu1>0.2</mu1>
    <mu2>0.2</mu2>
  </gazebo>
  <gazebo reference="/right_forearm">
    <kp>1000000000000000.0</kp>
    <kd>10000000000000.0</kd>
    <mu1>0.2</mu1>
    <mu2>0.2</mu2>
  </gazebo>
  <link name="/left_hip_side">
    <inertial>
      <origin xyz="0.0003695 0.0 0.01689" rpy="0.0 0.0 0.0"/>
      <mass value="0.009364"/>
      <inertia ixx="2e-06" ixy="0.0" ixz="0.0" iyy="5e-06" iyz="0.0" izz="4e-06"/>
    </inertial>
    <collision name="collision">
      <origin xyz="0.0 0.0 0.00899" rpy="0.0 0.0 0.0"/>
      <geometry>
        <box size="0.0485 0.022 0.0039"/>
      </geometry>
    </collision>
    <visual name="visual">
      <origin xyz="0.0 0.0 0.0" rpy="0.0 0.0 0.0"/>
      <geometry>
        <mesh filename="../bez1_description/meshes/left_hip_side.stl" scale="1.0 1.0 1.0"/>
      </geometry>
      <material name="cyan"/>
    </visual>
  </link>
  <link name="/left_hip_front">
    <inertial>
      <origin xyz="-0.02093 0.0 -0.011313" rpy="0.0 0.0 0.0"/>
      <mass value="0.153186"/>
      <inertia ixx="4.1e-05" ixy="0.0" ixz="-2e-06" iyy="0.000118" iyz="0.0" izz="0.000106"/>
    </inertial>
    <collision name="collision">
      <origin xyz="-0.02187 0.0 -0.01332" rpy="0.0 0.0 0.0"/>
      <geometry>
        <box size="0.083747 0.04885 0.0506"/>
      </geometry>
    </collision>
    <visual name="visual">
      <origin xyz="0.0 0.0 0.0" rpy="0.0 0.0 0.0"/>
      <geometry>
        <mesh filename="../bez1_description/meshes/left_hip_front.stl" scale="1.0 1.0 1.0"/>
      </geometry>
      <material name="blue"/>
    </visual>
  </link>
  <link name="/left_thigh">
    <inertial>
      <origin xyz="0.0019422 0.0001419 -0.0469409" rpy="0.0 0.0 0.0"/>
      <mass value="0.021438"/>
      <inertia ixx="2.5e-05" ixy="2e-06" ixz="0.0" iyy="1.6e-05" iyz="0.0" izz="1e-05"/>
    </inertial>
    <collision name="collision">
      <origin xyz="0.0 0.0 -0.0445" rpy="0.0 0.0 0.0"/>
      <geometry>
        <box size="0.022 0.048 0.111"/>
      </geometry>
    </collision>
    <visual name="visual">
      <origin xyz="0.0 0.0 0.0" rpy="0.0 0.0 0.0"/>
      <geometry>
        <mesh filename="../bez1_description/meshes/left_thigh.stl" scale="1.0 1.0 1.0"/>
      </geometry>
      <material name="red"/>
    </visual>
  </link>
  <link name="/left_calve">
    <inertial>
      <origin xyz="0.0 -3.259e-07 -1.50123e-05" rpy="0.0 0.0 0.0"/>
      <mass value="0.086547"/>
      <inertia ixx="5.4e-05" ixy="0.0" ixz="0.0" iyy="4.6e-05" iyz="-1e-06" izz="1.9e-05"/>
    </inertial>
    <collision name="collision">
      <origin xyz="0.0 0.0 -0.03385" rpy="0.0 0.0 0.0"/>
      <geometry>
        <box size="0.031883 0.048 0.105683"/>
      </geometry>
    </collision>
    <visual name="visual">
      <origin xyz="0.0 0.0 -0.0827" rpy="0.0 0.0 0.0"/>
      <geometry>
        <mesh filename="../bez1_description/meshes/left_calve.stl" scale="1.0 1.0 1.0"/>
      </geometry>
      <material name="yellow"/>
    </visual>
  </link>
  <link name="/left_ankle">
    <inertial>
      <origin xyz="-2.0939e-05 0.0 1.1313e-05" rpy="0.0 0.0 0.0"/>
      <mass value="0.153186"/>
      <inertia ixx="4.1e-05" ixy="0.0" ixz="2e-06" iyy="0.000118" iyz="0.0" izz="0.000106"/>
    </inertial>
    <collision name="collision">
      <origin xyz="-0.02014 0.0 0.01031" rpy="0.0 0.0 0.0"/>
      <geometry>
        <box size="0.090769 0.042 0.0506"/>
      </geometry>
    </collision>
    <visual name="visual">
      <origin xyz="0.0 0.0 0.0" rpy="0.0 0.0 0.0"/>
      <geometry>
        <mesh filename="../bez1_description/meshes/left_ankle.stl" scale="1.0 1.0 1.0"/>
      </geometry>
      <material name="purple"/>
    </visual>
  </link>
  <link name="/left_foot">
    <inertial>
      <origin xyz="-0.020939 0.0 0.011313" rpy="0.0 0.0 0.0"/>
      <mass value="0.023216"/>
      <inertia ixx="6e-06" ixy="0.0" ixz="0.0" iyy="1.8e-05" iyz="0.0" izz="2.2e-05"/>
    </inertial>
    <collision name="collision">
      <origin xyz="0.00385 -0.00401 -0.00737" rpy="0.0 0.0 0.0"/>
      <geometry>
        <box size="0.09 0.07 0.03674"/>
      </geometry>
    </collision>
    <visual name="visual">
      <origin xyz="0.0 0.0 0.0" rpy="0.0 0.0 0.0"/>
      <geometry>
        <mesh filename="../bez1_description/meshes/left_foot.stl" scale="1.0 1.0 1.0"/>
      </geometry>
      <material name="green"/>
    </visual>
  </link>
  <joint name="left_leg_motor_0" type="revolute">
    <origin xyz="0.0135 0.035 -0.156" rpy="0.0 0.0 0.0"/>
    <axis xyz="0.0 0.0 -1.0"/>
    <parent link="/torso"/>
    <child link="/left_hip_side"/>
    <limit effort="2.5" lower="-1.309" upper="0.524" velocity="1.0"/>
    <dynamics damping="0.01" friction="0.1"/>
  </joint>
  <joint name="left_leg_motor_1" type="revolute">
    <origin xyz="0.0 0.0 0.0" rpy="0.0 0.0 0.0"/>
    <axis xyz="1.0 0.0 0.0"/>
    <parent link="/left_hip_side"/>
    <child link="/left_hip_front"/>
    <limit effort="2.5" lower="-0.7853981633974483" upper="1.5707963267948966" velocity="1.0"/>
    <dynamics damping="0.01" friction="0.1"/>
  </joint>
  <joint name="left_leg_motor_2" type="revolute">
    <origin xyz="0.0 0.0 0.0" rpy="0.0 0.0 0.0"/>
    <axis xyz="0.0 -1.0 0.0"/>
    <parent link="/left_hip_front"/>
    <child link="/left_thigh"/>
    <limit effort="2.5" lower="-0.7853981633974483" upper="2.356194490192345" velocity="1.0"/>
    <dynamics damping="0.01" friction="0.1"/>
  </joint>
  <joint name="left_leg_motor_3" type="revolute">
    <origin xyz="0.0 0.0 -0.089" rpy="0.0 0.0 0.0"/>
    <axis xyz="0.0 -1.0 0.0"/>
    <parent link="/left_thigh"/>
    <child link="/left_calve"/>
    <limit effort="2.5" lower="-2.793" upper="0.0" velocity="1.0"/>
    <dynamics damping="0.01" friction="0.1"/>
  </joint>
  <joint name="left_leg_motor_4" type="revolute">
    <origin xyz="0.0 0.0 -0.0827" rpy="0.0 0.0 0.0"/>
    <axis xyz="0.0 -1.0 0.0"/>
    <parent link="/left_calve"/>
    <child link="/left_ankle"/>
    <limit effort="2.5" lower="-0.7853981633974483" upper="1.5707963267948966" velocity="1.0"/>
    <dynamics damping="0.01" friction="0.1"/>
  </joint>
  <joint name="left_leg_motor_5" type="revolute">
    <origin xyz="0.0 0.0 0.0" rpy="0.0 0.0 0.0"/>
    <axis xyz="1.0 0.0 0.0"/>
    <parent link="/left_ankle"/>
    <child link="/left_foot"/>
    <limit effort="2.5" lower="-0.7853981633974483" upper="0.7853981633974483" velocity="1.0"/>
    <dynamics damping="0.01" friction="0.1"/>
  </joint>
  <transmission name="left_leg_motor_0">
    <type>transmission_interface/SimpleTransmission</type>
    <joint name="left_leg_motor_0">
      <hardwareInterface>hardware_interface/EffortJointInterface</hardwareInterface>
    </joint>
    <actuator name="left_leg_motor_0">
      <mechanicalReduction>1.0</mechanicalReduction>
    </actuator>
  </transmission>
  <transmission name="left_leg_motor_1">
    <type>transmission_interface/SimpleTransmission</type>
    <joint name="left_leg_motor_1">
      <hardwareInterface>hardware_interface/EffortJointInterface</hardwareInterface>
    </joint>
    <actuator name="left_leg_motor_1">
      <mechanicalReduction>1.0</mechanicalReduction>
    </actuator>
  </transmission>
  <transmission name="left_leg_motor_2">
    <type>transmission_interface/SimpleTransmission</type>
    <joint name="left_leg_motor_2">
      <hardwareInterface>hardware_interface/EffortJointInterface</hardwareInterface>
    </joint>
    <actuator name="left_leg_motor_2">
      <mechanicalReduction>1.0</mechanicalReduction>
    </actuator>
  </transmission>
  <transmission name="left_leg_motor_3">
    <type>transmission_interface/SimpleTransmission</type>
    <joint name="left_leg_motor_3">
      <hardwareInterface>hardware_interface/EffortJointInterface</hardwareInterface>
    </joint>
    <actuator name="left_leg_motor_3">
      <mechanicalReduction>1.0</mechanicalReduction>
    </actuator>
  </transmission>
  <transmission name="left_leg_motor_4">
    <type>transmission_interface/SimpleTransmission</type>
    <joint name="left_leg_motor_4">
      <hardwareInterface>hardware_interface/EffortJointInterface</hardwareInterface>
    </joint>
    <actuator name="left_leg_motor_4">
      <mechanicalReduction>1.0</mechanicalReduction>
    </actuator>
  </transmission>
  <transmission name="left_leg_motor_5">
    <type>transmission_interface/SimpleTransmission</type>
    <joint name="left_leg_motor_5">
      <hardwareInterface>hardware_interface/EffortJointInterface</hardwareInterface>
    </joint>
    <actuator name="left_leg_motor_5">
      <mechanicalReduction>1.0</mechanicalReduction>
    </actuator>
  </transmission>
  <gazebo reference="/left_hip_side">
    <kp>1000000000000000.0</kp>
    <kd>10000000000000.0</kd>
    <mu1>0.2</mu1>
    <mu2>0.2</mu2>
  </gazebo>
  <gazebo reference="/left_hip_front">
    <kp>1000000000000000.0</kp>
    <kd>10000000000000.0</kd>
    <mu1>0.2</mu1>
    <mu2>0.2</mu2>
  </gazebo>
  <gazebo reference="/left_thigh">
    <kp>1000000000000000.0</kp>
    <kd>10000000000000.0</kd>
    <mu1>0.2</mu1>
    <mu2>0.2</mu2>
  </gazebo>
  <gazebo reference="/left_calve">
    <kp>1000000000000000.0</kp>
    <kd>10000000000000.0</kd>
    <mu1>0.2</mu1>
    <mu2>0.2</mu2>
  </gazebo>
  <gazebo reference="/left_ankle">
    <kp>1000000000000000.0</kp>
    <kd>10000000000000.0</kd>
    <mu1>0.2</mu1>
    <mu2>0.2</mu2>
  </gazebo>
  <gazebo reference="/left_foot">
    <mu1>0.2</mu1>
    <mu2>0.2</mu2>
  </gazebo>
  <link name="/right_hip_side">
    <inertial>
      <origin xyz="0.0003695 0.0 0.01689" rpy="0.0 0.0 0.0"/>
      <mass value="0.009364"/>
      <inertia ixx="2e-06" ixy="0.0" ixz="0.0" iyy="5e-06" iyz="0.0" izz="4e-06"/>
    </inertial>
    <collision name="collision">
      <origin xyz="0.0 0.0 0.00899" rpy="0.0 0.0 0.0"/>
      <geometry>
        <box size="0.0485 0.022 0.0039"/>
      </geometry>
    </collision>
    <visual name="visual">
      <origin xyz="0.0 0.0 0.0" rpy="0.0 0.0 0.0"/>
      <geometry>
        <mesh filename="../bez1_description/meshes/right_hip_side.stl" scale="1.0 1.0 1.0"/>
      </geometry>
      <material name="cyan"/>
    </visual>
  </link>
  <link name="/right_hip_front">
    <inertial>
      <origin xyz="-0.02093 0.0 -0.011313" rpy="0.0 0.0 0.0"/>
      <mass value="0.153186"/>
      <inertia ixx="4.1e-05" ixy="0.0" ixz="-2e-06" iyy="0.000118" iyz="0.0" izz="0.000106"/>
    </inertial>
    <collision name="collision">
      <origin xyz="-0.02187 0.0 -0.01332" rpy="0.0 0.0 0.0"/>
      <geometry>
        <box size="0.083747 0.04885 0.0506"/>
      </geometry>
    </collision>
    <visual name="visual">
      <origin xyz="0.0 0.0 0.0" rpy="0.0 0.0 0.0"/>
      <geometry>
        <mesh filename="../bez1_description/meshes/right_hip_front.stl" scale="1.0 1.0 1.0"/>
      </geometry>
      <material name="blue"/>
    </visual>
  </link>
  <link name="/right_thigh">
    <inertial>
      <origin xyz="0.0019422 -0.0001419 -0.0469409" rpy="0.0 0.0 0.0"/>
      <mass value="0.021438"/>
      <inertia ixx="2.5e-05" ixy="-2e-06" ixz="0.0" iyy="1.6e-05" iyz="0.0" izz="1e-05"/>
    </inertial>
    <collision name="collision">
      <origin xyz="0.0 0.0 -0.0445" rpy="0.0 0.0 0.0"/>
      <geometry>
        <box size="0.022 0.048 0.111"/>
      </geometry>
    </collision>
    <visual name="visual">
      <origin xyz="0.0 0.0 0.0" rpy="0.0 0.0 0.0"/>
      <geometry>
        <mesh filename="../bez1_description/meshes/right_thigh.stl" scale="1.0 1.0 1.0"/>
      </geometry>
      <material name="red"/>
    </visual>
  </link>
  <link name="/right_calve">
    <inertial>
      <origin xyz="0.0 3.259e-07 -1.50123e-05" rpy="0.0 0.0 0.0"/>
      <mass value="0.086547"/>
      <inertia ixx="5.4e-05" ixy="0.0" ixz="0.0" iyy="4.6e-05" iyz="-1e-06" izz="1.9e-05"/>
    </inertial>
    <collision name="collision">
      <origin xyz="0.0 0.0 -0.03385" rpy="0.0 0.0 0.0"/>
      <geometry>
        <box size="0.031883 0.048 0.105683"/>
      </geometry>
    </collision>
    <visual name="visual">
      <origin xyz="0.0 0.0 -0.0827" rpy="0.0 0.0 0.0"/>
      <geometry>
        <mesh filename="../bez1_description/meshes/right_calve.stl" scale="1.0 1.0 1.0"/>
      </geometry>
      <material name="yellow"/>
    </visual>
  </link>
  <link name="/right_ankle">
    <inertial>
      <origin xyz="-2.0939e-05 0.0 1.1313e-05" rpy="0.0 0.0 0.0"/>
      <mass value="0.153186"/>
      <inertia ixx="4.1e-05" ixy="0.0" ixz="2e-06" iyy="0.000118" iyz="0.0" izz="0.000106"/>
    </inertial>
    <collision name="collision">
      <origin xyz="-0.02014 0.0 0.01031" rpy="0.0 0.0 0.0"/>
      <geometry>
        <box size="0.090769 0.042 0.0506"/>
      </geometry>
    </collision>
    <visual name="visual">
      <origin xyz="0.0 0.0 0.0" rpy="0.0 0.0 0.0"/>
      <geometry>
        <mesh filename="../bez1_description/meshes/right_ankle.stl" scale="1.0 1.0 1.0"/>
      </geometry>
      <material name="purple"/>
    </visual>
  </link>
  <link name="/right_foot">
    <inertial>
      <origin xyz="-0.020939 0.0 0.011313" rpy="0.0 0.0 0.0"/>
      <mass value="0.023216"/>
      <inertia ixx="6e-06" ixy="0.0" ixz="0.0" iyy="1.8e-05" iyz="0.0" izz="2.2e-05"/>
    </inertial>
    <collision name="collision">
      <origin xyz="0.00385 0.00401 -0.00737" rpy="0.0 0.0 0.0"/>
      <geometry>
        <box size="0.09 0.07 0.03674"/>
      </geometry>
    </collision>
    <visual name="visual">
      <origin xyz="0.0 0.0 0.0" rpy="0.0 0.0 0.0"/>
      <geometry>
        <mesh filename="../bez1_description/meshes/right_foot.stl" scale="1.0 1.0 1.0"/>
      </geometry>
      <material name="green"/>
    </visual>
  </link>
  <joint name="right_leg_motor_0" type="revolute">
    <origin xyz="0.0135 -0.035 -0.156" rpy="0.0 0.0 0.0"/>
    <axis xyz="0.0 0.0 1.0"/>
    <parent link="/torso"/>
    <child link="/right_hip_side"/>
    <limit effort="2.5" lower="-1.309" upper="0.524" velocity="1.0"/>
    <dynamics damping="0.01" friction="0.1"/>
  </joint>
  <joint name="right_leg_motor_1" type="revolute">
    <origin xyz="0.0 0.0 0.0" rpy="0.0 0.0 0.0"/>
    <axis xyz="-1.0 0.0 0.0"/>
    <parent link="/right_hip_side"/>
    <child link="/right_hip_front"/>
    <limit effort="2.5" lower="-0.7853981633974483" upper="1.5707963267948966" velocity="1.0"/>
    <dynamics damping="0.01" friction="0.1"/>
  </joint>
  <joint name="right_leg_motor_2" type="revolute">
    <origin xyz="0.0 0.0 0.0" rpy="0.0 0.0 0.0"/>
    <axis xyz="0.0 -1.0 0.0"/>
    <parent link="/right_hip_front"/>
    <child link="/right_thigh"/>
    <limit effort="2.5" lower="-0.7853981633974483" upper="2.356194490192345" velocity="1.0"/>
    <dynamics damping="0.01" friction="0.1"/>
  </joint>
  <joint name="right_leg_motor_3" type="revolute">
    <origin xyz="0.0 0.0 -0.089" rpy="0.0 0.0 0.0"/>
    <axis xyz="0.0 -1.0 0.0"/>
    <parent link="/right_thigh"/>
    <child link="/right_calve"/>
    <limit effort="2.5" lower="-2.793" upper="0.0" velocity="1.0"/>
    <dynamics damping="0.01" friction="0.1"/>
  </joint>
  <joint name="right_leg_motor_4" type="revolute">
    <origin xyz="0.0 0.0 -0.0827" rpy="0.0 0.0 0.0"/>
    <axis xyz="0.0 -1.0 0.0"/>
    <parent link="/right_calve"/>
    <child link="/right_ankle"/>
    <limit effort="2.5" lower="-0.7853981633974483" upper="1.5707963267948966" velocity="1.0"/>
    <dynamics damping="0.01" friction="0.1"/>
  </joint>
  <joint name="right_leg_motor_5" type="revolute">
    <origin xyz="0.0 0.0 0.0" rpy="0.0 0.0 0.0"/>
    <axis xyz="-1.0 0.0 0.0"/>
    <parent link="/right_ankle"/>
    <child link="/right_foot"/>
    <limit effort="2.5" lower="-0.7853981633974483" upper="0.7853981633974483" velocity="1.0"/>
    <dynamics damping="0.01" friction="0.1"/>
  </joint>
  <transmission name="right_leg_motor_0">
    <type>transmission_interface/SimpleTransmission</type>
    <joint name="right_leg_motor_0">
      <hardwareInterface>hardware_interface/EffortJointInterface</hardwareInterface>
    </joint>
    <actuator name="right_leg_motor_0">
      <mechanicalReduction>1.0</mechanicalReduction>
    </actuator>
  </transmission>
  <transmission name="right_leg_motor_1">
    <type>transmission_interface/SimpleTransmission</type>
    <joint name="right_leg_motor_1">
      <hardwareInterface>hardware_interface/EffortJointInterface</hardwareInterface>
    </joint>
    <actuator name="right_leg_motor_1">
      <mechanicalReduction>1.0</mechanicalReduction>
    </actuator>
  </transmission>
  <transmission name="right_leg_motor_2">
    <type>transmission_interface/SimpleTransmission</type>
    <joint name="right_leg_motor_2">
      <hardwareInterface>hardware_interface/EffortJointInterface</hardwareInterface>
    </joint>
    <actuator name="right_leg_motor_2">
      <mechanicalReduction>1.0</mechanicalReduction>
    </actuator>
  </transmission>
  <transmission name="right_leg_motor_3">
    <type>transmission_interface/SimpleTransmission</type>
    <joint name="right_leg_motor_3">
      <hardwareInterface>hardware_interface/EffortJointInterface</hardwareInterface>
    </joint>
    <actuator name="right_leg_motor_3">
      <mechanicalReduction>1.0</mechanicalReduction>
    </actuator>
  </transmission>
  <transmission name="right_leg_motor_4">
    <type>transmission_interface/SimpleTransmission</type>
    <joint name="right_leg_motor_4">
      <hardwareInterface>hardware_interface/EffortJointInterface</hardwareInterface>
    </joint>
    <actuator name="right_leg_motor_4">
      <mechanicalReduction>1.0</mechanicalReduction>
    </actuator>
  </transmission>
  <transmission name="right_leg_motor_5">
    <type>transmission_interface/SimpleTransmission</type>
    <joint name="right_leg_motor_5">
      <hardwareInterface>hardware_interface/EffortJointInterface</hardwareInterface>
    </joint>
    <actuator name="right_leg_motor_5">
      <mechanicalReduction>1.0</mechanicalReduction>
    </actuator>
  </transmission>
  <gazebo reference="/right_hip_side">
    <kp>1000000000000000.0</kp>
    <kd>10000000000000.0</kd>
    <mu1>0.2</mu1>
    <mu2>0.2</mu2>
  </gazebo>
  <gazebo reference="/right_hip_front">
    <kp>1000000000000000.0</kp>
    <kd>10000000000000.0</kd>
    <mu1>0.2</mu1>
    <mu2>0.2</mu2>
  </gazebo>
  <gazebo reference="/right_thigh">
    <kp>1000000000000000.0</kp>
    <kd>10000000000000.0</kd>
    <mu1>0.2</mu1>
    <mu2>0.2</mu2>
  </gazebo>
  <gazebo reference="/right_calve">
    <kp>1000000000000000.0</kp>
    <kd>10000000000000.0</kd>
    <mu1>0.2</mu1>
    <mu2>0.2</mu2>
  </gazebo>
  <gazebo reference="/right_ankle">
    <kp>1000000000000000.0</kp>
    <kd>10000000000000.0</kd>
    <mu1>0.2</mu1>
    <mu2>0.2</mu2>
  </gazebo>
  <gazebo reference="/right_foot">
    <mu1>0.2</mu1>
    <mu2>0.2</mu2>
  </gazebo>
  <link name="/neck">
    <inertial>
      <origin xyz="0.0 -0.0006476 0.0092453" rpy="0.0 0.0 0.0"/>
      <mass value="0.011294"/>
      <inertia ixx="5.489e-06" ixy="0.0" ixz="0.0" iyy="1.433e-06" iyz="0.0" izz="4.955e-06"/>
    </inertial>
    <collision name="collision">
      <origin xyz="0.0 0.0 0.0165" rpy="0.0 0.0 0.0"/>
      <geometry>
        <box size="0.022 0.0523 0.033"/>
      </geometry>
    </collision>
    <visual name="visual">
      <origin xyz="0.0 0.0 0.0" rpy="0.0 0.0 0.0"/>
      <geometry>
        <mesh filename="../bez1_description/meshes/neck.stl" scale="1.0 1.0 1.0"/>
      </geometry>
      <material name="silver"/>
    </visual>
  </link>
  <link name="/head">
    <inertial>
      <origin xyz="0.0237166 0.0018096 0.0255966" rpy="0.0 0.0 0.0"/>
      <mass value="0.282"/>
      <inertia ixx="0.000206" ixy="1.06e-06" ixz="-5.73e-05" iyy="0.0002057" iyz="2.534e-06" izz="0.0001603"/>
    </inertial>
    <collision name="collision">
      <origin xyz="-0.013 0.0 0.025" rpy="0.0 0.0 0.0"/>
      <geometry>
        <box size="0.0712 0.094 0.0779"/>
      </geometry>
    </collision>
    <visual name="visual">
      <origin xyz="0.0 0.0 0.0" rpy="0.0 0.0 0.0"/>
      <geometry>
        <mesh filename="../bez1_description/meshes/head.stl" scale="1.0 1.0 1.0"/>
      </geometry>
      <material name="silver"/>
    </visual>
  </link>
  <joint name="head_motor_0" type="revolute">
    <origin xyz="0.024 0.0 0.05875" rpy="0.0 0.0 0.0"/>
    <axis xyz="0.0 0.0 1.0"/>
    <parent link="/torso"/>
    <child link="/neck"/>
    <limit effort="1.5" lower="-1.5707963267948966" upper="1.5707963267948966" velocity="1.0"/>
    <dynamics damping="0.01" friction="0.1"/>
  </joint>
  <joint name="head_motor_1" type="revolute">
    <origin xyz="0.0 0.0 0.024" rpy="0.0 0.0 0.0"/>
    <axis xyz="0.0 1.0 0.0"/>
    <parent link="/neck"/>
    <child link="/head"/>
    <limit effort="1.5" lower="-2.356194490192345" upper="2.356194490192345" velocity="1.0"/>
    <dynamics damping="0.01" friction="0.1"/>
  </joint>
  <transmission name="head_motor_0">
    <type>transmission_interface/SimpleTransmission</type>
    <joint name="head_motor_0">
      <hardwareInterface>hardware_interface/EffortJointInterface</hardwareInterface>
    </joint>
    <actuator name="head_motor_0">
      <mechanicalReduction>1.0</mechanicalReduction>
    </actuator>
  </transmission>
  <transmission name="head_motor_1">
    <type>transmission_interface/SimpleTransmission</type>
    <joint name="head_motor_1">
      <hardwareInterface>hardware_interface/EffortJointInterface</hardwareInterface>
    </joint>
    <actuator name="head_motor_1">
      <mechanicalReduction>1.0</mechanicalReduction>
    </actuator>
  </transmission>
  <gazebo reference="/neck">
    <kp>1000000000000000.0</kp>
    <kd>10000000000000.0</kd>
    <mu1>0.2</mu1>
    <mu2>0.2</mu2>
  </gazebo>
  <gazebo reference="/head">
    <kp>1000000000000000.0</kp>
    <kd>10000000000000.0</kd>
    <mu1>0.2</mu1>
    <mu2>0.2</mu2>
  </gazebo>
  <link name="/imu_link">
    <inertial>
      <origin xyz="0.0 0.0 0.0" rpy="0.0 0.0 0.0"/>
      <mass value="0.01"/>
      <inertia ixx="1e-09" ixy="0.0" ixz="0.0" iyy="1e-09" iyz="0.0" izz="1e-09"/>
    </inertial>
  </link>
  <joint name="/torso_imu" type="fixed">
    <origin xyz="0.0 0.0 0.0" rpy="0.0 0.0 0.0"/>
    <axis xyz="0.0 0.0 0.0"/>
    <parent link="/torso"/>
    <child link="/imu_link"/>
  </joint>
  <gazebo reference="/imu_link">
    <gravity>true</gravity>
    <sensor name="imu_sensor" type="imu">
      <always_on>true</always_on>
      <update_rate>100</update_rate>
      <visualize>true</visualize>
      <topic>__default_topic__</topic>
      <plugin filename="libgazebo_ros_imu_sensor.so" name="imu_plugin">
        <topicName>imu_raw</topicName>
        <bodyName>imu_link</bodyName>
        <updateRateHZ>50.0</updateRateHZ>
        <gaussianNoise>0.0</gaussianNoise>
        <xyzOffset>0 0 0</xyzOffset>
        <rpyOffset>0 0 0</rpyOffset>
        <frameName>imu_link</frameName>
      </plugin>
      <pose>0 0 0 0 0 0</pose>
    </sensor>
  </gazebo>
  <gazebo reference="/imu_link">
    <kp>1000000000000000.0</kp>
    <kd>10000000000000.0</kd>
    <mu1>0.2</mu1>
    <mu2>0.2</mu2>
  </gazebo>
  <link name="/camera">
    <inertial>
      <origin xyz="0.0 0.0 0.0" rpy="0.0 0.0 0.0"/>
      <mass value="0.01"/>
      <inertia ixx="1e-09" ixy="0.0" ixz="0.0" iyy="1e-09" iyz="0.0" izz="1e-09"/>
    </inertial>
  </link>
  <joint name="/head_camera" type="fixed">
    <origin xyz="0.015 0.00145 0.0474" rpy="0.0 0.0 0.0"/>
    <axis xyz="0.0 0.0 0.0"/>
    <parent link="/head"/>
    <child link="/camera"/>
    <limit effort="0.0" lower="0.0" upper="0.0" velocity="0.0"/>
    <dynamics damping="0.01" friction="0.1"/>
  </joint>
  <gazebo reference="/camera">
    <sensor name="main_camera" type="camera">
      <always_on>1</always_on>
      <visualize>1</visualize>
      <update_rate>30</update_rate>
      <camera>
        <horizontal_fov>1.39626</horizontal_fov>
        <image>
          <width>640</width>
          <height>480</height>
          <format>R8G8B8</format>
        </image>
        <clip>
          <near>0.2</near>
          <far>10</far>
        </clip>
        <noise>
          <type>gaussian</type>
          <mean>0</mean>
          <stddev>0.007</stddev>
        </noise>
      </camera>
      <plugin filename="libgazebo_ros_camera.so" name="camera_controller">
        <alwaysOn>true</alwaysOn>
        <updateRate>0.0</updateRate>
        <cameraName>camera</cameraName>
        <imageTopicName>image_raw</imageTopicName>
        <cameraInfoTopicName>camera_info</cameraInfoTopicName>
        <frameName>camera_link</frameName>
        <hackBaseline>0.07</hackBaseline>
        <distortionK1>0.0</distortionK1>
        <distortionK2>0.0</distortionK2>
        <distortionK3>0.0</distortionK3>
        <distortionT1>0.0</distortionT1>
        <distortionT2>0.0</distortionT2>
      </plugin>
    </sensor>
  </gazebo>
  <gazebo reference="/camera">
    <kp>1000000000000000.0</kp>
    <kd>10000000000000.0</kd>
    <mu1>0.2</mu1>
    <mu2>0.2</mu2>
  </gazebo>
  <gazebo>
    <plugin filename="libgazebo_ros_control.so" name="gazebo_ros_control">
      <robotNamespace>/</robotNamespace>
      <robotSimType>gazebo_ros_control/DefaultRobotHWSim</robotSimType>
    </plugin>
    <plugin filename="libgazebo_ros_p3d.so" name="p3d_base_controller">
      <alwaysOn>true</alwaysOn>
      <updateRate>50.0</updateRate>
      <bodyName>base_footprint</bodyName>
      <topicName>odom_ground_truth</topicName>
      <gaussianNoise>0.01</gaussianNoise>
      <frameName>world</frameName>
      <xyzOffsets>0 0 0</xyzOffsets>
      <rpyOffsets>0 0 0</rpyOffsets>
    </plugin>
  </gazebo>
  <gazebo reference="/torso">
    <kp>1000000000000000.0</kp>
    <kd>10000000000000.0</kd>
    <mu1>0.2</mu1>
    <mu2>0.2</mu2>
  </gazebo>
</robot>
