<?xml version="1.0" ?>
<robot name="bez3" version="1.0">
  <material name="silver_default">
    <color rgba="0.7 0.7 0.7 1.0"/>
  </material>
  <material name="steel_satin">
    <color rgba="0.6274509803921569 0.6274509803921569 0.6274509803921569 1.0"/>
  </material>
  <material name="plastic_matte_black">
    <color rgba="0.09803921568627451 0.09803921568627451 0.09803921568627451 1.0"/>
  </material>
  <material name="plastic_glossy_black">
    <color rgba="0.9058823529411765 0.0 0.0 1.0"/>
  </material>
  <material name="aluminum_satin">
    <color rgba="0.9607843137254902 0.9607843137254902 0.9647058823529412 1.0"/>
  </material>
  <material name="plastic_glossy_grey">
    <color rgba="0.2901960784313726 0.2901960784313726 0.2901960784313726 1.0"/>
  </material>
  <material name="polymide_kapton">
    <color rgba="0.7843137254901961 0.5568627450980392 0.027450980392156862 1.0"/>
  </material>
  <material name="plastic_matte_blue">
    <color rgba="0.1607843137254902 0.5058823529411764 0.807843137254902 1.0"/>
  </material>
  <transmission name="left_leg_motor_0_tran">
    <type>transmission_interface/SimpleTransmission</type>
    <joint name="left_leg_motor_0">
      <hardwareInterface>hardware_interface/EffortJointInterface</hardwareInterface>
    </joint>
    <actuator name="left_leg_motor_0_actr">
      <mechanicalReduction>1.0</mechanicalReduction>
    </actuator>
  </transmission>
  <transmission name="left_leg_motor_1_tran">
    <type>transmission_interface/SimpleTransmission</type>
    <joint name="left_leg_motor_1">
      <hardwareInterface>hardware_interface/EffortJointInterface</hardwareInterface>
    </joint>
    <actuator name="left_leg_motor_1_actr">
      <mechanicalReduction>1.0</mechanicalReduction>
    </actuator>
  </transmission>
  <transmission name="left_leg_motor_2_tran">
    <type>transmission_interface/SimpleTransmission</type>
    <joint name="left_leg_motor_2">
      <hardwareInterface>hardware_interface/EffortJointInterface</hardwareInterface>
    </joint>
    <actuator name="left_leg_motor_2_actr">
      <mechanicalReduction>1.0</mechanicalReduction>
    </actuator>
  </transmission>
  <transmission name="left_leg_motor_3_tran">
    <type>transmission_interface/SimpleTransmission</type>
    <joint name="left_leg_motor_3">
      <hardwareInterface>hardware_interface/EffortJointInterface</hardwareInterface>
    </joint>
    <actuator name="left_leg_motor_3_actr">
      <mechanicalReduction>1.0</mechanicalReduction>
    </actuator>
  </transmission>
  <transmission name="left_leg_motor_4_tran">
    <type>transmission_interface/SimpleTransmission</type>
    <joint name="left_leg_motor_4">
      <hardwareInterface>hardware_interface/EffortJointInterface</hardwareInterface>
    </joint>
    <actuator name="left_leg_motor_4_actr">
      <mechanicalReduction>1.0</mechanicalReduction>
    </actuator>
  </transmission>
  <transmission name="left_leg_motor_5_tran">
    <type>transmission_interface/SimpleTransmission</type>
    <joint name="left_leg_motor_5">
      <hardwareInterface>hardware_interface/EffortJointInterface</hardwareInterface>
    </joint>
    <actuator name="left_leg_motor_5_actr">
      <mechanicalReduction>1.0</mechanicalReduction>
    </actuator>
  </transmission>
  <transmission name="right_leg_motor_0_tran">
    <type>transmission_interface/SimpleTransmission</type>
    <joint name="right_leg_motor_0">
      <hardwareInterface>hardware_interface/EffortJointInterface</hardwareInterface>
    </joint>
    <actuator name="right_leg_motor_0_actr">
      <mechanicalReduction>1.0</mechanicalReduction>
    </actuator>
  </transmission>
  <transmission name="right_leg_motor_1_tran">
    <type>transmission_interface/SimpleTransmission</type>
    <joint name="right_leg_motor_1">
      <hardwareInterface>hardware_interface/EffortJointInterface</hardwareInterface>
    </joint>
    <actuator name="right_leg_motor_1_actr">
      <mechanicalReduction>1.0</mechanicalReduction>
    </actuator>
  </transmission>
  <transmission name="right_leg_motor_2_tran">
    <type>transmission_interface/SimpleTransmission</type>
    <joint name="right_leg_motor_2">
      <hardwareInterface>hardware_interface/EffortJointInterface</hardwareInterface>
    </joint>
    <actuator name="right_leg_motor_2_actr">
      <mechanicalReduction>1.0</mechanicalReduction>
    </actuator>
  </transmission>
  <transmission name="right_leg_motor_3_tran">
    <type>transmission_interface/SimpleTransmission</type>
    <joint name="right_leg_motor_3">
      <hardwareInterface>hardware_interface/EffortJointInterface</hardwareInterface>
    </joint>
    <actuator name="right_leg_motor_3_actr">
      <mechanicalReduction>1.0</mechanicalReduction>
    </actuator>
  </transmission>
  <transmission name="right_leg_motor_4_tran">
    <type>transmission_interface/SimpleTransmission</type>
    <joint name="right_leg_motor_4">
      <hardwareInterface>hardware_interface/EffortJointInterface</hardwareInterface>
    </joint>
    <actuator name="right_leg_motor_4_actr">
      <mechanicalReduction>1.0</mechanicalReduction>
    </actuator>
  </transmission>
  <transmission name="right_leg_motor_5_tran">
    <type>transmission_interface/SimpleTransmission</type>
    <joint name="right_leg_motor_5">
      <hardwareInterface>hardware_interface/EffortJointInterface</hardwareInterface>
    </joint>
    <actuator name="right_leg_motor_5_actr">
      <mechanicalReduction>1.0</mechanicalReduction>
    </actuator>
  </transmission>
  <transmission name="left_arm_motor_0_tran">
    <type>transmission_interface/SimpleTransmission</type>
    <joint name="left_arm_motor_0">
      <hardwareInterface>hardware_interface/EffortJointInterface</hardwareInterface>
    </joint>
    <actuator name="left_arm_motor_0_actr">
      <mechanicalReduction>1.0</mechanicalReduction>
    </actuator>
  </transmission>
  <transmission name="left_arm_motor_1_tran">
    <type>transmission_interface/SimpleTransmission</type>
    <joint name="left_arm_motor_1">
      <hardwareInterface>hardware_interface/EffortJointInterface</hardwareInterface>
    </joint>
    <actuator name="left_arm_motor_1_actr">
      <mechanicalReduction>1.0</mechanicalReduction>
    </actuator>
  </transmission>
  <transmission name="right_arm_motor_0_tran">
    <type>transmission_interface/SimpleTransmission</type>
    <joint name="right_arm_motor_0">
      <hardwareInterface>hardware_interface/EffortJointInterface</hardwareInterface>
    </joint>
    <actuator name="right_arm_motor_0_actr">
      <mechanicalReduction>1.0</mechanicalReduction>
    </actuator>
  </transmission>
  <transmission name="right_arm_motor_1_tran">
    <type>transmission_interface/SimpleTransmission</type>
    <joint name="right_arm_motor_1">
      <hardwareInterface>hardware_interface/EffortJointInterface</hardwareInterface>
    </joint>
    <actuator name="right_arm_motor_1_actr">
      <mechanicalReduction>1.0</mechanicalReduction>
    </actuator>
  </transmission>
  <transmission name="head_motor_0_tran">
    <type>transmission_interface/SimpleTransmission</type>
    <joint name="head_motor_0">
      <hardwareInterface>hardware_interface/EffortJointInterface</hardwareInterface>
    </joint>
    <actuator name="head_motor_0_actr">
      <mechanicalReduction>1.0</mechanicalReduction>
    </actuator>
  </transmission>
  <transmission name="head_motor_1_tran">
    <type>transmission_interface/SimpleTransmission</type>
    <joint name="head_motor_1">
      <hardwareInterface>hardware_interface/EffortJointInterface</hardwareInterface>
    </joint>
    <actuator name="head_motor_1_actr">
      <mechanicalReduction>1.0</mechanicalReduction>
    </actuator>
  </transmission>
  <transmission name="camera_joint_tran">
    <type>transmission_interface/SimpleTransmission</type>
    <joint name="camera_joint">
      <hardwareInterface>hardware_interface/EffortJointInterface</hardwareInterface>
    </joint>
    <actuator name="camera_joint_actr">
      <mechanicalReduction>1.0</mechanicalReduction>
    </actuator>
  </transmission>
  <transmission name="imu_joint_tran">
    <type>transmission_interface/SimpleTransmission</type>
    <joint name="imu_joint">
      <hardwareInterface>hardware_interface/EffortJointInterface</hardwareInterface>
    </joint>
    <actuator name="imu_joint_actr">
      <mechanicalReduction>1.0</mechanicalReduction>
    </actuator>
  </transmission>
  <gazebo>
    <plugin filename="libgazebo_ros_control.so" name="control"/>
  </gazebo>
  <gazebo reference="base_link">
    <material>Gazebo/Silver</material>
    <mu1>0.2</mu1>
    <mu2>0.2</mu2>
    <selfCollide>true</selfCollide>
    <gravity>true</gravity>
  </gazebo>
  <gazebo reference="torso_1">
    <material>Gazebo/Silver</material>
    <mu1>0.2</mu1>
    <mu2>0.2</mu2>
    <selfCollide>true</selfCollide>
  </gazebo>
  <gazebo reference="JX_servo_v12_1">
    <material>Gazebo/Silver</material>
    <mu1>0.2</mu1>
    <mu2>0.2</mu2>
    <selfCollide>true</selfCollide>
  </gazebo>
  <gazebo reference="left_hip_side_1">
    <material>Gazebo/Silver</material>
    <mu1>0.2</mu1>
    <mu2>0.2</mu2>
    <selfCollide>true</selfCollide>
  </gazebo>
  <gazebo reference="JX_servo_v12_8">
    <material>Gazebo/Silver</material>
    <mu1>0.2</mu1>
    <mu2>0.2</mu2>
    <selfCollide>true</selfCollide>
  </gazebo>
  <gazebo reference="left_hip_front_1">
    <material>Gazebo/Silver</material>
    <mu1>0.2</mu1>
    <mu2>0.2</mu2>
    <selfCollide>true</selfCollide>
  </gazebo>
  <gazebo reference="JX_servo_v12_9">
    <material>Gazebo/Silver</material>
    <mu1>0.2</mu1>
    <mu2>0.2</mu2>
    <selfCollide>true</selfCollide>
  </gazebo>
  <gazebo reference="left_thigh_1">
    <material>Gazebo/Silver</material>
    <mu1>0.2</mu1>
    <mu2>0.2</mu2>
    <selfCollide>true</selfCollide>
  </gazebo>
  <gazebo reference="JX_servo_v12_11">
    <material>Gazebo/Silver</material>
    <mu1>0.2</mu1>
    <mu2>0.2</mu2>
    <selfCollide>true</selfCollide>
  </gazebo>
  <gazebo reference="left_calve_1">
    <material>Gazebo/Silver</material>
    <mu1>0.2</mu1>
    <mu2>0.2</mu2>
    <selfCollide>true</selfCollide>
  </gazebo>
  <gazebo reference="JX_servo_v12_12">
    <material>Gazebo/Silver</material>
    <mu1>0.2</mu1>
    <mu2>0.2</mu2>
    <selfCollide>true</selfCollide>
  </gazebo>
  <gazebo reference="left_hip_front_2">
    <material>Gazebo/Silver</material>
    <mu1>0.2</mu1>
    <mu2>0.2</mu2>
    <selfCollide>true</selfCollide>
  </gazebo>
  <gazebo reference="JX_servo_v12_13">
    <material>Gazebo/Silver</material>
    <mu1>0.2</mu1>
    <mu2>0.2</mu2>
    <selfCollide>true</selfCollide>
  </gazebo>
  <gazebo reference="left_foot_1">
    <material>Gazebo/Silver</material>
    <mu1>0.2</mu1>
    <mu2>0.2</mu2>
    <selfCollide>true</selfCollide>
  </gazebo>
  <gazebo reference="JX_servo_v12_14">
    <material>Gazebo/Silver</material>
    <mu1>0.2</mu1>
    <mu2>0.2</mu2>
    <selfCollide>true</selfCollide>
  </gazebo>
  <gazebo reference="right_hip_side_1">
    <material>Gazebo/Silver</material>
    <mu1>0.2</mu1>
    <mu2>0.2</mu2>
    <selfCollide>true</selfCollide>
  </gazebo>
  <gazebo reference="JX_servo_v12_15">
    <material>Gazebo/Silver</material>
    <mu1>0.2</mu1>
    <mu2>0.2</mu2>
    <selfCollide>true</selfCollide>
  </gazebo>
  <gazebo reference="right_ankle_1">
    <material>Gazebo/Silver</material>
    <mu1>0.2</mu1>
    <mu2>0.2</mu2>
    <selfCollide>true</selfCollide>
  </gazebo>
  <gazebo reference="JX_servo_v12_16">
    <material>Gazebo/Silver</material>
    <mu1>0.2</mu1>
    <mu2>0.2</mu2>
    <selfCollide>true</selfCollide>
  </gazebo>
  <gazebo reference="right_thigh_1">
    <material>Gazebo/Silver</material>
    <mu1>0.2</mu1>
    <mu2>0.2</mu2>
    <selfCollide>true</selfCollide>
  </gazebo>
  <gazebo reference="JX_servo_v12_17">
    <material>Gazebo/Silver</material>
    <mu1>0.2</mu1>
    <mu2>0.2</mu2>
    <selfCollide>true</selfCollide>
  </gazebo>
  <gazebo reference="right_calve_1">
    <material>Gazebo/Silver</material>
    <mu1>0.2</mu1>
    <mu2>0.2</mu2>
    <selfCollide>true</selfCollide>
  </gazebo>
  <gazebo reference="JX_servo_v12_18">
    <material>Gazebo/Silver</material>
    <mu1>0.2</mu1>
    <mu2>0.2</mu2>
    <selfCollide>true</selfCollide>
  </gazebo>
  <gazebo reference="right_ankle_2">
    <material>Gazebo/Silver</material>
    <mu1>0.2</mu1>
    <mu2>0.2</mu2>
    <selfCollide>true</selfCollide>
  </gazebo>
  <gazebo reference="JX_servo_v12_19">
    <material>Gazebo/Silver</material>
    <mu1>0.2</mu1>
    <mu2>0.2</mu2>
    <selfCollide>true</selfCollide>
  </gazebo>
  <gazebo reference="right_foot_1">
    <material>Gazebo/Silver</material>
    <mu1>0.2</mu1>
    <mu2>0.2</mu2>
    <selfCollide>true</selfCollide>
  </gazebo>
  <gazebo reference="25t-servo-hub_1">
    <material>Gazebo/Silver</material>
    <mu1>0.2</mu1>
    <mu2>0.2</mu2>
    <selfCollide>true</selfCollide>
  </gazebo>
  <gazebo reference="gobilda-servo_1">
    <material>Gazebo/Silver</material>
    <mu1>0.2</mu1>
    <mu2>0.2</mu2>
    <selfCollide>true</selfCollide>
  </gazebo>
  <gazebo reference="left_bicep_1">
    <material>Gazebo/Silver</material>
    <mu1>0.2</mu1>
    <mu2>0.2</mu2>
    <selfCollide>true</selfCollide>
  </gazebo>
  <gazebo reference="gobilda-servo_3">
    <material>Gazebo/Silver</material>
    <mu1>0.2</mu1>
    <mu2>0.2</mu2>
    <selfCollide>true</selfCollide>
  </gazebo>
  <gazebo reference="25t-servo-hub_2">
    <material>Gazebo/Silver</material>
    <mu1>0.2</mu1>
    <mu2>0.2</mu2>
    <selfCollide>true</selfCollide>
  </gazebo>
  <gazebo reference="elbow-attach_1">
    <material>Gazebo/Silver</material>
    <mu1>0.2</mu1>
    <mu2>0.2</mu2>
    <selfCollide>true</selfCollide>
  </gazebo>
  <gazebo reference="left_forearm_1">
    <material>Gazebo/Silver</material>
    <mu1>0.2</mu1>
    <mu2>0.2</mu2>
    <selfCollide>true</selfCollide>
  </gazebo>
  <gazebo reference="elbow-bearing_1">
    <material>Gazebo/Silver</material>
    <mu1>0.2</mu1>
    <mu2>0.2</mu2>
    <selfCollide>true</selfCollide>
  </gazebo>
  <gazebo reference="25t-servo-hub_Mirror__1">
    <material>Gazebo/Silver</material>
    <mu1>0.2</mu1>
    <mu2>0.2</mu2>
    <selfCollide>true</selfCollide>
  </gazebo>
  <gazebo reference="gobilda-servo_Mirror__1">
    <material>Gazebo/Silver</material>
    <mu1>0.2</mu1>
    <mu2>0.2</mu2>
    <selfCollide>true</selfCollide>
  </gazebo>
  <gazebo reference="right_bicep_1">
    <material>Gazebo/Silver</material>
    <mu1>0.2</mu1>
    <mu2>0.2</mu2>
    <selfCollide>true</selfCollide>
  </gazebo>
  <gazebo reference="gobilda-servo_Mirror__2">
    <material>Gazebo/Silver</material>
    <mu1>0.2</mu1>
    <mu2>0.2</mu2>
    <selfCollide>true</selfCollide>
  </gazebo>
  <gazebo reference="25t-servo-hub_Mirror__2">
    <material>Gazebo/Silver</material>
    <mu1>0.2</mu1>
    <mu2>0.2</mu2>
    <selfCollide>true</selfCollide>
  </gazebo>
  <gazebo reference="elbow-attach_Mirror__1">
    <material>Gazebo/Silver</material>
    <mu1>0.2</mu1>
    <mu2>0.2</mu2>
    <selfCollide>true</selfCollide>
  </gazebo>
  <gazebo reference="right_forearm_1">
    <material>Gazebo/Silver</material>
    <mu1>0.2</mu1>
    <mu2>0.2</mu2>
    <selfCollide>true</selfCollide>
  </gazebo>
  <gazebo reference="elbow-bearing_Mirror__1">
    <material>Gazebo/Silver</material>
    <mu1>0.2</mu1>
    <mu2>0.2</mu2>
    <selfCollide>true</selfCollide>
  </gazebo>
  <gazebo reference="custom_servo_support__lower_neck__v2_1">
    <material>Gazebo/Silver</material>
    <mu1>0.2</mu1>
    <mu2>0.2</mu2>
    <selfCollide>true</selfCollide>
  </gazebo>
  <gazebo reference="gobilda-servo_4">
    <material>Gazebo/Silver</material>
    <mu1>0.2</mu1>
    <mu2>0.2</mu2>
    <selfCollide>true</selfCollide>
  </gazebo>
  <gazebo reference="25t-servo-hub_3">
    <material>Gazebo/Silver</material>
    <mu1>0.2</mu1>
    <mu2>0.2</mu2>
    <selfCollide>true</selfCollide>
  </gazebo>
  <gazebo reference="neck_1">
    <material>Gazebo/Silver</material>
    <mu1>0.2</mu1>
    <mu2>0.2</mu2>
    <selfCollide>true</selfCollide>
  </gazebo>
  <gazebo reference="25t-servo-hub_4">
    <material>Gazebo/Silver</material>
    <mu1>0.2</mu1>
    <mu2>0.2</mu2>
    <selfCollide>true</selfCollide>
  </gazebo>
  <gazebo reference="gobilda-servo_5">
    <material>Gazebo/Silver</material>
    <mu1>0.2</mu1>
    <mu2>0.2</mu2>
    <selfCollide>true</selfCollide>
  </gazebo>
  <gazebo reference="head_1">
    <material>Gazebo/Silver</material>
    <mu1>0.2</mu1>
    <mu2>0.2</mu2>
    <selfCollide>true</selfCollide>
  </gazebo>
  <gazebo reference="camera_1">
    <material>Gazebo/Silver</material>
    <mu1>0.2</mu1>
    <mu2>0.2</mu2>
    <selfCollide>true</selfCollide>
  </gazebo>
  <gazebo reference="camera-link_1">
    <material>Gazebo/Silver</material>
    <mu1>0.2</mu1>
    <mu2>0.2</mu2>
    <selfCollide>true</selfCollide>
  </gazebo>
  <gazebo reference="imu-link_1">
    <material>Gazebo/Silver</material>
    <mu1>0.2</mu1>
    <mu2>0.2</mu2>
    <selfCollide>true</selfCollide>
  </gazebo>
  <gazebo reference="Component32_1">
    <material>Gazebo/Silver</material>
    <mu1>0.2</mu1>
    <mu2>0.2</mu2>
    <selfCollide>true</selfCollide>
  </gazebo>
  <gazebo reference="TX2_board_v2_1">
    <material>Gazebo/Silver</material>
    <mu1>0.2</mu1>
    <mu2>0.2</mu2>
    <selfCollide>true</selfCollide>
  </gazebo>
  <link name="base_link">
    <inertial>
      <origin xyz="0.005 0.005 0.005" rpy="0.0 0.0 0.0"/>
      <mass value="0.00785"/>
      <inertia ixx="0.0" ixy="0.0" ixz="0.0" iyy="0.0" iyz="0.0" izz="0.0"/>
    </inertial>
    <visual>
      <origin xyz="0.0 0.0 0.0" rpy="0.0 0.0 0.0"/>
      <geometry>
        <mesh filename="package://bez3_description/meshes/base_link.stl" scale="1e-06 1e-06 1e-06"/>
      </geometry>
      <material name="steel_satin"/>
    </visual>
    <collision>
      <origin xyz="0.004999999888241291 0.004999999888241291 0.004999999888241291" rpy="0.0 -0.0 3.141592653589793"/>
      <geometry>
        <box size="0.009999999776482584 0.009999999776482584 0.009999999776482582"/>
      </geometry>
    </collision>
  </link>
  <link name="torso_1">
    <inertial>
      <origin xyz="-0.003658211229359205 -0.006167940664238083 -0.07338742094913071" rpy="0.0 0.0 0.0"/>
      <mass value="0.2968069064800233"/>
      <inertia ixx="0.002664" ixy="5e-06" ixz="6e-05" iyy="0.001243" iyz="0.0" izz="0.002203"/>
    </inertial>
    <visual>
      <origin xyz="-0.0 -0.005 -0.0" rpy="0.0 0.0 0.0"/>
      <geometry>
        <mesh filename="package://bez3_description/meshes/torso_1.stl" scale="1e-06 1e-06 1e-06"/>
      </geometry>
      <material name="polymide_kapton"/>
    </visual>
    <collision>
      <origin xyz="-0.00693073496222497 -0.004999999999999996 -0.0684999911467834" rpy="1.5707963267948966 6.123233995736766e-17 3.141592653589793"/>
      <geometry>
        <box size="0.12413852661848071 0.13700000673917856 0.21500000357627866"/>
      </geometry>
    </collision>
  </link>
  <link name="JX_servo_v12_1">
    <inertial>
      <origin xyz="0.00027407227629309625 4.531028330312381e-13 0.012509678934478005" rpy="0.0 0.0 0.0"/>
      <mass value="0.19853540350189508"/>
      <inertia ixx="7.7e-05" ixy="0.0" ixz="6e-06" iyy="0.000137" iyz="0.0" izz="9e-05"/>
    </inertial>
    <visual>
      <origin xyz="0.0225 -0.0545 0.13699" rpy="0.0 0.0 0.0"/>
      <geometry>
        <mesh filename="package://bez3_description/meshes/JX_servo_v12_1.stl" scale="1e-06 1e-06 1e-06"/>
      </geometry>
      <material name="plastic_matte_black"/>
    </visual>
    <collision>
      <origin xyz="-0.00019999962300062263 5.2953690290451216e-05 0.009882793267965317" rpy="1.5707963267948966 -0.0 1.5707963267948966"/>
      <geometry>
        <box size="0.04054670823531333 0.07320708274687829 0.08278942044884"/>
      </geometry>
    </collision>
  </link>
  <link name="left_hip_side_1">
    <inertial>
      <origin xyz="-0.0006601764265435524 7.984241046088414e-10 -0.021141547194982763" rpy="0.0 0.0 0.0"/>
      <mass value="0.018999817606213904"/>
      <inertia ixx="9e-06" ixy="0.0" ixz="-0.0" iyy="1.8e-05" iyz="0.0" izz="1.4e-05"/>
    </inertial>
    <visual>
      <origin xyz="0.0045 -0.0545 0.16339" rpy="0.0 0.0 0.0"/>
      <geometry>
        <mesh filename="package://bez3_description/meshes/left_hip_side_1.stl" scale="1e-06 1e-06 1e-06"/>
      </geometry>
      <material name="plastic_glossy_black"/>
    </visual>
    <collision>
      <origin xyz="0.0010049158781766884 5.513429643388967e-10 -0.029621850118637078" rpy="1.5707963267948966 -0.0 -1.5707963267948968"/>
      <geometry>
        <box size="0.040000002831220634 0.05924370884895324 0.06200983002781868"/>
      </geometry>
    </collision>
  </link>
  <link name="JX_servo_v12_8">
    <inertial>
      <origin xyz="-0.03890967893447789 4.529293606836404e-13 -0.017725838898350915" rpy="0.0 0.0 0.0"/>
      <mass value="0.19853540350189508"/>
      <inertia ixx="9e-05" ixy="-0.0" ixz="-6e-06" iyy="0.000137" iyz="0.0" izz="7.7e-05"/>
    </inertial>
    <visual>
      <origin xyz="0.0345 -0.0545 0.198726" rpy="0.0 0.0 0.0"/>
      <geometry>
        <mesh filename="package://bez3_description/meshes/JX_servo_v12_8.stl" scale="1e-06 1e-06 1e-06"/>
      </geometry>
      <material name="plastic_matte_black"/>
    </visual>
    <collision>
      <origin xyz="-0.03596211380975767 0.0001797117724589431 -0.018128179051623283" rpy="3.1304509503559896 -4.363444057494178e-05 1.566880191979498"/>
      <geometry>
        <box size="0.040008454801080326 0.07278504123650459 0.08183837373506664"/>
      </geometry>
    </collision>
  </link>
  <link name="left_hip_front_1">
    <inertial>
      <origin xyz="0.023758590398210495 0.009336273295607947 -0.06494791715192266" rpy="0.0 0.0 0.0"/>
      <mass value="0.025976181664280836"/>
      <inertia ixx="2.2e-05" ixy="0.0" ixz="8e-06" iyy="3.1e-05" iyz="-0.0" izz="2e-05"/>
    </inertial>
    <visual>
      <origin xyz="0.0609 -0.046 0.179826" rpy="0.0 0.0 0.0"/>
      <geometry>
        <mesh filename="package://bez3_description/meshes/left_hip_front_1.stl" scale="1e-06 1e-06 1e-06"/>
      </geometry>
      <material name="plastic_glossy_black"/>
    </visual>
    <collision>
      <origin xyz="0.0351999984882772 0.008500002413988114 -0.04010385159158705" rpy="3.141592653589793 -0.0 -1.5707963267948966"/>
      <geometry>
        <box size="0.04100000113248826 0.07840000372380018 0.08820788562297821"/>
      </geometry>
    </collision>
  </link>
  <link name="JX_servo_v12_9">
    <inertial>
      <origin xyz="-0.008499999657726187 -0.016409678591751728 0.03717416110164981" rpy="0.0 0.0 0.0"/>
      <mass value="0.19853540350189508"/>
      <inertia ixx="0.000137" ixy="0.0" ixz="-0.0" iyy="9e-05" iyz="-6e-06" izz="7.7e-05"/>
    </inertial>
    <visual>
      <origin xyz="-0.0035 -0.0699 0.253626" rpy="0.0 0.0 0.0"/>
      <geometry>
        <mesh filename="package://bez3_description/meshes/JX_servo_v12_9.stl" scale="1e-06 1e-06 1e-06"/>
      </geometry>
      <material name="plastic_matte_black"/>
    </visual>
    <collision>
      <origin xyz="-0.008679713846146865 -0.013462115138063314 0.036771820914720366" rpy="3.1304509491998873 -4.363443079811245e-05 3.137676520058225"/>
      <geometry>
        <box size="0.04000845479936067 0.07278504123672407 0.08183837369701641"/>
      </geometry>
    </collision>
  </link>
  <link name="left_thigh_1">
    <inertial>
      <origin xyz="0.0035522308946802695 -0.037286001427951104 -0.06738530321679864" rpy="0.0 0.0 0.0"/>
      <mass value="0.04698736144283967"/>
      <inertia ixx="0.000144" ixy="-0.0" ixz="3e-06" iyy="8.9e-05" iyz="0.0" izz="6.9e-05"/>
    </inertial>
    <visual>
      <origin xyz="0.005 -0.0924 0.198726" rpy="0.0 0.0 0.0"/>
      <geometry>
        <mesh filename="package://bez3_description/meshes/left_thigh_1.stl" scale="1e-06 1e-06 1e-06"/>
      </geometry>
      <material name="plastic_glossy_black"/>
    </visual>
    <collision>
      <origin xyz="3.057997935122531e-05 -0.037489075248688455 -0.061987566109073966" rpy="-3.141592653589793 2.45193662956113e-05 -3.141592653589793"/>
      <geometry>
        <box size="0.04007143189170146 0.08883423336978291 0.1640051519072386"/>
      </geometry>
    </collision>
  </link>
  <link name="JX_servo_v12_11">
    <inertial>
      <origin xyz="3.422737293243272e-10 -0.03890967859175239 -0.017725838898350055" rpy="0.0 0.0 0.0"/>
      <mass value="0.19853540350189508"/>
      <inertia ixx="0.000137" ixy="0.0" ixz="-0.0" iyy="9e-05" iyz="-6e-06" izz="7.7e-05"/>
    </inertial>
    <visual>
      <origin xyz="0.005 -0.0924 0.322726" rpy="0.0 0.0 0.0"/>
      <geometry>
        <mesh filename="package://bez3_description/meshes/JX_servo_v12_11.stl" scale="1e-06 1e-06 1e-06"/>
      </geometry>
      <material name="plastic_matte_black"/>
    </visual>
    <collision>
      <origin xyz="-0.0001797065804416756 -0.03596213782638021 -0.018128175205319896" rpy="3.130451779229603 -4.362882947211988e-05 3.137676731017014"/>
      <geometry>
        <box size="0.04000845578282203 0.07278502398499857 0.0818383861167361"/>
      </geometry>
    </collision>
  </link>
  <link name="left_calve_1">
    <inertial>
      <origin xyz="-0.008549992578499489 -0.011776675554452998 -0.0353123749558687" rpy="0.0 0.0 0.0"/>
      <mass value="0.035688451730559324"/>
      <inertia ixx="7.3e-05" ixy="-0.0" ixz="0.0" iyy="3.9e-05" iyz="-2e-06" izz="4.3e-05"/>
    </inertial>
    <visual>
      <origin xyz="-0.0035 -0.066 0.377626" rpy="0.0 0.0 0.0"/>
      <geometry>
        <mesh filename="package://bez3_description/meshes/left_calve_1.stl" scale="1e-06 1e-06 1e-06"/>
      </geometry>
      <material name="plastic_glossy_black"/>
    </visual>
    <collision>
      <origin xyz="-0.008515722475945951 -0.00923750399053097 -0.050510691451072676" rpy="3.141592653589793 -0.0 -6.123233995736766e-17"/>
      <geometry>
        <box size="0.04009244410387435 0.08934971823335128 0.1090484024603223"/>
      </geometry>
    </collision>
  </link>
  <link name="JX_servo_v12_12">
    <inertial>
      <origin xyz="3.43180092850226e-10 -0.0389096785917531 0.01772604982501308" rpy="0.0 0.0 0.0"/>
      <mass value="0.19853540350189508"/>
      <inertia ixx="0.000137" ixy="-0.0" ixz="-0.0" iyy="9e-05" iyz="6e-06" izz="7.7e-05"/>
    </inertial>
    <visual>
      <origin xyz="0.00505 -0.094 0.462631" rpy="0.0 0.0 0.0"/>
      <geometry>
        <mesh filename="package://bez3_description/meshes/JX_servo_v12_12.stl" scale="1e-06 1e-06 1e-06"/>
      </geometry>
      <material name="plastic_matte_black"/>
    </visual>
    <collision>
      <origin xyz="0.00017971633046555326 -0.03596211629437219 0.01812839467944216" rpy="3.1304509515117713 4.363436093896144e-05 0.003916128074513"/>
      <geometry>
        <box size="0.040008453871064664 0.07278503718039667 0.08183838867335402"/>
      </geometry>
    </collision>
  </link>
  <link name="left_hip_front_2">
    <inertial>
      <origin xyz="-0.040641409601790045 -0.017336272610156404 -0.008851871921414733" rpy="0.0 0.0 0.0"/>
      <mass value="0.025976181664280836"/>
      <inertia ixx="2.2e-05" ixy="-0.0" ixz="-8e-06" iyy="3.1e-05" iyz="-0.0" izz="2e-05"/>
    </inertial>
    <visual>
      <origin xyz="-0.00345 -0.0715 0.407731" rpy="0.0 0.0 0.0"/>
      <geometry>
        <mesh filename="package://bez3_description/meshes/left_hip_front_2.stl" scale="1e-06 1e-06 1e-06"/>
      </geometry>
      <material name="plastic_glossy_black"/>
    </visual>
    <collision>
      <origin xyz="-0.029224620929357667 -0.01650075488916955 -0.03344894239444418" rpy="0.007676694029128689 -1.2246122557041423e-16 -1.5715680571532535"/>
      <geometry>
        <box size="0.04105894538917622 0.07915189064439027 0.08831298710238125"/>
      </geometry>
    </collision>
  </link>
  <link name="JX_servo_v12_13">
    <inertial>
      <origin xyz="-0.01250967893447847 0.008500000684998912 -0.0371739501749872" rpy="0.0 0.0 0.0"/>
      <mass value="0.19853540350189508"/>
      <inertia ixx="9e-05" ixy="0.0" ixz="6e-06" iyy="0.000137" iyz="0.0" izz="7.7e-05"/>
    </inertial>
    <visual>
      <origin xyz="0.06095 -0.0465 0.407731" rpy="0.0 0.0 0.0"/>
      <geometry>
        <mesh filename="package://bez3_description/meshes/JX_servo_v12_13.stl" scale="1e-06 1e-06 1e-06"/>
      </geometry>
      <material name="plastic_matte_black"/>
    </visual>
    <collision>
      <origin xyz="-0.009882787081599238 0.008447040975093842 -0.03669987279796599" rpy="3.141592653589793 -0.0 -1.5707963267948966"/>
      <geometry>
        <box size="0.040546708572980955 0.07320709080496267 0.08278945243235761"/>
      </geometry>
    </collision>
  </link>
  <link name="left_foot_1">
    <inertial>
      <origin xyz="0.03678225489457133 -0.0014130788744076417 -0.02104523782784523" rpy="0.0 0.0 0.0"/>
      <mass value="0.03704332574321432"/>
      <inertia ixx="1.9e-05" ixy="-1e-06" ixz="4e-06" iyy="4.8e-05" iyz="-1e-06" izz="4.4e-05"/>
    </inertial>
    <visual>
      <origin xyz="0.03455 -0.055 0.462631" rpy="0.0 0.0 0.0"/>
      <geometry>
        <mesh filename="package://bez3_description/meshes/left_foot_1.stl" scale="1e-06 1e-06 1e-06"/>
      </geometry>
      <material name="plastic_glossy_black"/>
    </visual>
    <collision>
      <origin xyz="0.042295061255619264 -0.0014958652974801645 -0.005784707349777207" rpy="-0.06550389835154626 1.5707963267948966 0.0"/>
      <geometry>
        <box size="0.06015777061157024 0.06334595847485622 0.11811981933807195"/>
      </geometry>
    </collision>
  </link>
  <link name="JX_servo_v12_14">
    <inertial>
      <origin xyz="0.00027407227629309625 4.531167108190459e-13 0.012509678934477936" rpy="0.0 0.0 0.0"/>
      <mass value="0.19853540350189508"/>
      <inertia ixx="7.7e-05" ixy="0.0" ixz="6e-06" iyy="0.000137" iyz="0.0" izz="9e-05"/>
    </inertial>
    <visual>
      <origin xyz="0.0225 0.0545 0.137" rpy="0.0 0.0 0.0"/>
      <geometry>
        <mesh filename="package://bez3_description/meshes/JX_servo_v12_14.stl" scale="1e-06 1e-06 1e-06"/>
      </geometry>
      <material name="plastic_matte_black"/>
    </visual>
    <collision>
      <origin xyz="-0.00019999962300062263 5.2956312894821e-05 0.009882794588804256" rpy="1.5707963267948966 -0.0 1.5707963267948966"/>
      <geometry>
        <box size="0.04054670816493613 0.07320708270345652 0.08278942078053159"/>
      </geometry>
    </collision>
  </link>
  <link name="right_hip_side_1">
    <inertial>
      <origin xyz="-0.0006601764265435368 -7.984240907310536e-10 -0.021141552658250296" rpy="0.0 0.0 0.0"/>
      <mass value="0.018999817606213918"/>
      <inertia ixx="9e-06" ixy="-0.0" ixz="-0.0" iyy="1.8e-05" iyz="-0.0" izz="1.4e-05"/>
    </inertial>
    <visual>
      <origin xyz="0.0045 0.0545 0.1634" rpy="0.0 0.0 0.0"/>
      <geometry>
        <mesh filename="package://bez3_description/meshes/right_hip_side_1.stl" scale="1e-06 1e-06 1e-06"/>
      </geometry>
      <material name="plastic_glossy_black"/>
    </visual>
    <collision>
      <origin xyz="0.0010049158781766892 -3.4799724817277666e-06 -0.029584610795974742" rpy="1.5707963267948966 -0.0 -1.5707963267948968"/>
      <geometry>
        <box size="0.040058424427170426 0.059198398432720914 0.06200983002781868"/>
      </geometry>
    </collision>
  </link>
  <link name="JX_servo_v12_15">
    <inertial>
      <origin xyz="-0.03890967893447782 4.5325548869712406e-13 -0.017725838898350943" rpy="0.0 0.0 0.0"/>
      <mass value="0.19853540350189508"/>
      <inertia ixx="9e-05" ixy="-0.0" ixz="-6e-06" iyy="0.000137" iyz="0.0" izz="7.7e-05"/>
    </inertial>
    <visual>
      <origin xyz="0.0345 0.0545 0.198736" rpy="0.0 0.0 0.0"/>
      <geometry>
        <mesh filename="package://bez3_description/meshes/JX_servo_v12_15.stl" scale="1e-06 1e-06 1e-06"/>
      </geometry>
      <material name="plastic_matte_black"/>
    </visual>
    <collision>
      <origin xyz="-0.035962113529641085 0.00017971547424221884 -0.018128185178243855" rpy="3.130450950357447 -4.363481277270114e-05 1.5668801585750578"/>
      <geometry>
        <box size="0.04000845479340684 0.07278504140539158 0.0818383886353029"/>
      </geometry>
    </collision>
  </link>
  <link name="right_ankle_1">
    <inertial>
      <origin xyz="0.02375859039821196 -0.00933627329560792 -0.06494791715192275" rpy="0.0 0.0 0.0"/>
      <mass value="0.025976181664280826"/>
      <inertia ixx="2.2e-05" ixy="-0.0" ixz="8e-06" iyy="3.1e-05" iyz="0.0" izz="2e-05"/>
    </inertial>
    <visual>
      <origin xyz="0.0609 0.046 0.179836" rpy="0.0 0.0 0.0"/>
      <geometry>
        <mesh filename="package://bez3_description/meshes/right_ankle_1.stl" scale="1e-06 1e-06 1e-06"/>
      </geometry>
      <material name="plastic_glossy_black"/>
    </visual>
    <collision>
      <origin xyz="0.03530035501495003 -0.008500002413988121 -0.040103842820167546" rpy="3.141592653589793 -0.0 1.5707963267948966"/>
      <geometry>
        <box size="0.041000001132488265 0.07860071677714586 0.08820787072181702"/>
      </geometry>
    </collision>
  </link>
  <link name="JX_servo_v12_16">
    <inertial>
      <origin xyz="-0.008499999656819584 0.016409678591751596 0.03717416110164953" rpy="0.0 0.0 0.0"/>
      <mass value="0.19853540350189508"/>
      <inertia ixx="0.000137" ixy="0.0" ixz="0.0" iyy="9e-05" iyz="6e-06" izz="7.7e-05"/>
    </inertial>
    <visual>
      <origin xyz="-0.0035 0.0699 0.253636" rpy="0.0 0.0 0.0"/>
      <geometry>
        <mesh filename="package://bez3_description/meshes/JX_servo_v12_16.stl" scale="1e-06 1e-06 1e-06"/>
      </geometry>
      <material name="plastic_matte_black"/>
    </visual>
    <collision>
      <origin xyz="-0.008320283429703059 0.013462113900842676 0.03677181479876407" rpy="3.130450949202009 -4.363497255597832e-05 -0.003916182153882573"/>
      <geometry>
        <box size="0.040008452927453524 0.07278503955894784 0.08183838859725273"/>
      </geometry>
    </collision>
  </link>
  <link name="right_thigh_1">
    <inertial>
      <origin xyz="0.0035522343275843837 0.03728602282125167 -0.06738525640624529" rpy="0.0 0.0 0.0"/>
      <mass value="0.04698731628682583"/>
      <inertia ixx="0.000144" ixy="0.0" ixz="3e-06" iyy="8.9e-05" iyz="-0.0" izz="6.9e-05"/>
    </inertial>
    <visual>
      <origin xyz="0.005 0.0924 0.198736" rpy="0.0 0.0 0.0"/>
      <geometry>
        <mesh filename="package://bez3_description/meshes/right_thigh_1.stl" scale="1e-06 1e-06 1e-06"/>
      </geometry>
      <material name="plastic_glossy_black"/>
    </visual>
    <collision>
      <origin xyz="4.914926985191692e-07 0.03748603808118002 -0.062055144364796117" rpy="1.0605240439355027e-06 -0.0009001066787438 -3.1408194947480927"/>
      <geometry>
        <box size="0.04031622705210779 0.08885990114706975 0.16419299183864544"/>
      </geometry>
    </collision>
  </link>
  <link name="JX_servo_v12_17">
    <inertial>
      <origin xyz="3.431804328560273e-10 0.038909678591752296 -0.017725838898350554" rpy="0.0 0.0 0.0"/>
      <mass value="0.19853540350189508"/>
      <inertia ixx="0.000137" ixy="0.0" ixz="0.0" iyy="9e-05" iyz="6e-06" izz="7.7e-05"/>
    </inertial>
    <visual>
      <origin xyz="0.005 0.0924 0.322736" rpy="0.0 0.0 0.0"/>
      <geometry>
        <mesh filename="package://bez3_description/meshes/JX_servo_v12_17.stl" scale="1e-06 1e-06 1e-06"/>
      </geometry>
      <material name="plastic_matte_black"/>
    </visual>
    <collision>
      <origin xyz="0.00017970606744404337 0.03596213822447444 -0.018128188790077604" rpy="3.130451779224212 -4.3627452779136606e-05 -0.003915799006532933"/>
      <geometry>
        <box size="0.04000845301114797 0.07278502246569804 0.081838386116736"/>
      </geometry>
    </collision>
  </link>
  <link name="right_calve_1">
    <inertial>
      <origin xyz="-0.00854999027881307 0.011776733864301954 -0.035312401211175015" rpy="0.0 0.0 0.0"/>
      <mass value="0.03568840560735723"/>
      <inertia ixx="7.3e-05" ixy="0.0" ixz="0.0" iyy="3.9e-05" iyz="2e-06" izz="4.3e-05"/>
    </inertial>
    <visual>
      <origin xyz="-0.0035 0.066 0.377636" rpy="0.0 0.0 0.0"/>
      <geometry>
        <mesh filename="package://bez3_description/meshes/right_calve_1.stl" scale="1e-06 1e-06 1e-06"/>
      </geometry>
      <material name="plastic_glossy_black"/>
    </visual>
    <collision>
      <origin xyz="-0.008534496645798785 0.009197705408521169 -0.050504473828194674" rpy="-0.0010668932670843125 0.0006732299941212879 -3.1412849943483074"/>
      <geometry>
        <box size="0.04005597184791974 0.0893443198546015 0.10905559176825397"/>
      </geometry>
    </collision>
  </link>
  <link name="JX_servo_v12_18">
    <inertial>
      <origin xyz="3.422741994343892e-10 0.03890967859175305 0.017726049825012857" rpy="0.0 0.0 0.0"/>
      <mass value="0.19853540350189508"/>
      <inertia ixx="0.000137" ixy="-0.0" ixz="0.0" iyy="9e-05" iyz="-6e-06" izz="7.7e-05"/>
    </inertial>
    <visual>
      <origin xyz="0.00505 0.094 0.462641" rpy="0.0 0.0 0.0"/>
      <geometry>
        <mesh filename="package://bez3_description/meshes/JX_servo_v12_18.stl" scale="1e-06 1e-06 1e-06"/>
      </geometry>
      <material name="plastic_matte_black"/>
    </visual>
    <collision>
      <origin xyz="-0.0001797147350162077 0.03596211479198527 0.018128395983541212" rpy="3.130450951513926 4.36349111690556e-05 -3.1376764761325804"/>
      <geometry>
        <box size="0.04000845386164336 0.07278503585588014 0.0818383588728816"/>
      </geometry>
    </collision>
  </link>
  <link name="right_ankle_2">
    <inertial>
      <origin xyz="-0.040641409601788116 0.017336272610156585 -0.008851871921415178" rpy="0.0 0.0 0.0"/>
      <mass value="0.025976181664280826"/>
      <inertia ixx="2.2e-05" ixy="0.0" ixz="-8e-06" iyy="3.1e-05" iyz="0.0" izz="2e-05"/>
    </inertial>
    <visual>
      <origin xyz="-0.00345 0.0715 0.407741" rpy="0.0 0.0 0.0"/>
      <geometry>
        <mesh filename="package://bez3_description/meshes/right_ankle_2.stl" scale="1e-06 1e-06 1e-06"/>
      </geometry>
      <material name="plastic_glossy_black"/>
    </visual>
    <collision>
      <origin xyz="-0.029099642106145622 0.016500002160668367 -0.03369593149089811" rpy="6.123233995736766e-17 -1.2246467991473532e-16 -1.5707963267948966"/>
      <geometry>
        <box size="0.04099999740719798 0.07860070932656528 0.08820787072181702"/>
      </geometry>
    </collision>
  </link>
  <link name="JX_servo_v12_19">
    <inertial>
      <origin xyz="-0.012509678934477693 -0.00850000068590498 -0.03717395017498715" rpy="0.0 0.0 0.0"/>
      <mass value="0.19853540350189508"/>
      <inertia ixx="9e-05" ixy="0.0" ixz="6e-06" iyy="0.000137" iyz="0.0" izz="7.7e-05"/>
    </inertial>
    <visual>
      <origin xyz="0.06095 0.0465 0.407741" rpy="0.0 0.0 0.0"/>
      <geometry>
        <mesh filename="package://bez3_description/meshes/JX_servo_v12_19.stl" scale="1e-06 1e-06 1e-06"/>
      </geometry>
      <material name="plastic_matte_black"/>
    </visual>
    <collision>
      <origin xyz="-0.009882787081599238 -0.008552954703569413 -0.036699871477127055" rpy="3.141592653589793 -0.0 -1.5707963267948966"/>
      <geometry>
        <box size="0.04054672375968531 0.07320709212991403 0.08278942267814574"/>
      </geometry>
    </collision>
  </link>
  <link name="right_foot_1">
    <inertial>
      <origin xyz="0.03678225489457156 0.001413078874407711 -0.021045237827845564" rpy="0.0 0.0 0.0"/>
      <mass value="0.037043325743214305"/>
      <inertia ixx="1.9e-05" ixy="1e-06" ixz="4e-06" iyy="4.8e-05" iyz="1e-06" izz="4.4e-05"/>
    </inertial>
    <visual>
      <origin xyz="0.03455 0.055 0.462641" rpy="0.0 0.0 0.0"/>
      <geometry>
        <mesh filename="package://bez3_description/meshes/right_foot_1.stl" scale="1e-06 1e-06 1e-06"/>
      </geometry>
      <material name="plastic_glossy_black"/>
    </visual>
    <collision>
      <origin xyz="0.042271547159034174 0.001359037169906055 -0.005890176447868323" rpy="0.06358878910439683 1.5707963267948966 0.0"/>
      <geometry>
        <box size="0.05934509962590004 0.06383469121587682 0.11762418282986051"/>
      </geometry>
    </collision>
  </link>
  <link name="25t-servo-hub_1">
    <inertial>
      <origin xyz="-4.77893450374911e-07 0.003136191852991313 1.6215494567234368e-07" rpy="0.0 0.0 0.0"/>
      <mass value="0.005584850212079893"/>
      <inertia ixx="0.0" ixy="0.0" ixz="-0.0" iyy="0.0" iyz="-0.0" izz="0.0"/>
    </inertial>
    <visual>
      <origin xyz="0.021 -0.1075 0.0365" rpy="0.0 0.0 0.0"/>
      <geometry>
        <mesh filename="package://bez3_description/meshes/25t-servo-hub_1.stl" scale="1e-06 1e-06 1e-06"/>
      </geometry>
      <material name="aluminum_satin"/>
    </visual>
    <collision>
      <origin xyz="-3.171580817350195e-05 0.003174111211214803 -5.4296680713050716e-05" rpy="-0.5598258419043471 0.0005806200767886683 -1.5704324753336378"/>
      <geometry>
        <box size="0.006378183021786476 0.025251950007364292 0.02537998445146513"/>
      </geometry>
    </collision>
  </link>
  <link name="gobilda-servo_1">
    <inertial>
      <origin xyz="1.3433243441218767e-09 0.021117732524250116 -0.00976910769495494" rpy="0.0 0.0 0.0"/>
      <mass value="0.060587311248822606"/>
      <inertia ixx="1.4e-05" ixy="0.0" ixz="-0.0" iyy="1e-05" iyz="0.0" izz="7e-06"/>
    </inertial>
    <visual>
      <origin xyz="0.021 -0.110294 0.0365" rpy="0.0 0.0 0.0"/>
      <geometry>
        <mesh filename="package://bez3_description/meshes/gobilda-servo_1.stl" scale="1e-06 1e-06 1e-06"/>
      </geometry>
      <material name="plastic_glossy_grey"/>
    </visual>
    <collision>
      <origin xyz="2.831220639876175e-10 0.018994307465008353 -0.010194356218874802" rpy="-3.055023069836637 6.123233995736764e-17 3.141592653589793"/>
      <geometry>
        <box size="0.01999999955296517 0.0399826830600124 0.05437307046998198"/>
      </geometry>
    </collision>
  </link>
  <link name="left_bicep_1">
    <inertial>
      <origin xyz="0.007500000000005787 -0.003484179384329711 -0.06115545050144429" rpy="0.0 0.0 0.0"/>
      <mass value="0.011455626340925264"/>
      <inertia ixx="9e-06" ixy="-0.0" ixz="-0.0" iyy="8e-06" iyz="1e-06" izz="3e-06"/>
    </inertial>
    <visual>
      <origin xyz="0.0285 -0.147194 0.029" rpy="0.0 0.0 0.0"/>
      <geometry>
        <mesh filename="package://bez3_description/meshes/left_bicep_1.stl" scale="1e-06 1e-06 1e-06"/>
      </geometry>
      <material name="plastic_glossy_black"/>
    </visual>
    <collision>
      <origin xyz="0.007378911443071599 -0.01329429742303298 -0.05262818015085842" rpy="0.020587970630214846 -0.0025897215813599052 0.00018499526708807935"/>
      <geometry>
        <box size="0.03570982710179357 0.0428372093610371 0.110695531807019"/>
      </geometry>
    </collision>
  </link>
  <link name="gobilda-servo_3">
    <inertial>
      <origin xyz="0.007500001343324372 -0.015782267475749873 -0.01726910769495492" rpy="0.0 0.0 0.0"/>
      <mass value="0.060587311248822606"/>
      <inertia ixx="1.4e-05" ixy="0.0" ixz="-0.0" iyy="1e-05" iyz="0.0" izz="7e-06"/>
    </inertial>
    <visual>
      <origin xyz="0.0285 -0.147194 0.0993" rpy="0.0 0.0 0.0"/>
      <geometry>
        <mesh filename="package://bez3_description/meshes/gobilda-servo_3.stl" scale="1e-06 1e-06 1e-06"/>
      </geometry>
      <material name="plastic_glossy_grey"/>
    </visual>
    <collision>
      <origin xyz="0.007500000283122064 -0.017905685382801045 -0.017694366067121423" rpy="-3.0550235569830546 6.123233995736766e-17 3.141592653589793"/>
      <geometry>
        <box size="0.019999999552965168 0.03998268930005222 0.0543730750677536"/>
      </geometry>
    </collision>
  </link>
  <link name="25t-servo-hub_2">
    <inertial>
      <origin xyz="-4.77893450343686e-07 0.000342191852934437 1.6215494560989363e-07" rpy="0.0 0.0 0.0"/>
      <mass value="0.005584850212079893"/>
      <inertia ixx="0.0" ixy="0.0" ixz="-0.0" iyy="0.0" iyz="-0.0" izz="0.0"/>
    </inertial>
    <visual>
      <origin xyz="0.021 -0.110294 0.1068" rpy="0.0 0.0 0.0"/>
      <geometry>
        <mesh filename="package://bez3_description/meshes/25t-servo-hub_2.stl" scale="1e-06 1e-06 1e-06"/>
      </geometry>
      <material name="aluminum_satin"/>
    </visual>
    <collision>
      <origin xyz="-3.171457899391397e-05 0.00038094182149607525 -5.429658203201515e-05" rpy="-0.5598253617210756 0.0005806201457432881 -1.570432475274741"/>
      <geometry>
        <box size="0.00640692776428926 0.025662782879393775 0.025666952247185102"/>
      </geometry>
    </collision>
  </link>
  <link name="elbow-attach_1">
    <inertial>
      <origin xyz="-0.009233924925004727 -0.0015151372970110405 -0.002548115188024211" rpy="0.0 0.0 0.0"/>
      <mass value="0.005141835270301899"/>
      <inertia ixx="1e-06" ixy="0.0" ixz="0.0" iyy="2e-06" iyz="-0.0" izz="1e-06"/>
    </inertial>
    <visual>
      <origin xyz="0.021 -0.1075 0.1068" rpy="0.0 0.0 0.0"/>
      <geometry>
        <mesh filename="package://bez3_description/meshes/elbow-attach_1.stl" scale="1e-06 1e-06 1e-06"/>
      </geometry>
      <material name="plastic_glossy_black"/>
    </visual>
    <collision>
      <origin xyz="-0.007084808682369079 0.000427313198076415 -0.0025000024557113587" rpy="1.5707963267948966 -0.0 -1.5781534227960792"/>
      <geometry>
        <box size="0.009114717533457157 0.03501314090504535 0.04993097391197541"/>
      </geometry>
    </collision>
  </link>
  <link name="left_forearm_1">
    <inertial>
      <origin xyz="0.00223843912986596 0.02233699999994311 -0.06792564077352817" rpy="0.0 0.0 0.0"/>
      <mass value="0.027371737365874692"/>
      <inertia ixx="5.9e-05" ixy="0.0" ixz="4e-06" iyy="5.7e-05" iyz="0.0" izz="5e-06"/>
    </inertial>
    <visual>
      <origin xyz="0.0485 -0.1095 0.0968" rpy="0.0 0.0 0.0"/>
      <geometry>
        <mesh filename="package://bez3_description/meshes/left_forearm_1.stl" scale="1e-06 1e-06 1e-06"/>
      </geometry>
      <material name="plastic_glossy_black"/>
    </visual>
    <collision>
      <origin xyz="0.011120471889411947 0.022336995482444763 -0.06198512365272868" rpy="3.141592653589793 0.008182317302061249 3.141592653589793"/>
      <geometry>
        <box size="0.02753307769937075 0.050673991441726726 0.14429567831080597"/>
      </geometry>
    </collision>
  </link>
  <link name="elbow-bearing_1">
    <inertial>
      <origin xyz="0.017892138559024794 0.003495502323537125 -0.012651303520558516" rpy="0.0 0.0 0.0"/>
      <mass value="0.004941715818268227"/>
      <inertia ixx="1e-06" ixy="-0.0" ixz="0.0" iyy="2e-06" iyz="0.0" izz="1e-06"/>
    </inertial>
    <visual>
      <origin xyz="0.0485 -0.154174 0.0968" rpy="0.0 0.0 0.0"/>
      <geometry>
        <mesh filename="package://bez3_description/meshes/elbow-bearing_1.stl" scale="1e-06 1e-06 1e-06"/>
      </geometry>
      <material name="plastic_glossy_black"/>
    </visual>
    <collision>
      <origin xyz="0.02041884095309408 0.0016496404218039606 -0.012500003603923296" rpy="1.5707963267948968 0.0006450753886118652 -1.5564391999779805"/>
      <geometry>
        <box size="0.009762054381294787 0.03500627413562576 0.049966547492458914"/>
      </geometry>
    </collision>
  </link>
  <link name="25t-servo-hub_Mirror__1">
    <inertial>
      <origin xyz="8.974977877482249e-07 -0.0031361151897775635 1.0845728465602722e-06" rpy="0.0 0.0 0.0"/>
      <mass value="0.005584585205775494"/>
      <inertia ixx="0.0" ixy="-0.0" ixz="-0.0" iyy="0.0" iyz="-0.0" izz="0.0"/>
    </inertial>
    <visual>
      <origin xyz="0.021 0.1075 0.0365" rpy="0.0 0.0 0.0"/>
      <geometry>
        <mesh filename="package://bez3_description/meshes/25t-servo-hub_Mirror__1.stl" scale="1e-06 1e-06 1e-06"/>
      </geometry>
      <material name="aluminum_satin"/>
    </visual>
    <collision>
      <origin xyz="-1.193574791710783e-05 -0.003173922269996632 4.159194024988544e-05" rpy="-0.23669339222689686 0.000781128233353029 1.5700074366399004"/>
      <geometry>
        <box size="0.006413470648793196 0.02520474876690182 0.025302905680505465"/>
      </geometry>
    </collision>
  </link>
  <link name="gobilda-servo_Mirror__1">
    <inertial>
      <origin xyz="1.3433243441218767e-09 -0.02111773252430696 -0.009769107694954933" rpy="0.0 0.0 0.0"/>
      <mass value="0.06058731124882261"/>
      <inertia ixx="1.4e-05" ixy="-0.0" ixz="-0.0" iyy="1e-05" iyz="-0.0" izz="7e-06"/>
    </inertial>
    <visual>
      <origin xyz="0.021 0.110294 0.0365" rpy="0.0 0.0 0.0"/>
      <geometry>
        <mesh filename="package://bez3_description/meshes/gobilda-servo_Mirror__1.stl" scale="1e-06 1e-06 1e-06"/>
      </geometry>
      <material name="plastic_glossy_grey"/>
    </visual>
    <collision>
      <origin xyz="2.831220639876175e-10 -0.01917182751125976 -0.010209762561175888" rpy="-0.08656958375315639 6.123233995736764e-17 -3.141592653589793"/>
      <geometry>
        <box size="0.019999999552965164 0.04047670997108249 0.054373070469981966"/>
      </geometry>
    </collision>
  </link>
  <link name="right_bicep_1">
    <inertial>
      <origin xyz="0.00750000000000579 0.0034841793842728674 -0.06115545050144429" rpy="0.0 0.0 0.0"/>
      <mass value="0.011455626340925269"/>
      <inertia ixx="9e-06" ixy="0.0" ixz="-0.0" iyy="8e-06" iyz="-1e-06" izz="3e-06"/>
    </inertial>
    <visual>
      <origin xyz="0.0285 0.147194 0.029" rpy="0.0 0.0 0.0"/>
      <geometry>
        <mesh filename="package://bez3_description/meshes/right_bicep_1.stl" scale="1e-06 1e-06 1e-06"/>
      </geometry>
      <material name="plastic_glossy_black"/>
    </visual>
    <collision>
      <origin xyz="0.007327403050312764 0.013251794032334452 -0.05261901143553904" rpy="0.02037058846659325 0.0032112060911889174 -3.136766918948957"/>
      <geometry>
        <box size="0.03504697431706887 0.0429835820897832 0.11071014669788423"/>
      </geometry>
    </collision>
  </link>
  <link name="gobilda-servo_Mirror__2">
    <inertial>
      <origin xyz="0.007500001343324372 0.015782267475693 -0.017269107694954933" rpy="0.0 0.0 0.0"/>
      <mass value="0.06058731124882261"/>
      <inertia ixx="1.4e-05" ixy="-0.0" ixz="-0.0" iyy="1e-05" iyz="-0.0" izz="7e-06"/>
    </inertial>
    <visual>
      <origin xyz="0.0285 0.147194 0.0993" rpy="0.0 0.0 0.0"/>
      <geometry>
        <mesh filename="package://bez3_description/meshes/gobilda-servo_Mirror__2.stl" scale="1e-06 1e-06 1e-06"/>
      </geometry>
      <material name="plastic_glossy_grey"/>
    </visual>
    <collision>
      <origin xyz="0.007500000283122064 0.01772817021981324 -0.017709769389116045" rpy="-0.08656942137102153 6.123233995736769e-17 3.141592653589793"/>
      <geometry>
        <box size="0.019999999552965168 0.040476712084511424 0.054373081899480175"/>
      </geometry>
    </collision>
  </link>
  <link name="25t-servo-hub_Mirror__2">
    <inertial>
      <origin xyz="8.97497787772511e-07 -0.00034211518977761424 1.0845728465325166e-06" rpy="0.0 0.0 0.0"/>
      <mass value="0.005584585205775494"/>
      <inertia ixx="0.0" ixy="-0.0" ixz="-0.0" iyy="0.0" iyz="-0.0" izz="0.0"/>
    </inertial>
    <visual>
      <origin xyz="0.021 0.110294 0.1068" rpy="0.0 0.0 0.0"/>
      <geometry>
        <mesh filename="package://bez3_description/meshes/25t-servo-hub_Mirror__2.stl" scale="1e-06 1e-06 1e-06"/>
      </geometry>
      <material name="aluminum_satin"/>
    </visual>
    <collision>
      <origin xyz="-1.193628953856038e-05 -0.00037992227125373257 4.1592482864491465e-05" rpy="-0.23669337922428435 0.0007811278374792509 1.5700074377905477"/>
      <geometry>
        <box size="0.006413470600263925 0.025204755950700975 0.025302910742906724"/>
      </geometry>
    </collision>
  </link>
  <link name="elbow-attach_Mirror__1">
    <inertial>
      <origin xyz="-0.009233924925004636 0.001515137296954086 -0.0025481151880241137" rpy="0.0 0.0 0.0"/>
      <mass value="0.005141835270301901"/>
      <inertia ixx="1e-06" ixy="-0.0" ixz="0.0" iyy="2e-06" iyz="0.0" izz="1e-06"/>
    </inertial>
    <visual>
      <origin xyz="0.021 0.1075 0.1068" rpy="0.0 0.0 0.0"/>
      <geometry>
        <mesh filename="package://bez3_description/meshes/elbow-attach_Mirror__1.stl" scale="1e-06 1e-06 1e-06"/>
      </geometry>
      <material name="plastic_glossy_black"/>
    </visual>
    <collision>
      <origin xyz="-0.0071542003519668995 -0.000351402023821501 -0.002500003606287493" rpy="1.5707963267948968 0.0006452897962575035 -1.5564389977594544"/>
      <geometry>
        <box size="0.009758820468505985 0.035006274132078054 0.04982045149188342"/>
      </geometry>
    </collision>
  </link>
  <link name="right_forearm_1">
    <inertial>
      <origin xyz="0.0022384391298659947 -0.02233700000000001 -0.06792564077352811" rpy="0.0 0.0 0.0"/>
      <mass value="0.027371737365874692"/>
      <inertia ixx="5.9e-05" ixy="-0.0" ixz="4e-06" iyy="5.7e-05" iyz="0.0" izz="5e-06"/>
    </inertial>
    <visual>
      <origin xyz="0.0485 0.1095 0.0968" rpy="0.0 0.0 0.0"/>
      <geometry>
        <mesh filename="package://bez3_description/meshes/right_forearm_1.stl" scale="1e-06 1e-06 1e-06"/>
      </geometry>
      <material name="plastic_glossy_black"/>
    </visual>
    <collision>
      <origin xyz="0.011082033087798114 -0.022336995482444763 -0.0619567496626203" rpy="3.141592653589793 0.006978315863839344 3.141592653589793"/>
      <geometry>
        <box size="0.027546153323796983 0.050673991441726685 0.14420582940986237"/>
      </geometry>
    </collision>
  </link>
  <link name="elbow-bearing_Mirror__1">
    <inertial>
      <origin xyz="0.01789213855902462 -0.003495502323594024 -0.012651303520558488" rpy="0.0 0.0 0.0"/>
      <mass value="0.004941715818268223"/>
      <inertia ixx="1e-06" ixy="0.0" ixz="0.0" iyy="2e-06" iyz="-0.0" izz="1e-06"/>
    </inertial>
    <visual>
      <origin xyz="0.0485 0.154174 0.0968" rpy="0.0 0.0 0.0"/>
      <geometry>
        <mesh filename="package://bez3_description/meshes/elbow-bearing_Mirror__1.stl" scale="1e-06 1e-06 1e-06"/>
      </geometry>
      <material name="plastic_glossy_black"/>
    </visual>
    <collision>
      <origin xyz="0.020400424319643663 -0.0015730473084052399 -0.012500002455711368" rpy="1.5707963267948966 -0.0 -1.578177004077218"/>
      <geometry>
        <box size="0.009221219110703038 0.034999996423721313 0.04986695010517463"/>
      </geometry>
    </collision>
  </link>
  <link name="custom_servo_support__lower_neck__v2_1">
    <inertial>
      <origin xyz="-0.0001818603745370151 4.095612737842203e-15 0.001967193599301919" rpy="0.0 0.0 0.0"/>
      <mass value="0.003136252201459725"/>
      <inertia ixx="0.0" ixy="-0.0" ixz="0.0" iyy="0.0" iyz="-0.0" izz="1e-06"/>
    </inertial>
    <visual>
      <origin xyz="-0.0 -0.0 1e-05" rpy="0.0 0.0 0.0"/>
      <geometry>
        <mesh filename="package://bez3_description/meshes/custom_servo_support__lower_neck__v2_1.stl" scale="1e-06 1e-06 1e-06"/>
      </geometry>
      <material name="plastic_glossy_black"/>
    </visual>
    <collision>
      <origin xyz="-0.00013732685976796522 8.890786322031956e-05 0.003489795051670385" rpy="-3.1360908725677232 1.5690748158967238 -1.2300521765077673e-16"/>
      <geometry>
        <box size="0.007049533893643815 0.04002735960495628 0.04114593061934336"/>
      </geometry>
    </collision>
  </link>
  <link name="gobilda-servo_4">
    <inertial>
      <origin xyz="0.017269107739658406 0.007500001343324397 0.015782267475689782" rpy="0.0 0.0 0.0"/>
      <mass value="0.060587311248822606"/>
      <inertia ixx="7e-06" ixy="0.0" ixz="0.0" iyy="1.4e-05" iyz="-0.0" izz="1e-05"/>
    </inertial>
    <visual>
      <origin xyz="0.01715 0.0075 -0.00697" rpy="0.0 0.0 0.0"/>
      <geometry>
        <mesh filename="package://bez3_description/meshes/gobilda-servo_4.stl" scale="1e-06 1e-06 1e-06"/>
      </geometry>
      <material name="plastic_glossy_grey"/>
    </visual>
    <collision>
      <origin xyz="0.017694360268675182 0.0075 0.01790568867727215" rpy="-1.4842268930928921 6.123233995736766e-17 -1.5707963267948968"/>
      <geometry>
        <box size="0.019999999552965175 0.03998267586685512 0.054373076793172784"/>
      </geometry>
    </collision>
  </link>
  <link name="25t-servo-hub_3">
    <inertial>
      <origin xyz="-4.778487469048187e-07 1.6215494569815637e-07 -0.0003421918530514406" rpy="0.0 0.0 0.0"/>
      <mass value="0.005584850212079893"/>
      <inertia ixx="0.0" ixy="-0.0" ixz="-0.0" iyy="0.0" iyz="0.0" izz="0.0"/>
    </inertial>
    <visual>
      <origin xyz="0.00965 -0.0 -0.04387" rpy="0.0 0.0 0.0"/>
      <geometry>
        <mesh filename="package://bez3_description/meshes/25t-servo-hub_3.stl" scale="1e-06 1e-06 1e-06"/>
      </geometry>
      <material name="aluminum_satin"/>
    </visual>
    <collision>
      <origin xyz="-3.2911155228985967e-05 -5.287698422700278e-05 -0.00038600224241237824" rpy="0.42078869605462443 1.5706069747308538 1.4309180112728737"/>
      <geometry>
        <box size="0.006369504964453446 0.025233453945395844 0.02535752086366205"/>
      </geometry>
    </collision>
  </link>
  <link name="neck_1">
    <inertial>
      <origin xyz="4.4703468357609744e-11 0.0015600923125218369 0.014702901470170587" rpy="0.0 0.0 0.0"/>
      <mass value="0.012940388012734224"/>
      <inertia ixx="9e-06" ixy="-0.0" ixz="-0.0" iyy="4e-06" iyz="0.0" izz="8e-06"/>
    </inertial>
    <visual>
      <origin xyz="0.00965 -0.0 -0.046664" rpy="0.0 0.0 0.0"/>
      <geometry>
        <mesh filename="package://bez3_description/meshes/neck_1.stl" scale="1e-06 1e-06 1e-06"/>
      </geometry>
      <material name="plastic_glossy_black"/>
    </visual>
    <collision>
      <origin xyz="9.462237417212638e-11 0.0019999993965029734 0.024207384814381602" rpy="1.5707963267948966 -0.0 -1.8369701987210297e-16"/>
      <geometry>
        <box size="0.034999999217689065 0.048414763063192374 0.05637400038540363"/>
      </geometry>
    </collision>
  </link>
  <link name="25t-servo-hub_4">
    <inertial>
      <origin xyz="-4.77848746903084e-07 0.003136191852991365 6.322169145839274e-07" rpy="0.0 0.0 0.0"/>
      <mass value="0.005584850212079893"/>
      <inertia ixx="0.0" ixy="0.0" ixz="-0.0" iyy="0.0" iyz="-0.0" izz="0.0"/>
    </inertial>
    <visual>
      <origin xyz="0.00965 0.022187 -0.080481" rpy="0.0 0.0 0.0"/>
      <geometry>
        <mesh filename="package://bez3_description/meshes/25t-servo-hub_4.stl" scale="1e-06 1e-06 1e-06"/>
      </geometry>
      <material name="aluminum_satin"/>
    </visual>
    <collision>
      <origin xyz="-3.1716513982652655e-05 0.0031741109128717616 -5.38283556324598e-05" rpy="-0.5598262270144968 0.0005805750605681393 -1.570431789146514"/>
      <geometry>
        <box size="0.006378195737828646 0.02525196060038335 0.025380002425038"/>
      </geometry>
    </collision>
  </link>
  <link name="gobilda-servo_5">
    <inertial>
      <origin xyz="0.009769107739658408 0.021117732524250185 4.714052932869306e-07" rpy="0.0 0.0 0.0"/>
      <mass value="0.060587311248822606"/>
      <inertia ixx="7e-06" ixy="-0.0" ixz="0.0" iyy="1e-05" iyz="0.0" izz="1.4e-05"/>
    </inertial>
    <visual>
      <origin xyz="0.00965 0.019393 -0.080481" rpy="0.0 0.0 0.0"/>
      <geometry>
        <mesh filename="package://bez3_description/meshes/gobilda-servo_5.stl" scale="1e-06 1e-06 1e-06"/>
      </geometry>
      <material name="plastic_glossy_grey"/>
    </visual>
    <collision>
      <origin xyz="0.0101943591508138 0.01899430934539049 4.6963119507137385e-07" rpy="0.08656942665572807 1.5707963267948966 0.0"/>
      <geometry>
        <box size="0.01999999582767487 0.03998267775876498 0.05437307478927776"/>
      </geometry>
    </collision>
  </link>
  <link name="head_1">
    <inertial>
      <origin xyz="0.017762050405363966 -0.005180173125019489 5.450273398273364e-05" rpy="0.0 0.0 0.0"/>
      <mass value="0.007653734054253099"/>
      <inertia ixx="2e-06" ixy="0.0" ixz="-0.0" iyy="3e-06" iyz="0.0" izz="3e-06"/>
    </inertial>
    <visual>
      <origin xyz="0.01715 -0.017507 -0.087981" rpy="0.0 0.0 0.0"/>
      <geometry>
        <mesh filename="package://bez3_description/meshes/head_1.stl" scale="1e-06 1e-06 1e-06"/>
      </geometry>
      <material name="plastic_glossy_black"/>
    </visual>
    <collision>
      <origin xyz="0.017068720920424017 -0.008737395622551443 -0.0039062448800839394" rpy="1.5661853882668013 -5.646751100416475e-19 -1.5707963267948968"/>
      <geometry>
        <box size="0.033965209499001524 0.03509340922727139 0.060851060727450515"/>
      </geometry>
    </collision>
  </link>
  <link name="camera_1">
    <inertial>
      <origin xyz="0.014184398578565184 -1.0759407732763727e-05 0.019215618136865634" rpy="0.0 0.0 0.0"/>
      <mass value="0.094257141411043"/>
      <inertia ixx="5.2e-05" ixy="0.0" ixz="-1.1e-05" iyy="4.3e-05" iyz="-0.0" izz="6.9e-05"/>
    </inertial>
    <visual>
      <origin xyz="-0.00685 -0.003487 -0.101481" rpy="0.0 0.0 0.0"/>
      <geometry>
        <mesh filename="package://bez3_description/meshes/camera_1.stl" scale="1e-06 1e-06 1e-06"/>
      </geometry>
      <material name="plastic_glossy_black"/>
    </visual>
    <collision>
      <origin xyz="0.0027084637310454285 5.026244126360609e-07 0.02075046855831146" rpy="1.5708197026415196 1.5707963267948966 0.0"/>
      <geometry>
        <box size="0.04150000214576721 0.07098785349728846 0.09400000048161036"/>
      </geometry>
    </collision>
  </link>
  <link name="camera-link_1">
    <inertial>
      <origin xyz="0.0005000006258488593 -3.1298447384156547e-10 4.7006196884913365e-07" rpy="0.0 0.0 0.0"/>
      <mass value="0.00019624999999999932"/>
      <inertia ixx="0.0" ixy="-0.0" ixz="0.0" iyy="0.0" iyz="0.0" izz="0.0"/>
    </inertial>
    <visual>
      <origin xyz="-0.04405 -0.003487 -0.128481" rpy="0.0 0.0 0.0"/>
      <geometry>
        <mesh filename="package://bez3_description/meshes/camera-link_1.stl" scale="1e-06 1e-06 1e-06"/>
      </geometry>
      <material name="steel_satin"/>
    </visual>
    <collision>
      <origin xyz="0.0004999997586011898 -2.8199329980480026e-10 4.700484275699246e-07" rpy="3.141592653589793 -0.0 3.141592653589793"/>
      <geometry>
        <box size="0.0009999983012676248 0.005000000004656614 0.005000010132789612"/>
      </geometry>
    </collision>
  </link>
  <link name="imu-link_1">
    <inertial>
      <origin xyz="-4.440892098500626e-18 -1.7763568394002505e-17 -0.0495" rpy="0.0 0.0 0.0"/>
      <mass value="0.00019625"/>
      <inertia ixx="0.0" ixy="0.0" ixz="0.0" iyy="0.0" iyz="0.0" izz="0.0"/>
    </inertial>
    <visual>
      <origin xyz="-0.0 -0.0 0.005" rpy="0.0 0.0 0.0"/>
      <geometry>
        <mesh filename="package://bez3_description/meshes/imu-link_1.stl" scale="1e-06 1e-06 1e-06"/>
      </geometry>
      <material name="steel_satin"/>
    </visual>
    <collision>
      <origin xyz="0.0 0.0 -0.04950000055134297" rpy="1.5707963267948966 -1.5707963267948966 0.0"/>
      <geometry>
        <box size="0.0009999983012676241 0.004999999888241291 0.004999999888241291"/>
      </geometry>
    </collision>
  </link>
  <link name="Component32_1">
    <inertial>
      <origin xyz="-8.673617379884035e-18 3.3333333333211267e-07 -0.0235" rpy="0.0 0.0 0.0"/>
      <mass value="0.31999527000000005"/>
      <inertia ixx="0.000364" ixy="-0.0" ixz="-0.0" iyy="9.2e-05" iyz="0.0" izz="0.000338"/>
    </inertial>
    <visual>
      <origin xyz="0.012 -0.000333 0.005" rpy="0.0 0.0 0.0"/>
      <geometry>
        <mesh filename="package://bez3_description/meshes/Component32_1.stl" scale="1e-06 1e-06 1e-06"/>
      </geometry>
      <material name="plastic_matte_blue"/>
    </visual>
    <collision>
      <origin xyz="-1.0430812810713341e-10 3.315253257773522e-07 -0.023500000480562448" rpy="1.5707963267948966 -0.0 -1.8369701987210297e-16"/>
      <geometry>
        <box size="0.03500000014901161 0.04700000118464232 0.10700000077486038"/>
      </geometry>
    </collision>
  </link>
  <link name="TX2_board_v2_1">
    <inertial>
      <origin xyz="0.0007727737790098402 -3.4264823634152304e-05 -0.015294861644822792" rpy="0.0 0.0 0.0"/>
      <mass value="0.2621637298853286"/>
      <inertia ixx="0.000165" ixy="-0.0" ixz="3e-06" iyy="7.1e-05" iyz="-0.0" izz="0.000195"/>
    </inertial>
  </link>
  <joint name="Rigid1" type="fixed">
    <origin xyz="0.0 0.005 0.0" rpy="0.0 0.0 0.0"/>
    <parent link="base_link"/>
    <child link="torso_1"/>
  </joint>
  <joint name="Rigid2" type="fixed">
    <origin xyz="-0.0225 0.0495 -0.13699" rpy="0.0 0.0 0.0"/>
    <parent link="torso_1"/>
    <child link="JX_servo_v12_1"/>
  </joint>
  <joint name="left_leg_motor_0" type="continuous">
    <origin xyz="0.018 0.0 -0.0264" rpy="0.0 0.0 0.0"/>
    <axis xyz="0.0 0.0 -1.0"/>
    <parent link="JX_servo_v12_1"/>
    <child link="left_hip_side_1"/>
  </joint>
  <joint name="left_leg_motor_1" type="continuous">
    <origin xyz="-0.03 0.0 -0.035336" rpy="0.0 0.0 0.0"/>
    <axis xyz="1.0 -0.0 -0.0"/>
    <parent link="left_hip_side_1"/>
    <child link="JX_servo_v12_8"/>
  </joint>
  <joint name="Rigid5" type="fixed">
    <origin xyz="-0.0264 -0.0085 0.0189" rpy="0.0 0.0 0.0"/>
    <parent link="JX_servo_v12_8"/>
    <child link="left_hip_front_1"/>
  </joint>
  <joint name="Rigid6" type="fixed">
    <origin xyz="0.0644 0.0239 -0.0738" rpy="0.0 0.0 0.0"/>
    <parent link="left_hip_front_1"/>
    <child link="JX_servo_v12_9"/>
  </joint>
  <joint name="left_leg_motor_2" type="continuous">
    <origin xyz="-0.0085 0.0225 0.0549" rpy="0.0 0.0 0.0"/>
    <axis xyz="0.0 -1.0 0.0"/>
    <parent link="JX_servo_v12_9"/>
    <child link="left_thigh_1"/>
  </joint>
  <joint name="left_leg_motor_3" type="continuous">
    <origin xyz="0.0 0.0 -0.124" rpy="0.0 0.0 0.0"/>
    <axis xyz="0.0 -1.0 0.0"/>
    <parent link="left_thigh_1"/>
    <child link="JX_servo_v12_11"/>
  </joint>
  <joint name="Rigid9" type="fixed">
    <origin xyz="0.0085 -0.0264 -0.0549" rpy="0.0 0.0 0.0"/>
    <parent link="JX_servo_v12_11"/>
    <child link="left_calve_1"/>
  </joint>
  <joint name="left_leg_motor_4" type="continuous">
    <origin xyz="-0.00855 0.028 -0.085005" rpy="0.0 0.0 0.0"/>
    <axis xyz="0.0 -1.0 0.0"/>
    <parent link="left_calve_1"/>
    <child link="JX_servo_v12_12"/>
  </joint>
  <joint name="Rigid11" type="fixed">
    <origin xyz="0.0085 -0.0225 0.0549" rpy="0.0 0.0 0.0"/>
    <parent link="JX_servo_v12_12"/>
    <child link="left_hip_front_2"/>
  </joint>
  <joint name="Rigid12" type="fixed">
    <origin xyz="-0.0644 -0.025 0.0" rpy="0.0 0.0 0.0"/>
    <parent link="left_hip_front_2"/>
    <child link="JX_servo_v12_13"/>
  </joint>
  <joint name="left_leg_motor_5" type="continuous">
    <origin xyz="0.0264 0.0085 -0.0549" rpy="0.0 0.0 0.0"/>
    <axis xyz="1.0 -0.0 -0.0"/>
    <parent link="JX_servo_v12_13"/>
    <child link="left_foot_1"/>
  </joint>
  <joint name="Rigid14" type="fixed">
    <origin xyz="-0.0225 -0.0595 -0.137" rpy="0.0 0.0 0.0"/>
    <parent link="torso_1"/>
    <child link="JX_servo_v12_14"/>
  </joint>
  <joint name="right_leg_motor_0" type="continuous">
    <origin xyz="0.018 0.0 -0.0264" rpy="0.0 0.0 0.0"/>
    <axis xyz="-0.0 0.0 1.0"/>
    <parent link="JX_servo_v12_14"/>
    <child link="right_hip_side_1"/>
  </joint>
  <joint name="right_leg_motor_1" type="continuous">
    <origin xyz="-0.03 0.0 -0.035336" rpy="0.0 0.0 0.0"/>
    <axis xyz="-1.0 0.0 0.0"/>
    <parent link="right_hip_side_1"/>
    <child link="JX_servo_v12_15"/>
  </joint>
  <joint name="Rigid17" type="fixed">
    <origin xyz="-0.0264 0.0085 0.0189" rpy="0.0 0.0 0.0"/>
    <parent link="JX_servo_v12_15"/>
    <child link="right_ankle_1"/>
  </joint>
  <joint name="Rigid18" type="fixed">
    <origin xyz="0.0644 -0.0239 -0.0738" rpy="0.0 0.0 0.0"/>
    <parent link="right_ankle_1"/>
    <child link="JX_servo_v12_16"/>
  </joint>
  <joint name="right_leg_motor_2" type="continuous">
    <origin xyz="-0.0085 -0.0225 0.0549" rpy="0.0 0.0 0.0"/>
    <axis xyz="0.0 -1.0 0.0"/>
    <parent link="JX_servo_v12_16"/>
    <child link="right_thigh_1"/>
  </joint>
  <joint name="right_leg_motor_3" type="continuous">
    <origin xyz="0.0 0.0 -0.124" rpy="0.0 0.0 0.0"/>
    <axis xyz="-0.0 -1.0 -0.0"/>
    <parent link="right_thigh_1"/>
    <child link="JX_servo_v12_17"/>
  </joint>
  <joint name="Rigid21" type="fixed">
    <origin xyz="0.0085 0.0264 -0.0549" rpy="0.0 0.0 0.0"/>
    <parent link="JX_servo_v12_17"/>
    <child link="right_calve_1"/>
  </joint>
  <joint name="right_leg_motor_4" type="continuous">
    <origin xyz="-0.00855 -0.028 -0.085005" rpy="0.0 0.0 0.0"/>
    <axis xyz="-0.0 -1.0 -0.0"/>
    <parent link="right_calve_1"/>
    <child link="JX_servo_v12_18"/>
  </joint>
  <joint name="Rigid23" type="fixed">
    <origin xyz="0.0085 0.0225 0.0549" rpy="0.0 0.0 0.0"/>
    <parent link="JX_servo_v12_18"/>
    <child link="right_ankle_2"/>
  </joint>
  <joint name="Rigid24" type="fixed">
    <origin xyz="-0.0644 0.025 0.0" rpy="0.0 0.0 0.0"/>
    <parent link="right_ankle_2"/>
    <child link="JX_servo_v12_19"/>
  </joint>
  <joint name="right_leg_motor_5" type="continuous">
    <origin xyz="0.0264 -0.0085 -0.0549" rpy="0.0 0.0 0.0"/>
    <axis xyz="-1.0 0.0 -0.0"/>
    <parent link="JX_servo_v12_19"/>
    <child link="right_foot_1"/>
  </joint>
  <joint name="Rigid26" type="fixed">
    <origin xyz="-0.021 0.1025 -0.0365" rpy="0.0 0.0 0.0"/>
    <parent link="torso_1"/>
    <child link="25t-servo-hub_1"/>
  </joint>
  <joint name="left_arm_motor_0" type="continuous">
    <origin xyz="0.0 0.002794 0.0" rpy="0.0 0.0 0.0"/>
    <axis xyz="0.0 -1.0 0.0"/>
    <parent link="25t-servo-hub_1"/>
    <child link="gobilda-servo_1"/>
  </joint>
  <joint name="Rigid28" type="fixed">
    <origin xyz="-0.0075 0.0369 0.0075" rpy="0.0 0.0 0.0"/>
    <parent link="gobilda-servo_1"/>
    <child link="left_bicep_1"/>
  </joint>
  <joint name="Rigid29" type="fixed">
    <origin xyz="0.0 0.0 -0.0703" rpy="0.0 0.0 0.0"/>
    <parent link="left_bicep_1"/>
    <child link="gobilda-servo_3"/>
  </joint>
  <joint name="left_arm_motor_1" type="continuous">
    <origin xyz="0.0075 -0.0369 -0.0075" rpy="0.0 0.0 0.0"/>
    <axis xyz="-0.0 -1.0 -0.0"/>
    <parent link="gobilda-servo_3"/>
    <child link="25t-servo-hub_2"/>
  </joint>
  <joint name="Rigid31" type="fixed">
    <origin xyz="0.0 -0.002794 0.0" rpy="0.0 0.0 0.0"/>
    <parent link="25t-servo-hub_2"/>
    <child link="elbow-attach_1"/>
  </joint>
  <joint name="Rigid32" type="fixed">
    <origin xyz="-0.0275 0.002 0.01" rpy="0.0 0.0 0.0"/>
    <parent link="elbow-attach_1"/>
    <child link="left_forearm_1"/>
  </joint>
  <joint name="Rigid33" type="fixed">
    <origin xyz="0.0 0.044674 0.0" rpy="0.0 0.0 0.0"/>
    <parent link="left_forearm_1"/>
    <child link="elbow-bearing_1"/>
  </joint>
  <joint name="Rigid34" type="fixed">
    <origin xyz="-0.021 -0.1125 -0.0365" rpy="0.0 0.0 0.0"/>
    <parent link="torso_1"/>
    <child link="25t-servo-hub_Mirror__1"/>
  </joint>
  <joint name="right_arm_motor_0" type="continuous">
    <origin xyz="0.0 -0.002794 0.0" rpy="0.0 0.0 0.0"/>
    <axis xyz="0.0 -1.0 0.0"/>
    <parent link="25t-servo-hub_Mirror__1"/>
    <child link="gobilda-servo_Mirror__1"/>
  </joint>
  <joint name="Rigid36" type="fixed">
    <origin xyz="-0.0075 -0.0369 0.0075" rpy="0.0 0.0 0.0"/>
    <parent link="gobilda-servo_Mirror__1"/>
    <child link="right_bicep_1"/>
  </joint>
  <joint name="Rigid37" type="fixed">
    <origin xyz="0.0 0.0 -0.0703" rpy="0.0 0.0 0.0"/>
    <parent link="right_bicep_1"/>
    <child link="gobilda-servo_Mirror__2"/>
  </joint>
  <joint name="right_arm_motor_1" type="continuous">
    <origin xyz="0.0075 0.0369 -0.0075" rpy="0.0 0.0 0.0"/>
    <axis xyz="-0.0 -1.0 0.0"/>
    <parent link="gobilda-servo_Mirror__2"/>
    <child link="25t-servo-hub_Mirror__2"/>
  </joint>
  <joint name="Rigid39" type="fixed">
    <origin xyz="0.0 0.002794 0.0" rpy="0.0 0.0 0.0"/>
    <parent link="25t-servo-hub_Mirror__2"/>
    <child link="elbow-attach_Mirror__1"/>
  </joint>
  <joint name="Rigid40" type="fixed">
    <origin xyz="-0.0275 -0.002 0.01" rpy="0.0 0.0 0.0"/>
    <parent link="elbow-attach_Mirror__1"/>
    <child link="right_forearm_1"/>
  </joint>
  <joint name="Rigid41" type="fixed">
    <origin xyz="0.0 -0.044674 0.0" rpy="0.0 0.0 0.0"/>
    <parent link="right_forearm_1"/>
    <child link="elbow-bearing_Mirror__1"/>
  </joint>
  <joint name="Rigid42" type="fixed">
    <origin xyz="0.0 -0.005 -1e-05" rpy="0.0 0.0 0.0"/>
    <parent link="torso_1"/>
    <child link="custom_servo_support__lower_neck__v2_1"/>
  </joint>
  <joint name="Rigid43" type="fixed">
    <origin xyz="-0.01715 -0.0075 0.00698" rpy="0.0 0.0 0.0"/>
    <parent link="custom_servo_support__lower_neck__v2_1"/>
    <child link="gobilda-servo_4"/>
  </joint>
  <joint name="head_motor_0" type="continuous">
    <origin xyz="0.0075 0.0075 0.0369" rpy="0.0 0.0 0.0"/>
    <axis xyz="0.0 -0.0 1.0"/>
    <parent link="gobilda-servo_4"/>
    <child link="25t-servo-hub_3"/>
  </joint>
  <joint name="Rigid45" type="fixed">
    <origin xyz="0.0 0.0 0.002794" rpy="0.0 0.0 0.0"/>
    <parent link="25t-servo-hub_3"/>
    <child link="neck_1"/>
  </joint>
  <joint name="Rigid46" type="fixed">
    <origin xyz="0.0 -0.022187 0.033817" rpy="0.0 0.0 0.0"/>
    <parent link="neck_1"/>
    <child link="25t-servo-hub_4"/>
  </joint>
  <joint name="head_motor_1" type="continuous">
    <origin xyz="0.0 0.002794 0.0" rpy="0.0 0.0 0.0"/>
    <axis xyz="-0.0 1.0 -0.0"/>
    <parent link="25t-servo-hub_4"/>
    <child link="gobilda-servo_5"/>
  </joint>
  <joint name="Rigid48" type="fixed">
    <origin xyz="-0.0075 0.0369 0.0075" rpy="0.0 0.0 0.0"/>
    <parent link="gobilda-servo_5"/>
    <child link="head_1"/>
  </joint>
  <joint name="Rigid49" type="fixed">
    <origin xyz="0.024 -0.01402 0.0135" rpy="0.0 0.0 0.0"/>
    <parent link="head_1"/>
    <child link="camera_1"/>
  </joint>
  <joint name="camera_joint" type="fixed">
    <origin xyz="0.0372 0.0 0.027" rpy="0.0 0.0 0.0"/>
    <axis xyz="1.0 -0.0 0.0"/>
    <parent link="camera_1"/>
    <child link="camera-link_1"/>
  </joint>
  <joint name="imu_joint" type="fixed">
    <origin xyz="0.0 -0.005 -0.005" rpy="0.0 0.0 0.0"/>
    <axis xyz="0.0 0.0 1.0"/>
    <parent link="torso_1"/>
    <child link="imu-link_1"/>
  </joint>
  <joint name="Rigid52" type="fixed">
    <origin xyz="-0.012 -0.004667 -0.005" rpy="0.0 0.0 0.0"/>
    <parent link="torso_1"/>
    <child link="Component32_1"/>
  </joint>
  <joint name="Rigid53" type="fixed">
    <origin xyz="0.0 0.0 -0.047" rpy="0.0 0.0 0.0"/>
    <parent link="Component32_1"/>
    <child link="TX2_board_v2_1"/>
  </joint>
</robot>
