#VRML_SIM R2022b utf8
# license: Apache License 2.0
# license url: http://www.apache.org/licenses/LICENSE-2.0
# This is a proto file for Webots for the Bez2
# Extracted from: /home/nam/catkin_ws/src/soccerbot/bez2_description/urdf/bez2_simple.urdf

PROTO Bez2 [
  field  SFVec3f     translation     0 0 0
  field  SFRotation  rotation        0 0 1 0
  field  SFString    name            "Bez2"  # Is `Robot.name`.
  field  SFString    controller      "player"  # Is `Robot.controller`.
  field  MFString    controllerArgs  []      # Is `Robot.controllerArgs`.
  field  SFString    customData      ""      # Is `Robot.customData`.
  field  SFBool      supervisor      FALSE   # Is `Robot.supervisor`.
  field  SFBool      synchronization TRUE    # Is `Robot.synchronization`.
  field  SFBool      selfCollision   FALSE   # Is `Robot.selfCollision`.
]
{
  Robot {
    translation IS translation
    rotation IS rotation
    controller IS controller
    controllerArgs IS controllerArgs
    customData IS customData
    supervisor IS supervisor
    synchronization IS synchronization
    selfCollision IS selfCollision
    children [
      Transform {
        scale 0.001000 0.001000 0.001000
        children [
          Shape {
            appearance DEF polymide_kapton PBRAppearance {
              baseColor 0.500000 0.500000 0.500000
              roughness 1.000000
              metalness 0
            }
            geometry DEF base_link Mesh {
              url "Bez2_meshes/base_link.stl"
            }
          }
        ]
      }
      HingeJoint {
        jointParameters HingeJointParameters {
          axis -0.000000 -1.000000 0.000000
          anchor 0.000000 0.072500 0.000450
        }
        device [
          RotationalMotor {
            name "left_arm_motor_0"
            maxTorque 10000
          }
          PositionSensor {
            name "left_arm_motor_0_sensor"
          }
        ]
        endPoint Solid {
          translation 0.000000 0.072500 0.000450
          children [
            Transform {
              translation -0.000000 -0.072500 -0.000450
              scale 0.001000 0.001000 0.001000
              children [
                Shape {
                  appearance DEF plastic_glossy_black PBRAppearance {
                    baseColor 0.500000 0.500000 0.500000
                    roughness 1.000000
                    metalness 0
                  }
                  geometry DEF biceps_v3_1 Mesh {
                    url "Bez2_meshes/biceps_v3_1.stl"
                  }
                }
              ]
            }
            HingeJoint {
              jointParameters HingeJointParameters {
                axis 0.000000 -1.000000 0.000000
                anchor 0.000000 0.008000 -0.090600
              }
              device [
                RotationalMotor {
                  name "left_arm_motor_1"
                  maxTorque 10000
                }
                PositionSensor {
                  name "left_arm_motor_1_sensor"
                }
              ]
              endPoint Solid {
                translation 0.000000 0.008000 -0.090600
                children [
                  Transform {
                    translation -0.000000 -0.080500 0.090150
                    scale 0.001000 0.001000 0.001000
                    children [
                      Shape {
                        appearance DEF abs_white PBRAppearance {
                          baseColor 0.500000 0.500000 0.500000
                          roughness 1.000000
                          metalness 0
                        }
                        geometry DEF Arm_Assembly-bez3_v12_2 Mesh {
                          url "Bez2_meshes/Arm_Assembly-bez3_v12_2.stl"
                        }
                      }
                    ]
                  }
                ]
                name "Arm_Assembly-bez3_v12_2"
                boundingObject Transform {
                  translation -6.999979 104.756498 -168.749934
                  rotation 0.000000 -1.000000 -0.000000 3.141593
                  children [
                    Box {
                       size 50.000000 56.673996 197.480171
                    }
                  ]
                }
                physics Physics {
                  density -1
                  mass 0.321104
                  centerOfMass [ -0.005330 0.022845 0.029751 ]
                  inertiaMatrix [
                    2.148000e-03 2.137000e-03 1.030000e-04
                    3.000000e-06 -1.750000e-04 1.600000e-05
                  ]
                }
              }
            }
          ]
          name "biceps_v3_1"
          boundingObject Transform {
            translation -0.000000 100.764498 -44.850448
            rotation 0.000000 1.000000 0.000000 3.141593
            children [
              Box {
                 size 36.000000 56.673996 125.199997
              }
            ]
          }
          physics Physics {
            density -1
            mass 0.258254
            centerOfMass [ -0.000000 0.026300 -0.038386 ]
            inertiaMatrix [
              4.370000e-04 3.940000e-04 6.400000e-05
              0.000000e+00 -0.000000e+00 3.300000e-05
            ]
          }
        }
      }
      HingeJoint {
        jointParameters HingeJointParameters {
          axis 0.000000 -1.000000 0.000000
          anchor 0.000000 -0.072500 0.000450
        }
        device [
          RotationalMotor {
            name "right_arm_motor_0"
            maxTorque 10000
          }
          PositionSensor {
            name "right_arm_motor_0_sensor"
          }
        ]
        endPoint Solid {
          translation 0.000000 -0.072500 0.000450
          children [
            Transform {
              translation -0.000000 0.072500 -0.000450
              scale 0.001000 0.001000 0.001000
              children [
                Shape {
                  appearance USE plastic_glossy_black
                  geometry DEF biceps_v3_2 Mesh {
                    url "Bez2_meshes/biceps_v3_2.stl"
                  }
                }
              ]
            }
            HingeJoint {
              jointParameters HingeJointParameters {
                axis -0.000000 -1.000000 0.000000
                anchor -0.000000 -0.008000 -0.090600
              }
              device [
                RotationalMotor {
                  name "right_arm_motor_1"
                  maxTorque 10000
                }
                PositionSensor {
                  name "right_arm_motor_1_sensor"
                }
              ]
              endPoint Solid {
                translation -0.000000 -0.008000 -0.090600
                children [
                  Transform {
                    translation 0.000000 0.080500 0.090150
                    scale 0.001000 0.001000 0.001000
                    children [
                      Shape {
                        appearance USE abs_white
                        geometry DEF Arm_Assembly-bez3_v12_1 Mesh {
                          url "Bez2_meshes/Arm_Assembly-bez3_v12_1.stl"
                        }
                      }
                    ]
                  }
                ]
                name "Arm_Assembly-bez3_v12_1"
                boundingObject Transform {
                  translation -6.999979 -104.756498 -168.749934
                  rotation 0.000000 -1.000000 -0.000000 3.141593
                  children [
                    Box {
                       size 50.000000 56.673996 197.480171
                    }
                  ]
                }
                physics Physics {
                  density -1
                  mass 0.321104
                  centerOfMass [ -0.005330 -0.025829 0.029751 ]
                  inertiaMatrix [
                    2.148000e-03 2.137000e-03 1.030000e-04
                    3.000000e-06 -1.750000e-04 1.600000e-05
                  ]
                }
              }
            }
          ]
          name "biceps_v3_2"
          boundingObject Transform {
            translation 0.000000 -100.764498 -44.850448
            rotation 1.000000 -0.000000 -0.000000 3.141593
            children [
              Box {
                 size 36.000000 56.673996 125.199997
              }
            ]
          }
          physics Physics {
            density -1
            mass 0.258254
            centerOfMass [ 0.000000 -0.026300 -0.038386 ]
            inertiaMatrix [
              4.370000e-04 3.940000e-04 6.400000e-05
              0.000000e+00 0.000000e+00 -3.300000e-05
            ]
          }
        }
      }
      HingeJoint {
        jointParameters HingeJointParameters {
          axis -0.000000 0.000000 -1.000000
          anchor 0.015970 0.037700 -0.144050
        }
        device [
          RotationalMotor {
            name "left_leg_motor_0"
            maxTorque 10000
          }
          PositionSensor {
            name "left_leg_motor_0_sensor"
          }
        ]
        endPoint Solid {
          translation 0.015970 0.037700 -0.144050
          children [
            Transform {
              translation -0.015970 -0.037700 0.144050
              scale 0.001000 0.001000 0.001000
              children [
                Shape {
                  appearance USE abs_white
                  geometry DEF Hip_Printable_v2_v10_2 Mesh {
                    url "Bez2_meshes/Hip_Printable_v2_v10_2.stl"
                  }
                }
              ]
            }
            HingeJoint {
              jointParameters HingeJointParameters {
                anchor -0.025000 0.000000 -0.032000
              }
              device [
                RotationalMotor {
                  name "left_leg_motor_1"
                  maxTorque 10000
                }
                PositionSensor {
                  name "left_leg_motor_1_sensor"
                }
              ]
              endPoint Solid {
                translation -0.025000 0.000000 -0.032000
                children [
                  Transform {
                    translation 0.009030 -0.037700 0.176050
                    scale 0.001000 0.001000 0.001000
                    children [
                      Shape {
                        appearance DEF silver_default PBRAppearance {
                          baseColor 0.500000 0.500000 0.500000
                          roughness 1.000000
                          metalness 0
                        }
                        geometry DEF hip_motors_v4_2 Mesh {
                          url "Bez2_meshes/hip_motors_v4_2.stl"
                        }
                      }
                    ]
                  }
                  HingeJoint {
                    jointParameters HingeJointParameters {
                      axis 0.000000 -1.000000 0.000000
                      anchor 0.023650 -0.020000 0.000000
                    }
                    device [
                      RotationalMotor {
                        name "left_leg_motor_2"
                        maxTorque 10000
                      }
                      PositionSensor {
                        name "left_leg_motor_2_sensor"
                      }
                    ]
                    endPoint Solid {
                      translation 0.023650 -0.020000 0.000000
                      children [
                        Transform {
                          translation -0.014620 -0.017700 0.176050
                          scale 0.001000 0.001000 0.001000
                          children [
                            Shape {
                              appearance USE abs_white
                              geometry DEF Upper_left_leg_support__bottom__v8_1 Mesh {
                                url "Bez2_meshes/Upper_left_leg_support__bottom__v8_1.stl"
                              }
                            }
                          ]
                        }
                        HingeJoint {
                          jointParameters HingeJointParameters {
                            axis 0.000000 -1.000000 0.000000
                            anchor 0.000000 -0.004500 -0.091700
                          }
                          device [
                            RotationalMotor {
                              name "left_leg_motor_3"
                              maxTorque 10000
                            }
                            PositionSensor {
                              name "left_leg_motor_3_sensor"
                            }
                          ]
                          endPoint Solid {
                            translation 0.000000 -0.004500 -0.091700
                            children [
                              Transform {
                                translation -0.014620 -0.013200 0.267750
                                scale 0.001000 0.001000 0.001000
                                children [
                                  Shape {
                                    appearance USE abs_white
                                    geometry DEF lower_leg_v4_2 Mesh {
                                      url "Bez2_meshes/lower_leg_v4_2.stl"
                                    }
                                  }
                                ]
                              }
                              HingeJoint {
                                jointParameters HingeJointParameters {
                                  axis 0.000000 -1.000000 0.000000
                                  anchor 0.000000 -0.000500 -0.108300
                                }
                                device [
                                  RotationalMotor {
                                    name "left_leg_motor_4"
                                    maxTorque 10000
                                  }
                                  PositionSensor {
                                    name "left_leg_motor_4_sensor"
                                  }
                                ]
                                endPoint Solid {
                                  translation 0.000000 -0.000500 -0.108300
                                  children [
                                    Transform {
                                      translation -0.014620 -0.012700 0.376050
                                      scale 0.001000 0.001000 0.001000
                                      children [
                                        Shape {
                                          appearance DEF steel_satin PBRAppearance {
                                            baseColor 0.500000 0.500000 0.500000
                                            roughness 1.000000
                                            metalness 0
                                          }
                                          geometry DEF ankle_motors_v4_1 Mesh {
                                            url "Bez2_meshes/ankle_motors_v4_1.stl"
                                          }
                                        }
                                      ]
                                    }
                                    HingeJoint {
                                      jointParameters HingeJointParameters {
                                        axis -1.000000 0.000000 0.000000
                                        anchor -0.084300 0.023300 0.000000
                                      }
                                      device [
                                        RotationalMotor {
                                          name "left_leg_motor_5"
                                          maxTorque 10000
                                        }
                                        PositionSensor {
                                          name "left_leg_motor_5_sensor"
                                        }
                                      ]
                                      endPoint Solid {
                                        translation -0.084300 0.023300 0.000000
                                        children [
                                          Transform {
                                            translation 0.069680 -0.036000 0.376050
                                            scale 0.001000 0.001000 0.001000
                                            children [
                                              Shape {
                                                appearance USE abs_white
                                                geometry DEF New_right_foot_upperhalf_v3_1 Mesh {
                                                  url "Bez2_meshes/New_right_foot_upperhalf_v3_1.stl"
                                                }
                                              }
                                            ]
                                          }
                                        ]
                                        name "New_right_foot_upperhalf_v3_1"
                                        boundingObject Transform {
                                          translation -17.450317 50.964000 -381.173938
                                          rotation -0.707107 0.000000 0.707107 3.141593
                                          children [
                                            Box {
                                               size 43.000000 90.000000 170.000000
                                            }
                                          ]
                                        }
                                        physics Physics {
                                          density -1
                                          mass 0.117713
                                          centerOfMass [ 0.051393 0.060000 -0.021777 ]
                                          inertiaMatrix [
                                            3.480000e-04 2.970000e-04 6.250000e-04
                                            0.000000e+00 -1.000000e-06 0.000000e+00
                                          ]
                                        }
                                      }
                                    }
                                  ]
                                  name "ankle_motors_v4_1"
                                  boundingObject Transform {
                                    translation -19.297084 36.019095 -358.618426
                                    rotation 0.552091 -0.589574 -0.589574 2.132698
                                    children [
                                      Box {
                                         size 51.456559 62.088928 109.914851
                                      }
                                    ]
                                  }
                                  physics Physics {
                                    density -1
                                    mass 0.395560
                                    centerOfMass [ -0.020543 0.023300 0.015063 ]
                                    inertiaMatrix [
                                      1.550000e-04 4.680000e-04 4.190000e-04
                                      0.000000e+00 -2.000000e-06 -0.000000e+00
                                    ]
                                  }
                                }
                              }
                            ]
                            name "lower_leg_v4_2"
                            boundingObject Transform {
                              translation 14.605380 36.420245 -322.148972
                              rotation -0.000000 -0.004148 0.999991 3.141593
                              children [
                                Box {
                                   size 40.200002 54.603680 137.714163
                                }
                              ]
                            }
                            physics Physics {
                              density -1
                              mass 0.147673
                              centerOfMass [ 0.000000 0.023192 -0.022134 ]
                              inertiaMatrix [
                                1.240000e-04 1.070000e-04 4.100000e-05
                                0.000000e+00 0.000000e+00 2.000000e-06
                              ]
                            }
                          }
                        }
                      ]
                      name "Upper_left_leg_support__bottom__v8_1"
                      boundingObject Transform {
                        translation 14.605379 37.182298 -222.773947
                        rotation -0.000000 0.000000 1.000000 3.141593
                        children [
                          Box {
                             size 27.999999 53.999997 119.558929
                          }
                        ]
                      }
                      physics Physics {
                        density -1
                        mass 0.027169
                        centerOfMass [ -0.000000 0.019462 -0.048114 ]
                        inertiaMatrix [
                          3.200000e-05 2.200000e-05 1.300000e-05
                          0.000000e+00 -0.000000e+00 -0.000000e+00
                        ]
                      }
                    }
                  }
                ]
                name "hip_motors_v4_2"
                boundingObject Transform {
                  translation -9.570970 36.162300 -187.873953
                  rotation 0.577350 0.577350 0.577350 2.094395
                  children [
                    Box {
                       size 41.000001 46.500000 76.899998
                    }
                  ]
                }
                physics Physics {
                  density -1
                  mass 0.272820
                  centerOfMass [ 0.009088 -0.000000 -0.011907 ]
                  inertiaMatrix [
                    7.400000e-05 1.780000e-04 1.530000e-04
                    -0.000000e+00 -1.000000e-06 0.000000e+00
                  ]
                }
              }
            }
          ]
          name "Hip_Printable_v2_v10_2"
          boundingObject Transform {
            translation 15.954030 37.662301 -166.405953
            rotation 0.577350 0.577350 0.577350 2.094395
            children [
              Box {
                 size 26.000000 45.000000 50.000002
              }
            ]
          }
          physics Physics {
            density -1
            mass 0.010089
            centerOfMass [ 0.000042 -0.000000 -0.014017 ]
            inertiaMatrix [
              2.000000e-06 6.000000e-06 5.000000e-06
              0.000000e+00 0.000000e+00 -0.000000e+00
            ]
          }
        }
      }
      HingeJoint {
        jointParameters HingeJointParameters {
          axis -0.000000 -0.000000 1.000000
          anchor 0.015970 -0.036800 -0.144050
        }
        device [
          RotationalMotor {
            name "right_leg_motor_0"
            maxTorque 10000
          }
          PositionSensor {
            name "right_leg_motor_0_sensor"
          }
        ]
        endPoint Solid {
          translation 0.015970 -0.036800 -0.144050
          children [
            Transform {
              translation -0.015970 0.036800 0.144050
              scale 0.001000 0.001000 0.001000
              children [
                Shape {
                  appearance USE abs_white
                  geometry DEF Hip_Printable_v2_v10_1 Mesh {
                    url "Bez2_meshes/Hip_Printable_v2_v10_1.stl"
                  }
                }
              ]
            }
            HingeJoint {
              jointParameters HingeJointParameters {
                axis -1.000000 0.000000 0.000000
                anchor -0.023500 0.000000 -0.032000
              }
              device [
                RotationalMotor {
                  name "right_leg_motor_1"
                  maxTorque 10000
                }
                PositionSensor {
                  name "right_leg_motor_1_sensor"
                }
              ]
              endPoint Solid {
                translation -0.023500 0.000000 -0.032000
                children [
                  Transform {
                    translation 0.007530 0.036800 0.176050
                    scale 0.001000 0.001000 0.001000
                    children [
                      Shape {
                        appearance USE silver_default
                        geometry DEF hip_motors_v4_1 Mesh {
                          url "Bez2_meshes/hip_motors_v4_1.stl"
                        }
                      }
                    ]
                  }
                  HingeJoint {
                    jointParameters HingeJointParameters {
                      axis 0.000000 -1.000000 0.000000
                      anchor 0.023650 0.020000 0.000000
                    }
                    device [
                      RotationalMotor {
                        name "right_leg_motor_2"
                        maxTorque 10000
                      }
                      PositionSensor {
                        name "right_leg_motor_2_sensor"
                      }
                    ]
                    endPoint Solid {
                      translation 0.023650 0.020000 0.000000
                      children [
                        Transform {
                          translation -0.016120 0.016800 0.176050
                          scale 0.001000 0.001000 0.001000
                          children [
                            Shape {
                              appearance USE abs_white
                              geometry DEF Upper_left_leg_support__bottom__v8_2 Mesh {
                                url "Bez2_meshes/Upper_left_leg_support__bottom__v8_2.stl"
                              }
                            }
                          ]
                        }
                        HingeJoint {
                          jointParameters HingeJointParameters {
                            axis 0.000000 -1.000000 0.000000
                            anchor 0.000000 0.004500 -0.091700
                          }
                          device [
                            RotationalMotor {
                              name "right_leg_motor_3"
                              maxTorque 10000
                            }
                            PositionSensor {
                              name "right_leg_motor_3_sensor"
                            }
                          ]
                          endPoint Solid {
                            translation 0.000000 0.004500 -0.091700
                            children [
                              Transform {
                                translation -0.016120 0.012300 0.267750
                                scale 0.001000 0.001000 0.001000
                                children [
                                  Shape {
                                    appearance USE abs_white
                                    geometry DEF lower_leg_v4_1 Mesh {
                                      url "Bez2_meshes/lower_leg_v4_1.stl"
                                    }
                                  }
                                ]
                              }
                              HingeJoint {
                                jointParameters HingeJointParameters {
                                  axis 0.000000 -1.000000 0.000000
                                  anchor 0.000000 0.000500 -0.108300
                                }
                                device [
                                  RotationalMotor {
                                    name "right_leg_motor_4"
                                    maxTorque 10000
                                  }
                                  PositionSensor {
                                    name "right_leg_motor_4_sensor"
                                  }
                                ]
                                endPoint Solid {
                                  translation 0.000000 0.000500 -0.108300
                                  children [
                                    Transform {
                                      translation -0.016120 0.011800 0.376050
                                      scale 0.001000 0.001000 0.001000
                                      children [
                                        Shape {
                                          appearance USE steel_satin
                                          geometry DEF ankle_motors_v4_2 Mesh {
                                            url "Bez2_meshes/ankle_motors_v4_2.stl"
                                          }
                                        }
                                      ]
                                    }
                                    HingeJoint {
                                      jointParameters HingeJointParameters {
                                        anchor -0.084300 -0.023300 0.000000
                                      }
                                      device [
                                        RotationalMotor {
                                          name "right_leg_motor_5"
                                          maxTorque 10000
                                        }
                                        PositionSensor {
                                          name "right_leg_motor_5_sensor"
                                        }
                                      ]
                                      endPoint Solid {
                                        translation -0.084300 -0.023300 0.000000
                                        children [
                                          Transform {
                                            translation 0.068180 0.035100 0.376050
                                            scale 0.001000 0.001000 0.001000
                                            children [
                                              Shape {
                                                appearance USE abs_white
                                                geometry DEF New_left_foot_upperhalf_v5_1 Mesh {
                                                  url "Bez2_meshes/New_left_foot_upperhalf_v5_1.stl"
                                                }
                                              }
                                            ]
                                          }
                                        ]
                                        name "New_left_foot_upperhalf_v5_1"
                                        boundingObject Transform {
                                          translation -15.951824 -50.064899 -381.173938
                                          rotation 0.000000 1.000000 -0.000000 1.570796
                                          children [
                                            Box {
                                               size 43.000000 89.999999 170.000000
                                            }
                                          ]
                                        }
                                        physics Physics {
                                          density -1
                                          mass 0.058856
                                          centerOfMass [ 0.051393 -0.012181 -0.021777 ]
                                          inertiaMatrix [
                                            3.900000e-05 1.490000e-04 1.780000e-04
                                            -0.000000e+00 -0.000000e+00 -3.000000e-06
                                          ]
                                        }
                                      }
                                    }
                                  ]
                                  name "ankle_motors_v4_2"
                                  boundingObject Transform {
                                    translation -17.798586 -35.119994 -358.618426
                                    rotation -0.602609 0.564297 -0.564297 2.056921
                                    children [
                                      Box {
                                         size 51.456558 62.088928 109.914847
                                      }
                                    ]
                                  }
                                  physics Physics {
                                    density -1
                                    mass 0.395560
                                    centerOfMass [ -0.020543 -0.023300 0.015063 ]
                                    inertiaMatrix [
                                      1.550000e-04 4.680000e-04 4.190000e-04
                                      0.000000e+00 -2.000000e-06 -0.000000e+00
                                    ]
                                  }
                                }
                              }
                            ]
                            name "lower_leg_v4_1"
                            boundingObject Transform {
                              translation 16.103880 -35.521144 -322.148972
                              rotation 0.000000 -0.004148 -0.999991 3.141593
                              children [
                                Box {
                                   size 40.200002 54.603678 137.714163
                                }
                              ]
                            }
                            physics Physics {
                              density -1
                              mass 0.147673
                              centerOfMass [ -0.000000 -0.023192 -0.022134 ]
                              inertiaMatrix [
                                1.240000e-04 1.070000e-04 4.100000e-05
                                0.000000e+00 -0.000000e+00 -2.000000e-06
                              ]
                            }
                          }
                        }
                      ]
                      name "Upper_left_leg_support__bottom__v8_2"
                      boundingObject Transform {
                        translation 16.103879 -36.283200 -222.773947
                        rotation 0.000000 1.000000 0.000000 3.141593
                        children [
                          Box {
                             size 28.000000 53.999999 119.558929
                          }
                        ]
                      }
                      physics Physics {
                        density -1
                        mass 0.027169
                        centerOfMass [ -0.000000 -0.019538 -0.048114 ]
                        inertiaMatrix [
                          3.200000e-05 2.200000e-05 1.300000e-05
                          0.000000e+00 -0.000000e+00 -0.000000e+00
                        ]
                      }
                    }
                  }
                ]
                name "hip_motors_v4_1"
                boundingObject Transform {
                  translation -8.072470 -35.263200 -187.873953
                  rotation 0.577350 -0.577350 -0.577350 2.094395
                  children [
                    Box {
                       size 40.999999 46.500000 76.899998
                    }
                  ]
                }
                physics Physics {
                  density -1
                  mass 0.272820
                  centerOfMass [ 0.009088 -0.000000 -0.011907 ]
                  inertiaMatrix [
                    7.400000e-05 1.780000e-04 1.530000e-04
                    -0.000000e+00 -1.000000e-06 0.000000e+00
                  ]
                }
              }
            }
          ]
          name "Hip_Printable_v2_v10_1"
          boundingObject Transform {
            translation 15.954030 -36.763199 -166.405953
            rotation 0.577350 0.577350 0.577350 2.094395
            children [
              Box {
                 size 26.000000 45.000000 50.000002
              }
            ]
          }
          physics Physics {
            density -1
            mass 0.010089
            centerOfMass [ 0.000042 -0.000000 -0.014017 ]
            inertiaMatrix [
              2.000000e-06 6.000000e-06 5.000000e-06
              0.000000e+00 0.000000e+00 -0.000000e+00
            ]
          }
        }
      }
      HingeJoint {
        jointParameters HingeJointParameters {
          axis 0.000000 0.000000 -1.000000
          anchor 0.033250 -0.000333 0.075624
        }
        device [
          RotationalMotor {
            name "head_motor_0"
            maxTorque 10000
          }
          PositionSensor {
            name "head_motor_0_sensor"
          }
        ]
        endPoint Solid {
          translation 0.033250 -0.000333 0.075624
          children [
            Transform {
              translation -0.033250 0.000333 -0.075624
              scale 0.001000 0.001000 0.001000
              children [
                Shape {
                  appearance USE abs_white
                  geometry DEF custom_servo_support__middle_neck__v9_1 Mesh {
                    url "Bez2_meshes/custom_servo_support__middle_neck__v9_1.stl"
                  }
                }
              ]
            }
            HingeJoint {
              jointParameters HingeJointParameters {
                axis -0.000000 1.000000 0.000000
                anchor 0.000000 -0.022187 0.033817
              }
              device [
                RotationalMotor {
                  name "head_motor_1"
                  maxTorque 10000
                }
                PositionSensor {
                  name "head_motor_1_sensor"
                }
              ]
              endPoint Solid {
                translation 0.000000 -0.022187 0.033817
                children [
                  Transform {
                    translation -0.033250 0.022520 -0.109441
                    scale 0.001000 0.001000 0.001000
                    children [
                      Shape {
                        appearance USE plastic_glossy_black
                        geometry DEF head_v4_1 Mesh {
                          url "Bez2_meshes/head_v4_1.stl"
                        }
                      }
                    ]
                  }
                  HingeJoint {
                    jointParameters HingeJointParameters {
                      anchor 0.034400 0.025674 0.048000
                    }
                    device [
                      RotationalMotor {
                        name "head_camera"
                        maxTorque 10000
                      }
                      PositionSensor {
                        name "head_camera_sensor"
                      }
                    ]
                    endPoint Solid {
                      translation 0.034400 0.025674 0.048000
                      children [
                        Transform {
                          translation -0.067650 -0.003154 -0.157441
                          scale 0.001000 0.001000 0.001000
                          children [
                            Shape {
                              appearance USE steel_satin
                              geometry DEF camera_point_1 Mesh {
                                url "Bez2_meshes/camera_point_1.stl"
                              }
                            }
                          ]
                        }
                      ]
                      name "camera_point_1"
                      boundingObject Transform {
                        translation 66.582352 3.150512 157.284026
                        rotation 0.000000 0.707107 0.707107 3.141593
                        children [
                          Box {
                             size 4.000000 4.000000 4.000000
                          }
                        ]
                      }
                      physics Physics {
                        density -1
                        mass 0.000502
                        centerOfMass [ -0.001000 -0.000000 0.000000 ]
                      }
                    }
                  }
                ]
                name "head_v4_1"
                boundingObject Transform {
                  translation 30.566751 3.176187 133.582026
                  rotation 1.000000 0.000000 0.000000 1.570796
                  children [
                    Box {
                       size 76.100001 76.500000 94.000000
                    }
                  ]
                }
                physics Physics {
                  density -1
                  mass 0.293385
                  centerOfMass [ 0.003749 0.024245 0.024989 ]
                  inertiaMatrix [
                    2.300000e-04 2.390000e-04 1.940000e-04
                    -2.000000e-06 -7.600000e-05 -1.100000e-05
                  ]
                }
              }
            }
          ]
          name "custom_servo_support__middle_neck__v9_1"
          boundingObject Transform {
            translation 33.216750 1.666999 99.668589
            rotation 0.000000 0.707107 0.707107 3.141593
            children [
              Box {
                 size 35.000000 48.240425 56.374001
              }
            ]
          }
          physics Physics {
            density -1
            mass 0.019595
            centerOfMass [ -0.000000 0.001560 0.014703 ]
            inertiaMatrix [
              1.400000e-05 6.000000e-06 1.200000e-05
              -0.000000e+00 -0.000000e+00 0.000000e+00
            ]
          }
        }
      }
      HingeJoint {
        jointParameters HingeJointParameters {
          axis 0.000000 0.000000 1.000000
          anchor 0.013000 0.000000 0.028950
        }
        device [
          RotationalMotor {
            name "torso_imu"
            maxTorque 10000
          }
          PositionSensor {
            name "torso_imu_sensor"
          }
        ]
        endPoint Solid {
          translation 0.013000 0.000000 0.028950
          children [
            Transform {
              translation -0.013000 0.000000 -0.028950
              scale 0.001000 0.001000 0.001000
              children [
                Shape {
                  appearance USE steel_satin
                  geometry DEF imu_1 Mesh {
                    url "Bez2_meshes/imu_1.stl"
                  }
                }
              ]
            }
          ]
          name "imu_1"
          boundingObject Transform {
            translation 14.987000 -0.000000 -14.078950
            rotation -0.000000 -1.000000 -0.000000 1.570796
            children [
              Box {
                 size 3.999999 4.000000 4.000000
              }
            ]
          }
          physics Physics {
            density -1
            mass 0.000502
            centerOfMass [ 0.002000 -0.000000 -0.043000 ]
          }
        }
      }
    ]
    name IS name
    boundingObject Transform {
      translation 6.000000 0.000000 -34.713001
      children [
        Box {
           size 124.000000 145.000000 220.674004
        }
      ]
    }
    physics Physics {
      density -1
      mass 1.494053
      centerOfMass [ 0.005344 0.001160 -0.043276 ]
      inertiaMatrix [
        6.599000e-03 5.741000e-03 3.932000e-03
        0.000000e+00 0.000000e+00 0.000000e+00
      ]
    }
  }
}
