<?xml version="1.0" ?>
<robot name="bez2" version="1.0">
  <material name="silver_default">
    <color rgba="0.7 0.7 0.7 1.0"/>
  </material>
  <material name="polymide_kapton">
    <color rgba="0.7843137254901961 0.5568627450980392 0.027450980392156862 1.0"/>
  </material>
  <material name="plastic_glossy_black">
    <color rgba="0.09803921568627451 0.09803921568627451 0.09803921568627451 1.0"/>
  </material>
  <material name="abs_white">
    <color rgba="0.9647058823529412 0.9647058823529412 0.9529411764705882 1.0"/>
  </material>
  <material name="steel_satin">
    <color rgba="0.6274509803921569 0.6274509803921569 0.6274509803921569 1.0"/>
  </material>
  <transmission name="left_arm_motor_0_tran">
    <type>transmission_interface/SimpleTransmission</type>
    <joint name="left_arm_motor_0">
      <hardwareInterface>hardware_interface/EffortJointInterface</hardwareInterface>
    </joint>
    <actuator name="left_arm_motor_0_actr">
      <mechanicalReduction>1.0</mechanicalReduction>
    </actuator>
  </transmission>
  <transmission name="left_arm_motor_1_tran">
    <type>transmission_interface/SimpleTransmission</type>
    <joint name="left_arm_motor_1">
      <hardwareInterface>hardware_interface/EffortJointInterface</hardwareInterface>
    </joint>
    <actuator name="left_arm_motor_1_actr">
      <mechanicalReduction>1.0</mechanicalReduction>
    </actuator>
  </transmission>
  <transmission name="right_arm_motor_0_tran">
    <type>transmission_interface/SimpleTransmission</type>
    <joint name="right_arm_motor_0">
      <hardwareInterface>hardware_interface/EffortJointInterface</hardwareInterface>
    </joint>
    <actuator name="right_arm_motor_0_actr">
      <mechanicalReduction>1.0</mechanicalReduction>
    </actuator>
  </transmission>
  <transmission name="right_arm_motor_1_tran">
    <type>transmission_interface/SimpleTransmission</type>
    <joint name="right_arm_motor_1">
      <hardwareInterface>hardware_interface/EffortJointInterface</hardwareInterface>
    </joint>
    <actuator name="right_arm_motor_1_actr">
      <mechanicalReduction>1.0</mechanicalReduction>
    </actuator>
  </transmission>
  <transmission name="right_leg_motor_0_tran">
    <type>transmission_interface/SimpleTransmission</type>
    <joint name="right_leg_motor_0">
      <hardwareInterface>hardware_interface/EffortJointInterface</hardwareInterface>
    </joint>
    <actuator name="right_leg_motor_0_actr">
      <mechanicalReduction>1.0</mechanicalReduction>
    </actuator>
  </transmission>
  <transmission name="left_leg_motor_0_tran">
    <type>transmission_interface/SimpleTransmission</type>
    <joint name="left_leg_motor_0">
      <hardwareInterface>hardware_interface/EffortJointInterface</hardwareInterface>
    </joint>
    <actuator name="left_leg_motor_0_actr">
      <mechanicalReduction>1.0</mechanicalReduction>
    </actuator>
  </transmission>
  <transmission name="right_leg_motor_1_tran">
    <type>transmission_interface/SimpleTransmission</type>
    <joint name="right_leg_motor_1">
      <hardwareInterface>hardware_interface/EffortJointInterface</hardwareInterface>
    </joint>
    <actuator name="right_leg_motor_1_actr">
      <mechanicalReduction>1.0</mechanicalReduction>
    </actuator>
  </transmission>
  <transmission name="left_leg_motor_1_tran">
    <type>transmission_interface/SimpleTransmission</type>
    <joint name="left_leg_motor_1">
      <hardwareInterface>hardware_interface/EffortJointInterface</hardwareInterface>
    </joint>
    <actuator name="left_leg_motor_1_actr">
      <mechanicalReduction>1.0</mechanicalReduction>
    </actuator>
  </transmission>
  <transmission name="left_leg_motor_2_tran">
    <type>transmission_interface/SimpleTransmission</type>
    <joint name="left_leg_motor_2">
      <hardwareInterface>hardware_interface/EffortJointInterface</hardwareInterface>
    </joint>
    <actuator name="left_leg_motor_2_actr">
      <mechanicalReduction>1.0</mechanicalReduction>
    </actuator>
  </transmission>
  <transmission name="right_leg_motor_2_tran">
    <type>transmission_interface/SimpleTransmission</type>
    <joint name="right_leg_motor_2">
      <hardwareInterface>hardware_interface/EffortJointInterface</hardwareInterface>
    </joint>
    <actuator name="right_leg_motor_2_actr">
      <mechanicalReduction>1.0</mechanicalReduction>
    </actuator>
  </transmission>
  <transmission name="right_leg_motor_5_tran">
    <type>transmission_interface/SimpleTransmission</type>
    <joint name="right_leg_motor_5">
      <hardwareInterface>hardware_interface/EffortJointInterface</hardwareInterface>
    </joint>
    <actuator name="right_leg_motor_5_actr">
      <mechanicalReduction>1.0</mechanicalReduction>
    </actuator>
  </transmission>
  <transmission name="left_leg_motor_5_tran">
    <type>transmission_interface/SimpleTransmission</type>
    <joint name="left_leg_motor_5">
      <hardwareInterface>hardware_interface/EffortJointInterface</hardwareInterface>
    </joint>
    <actuator name="left_leg_motor_5_actr">
      <mechanicalReduction>1.0</mechanicalReduction>
    </actuator>
  </transmission>
  <transmission name="head_motor_0_tran">
    <type>transmission_interface/SimpleTransmission</type>
    <joint name="head_motor_0">
      <hardwareInterface>hardware_interface/EffortJointInterface</hardwareInterface>
    </joint>
    <actuator name="head_motor_0_actr">
      <mechanicalReduction>1.0</mechanicalReduction>
    </actuator>
  </transmission>
  <transmission name="head_motor_1_tran">
    <type>transmission_interface/SimpleTransmission</type>
    <joint name="head_motor_1">
      <hardwareInterface>hardware_interface/EffortJointInterface</hardwareInterface>
    </joint>
    <actuator name="head_motor_1_actr">
      <mechanicalReduction>1.0</mechanicalReduction>
    </actuator>
  </transmission>
  <transmission name="right_leg_motor_3_tran">
    <type>transmission_interface/SimpleTransmission</type>
    <joint name="right_leg_motor_3">
      <hardwareInterface>hardware_interface/EffortJointInterface</hardwareInterface>
    </joint>
    <actuator name="right_leg_motor_3_actr">
      <mechanicalReduction>1.0</mechanicalReduction>
    </actuator>
  </transmission>
  <transmission name="left_leg_motor_3_tran">
    <type>transmission_interface/SimpleTransmission</type>
    <joint name="left_leg_motor_3">
      <hardwareInterface>hardware_interface/EffortJointInterface</hardwareInterface>
    </joint>
    <actuator name="left_leg_motor_3_actr">
      <mechanicalReduction>1.0</mechanicalReduction>
    </actuator>
  </transmission>
  <transmission name="left_leg_motor_4_tran">
    <type>transmission_interface/SimpleTransmission</type>
    <joint name="left_leg_motor_4">
      <hardwareInterface>hardware_interface/EffortJointInterface</hardwareInterface>
    </joint>
    <actuator name="left_leg_motor_4_actr">
      <mechanicalReduction>1.0</mechanicalReduction>
    </actuator>
  </transmission>
  <transmission name="right_leg_motor_4_tran">
    <type>transmission_interface/SimpleTransmission</type>
    <joint name="right_leg_motor_4">
      <hardwareInterface>hardware_interface/EffortJointInterface</hardwareInterface>
    </joint>
    <actuator name="right_leg_motor_4_actr">
      <mechanicalReduction>1.0</mechanicalReduction>
    </actuator>
  </transmission>
  <transmission name="camera_joint_tran">
    <type>transmission_interface/SimpleTransmission</type>
    <joint name="camera_joint">
      <hardwareInterface>hardware_interface/EffortJointInterface</hardwareInterface>
    </joint>
    <actuator name="camera_joint_actr">
      <mechanicalReduction>1.0</mechanicalReduction>
    </actuator>
  </transmission>
  <transmission name="imu_joint_tran">
    <type>transmission_interface/SimpleTransmission</type>
    <joint name="imu_joint">
      <hardwareInterface>hardware_interface/EffortJointInterface</hardwareInterface>
    </joint>
    <actuator name="imu_joint_actr">
      <mechanicalReduction>1.0</mechanicalReduction>
    </actuator>
  </transmission>
  <gazebo>
    <plugin filename="libgazebo_ros_control.so" name="control"/>
  </gazebo>
  <gazebo reference="base_link">
    <material>Gazebo/Silver</material>
    <mu1>0.2</mu1>
    <mu2>0.2</mu2>
    <selfCollide>true</selfCollide>
    <gravity>true</gravity>
  </gazebo>
  <gazebo reference="biceps_v3_1">
    <material>Gazebo/Silver</material>
    <mu1>0.2</mu1>
    <mu2>0.2</mu2>
    <selfCollide>true</selfCollide>
  </gazebo>
  <gazebo reference="Arm_Assembly-bez3_v12_2">
    <material>Gazebo/Silver</material>
    <mu1>0.2</mu1>
    <mu2>0.2</mu2>
    <selfCollide>true</selfCollide>
  </gazebo>
  <gazebo reference="biceps_v3_2">
    <material>Gazebo/Silver</material>
    <mu1>0.2</mu1>
    <mu2>0.2</mu2>
    <selfCollide>true</selfCollide>
  </gazebo>
  <gazebo reference="Arm_Assembly-bez3_v12_1">
    <material>Gazebo/Silver</material>
    <mu1>0.2</mu1>
    <mu2>0.2</mu2>
    <selfCollide>true</selfCollide>
  </gazebo>
  <gazebo reference="Hip_Printable_v2_v10_1">
    <material>Gazebo/Silver</material>
    <mu1>0.2</mu1>
    <mu2>0.2</mu2>
    <selfCollide>true</selfCollide>
  </gazebo>
  <gazebo reference="Hip_Printable_v2_v10_2">
    <material>Gazebo/Silver</material>
    <mu1>0.2</mu1>
    <mu2>0.2</mu2>
    <selfCollide>true</selfCollide>
  </gazebo>
  <gazebo reference="hip_motors_v4_1">
    <material>Gazebo/Silver</material>
    <mu1>0.2</mu1>
    <mu2>0.2</mu2>
    <selfCollide>true</selfCollide>
  </gazebo>
  <gazebo reference="hip_motors_v4_2">
    <material>Gazebo/Silver</material>
    <mu1>0.2</mu1>
    <mu2>0.2</mu2>
    <selfCollide>true</selfCollide>
  </gazebo>
  <gazebo reference="Upper_left_leg_support__bottom__v8_1">
    <material>Gazebo/Silver</material>
    <mu1>0.2</mu1>
    <mu2>0.2</mu2>
    <selfCollide>true</selfCollide>
  </gazebo>
  <gazebo reference="Upper_left_leg_support__bottom__v8_2">
    <material>Gazebo/Silver</material>
    <mu1>0.2</mu1>
    <mu2>0.2</mu2>
    <selfCollide>true</selfCollide>
  </gazebo>
  <gazebo reference="New_left_foot_upperhalf_v5_1">
    <material>Gazebo/Silver</material>
    <mu1>0.2</mu1>
    <mu2>0.2</mu2>
    <selfCollide>true</selfCollide>
  </gazebo>
  <gazebo reference="New_right_foot_upperhalf_v3_1">
    <material>Gazebo/Silver</material>
    <mu1>0.2</mu1>
    <mu2>0.2</mu2>
    <selfCollide>true</selfCollide>
  </gazebo>
  <gazebo reference="neck_v4_1">
    <material>Gazebo/Silver</material>
    <mu1>0.2</mu1>
    <mu2>0.2</mu2>
    <selfCollide>true</selfCollide>
  </gazebo>
  <gazebo reference="custom_servo_support__middle_neck__v9_1">
    <material>Gazebo/Silver</material>
    <mu1>0.2</mu1>
    <mu2>0.2</mu2>
    <selfCollide>true</selfCollide>
  </gazebo>
  <gazebo reference="head_v4_1">
    <material>Gazebo/Silver</material>
    <mu1>0.2</mu1>
    <mu2>0.2</mu2>
    <selfCollide>true</selfCollide>
  </gazebo>
  <gazebo reference="lower_leg_v4_1">
    <material>Gazebo/Silver</material>
    <mu1>0.2</mu1>
    <mu2>0.2</mu2>
    <selfCollide>true</selfCollide>
  </gazebo>
  <gazebo reference="lower_leg_v4_2">
    <material>Gazebo/Silver</material>
    <mu1>0.2</mu1>
    <mu2>0.2</mu2>
    <selfCollide>true</selfCollide>
  </gazebo>
  <gazebo reference="ankle_motors_v4_1">
    <material>Gazebo/Silver</material>
    <mu1>0.2</mu1>
    <mu2>0.2</mu2>
    <selfCollide>true</selfCollide>
  </gazebo>
  <gazebo reference="ankle_motors_v4_2">
    <material>Gazebo/Silver</material>
    <mu1>0.2</mu1>
    <mu2>0.2</mu2>
    <selfCollide>true</selfCollide>
  </gazebo>
  <gazebo reference="camera_point_1">
    <material>Gazebo/Silver</material>
    <mu1>0.2</mu1>
    <mu2>0.2</mu2>
    <selfCollide>true</selfCollide>
  </gazebo>
  <gazebo reference="imu_1">
    <material>Gazebo/Silver</material>
    <mu1>0.2</mu1>
    <mu2>0.2</mu2>
    <selfCollide>true</selfCollide>
  </gazebo>
  <link name="base_link">
    <inertial>
      <origin xyz="0.07343372628291743 0.07159927292954832 0.020872010814779768" rpy="0.0 0.0 0.0"/>
      <mass value="1.3874949527504563"/>
      <inertia ixx="0.004586" ixy="-8e-06" ixz="0.000118" iyy="0.005498" iyz="0.000146" izz="0.00387"/>
    </inertial>
    <visual>
      <origin xyz="0.0 0.0 0.0" rpy="0.0 0.0 0.0"/>
      <geometry>
        <mesh filename="package://bez2_description/meshes/base_link.stl" scale="0.001 0.001 0.001"/>
      </geometry>
      <material name="polymide_kapton"/>
    </visual>
    <collision>
      <origin xyz="0.0721593237540219 0.06944389967247844 0.013556104153394704" rpy="3.141592653589793 -0.0 1.5707963267948966"/>
      <geometry>
        <box size="0.12400000635534526 0.14500000345287845 0.17400000244379044"/>
      </geometry>
    </collision>
  </link>
  <link name="biceps_v3_1">
    <inertial>
      <origin xyz="0.026300253416251113 -1.0338235605089618e-07 -0.03838594777031868" rpy="0.0 0.0 0.0"/>
      <mass value="0.25825416029102555"/>
      <inertia ixx="0.000394" ixy="-0.0" ixz="3.3e-05" iyy="0.000437" iyz="0.0" izz="6.4e-05"/>
    </inertial>
    <visual>
      <origin xyz="-0.144659 -0.075444 -0.072056" rpy="0.0 0.0 0.0"/>
      <geometry>
        <mesh filename="package://bez2_description/meshes/biceps_v3_1.stl" scale="0.001 0.001 0.001"/>
      </geometry>
      <material name="plastic_glossy_black"/>
    </visual>
    <collision>
      <origin xyz="0.02833732728099822 -1.0446631908134218e-07 -0.04529989778077602" rpy="3.141592653589793 -0.0 -1.5707963267948966"/>
      <geometry>
        <box size="0.03599999472498894 0.05667400360107421 0.12519999966025352"/>
      </geometry>
    </collision>
  </link>
  <link name="Arm_Assembly-bez3_v12_2">
    <inertial>
      <origin xyz="0.02284504145700883 0.005329912793864702 0.029751383749166617" rpy="0.0 0.0 0.0"/>
      <mass value="0.32110352957731503"/>
      <inertia ixx="0.002137" ixy="-3e-06" ixz="1.6e-05" iyy="0.002148" iyz="0.000175" izz="0.000103"/>
    </inertial>
    <visual>
      <origin xyz="-0.152659 -0.075444 0.018544" rpy="0.0 0.0 0.0"/>
      <geometry>
        <mesh filename="package://bez2_description/meshes/Arm_Assembly-bez3_v12_2.stl" scale="0.001 0.001 0.001"/>
      </geometry>
      <material name="abs_white"/>
    </visual>
    <collision>
      <origin xyz="0.024337320486068736 0.006999876191973689 -0.0786998984317705" rpy="3.141592653589793 -0.0 1.5707963267948966"/>
      <geometry>
        <box size="0.05000000074505805 0.056674003601074226 0.19750000373460352"/>
      </geometry>
    </collision>
  </link>
  <link name="biceps_v3_2">
    <inertial>
      <origin xyz="-0.026299609355872014 -1.0338333342185813e-07 -0.03838594777031868" rpy="0.0 0.0 0.0"/>
      <mass value="0.25825416029102555"/>
      <inertia ixx="0.000394" ixy="-0.0" ixz="-3.3e-05" iyy="0.000437" iyz="-0.0" izz="6.4e-05"/>
    </inertial>
    <visual>
      <origin xyz="0.000341 -0.075444 -0.072056" rpy="0.0 0.0 0.0"/>
      <geometry>
        <mesh filename="package://bez2_description/meshes/biceps_v3_2.stl" scale="0.001 0.001 0.001"/>
      </geometry>
      <material name="plastic_glossy_black"/>
    </visual>
    <collision>
      <origin xyz="-0.02833667782299779 -1.0446631908134218e-07 -0.04529989778077602" rpy="-3.141592653589793 6.123233995736766e-17 -1.5707963267948968"/>
      <geometry>
        <box size="0.03599999472498894 0.05667399970116094 0.12519999966025352"/>
      </geometry>
    </collision>
  </link>
  <link name="Arm_Assembly-bez3_v12_1">
    <inertial>
      <origin xyz="-0.025828958542993025 0.005329912793873015 0.02975138374916475" rpy="0.0 0.0 0.0"/>
      <mass value="0.32110352957731503"/>
      <inertia ixx="0.002137" ixy="-3e-06" ixz="1.6e-05" iyy="0.002148" iyz="0.000175" izz="0.000103"/>
    </inertial>
    <visual>
      <origin xyz="0.008341 -0.075444 0.018544" rpy="0.0 0.0 0.0"/>
      <geometry>
        <mesh filename="package://bez2_description/meshes/Arm_Assembly-bez3_v12_1.stl" scale="0.001 0.001 0.001"/>
      </geometry>
      <material name="abs_white"/>
    </visual>
    <collision>
      <origin xyz="-0.024336678158506757 0.006999876191973689 -0.0786998984317705" rpy="3.141592653589793 -0.0 1.5707963267948966"/>
      <geometry>
        <box size="0.05000000074505806 0.05667400034144522 0.19750000373460352"/>
      </geometry>
    </collision>
  </link>
  <link name="Hip_Printable_v2_v10_1">
    <inertial>
      <origin xyz="3.220301637574252e-07 -4.2278800908499004e-05 -0.014017264198397453" rpy="0.0 0.0 0.0"/>
      <mass value="0.010089224750638792"/>
      <inertia ixx="6e-06" ixy="-0.0" ixz="-0.0" iyy="2e-06" iyz="-0.0" izz="5e-06"/>
    </inertial>
    <visual>
      <origin xyz="-0.035359 -0.059474 0.072444" rpy="0.0 0.0 0.0"/>
      <geometry>
        <mesh filename="package://bez2_description/meshes/Hip_Printable_v2_v10_1.stl" scale="0.001 0.001 0.001"/>
      </geometry>
      <material name="abs_white"/>
    </visual>
    <collision>
      <origin xyz="3.2302474976125817e-07 -1.0173821449188658e-07 -0.022499895936012274" rpy="1.5707963267948966 -0.0 3.141592653589793"/>
      <geometry>
        <box size="0.026000000536441806 0.04500000178813934 0.05000000447034835"/>
      </geometry>
    </collision>
  </link>
  <link name="Hip_Printable_v2_v10_2">
    <inertial>
      <origin xyz="3.220301620365795e-07 -4.227880091287051e-05 -0.01401726419839748" rpy="0.0 0.0 0.0"/>
      <mass value="0.010089224750638792"/>
      <inertia ixx="6e-06" ixy="-0.0" ixz="-0.0" iyy="2e-06" iyz="-0.0" izz="5e-06"/>
    </inertial>
    <visual>
      <origin xyz="-0.109859 -0.059474 0.072444" rpy="0.0 0.0 0.0"/>
      <geometry>
        <mesh filename="package://bez2_description/meshes/Hip_Printable_v2_v10_2.stl" scale="0.001 0.001 0.001"/>
      </geometry>
      <material name="abs_white"/>
    </visual>
    <collision>
      <origin xyz="3.212664127366649e-07 -1.0173821448494769e-07 -0.022499895936012274" rpy="1.5707963267948966 -0.0 3.141592653589793"/>
      <geometry>
        <box size="0.02600000053644181 0.04500000178813934 0.05000000447034836"/>
      </geometry>
    </collision>
  </link>
  <link name="hip_motors_v4_1">
    <inertial>
      <origin xyz="2.491527500980695e-07 -0.009088099875617373 -0.011907281385175342" rpy="0.0 0.0 0.0"/>
      <mass value="0.2728199051639206"/>
      <inertia ixx="0.000178" ixy="0.0" ixz="0.0" iyy="7.4e-05" iyz="1e-06" izz="0.000153"/>
    </inertial>
    <visual>
      <origin xyz="-0.035359 -0.082974 0.104444" rpy="0.0 0.0 0.0"/>
      <geometry>
        <mesh filename="package://bez2_description/meshes/hip_motors_v4_1.stl" scale="0.001 0.001 0.001"/>
      </geometry>
      <material name="silver_default"/>
    </visual>
    <collision>
      <origin xyz="0.0015003223392963463 0.0005498955914974152 -0.01199989852881432" rpy="1.5707963267948966 -0.0 3.141592653589793"/>
      <geometry>
        <box size="0.04100000113248826 0.04650000482797623 0.07689999788999557"/>
      </geometry>
    </collision>
  </link>
  <link name="hip_motors_v4_2">
    <inertial>
      <origin xyz="2.491527557740847e-07 -0.009088099875621716 -0.011907281385175342" rpy="0.0 0.0 0.0"/>
      <mass value="0.2728199051639206"/>
      <inertia ixx="0.000178" ixy="0.0" ixz="0.0" iyy="7.4e-05" iyz="1e-06" izz="0.000153"/>
    </inertial>
    <visual>
      <origin xyz="-0.109859 -0.084474 0.104444" rpy="0.0 0.0 0.0"/>
      <geometry>
        <mesh filename="package://bez2_description/meshes/hip_motors_v4_2.stl" scale="0.001 0.001 0.001"/>
      </geometry>
      <material name="silver_default"/>
    </visual>
    <collision>
      <origin xyz="-0.00149967432284355 0.000549896768689162 -0.01199989852881432" rpy="1.5707963267948966 -0.0 6.123233995736766e-17"/>
      <geometry>
        <box size="0.04100000113248826 0.04650000482797622 0.07690000161528589"/>
      </geometry>
    </collision>
  </link>
  <link name="Upper_left_leg_support__bottom__v8_1">
    <inertial>
      <origin xyz="0.019462816432113214 -1.0283150438106237e-07 -0.048113683972305823" rpy="0.0 0.0 0.0"/>
      <mass value="0.027169463894965433"/>
      <inertia ixx="2.2e-05" ixy="-0.0" ixz="-0.0" iyy="3.2e-05" iyz="0.0" izz="1.3e-05"/>
    </inertial>
    <visual>
      <origin xyz="-0.089859 -0.060824 0.104444" rpy="0.0 0.0 0.0"/>
      <geometry>
        <mesh filename="package://bez2_description/meshes/Upper_left_leg_support__bottom__v8_1.stl" scale="0.001 0.001 0.001"/>
      </geometry>
      <material name="abs_white"/>
    </visual>
    <collision>
      <origin xyz="0.019500320253133793 -1.0496282577820981e-07 -0.04689989698505402" rpy="6.123233995736766e-17 -1.2246467991473532e-16 -1.5707963267948966"/>
      <geometry>
        <box size="0.02799999713897706 0.05399999767541887 0.11959999799728394"/>
      </geometry>
    </collision>
  </link>
  <link name="Upper_left_leg_support__bottom__v8_2">
    <inertial>
      <origin xyz="-0.019537183567898096 -1.028314992185253e-07 -0.048113683972305823" rpy="0.0 0.0 0.0"/>
      <mass value="0.027169463894965433"/>
      <inertia ixx="2.2e-05" ixy="-0.0" ixz="-0.0" iyy="3.2e-05" iyz="0.0" izz="1.3e-05"/>
    </inertial>
    <visual>
      <origin xyz="-0.055359 -0.059324 0.104444" rpy="0.0 0.0 0.0"/>
      <geometry>
        <mesh filename="package://bez2_description/meshes/Upper_left_leg_support__bottom__v8_2.stl" scale="0.001 0.001 0.001"/>
      </geometry>
      <material name="abs_white"/>
    </visual>
    <collision>
      <origin xyz="-0.0194996792216003 -1.024147272127296e-07 -0.04689989698505402" rpy="6.123233995736766e-17 -1.2246467991473532e-16 -1.5707963267948966"/>
      <geometry>
        <box size="0.028000000864267387 0.05399999674409628 0.11959999799728395"/>
      </geometry>
    </collision>
  </link>
  <link name="New_left_foot_upperhalf_v5_1">
    <inertial>
      <origin xyz="-0.012180584726820248 -0.05139354649788158 -0.0217764734148449" rpy="0.0 0.0 0.0"/>
      <mass value="0.0588564551543425"/>
      <inertia ixx="0.000149" ixy="0.0" ixz="-3e-06" iyy="3.9e-05" iyz="0.0" izz="0.000178"/>
    </inertial>
    <visual>
      <origin xyz="-0.037059 -0.143624 0.304444" rpy="0.0 0.0 0.0"/>
      <geometry>
        <mesh filename="package://bez2_description/meshes/New_left_foot_upperhalf_v5_1.stl" scale="0.001 0.001 0.001"/>
      </geometry>
      <material name="abs_white"/>
    </visual>
    <collision>
      <origin xyz="-0.014999677665174009 -0.052160100294440986 -0.005499899512290962" rpy="1.5707963267948968 1.5707963267948966 0.0"/>
      <geometry>
        <box size="0.043000012636184706 0.09000000171363354 0.17000000458210707"/>
      </geometry>
    </collision>
  </link>
  <link name="New_right_foot_upperhalf_v3_1">
    <inertial>
      <origin xyz="0.060000322030201225 -0.051393547332351824 -0.021776473414845232" rpy="0.0 0.0 0.0"/>
      <mass value="0.117712910308685"/>
      <inertia ixx="0.000297" ixy="0.0" ixz="0.0" iyy="0.000348" iyz="1e-06" izz="0.000625"/>
    </inertial>
    <visual>
      <origin xyz="-0.108159 -0.145124 0.304444" rpy="0.0 0.0 0.0"/>
      <geometry>
        <mesh filename="package://bez2_description/meshes/New_right_foot_upperhalf_v3_1.stl" scale="0.001 0.001 0.001"/>
      </geometry>
      <material name="abs_white"/>
    </visual>
    <collision>
      <origin xyz="0.015000322887659054 -0.05216010284253954 -0.005499899512290962" rpy="-1.5707963267948966 -1.5707963267948966 0.0"/>
      <geometry>
        <box size="0.0430000126361847 0.08999999612569809 0.17000000085681677"/>
      </geometry>
    </collision>
  </link>
  <link name="neck_v4_1">
    <inertial>
      <origin xyz="0.014999915739446909 0.012879582990262754 0.024886118937898494" rpy="0.0 0.0 0.0"/>
      <mass value="0.10655783809755558"/>
      <inertia ixx="3e-05" ixy="-0.0" ixz="0.0" iyy="1.9e-05" iyz="3e-06" izz="1.9e-05"/>
    </inertial>
    <visual>
      <origin xyz="-0.056826 -0.037694 -0.100556" rpy="0.0 0.0 0.0"/>
      <geometry>
        <mesh filename="package://bez2_description/meshes/neck_v4_1.stl" scale="0.001 0.001 0.001"/>
      </geometry>
      <material name="abs_white"/>
    </visual>
    <collision>
      <origin xyz="0.01499999045336245 0.014349897099792952 0.023337104493618005" rpy="-1.5707963267948966 6.123233995736766e-17 3.141592653589793"/>
      <geometry>
        <box size="0.040000002831220606 0.04667399823665619 0.054300000891089426"/>
      </geometry>
    </collision>
  </link>
  <link name="custom_servo_support__middle_neck__v9_1">
    <inertial>
      <origin xyz="0.0015600810093761297 -1.0333814156465726e-07 0.014703004853071633" rpy="0.0 0.0 0.0"/>
      <mass value="0.01959544470499754"/>
      <inertia ixx="6e-06" ixy="0.0" ixz="0.0" iyy="1.4e-05" iyz="0.0" izz="1.2e-05"/>
    </inertial>
    <visual>
      <origin xyz="-0.071826 -0.042194 -0.14723" rpy="0.0 0.0 0.0"/>
      <geometry>
        <mesh filename="package://bez2_description/meshes/custom_servo_support__middle_neck__v9_1.stl" scale="0.001 0.001 0.001"/>
      </geometry>
      <material name="abs_white"/>
    </visual>
    <collision>
      <origin xyz="0.00199999078118801 -1.03862822051215e-07 0.02412673761367798" rpy="1.5707963267948966 -0.0 -1.5707963267948968"/>
      <geometry>
        <box size="0.034999998286366456 0.048253268003463745 0.056374002248048775"/>
      </geometry>
    </collision>
  </link>
  <link name="head_v4_1">
    <inertial>
      <origin xyz="0.024245597582648673 -0.0037488657746306553 0.024987900172004557" rpy="0.0 0.0 0.0"/>
      <mass value="0.29338454987270446"/>
      <inertia ixx="0.000239" ixy="2e-06" ixz="-1.1e-05" iyy="0.00023" iyz="7.6e-05" izz="0.000194"/>
    </inertial>
    <visual>
      <origin xyz="-0.049639 -0.042194 -0.181048" rpy="0.0 0.0 0.0"/>
      <geometry>
        <mesh filename="package://bez2_description/meshes/head_v4_1.stl" scale="0.001 0.001 0.001"/>
      </geometry>
      <material name="plastic_glossy_black"/>
    </visual>
    <collision>
      <origin xyz="0.025673986969947812 0.0026498946623355057 0.024249574400901808" rpy="-1.5707963267948966 6.123233995736766e-17 -1.5707963267948968"/>
      <geometry>
        <box size="0.07609999692067504 0.07649999856948851 0.09399999678134917"/>
      </geometry>
    </collision>
  </link>
  <link name="lower_leg_v4_1">
    <inertial>
      <origin xyz="-0.023191603027466604 -9.582728020818276e-08 -0.02213339724981117" rpy="0.0 0.0 0.0"/>
      <mass value="0.1476733120184745"/>
      <inertia ixx="0.000107" ixy="-0.0" ixz="-2e-06" iyy="0.000124" iyz="0.0" izz="4.1e-05"/>
    </inertial>
    <visual>
      <origin xyz="-0.059859 -0.059324 0.196144" rpy="0.0 0.0 0.0"/>
      <geometry>
        <mesh filename="package://bez2_description/meshes/lower_leg_v4_1.stl" scale="0.001 0.001 0.001"/>
      </geometry>
      <material name="abs_white"/>
    </visual>
    <collision>
      <origin xyz="-0.023233122624860686 -1.024147272127296e-07 -0.054666632059423376" rpy="-0.008295138211358258 6.123233995736767e-17 -1.5707963267948968"/>
      <geometry>
        <box size="0.04019999876618386 0.05460367809420252 0.13771419042204602"/>
      </geometry>
    </collision>
  </link>
  <link name="lower_leg_v4_2">
    <inertial>
      <origin xyz="0.02319224708785829 -1.0983572364814398e-07 -0.02213339724981142" rpy="0.0 0.0 0.0"/>
      <mass value="0.1476733120184745"/>
      <inertia ixx="0.000107" ixy="-0.0" ixz="2e-06" iyy="0.000124" iyz="-0.0" izz="4.1e-05"/>
    </inertial>
    <visual>
      <origin xyz="-0.085359 -0.060824 0.196144" rpy="0.0 0.0 0.0"/>
      <geometry>
        <mesh filename="package://bez2_description/meshes/lower_leg_v4_2.stl" scale="0.001 0.001 0.001"/>
      </geometry>
      <material name="abs_white"/>
    </visual>
    <collision>
      <origin xyz="0.02323376691602322 -1.01237535472809e-07 -0.05466663205942332" rpy="0.008295138211358258 6.123233995736765e-17 -1.5707963267948968"/>
      <geometry>
        <box size="0.040200002491474186 0.05460368554452673 0.13771419048384892"/>
      </geometry>
    </collision>
  </link>
  <link name="ankle_motors_v4_1">
    <inertial>
      <origin xyz="0.023300324626133573 0.020543270558517568 0.015062653184791719" rpy="0.0 0.0 0.0"/>
      <mass value="0.3955604131597503"/>
      <inertia ixx="0.000468" ixy="-0.0" ixz="-0.0" iyy="0.000155" iyz="2e-06" izz="0.000419"/>
    </inertial>
    <visual>
      <origin xyz="-0.084859 -0.060824 0.304444" rpy="0.0 0.0 0.0"/>
      <geometry>
        <mesh filename="package://bez2_description/meshes/ankle_motors_v4_1.stl" scale="0.001 0.001 0.001"/>
      </geometry>
      <material name="steel_satin"/>
    </visual>
    <collision>
      <origin xyz="0.023332126985089283 0.033902422584187936 0.017050102228164665" rpy="1.5707963267948966 -0.0 3.075947556306143"/>
      <geometry>
        <box size="0.05145662812639435 0.06209999322891235 0.10991508842745541"/>
      </geometry>
    </collision>
  </link>
  <link name="ankle_motors_v4_2">
    <inertial>
      <origin xyz="-0.023299675373877886 0.02054327139298781 0.01506265318479183" rpy="0.0 0.0 0.0"/>
      <mass value="0.3955604131597503"/>
      <inertia ixx="0.000468" ixy="-0.0" ixz="-0.0" iyy="0.000155" iyz="2e-06" izz="0.000419"/>
    </inertial>
    <visual>
      <origin xyz="-0.060359 -0.059324 0.304444" rpy="0.0 0.0 0.0"/>
      <geometry>
        <mesh filename="package://bez2_description/meshes/ankle_motors_v4_2.stl" scale="0.001 0.001 0.001"/>
      </geometry>
      <material name="steel_satin"/>
    </visual>
    <collision>
      <origin xyz="-0.023331479557406415 0.033902417411351735 0.017050102228164665" rpy="1.5707963267948966 -0.0 -3.0759474686850385"/>
      <geometry>
        <box size="0.05145662430256209 0.06209999322891237 0.109915078070939"/>
      </geometry>
    </collision>
  </link>
  <link name="camera_point_1">
    <inertial>
      <origin xyz="-1.1616073519737924e-08 0.000999895991307411 -4.265551301618764e-07" rpy="0.0 0.0 0.0"/>
      <mass value="0.0005023999999999976"/>
      <inertia ixx="0.0" ixy="-0.0" ixz="0.0" iyy="0.0" iyz="-0.0" izz="0.0"/>
    </inertial>
    <visual>
      <origin xyz="-0.075313 -0.007794 -0.229048" rpy="0.0 0.0 0.0"/>
      <geometry>
        <mesh filename="package://bez2_description/meshes/camera_point_1.stl" scale="0.001 0.001 0.001"/>
      </geometry>
      <material name="steel_satin"/>
    </visual>
    <collision>
      <origin xyz="-9.304761891537616e-09 0.0009998962969928983 -4.258971214310403e-07" rpy="1.2246467991473532e-16 1.5707963267948966 0.0"/>
      <geometry>
        <box size="0.0039999932050704965 0.004000000189989806 0.0040000006556510925"/>
      </geometry>
    </collision>
  </link>
  <link name="imu_1">
    <inertial>
      <origin xyz="3.220301867390418e-07 -0.04000010338284481 -0.04299989661715594" rpy="0.0 0.0 0.0"/>
      <mass value="0.0005024000000000008"/>
      <inertia ixx="0.0" ixy="0.0" ixz="-0.0" iyy="0.0" iyz="0.0" izz="0.0"/>
    </inertial>
    <visual>
      <origin xyz="-0.072159 -0.062444 -0.100556" rpy="0.0 0.0 0.0"/>
      <geometry>
        <mesh filename="package://bez2_description/meshes/imu_1.stl" scale="0.001 0.001 0.001"/>
      </geometry>
      <material name="steel_satin"/>
    </visual>
    <collision>
      <origin xyz="3.2384133338836385e-07 -0.040000103840470314 -0.042999896085023886" rpy="0.0 -0.0 3.141592653589793"/>
      <geometry>
        <box size="0.0040000006556511 0.004000000655651093 0.0040000006556510925"/>
      </geometry>
    </collision>
  </link>
  <joint name="left_arm_motor_0" type="continuous">
    <origin xyz="0.144659 0.075444 0.072056" rpy="0.0 0.0 0.0"/>
    <axis xyz="-1.0 0.0 0.0"/>
    <parent link="base_link"/>
    <child link="biceps_v3_1"/>
  </joint>
  <joint name="left_arm_motor_1" type="continuous">
    <origin xyz="0.008 0.0 -0.0906" rpy="0.0 0.0 0.0"/>
    <axis xyz="-1.0 -0.0 0.0"/>
    <parent link="biceps_v3_1"/>
    <child link="Arm_Assembly-bez3_v12_2"/>
  </joint>
  <joint name="right_arm_motor_0" type="continuous">
    <origin xyz="-0.000341 0.075444 0.072056" rpy="0.0 0.0 0.0"/>
    <axis xyz="1.0 -0.0 -0.0"/>
    <parent link="base_link"/>
    <child link="biceps_v3_2"/>
  </joint>
  <joint name="right_arm_motor_1" type="continuous">
    <origin xyz="-0.008 0.0 -0.0906" rpy="0.0 0.0 0.0"/>
    <axis xyz="1.0 0.0 0.0"/>
    <parent link="biceps_v3_2"/>
    <child link="Arm_Assembly-bez3_v12_1"/>
  </joint>
  <joint name="right_leg_motor_0" type="continuous">
    <origin xyz="0.035359 0.059474 -0.072444" rpy="0.0 0.0 0.0"/>
    <axis xyz="0.0 0.0 -1.0"/>
    <parent link="base_link"/>
    <child link="Hip_Printable_v2_v10_1"/>
  </joint>
  <joint name="left_leg_motor_0" type="continuous">
    <origin xyz="0.109859 0.059474 -0.072444" rpy="0.0 0.0 0.0"/>
    <axis xyz="0.0 0.0 -1.0"/>
    <parent link="base_link"/>
    <child link="Hip_Printable_v2_v10_2"/>
  </joint>
  <joint name="right_leg_motor_1" type="continuous">
    <origin xyz="0.0 0.0235 -0.032" rpy="0.0 0.0 0.0"/>
    <axis xyz="-0.0 -1.0 -0.0"/>
    <parent link="Hip_Printable_v2_v10_1"/>
    <child link="hip_motors_v4_1"/>
  </joint>
  <joint name="left_leg_motor_1" type="continuous">
    <origin xyz="0.0 0.025 -0.032" rpy="0.0 0.0 0.0"/>
    <axis xyz="-0.0 -1.0 -0.0"/>
    <parent link="Hip_Printable_v2_v10_2"/>
    <child link="hip_motors_v4_2"/>
  </joint>
  <joint name="left_leg_motor_2" type="continuous">
    <origin xyz="-0.02 -0.02365 0.0" rpy="0.0 0.0 0.0"/>
    <axis xyz="-1.0 -0.0 0.0"/>
    <parent link="hip_motors_v4_2"/>
    <child link="Upper_left_leg_support__bottom__v8_1"/>
  </joint>
  <joint name="right_leg_motor_2" type="continuous">
    <origin xyz="0.02 -0.02365 0.0" rpy="0.0 0.0 0.0"/>
    <axis xyz="1.0 0.0 0.0"/>
    <parent link="hip_motors_v4_1"/>
    <child link="Upper_left_leg_support__bottom__v8_2"/>
  </joint>
  <joint name="right_leg_motor_5" type="continuous">
    <origin xyz="-0.0233 0.0843 0.0" rpy="0.0 0.0 0.0"/>
    <axis xyz="0.0 -1.0 -0.0"/>
    <parent link="ankle_motors_v4_2"/>
    <child link="New_left_foot_upperhalf_v5_1"/>
  </joint>
  <joint name="left_leg_motor_5" type="continuous">
    <origin xyz="0.0233 0.0843 0.0" rpy="0.0 0.0 0.0"/>
    <axis xyz="0.0 -1.0 -0.0"/>
    <parent link="ankle_motors_v4_1"/>
    <child link="New_right_foot_upperhalf_v3_1"/>
  </joint>
  <joint name="Rigid19" type="fixed">
    <origin xyz="0.056826 0.037694 0.100556" rpy="0.0 0.0 0.0"/>
    <parent link="base_link"/>
    <child link="neck_v4_1"/>
  </joint>
  <joint name="head_motor_0" type="continuous">
    <origin xyz="0.015 0.0045 0.046674" rpy="0.0 0.0 0.0"/>
    <axis xyz="0.0 -0.0 1.0"/>
    <parent link="neck_v4_1"/>
    <child link="custom_servo_support__middle_neck__v9_1"/>
  </joint>
  <joint name="head_motor_1" type="continuous">
    <origin xyz="-0.022187 0.0 0.033818" rpy="0.0 0.0 0.0"/>
    <axis xyz="-1.0 0.0 0.0"/>
    <parent link="custom_servo_support__middle_neck__v9_1"/>
    <child link="head_v4_1"/>
  </joint>
  <joint name="right_leg_motor_3" type="continuous">
    <origin xyz="0.0045 0.0 -0.0917" rpy="0.0 0.0 0.0"/>
    <axis xyz="1.0 0.0 0.0"/>
    <parent link="Upper_left_leg_support__bottom__v8_2"/>
    <child link="lower_leg_v4_1"/>
  </joint>
  <joint name="left_leg_motor_3" type="continuous">
    <origin xyz="-0.0045 0.0 -0.0917" rpy="0.0 0.0 0.0"/>
    <axis xyz="-1.0 -0.0 0.0"/>
    <parent link="Upper_left_leg_support__bottom__v8_1"/>
    <child link="lower_leg_v4_2"/>
  </joint>
  <joint name="left_leg_motor_4" type="continuous">
    <origin xyz="-0.0005 0.0 -0.1083" rpy="0.0 0.0 0.0"/>
    <axis xyz="-1.0 0.0 0.0"/>
    <parent link="lower_leg_v4_2"/>
    <child link="ankle_motors_v4_1"/>
  </joint>
  <joint name="right_leg_motor_4" type="continuous">
    <origin xyz="0.0005 0.0 -0.1083" rpy="0.0 0.0 0.0"/>
    <axis xyz="1.0 -0.0 0.0"/>
    <parent link="lower_leg_v4_1"/>
    <child link="ankle_motors_v4_2"/>
  </joint>
  <joint name="camera_joint" type="continuous">
    <origin xyz="0.025674 -0.0344 0.048" rpy="0.0 0.0 0.0"/>
    <axis xyz="-0.0 -1.0 -0.0"/>
    <parent link="head_v4_1"/>
    <child link="camera_point_1"/>
  </joint>
  <joint name="imu_joint" type="continuous">
    <origin xyz="0.072159 0.062444 0.100556" rpy="0.0 0.0 0.0"/>
    <axis xyz="-0.0 -0.0 1.0"/>
    <parent link="base_link"/>
    <child link="imu_1"/>
  </joint>
</robot>