<?xml version="1.0" ?>
<robot name="bez2" xmlns:xacro="http://www.ros.org/wiki/xacro">

<xacro:include filename="$(find bez2_description)/urdf/materials.xacro" />
<xacro:include filename="$(find bez2_description)/urdf/bez2.trans" />
<xacro:include filename="$(find bez2_description)/urdf/bez2.gazebo" />
<link name="base_link">
  <inertial>
    <origin xyz="0.07226346929359313 0.07145981340933207 0.03052377805008874" rpy="0 0 0"/>
    <mass value="19.222054389299405"/>
    <inertia ixx="0.055868" iyy="0.06663" izz="0.056107" ixy="-1.7e-05" iyz="0.002149" ixz="0.000158"/>
  </inertial>
  <visual>
    <origin xyz="0 0 0" rpy="0 0 0"/>
    <geometry>
      <mesh filename="package://bez2_description/meshes/base_link.stl" scale="0.001 0.001 0.001"/>
    </geometry>
    <material name="polymide_kapton"/>
  </visual>
  <collision>
    <origin xyz="0 0 0" rpy="0 0 0"/>
    <geometry>
      <mesh filename="package://bez2_description/meshes/base_link.stl" scale="0.001 0.001 0.001"/>
    </geometry>
  </collision>
</link>

<link name="biceps_v2_1">
  <inertial>
    <origin xyz="0.028967421829123152 -1.0338258438213899e-07 -0.041589282843954946" rpy="0 0 0"/>
    <mass value="0.4812023462616311"/>
    <inertia ixx="0.000718" iyy="0.000776" izz="9.3e-05" ixy="-0.0" iyz="0.0" ixz="3.8e-05"/>
  </inertial>
  <visual>
    <origin xyz="-0.144659 -0.075444 -0.072056" rpy="0 0 0"/>
    <geometry>
      <mesh filename="package://bez2_description/meshes/biceps_v2_1.stl" scale="0.001 0.001 0.001"/>
    </geometry>
    <material name="steel_satin"/>
  </visual>
  <collision>
    <origin xyz="-0.144659 -0.075444 -0.072056" rpy="0 0 0"/>
    <geometry>
      <mesh filename="package://bez2_description/meshes/biceps_v2_1.stl" scale="0.001 0.001 0.001"/>
    </geometry>
  </collision>
</link>

<link name="Arm_Assembly-bez3_v10_2">
  <inertial>
    <origin xyz="0.02377578012690784 0.012006216401902609 -0.012141480437552529" rpy="0 0 0"/>
    <mass value="1.0556766109367164"/>
    <inertia ixx="0.008653" iyy="0.008654" izz="0.00041" ixy="-7e-06" iyz="0.000768" ixz="4.2e-05"/>
  </inertial>
  <visual>
    <origin xyz="-0.152659 -0.075444 0.018544" rpy="0 0 0"/>
    <geometry>
      <mesh filename="package://bez2_description/meshes/Arm_Assembly-bez3_v10_2.stl" scale="0.001 0.001 0.001"/>
    </geometry>
    <material name="steel_satin"/>
  </visual>
  <collision>
    <origin xyz="-0.152659 -0.075444 0.018544" rpy="0 0 0"/>
    <geometry>
      <mesh filename="package://bez2_description/meshes/Arm_Assembly-bez3_v10_2.stl" scale="0.001 0.001 0.001"/>
    </geometry>
  </collision>
</link>

<link name="biceps_v2_2">
  <inertial>
    <origin xyz="-0.02896677776874408 -1.0338310509061532e-07 -0.041589282843954946" rpy="0 0 0"/>
    <mass value="0.4812023462616311"/>
    <inertia ixx="0.000718" iyy="0.000776" izz="9.3e-05" ixy="-0.0" iyz="-0.0" ixz="-3.8e-05"/>
  </inertial>
  <visual>
    <origin xyz="0.000341 -0.075444 -0.072056" rpy="0 0 0"/>
    <geometry>
      <mesh filename="package://bez2_description/meshes/biceps_v2_2.stl" scale="0.001 0.001 0.001"/>
    </geometry>
    <material name="steel_satin"/>
  </visual>
  <collision>
    <origin xyz="0.000341 -0.075444 -0.072056" rpy="0 0 0"/>
    <geometry>
      <mesh filename="package://bez2_description/meshes/biceps_v2_2.stl" scale="0.001 0.001 0.001"/>
    </geometry>
  </collision>
</link>

<link name="Arm_Assembly-bez3_v10_1">
  <inertial>
    <origin xyz="-0.024898219873093895 0.012006216401910838 -0.012141480437554357" rpy="0 0 0"/>
    <mass value="1.0556766109367164"/>
    <inertia ixx="0.008653" iyy="0.008654" izz="0.00041" ixy="-7e-06" iyz="0.000768" ixz="4.2e-05"/>
  </inertial>
  <visual>
    <origin xyz="0.008341 -0.075444 0.018544" rpy="0 0 0"/>
    <geometry>
      <mesh filename="package://bez2_description/meshes/Arm_Assembly-bez3_v10_1.stl" scale="0.001 0.001 0.001"/>
    </geometry>
    <material name="steel_satin"/>
  </visual>
  <collision>
    <origin xyz="0.008341 -0.075444 0.018544" rpy="0 0 0"/>
    <geometry>
      <mesh filename="package://bez2_description/meshes/Arm_Assembly-bez3_v10_1.stl" scale="0.001 0.001 0.001"/>
    </geometry>
  </collision>
</link>

<link name="Hip_Printable_v2_v9_1">
  <inertial>
    <origin xyz="3.220301637574252e-07 -4.2278800908499004e-05 -0.014017264198397453" rpy="0 0 0"/>
    <mass value="0.007614509245765126"/>
    <inertia ixx="5e-06" iyy="2e-06" izz="4e-06" ixy="-0.0" iyz="-0.0" ixz="-0.0"/>
  </inertial>
  <visual>
    <origin xyz="-0.035359 -0.059474 0.072444" rpy="0 0 0"/>
    <geometry>
      <mesh filename="package://bez2_description/meshes/Hip_Printable_v2_v9_1.stl" scale="0.001 0.001 0.001"/>
    </geometry>
    <material name="abs_white"/>
  </visual>
  <collision>
    <origin xyz="-0.035359 -0.059474 0.072444" rpy="0 0 0"/>
    <geometry>
      <mesh filename="package://bez2_description/meshes/Hip_Printable_v2_v9_1.stl" scale="0.001 0.001 0.001"/>
    </geometry>
  </collision>
</link>

<link name="Hip_Printable_v2_v9_2">
  <inertial>
    <origin xyz="3.220301620365795e-07 -4.227880091287051e-05 -0.01401726419839748" rpy="0 0 0"/>
    <mass value="0.007614509245765126"/>
    <inertia ixx="5e-06" iyy="2e-06" izz="4e-06" ixy="-0.0" iyz="-0.0" ixz="-0.0"/>
  </inertial>
  <visual>
    <origin xyz="-0.109859 -0.059474 0.072444" rpy="0 0 0"/>
    <geometry>
      <mesh filename="package://bez2_description/meshes/Hip_Printable_v2_v9_2.stl" scale="0.001 0.001 0.001"/>
    </geometry>
    <material name="abs_white"/>
  </visual>
  <collision>
    <origin xyz="-0.109859 -0.059474 0.072444" rpy="0 0 0"/>
    <geometry>
      <mesh filename="package://bez2_description/meshes/Hip_Printable_v2_v9_2.stl" scale="0.001 0.001 0.001"/>
    </geometry>
  </collision>
</link>

<link name="hip_motors_v3_1">
  <inertial>
    <origin xyz="2.4839556932165774e-07 -0.009182232274110635 -0.011866842676855963" rpy="0 0 0"/>
    <mass value="1.0339580130905694"/>
    <inertia ixx="0.00068" iyy="0.000279" izz="0.000584" ixy="0.0" iyz="2e-06" ixz="0.0"/>
  </inertial>
  <visual>
    <origin xyz="-0.035359 -0.082974 0.104444" rpy="0 0 0"/>
    <geometry>
      <mesh filename="package://bez2_description/meshes/hip_motors_v3_1.stl" scale="0.001 0.001 0.001"/>
    </geometry>
    <material name="silver_default"/>
  </visual>
  <collision>
    <origin xyz="-0.035359 -0.082974 0.104444" rpy="0 0 0"/>
    <geometry>
      <mesh filename="package://bez2_description/meshes/hip_motors_v3_1.stl" scale="0.001 0.001 0.001"/>
    </geometry>
  </collision>
</link>

<link name="hip_motors_v3_2">
  <inertial>
    <origin xyz="2.483955749699174e-07 -0.009182232274114993 -0.011866842676856004" rpy="0 0 0"/>
    <mass value="1.0339580130905694"/>
    <inertia ixx="0.00068" iyy="0.000279" izz="0.000584" ixy="0.0" iyz="2e-06" ixz="0.0"/>
  </inertial>
  <visual>
    <origin xyz="-0.109859 -0.084474 0.104444" rpy="0 0 0"/>
    <geometry>
      <mesh filename="package://bez2_description/meshes/hip_motors_v3_2.stl" scale="0.001 0.001 0.001"/>
    </geometry>
    <material name="silver_default"/>
  </visual>
  <collision>
    <origin xyz="-0.109859 -0.084474 0.104444" rpy="0 0 0"/>
    <geometry>
      <mesh filename="package://bez2_description/meshes/hip_motors_v3_2.stl" scale="0.001 0.001 0.001"/>
    </geometry>
  </collision>
</link>

<link name="Upper_left_leg_support__bottom__v7_1">
  <inertial>
    <origin xyz="0.019462816432113214 -1.0283150442963462e-07 -0.048113683972305823" rpy="0 0 0"/>
    <mass value="0.20120782224101758"/>
    <inertia ixx="0.000162" iyy="0.000235" izz="9.9e-05" ixy="-0.0" iyz="0.0" ixz="-0.0"/>
  </inertial>
  <visual>
    <origin xyz="-0.089859 -0.060824 0.104444" rpy="0 0 0"/>
    <geometry>
      <mesh filename="package://bez2_description/meshes/Upper_left_leg_support__bottom__v7_1.stl" scale="0.001 0.001 0.001"/>
    </geometry>
    <material name="steel_satin"/>
  </visual>
  <collision>
    <origin xyz="-0.089859 -0.060824 0.104444" rpy="0 0 0"/>
    <geometry>
      <mesh filename="package://bez2_description/meshes/Upper_left_leg_support__bottom__v7_1.stl" scale="0.001 0.001 0.001"/>
    </geometry>
  </collision>
</link>

<link name="Upper_left_leg_support__bottom__v7_2">
  <inertial>
    <origin xyz="-0.019537183567898096 -1.028314992185253e-07 -0.048113683972305823" rpy="0 0 0"/>
    <mass value="0.20120782224101758"/>
    <inertia ixx="0.000162" iyy="0.000235" izz="9.9e-05" ixy="-0.0" iyz="0.0" ixz="-0.0"/>
  </inertial>
  <visual>
    <origin xyz="-0.055359 -0.059324 0.104444" rpy="0 0 0"/>
    <geometry>
      <mesh filename="package://bez2_description/meshes/Upper_left_leg_support__bottom__v7_2.stl" scale="0.001 0.001 0.001"/>
    </geometry>
    <material name="steel_satin"/>
  </visual>
  <collision>
    <origin xyz="-0.055359 -0.059324 0.104444" rpy="0 0 0"/>
    <geometry>
      <mesh filename="package://bez2_description/meshes/Upper_left_leg_support__bottom__v7_2.stl" scale="0.001 0.001 0.001"/>
    </geometry>
  </collision>
</link>

<link name="New_left_foot_upperhalf_v4_1">
  <inertial>
    <origin xyz="-0.012180584726820251 -0.05139354649788158 -0.0217764734148449" rpy="0 0 0"/>
    <mass value="0.43587091788829113"/>
    <inertia ixx="0.001101" iyy="0.000292" izz="0.001317" ixy="1e-06" iyz="2e-06" ixz="-2e-05"/>
  </inertial>
  <visual>
    <origin xyz="-0.037059 -0.143624 0.304444" rpy="0 0 0"/>
    <geometry>
      <mesh filename="package://bez2_description/meshes/New_left_foot_upperhalf_v4_1.stl" scale="0.001 0.001 0.001"/>
    </geometry>
    <material name="steel_satin"/>
  </visual>
  <collision>
    <origin xyz="-0.037059 -0.143624 0.304444" rpy="0 0 0"/>
    <geometry>
      <mesh filename="package://bez2_description/meshes/New_left_foot_upperhalf_v4_1.stl" scale="0.001 0.001 0.001"/>
    </geometry>
  </collision>
</link>

<link name="New_right_foot_upperhalf_v2_1">
  <inertial>
    <origin xyz="0.060000322030201225 -0.051393547332351824 -0.021776473414845232" rpy="0 0 0"/>
    <mass value="0.8717418357765823"/>
    <inertia ixx="0.002201" iyy="0.002577" izz="0.004628" ixy="-0.0" iyz="5e-06" ixz="0.0"/>
  </inertial>
  <visual>
    <origin xyz="-0.108159 -0.145124 0.304444" rpy="0 0 0"/>
    <geometry>
      <mesh filename="package://bez2_description/meshes/New_right_foot_upperhalf_v2_1.stl" scale="0.001 0.001 0.001"/>
    </geometry>
    <material name="steel_satin"/>
  </visual>
  <collision>
    <origin xyz="-0.108159 -0.145124 0.304444" rpy="0 0 0"/>
    <geometry>
      <mesh filename="package://bez2_description/meshes/New_right_foot_upperhalf_v2_1.stl" scale="0.001 0.001 0.001"/>
    </geometry>
  </collision>
</link>

<link name="neck_v2_1">
  <inertial>
    <origin xyz="0.014999956874560072 0.013704810841773656 0.02123668355471972" rpy="0 0 0"/>
    <mass value="0.24638401500572749"/>
    <inertia ixx="7.1e-05" iyy="4.8e-05" izz="4.6e-05" ixy="-0.0" iyz="4e-06" ixz="0.0"/>
  </inertial>
  <visual>
    <origin xyz="-0.056826 -0.037694 -0.100556" rpy="0 0 0"/>
    <geometry>
      <mesh filename="package://bez2_description/meshes/neck_v2_1.stl" scale="0.001 0.001 0.001"/>
    </geometry>
    <material name="steel_satin"/>
  </visual>
  <collision>
    <origin xyz="-0.056826 -0.037694 -0.100556" rpy="0 0 0"/>
    <geometry>
      <mesh filename="package://bez2_description/meshes/neck_v2_1.stl" scale="0.001 0.001 0.001"/>
    </geometry>
  </collision>
</link>

<link name="custom_servo_support__middle_neck__v8_1">
  <inertial>
    <origin xyz="0.0015600810093761297 -1.0333814156465726e-07 0.014703004853071633" rpy="0 0 0"/>
    <mass value="0.1451172084285195"/>
    <inertia ixx="4.4e-05" iyy="0.000103" izz="8.9e-05" ixy="0.0" iyz="0.0" ixz="1e-06"/>
  </inertial>
  <visual>
    <origin xyz="-0.071826 -0.042194 -0.14723" rpy="0 0 0"/>
    <geometry>
      <mesh filename="package://bez2_description/meshes/custom_servo_support__middle_neck__v8_1.stl" scale="0.001 0.001 0.001"/>
    </geometry>
    <material name="steel_satin"/>
  </visual>
  <collision>
    <origin xyz="-0.071826 -0.042194 -0.14723" rpy="0 0 0"/>
    <geometry>
      <mesh filename="package://bez2_description/meshes/custom_servo_support__middle_neck__v8_1.stl" scale="0.001 0.001 0.001"/>
    </geometry>
  </collision>
</link>

<link name="head_v2_1">
  <inertial>
    <origin xyz="0.02550042089765836 0.0013348220212865414 0.01661303627347699" rpy="0 0 0"/>
    <mass value="0.47694495505240925"/>
    <inertia ixx="0.00036" iyy="0.000326" izz="0.000273" ixy="-4e-06" iyz="0.00011" ixz="-3e-06"/>
  </inertial>
  <visual>
    <origin xyz="-0.049639 -0.042194 -0.181048" rpy="0 0 0"/>
    <geometry>
      <mesh filename="package://bez2_description/meshes/head_v2_1.stl" scale="0.001 0.001 0.001"/>
    </geometry>
    <material name="plastic_glossy_black"/>
  </visual>
  <collision>
    <origin xyz="-0.049639 -0.042194 -0.181048" rpy="0 0 0"/>
    <geometry>
      <mesh filename="package://bez2_description/meshes/head_v2_1.stl" scale="0.001 0.001 0.001"/>
    </geometry>
  </collision>
</link>

<link name="lower_leg_v2_1">
  <inertial>
    <origin xyz="-0.023222560542468983 -9.634068400682372e-08 -0.026061056668866184" rpy="0 0 0"/>
    <mass value="0.6984721747198837"/>
    <inertia ixx="0.000628" iyy="0.000727" izz="0.00021" ixy="-0.0" iyz="0.0" ixz="-1e-05"/>
  </inertial>
  <visual>
    <origin xyz="-0.059859 -0.059324 0.196144" rpy="0 0 0"/>
    <geometry>
      <mesh filename="package://bez2_description/meshes/lower_leg_v2_1.stl" scale="0.001 0.001 0.001"/>
    </geometry>
    <material name="steel_satin"/>
  </visual>
  <collision>
    <origin xyz="-0.059859 -0.059324 0.196144" rpy="0 0 0"/>
    <geometry>
      <mesh filename="package://bez2_description/meshes/lower_leg_v2_1.stl" scale="0.001 0.001 0.001"/>
    </geometry>
  </collision>
</link>

<link name="lower_leg_v2_2">
  <inertial>
    <origin xyz="0.023223204602860675 -1.0932231984950302e-07 -0.026061056668866434" rpy="0 0 0"/>
    <mass value="0.6984721747198837"/>
    <inertia ixx="0.000628" iyy="0.000727" izz="0.00021" ixy="-0.0" iyz="-0.0" ixz="1e-05"/>
  </inertial>
  <visual>
    <origin xyz="-0.085359 -0.060824 0.196144" rpy="0 0 0"/>
    <geometry>
      <mesh filename="package://bez2_description/meshes/lower_leg_v2_2.stl" scale="0.001 0.001 0.001"/>
    </geometry>
    <material name="steel_satin"/>
  </visual>
  <collision>
    <origin xyz="-0.085359 -0.060824 0.196144" rpy="0 0 0"/>
    <geometry>
      <mesh filename="package://bez2_description/meshes/lower_leg_v2_2.stl" scale="0.001 0.001 0.001"/>
    </geometry>
  </collision>
</link>

<link name="ankle_motors_v3_1">
  <inertial>
    <origin xyz="0.023300324598053007 0.020649157771031837 0.014975439548538305" rpy="0 0 0"/>
    <mass value="1.7439474159228268"/>
    <inertia ixx="0.002047" iyy="0.000687" izz="0.001838" ixy="-0.0" iyz="1.1e-05" ixz="-0.0"/>
  </inertial>
  <visual>
    <origin xyz="-0.084859 -0.060824 0.304444" rpy="0 0 0"/>
    <geometry>
      <mesh filename="package://bez2_description/meshes/ankle_motors_v3_1.stl" scale="0.001 0.001 0.001"/>
    </geometry>
    <material name="steel_satin"/>
  </visual>
  <collision>
    <origin xyz="-0.084859 -0.060824 0.304444" rpy="0 0 0"/>
    <geometry>
      <mesh filename="package://bez2_description/meshes/ankle_motors_v3_1.stl" scale="0.001 0.001 0.001"/>
    </geometry>
  </collision>
</link>

<link name="ankle_motors_v3_2">
  <inertial>
    <origin xyz="-0.023299675401958417 0.02064915860550208 0.01497543954853836" rpy="0 0 0"/>
    <mass value="1.7439474159228268"/>
    <inertia ixx="0.002047" iyy="0.000687" izz="0.001838" ixy="-0.0" iyz="1.1e-05" ixz="-0.0"/>
  </inertial>
  <visual>
    <origin xyz="-0.060359 -0.059324 0.304444" rpy="0 0 0"/>
    <geometry>
      <mesh filename="package://bez2_description/meshes/ankle_motors_v3_2.stl" scale="0.001 0.001 0.001"/>
    </geometry>
    <material name="steel_satin"/>
  </visual>
  <collision>
    <origin xyz="-0.060359 -0.059324 0.304444" rpy="0 0 0"/>
    <geometry>
      <mesh filename="package://bez2_description/meshes/ankle_motors_v3_2.stl" scale="0.001 0.001 0.001"/>
    </geometry>
  </collision>
</link>

<joint name="Rev1" type="continuous">
  <origin xyz="0.144659 0.075444 0.072056" rpy="0 0 0"/>
  <parent link="base_link"/>
  <child link="biceps_v2_1"/>
  <axis xyz="-1.0 0.0 0.0"/>
</joint>

<joint name="Rev2" type="continuous">
  <origin xyz="0.008 0.0 -0.0906" rpy="0 0 0"/>
  <parent link="biceps_v2_1"/>
  <child link="Arm_Assembly-bez3_v10_2"/>
  <axis xyz="-1.0 -0.0 0.0"/>
</joint>

<joint name="Rev3" type="continuous">
  <origin xyz="-0.000341 0.075444 0.072056" rpy="0 0 0"/>
  <parent link="base_link"/>
  <child link="biceps_v2_2"/>
  <axis xyz="1.0 -0.0 -0.0"/>
</joint>

<joint name="Rev4" type="continuous">
  <origin xyz="-0.008 0.0 -0.0906" rpy="0 0 0"/>
  <parent link="biceps_v2_2"/>
  <child link="Arm_Assembly-bez3_v10_1"/>
  <axis xyz="1.0 0.0 0.0"/>
</joint>

<joint name="Rev5" type="continuous">
  <origin xyz="0.035359 0.059474 -0.072444" rpy="0 0 0"/>
  <parent link="base_link"/>
  <child link="Hip_Printable_v2_v9_1"/>
  <axis xyz="0.0 0.0 -1.0"/>
</joint>

<joint name="Rev6" type="continuous">
  <origin xyz="0.109859 0.059474 -0.072444" rpy="0 0 0"/>
  <parent link="base_link"/>
  <child link="Hip_Printable_v2_v9_2"/>
  <axis xyz="0.0 0.0 -1.0"/>
</joint>

<joint name="Rev7" type="continuous">
  <origin xyz="0.0 0.0235 -0.032" rpy="0 0 0"/>
  <parent link="Hip_Printable_v2_v9_1"/>
  <child link="hip_motors_v3_1"/>
  <axis xyz="-0.0 -1.0 -0.0"/>
</joint>

<joint name="Rev8" type="continuous">
  <origin xyz="0.0 0.025 -0.032" rpy="0 0 0"/>
  <parent link="Hip_Printable_v2_v9_2"/>
  <child link="hip_motors_v3_2"/>
  <axis xyz="-0.0 -1.0 -0.0"/>
</joint>

<joint name="Rev9" type="continuous">
  <origin xyz="-0.02 -0.02365 0.0" rpy="0 0 0"/>
  <parent link="hip_motors_v3_2"/>
  <child link="Upper_left_leg_support__bottom__v7_1"/>
  <axis xyz="-1.0 -0.0 0.0"/>
</joint>

<joint name="Rev10" type="continuous">
  <origin xyz="0.02 -0.02365 0.0" rpy="0 0 0"/>
  <parent link="hip_motors_v3_1"/>
  <child link="Upper_left_leg_support__bottom__v7_2"/>
  <axis xyz="1.0 0.0 0.0"/>
</joint>

<joint name="Rev17" type="continuous">
  <origin xyz="-0.0233 0.0843 0.0" rpy="0 0 0"/>
  <parent link="ankle_motors_v3_2"/>
  <child link="New_left_foot_upperhalf_v4_1"/>
  <axis xyz="0.0 -1.0 -0.0"/>
</joint>

<joint name="Rev18" type="continuous">
  <origin xyz="0.0233 0.0843 0.0" rpy="0 0 0"/>
  <parent link="ankle_motors_v3_1"/>
  <child link="New_right_foot_upperhalf_v2_1"/>
  <axis xyz="0.0 -1.0 -0.0"/>
</joint>

<joint name="Rigid19" type="fixed">
  <origin xyz="0.056826 0.037694 0.100556" rpy="0 0 0"/>
  <parent link="base_link"/>
  <child link="neck_v2_1"/>
</joint>

<joint name="Rev20" type="continuous">
  <origin xyz="0.015 0.0045 0.046674" rpy="0 0 0"/>
  <parent link="neck_v2_1"/>
  <child link="custom_servo_support__middle_neck__v8_1"/>
  <axis xyz="0.0 -0.0 1.0"/>
</joint>

<joint name="Rev21" type="continuous">
  <origin xyz="-0.022187 0.0 0.033818" rpy="0 0 0"/>
  <parent link="custom_servo_support__middle_neck__v8_1"/>
  <child link="head_v2_1"/>
  <axis xyz="-1.0 0.0 0.0"/>
</joint>

<joint name="Rev22" type="continuous">
  <origin xyz="0.0045 0.0 -0.0917" rpy="0 0 0"/>
  <parent link="Upper_left_leg_support__bottom__v7_2"/>
  <child link="lower_leg_v2_1"/>
  <axis xyz="1.0 0.0 0.0"/>
</joint>

<joint name="Rev23" type="continuous">
  <origin xyz="-0.0045 0.0 -0.0917" rpy="0 0 0"/>
  <parent link="Upper_left_leg_support__bottom__v7_1"/>
  <child link="lower_leg_v2_2"/>
  <axis xyz="-1.0 -0.0 0.0"/>
</joint>

<joint name="Rev25" type="continuous">
  <origin xyz="-0.0005 0.0 -0.1083" rpy="0 0 0"/>
  <parent link="lower_leg_v2_2"/>
  <child link="ankle_motors_v3_1"/>
  <axis xyz="-1.0 0.0 0.0"/>
</joint>

<joint name="Rev26" type="continuous">
  <origin xyz="0.0005 0.0 -0.1083" rpy="0 0 0"/>
  <parent link="lower_leg_v2_1"/>
  <child link="ankle_motors_v3_2"/>
  <axis xyz="1.0 -0.0 0.0"/>
</joint>

</robot>
