<?xml version="1.0" ?>
<robot name="bez2" xmlns:xacro="http://www.ros.org/wiki/xacro">

<xacro:include filename="$(find bez2_description)/urdf/materials.xacro" />
<xacro:include filename="$(find bez2_description)/urdf/bez2.trans" />
<xacro:include filename="$(find bez2_description)/urdf/bez2.gazebo" />
<link name="base_link">
  <inertial>
    <origin xyz="0.07343372628291743 0.07159927292954832 0.020872010814779768" rpy="0 0 0"/>
    <mass value="1.3874949527504563"/>
    <inertia ixx="0.004586" iyy="0.005498" izz="0.00387" ixy="-8e-06" iyz="0.000146" ixz="0.000118"/>
  </inertial>
  <visual>
    <origin xyz="0 0 0" rpy="0 0 0"/>
    <geometry>
      <mesh filename="package://bez2_description/meshes/base_link.stl" scale="0.001 0.001 0.001"/>
    </geometry>
    <material name="polymide_kapton"/>
  </visual>
  <collision>
    <origin xyz="0 0 0" rpy="0 0 0"/>
    <geometry>
      <mesh filename="package://bez2_description/meshes/base_link.stl" scale="0.001 0.001 0.001"/>
    </geometry>
  </collision>
</link>

<link name="biceps_v3_1">
  <inertial>
    <origin xyz="0.026300253416251113 -1.0338235605089618e-07 -0.03838594777031868" rpy="0 0 0"/>
    <mass value="0.25825416029102555"/>
    <inertia ixx="0.000394" iyy="0.000437" izz="6.4e-05" ixy="-0.0" iyz="0.0" ixz="3.3e-05"/>
  </inertial>
  <visual>
    <origin xyz="-0.144659 -0.075444 -0.072056" rpy="0 0 0"/>
    <geometry>
      <mesh filename="package://bez2_description/meshes/biceps_v3_1.stl" scale="0.001 0.001 0.001"/>
    </geometry>
    <material name="plastic_glossy_black"/>
  </visual>
  <collision>
    <origin xyz="-0.144659 -0.075444 -0.072056" rpy="0 0 0"/>
    <geometry>
      <mesh filename="package://bez2_description/meshes/biceps_v3_1.stl" scale="0.001 0.001 0.001"/>
    </geometry>
  </collision>
</link>

<link name="Arm_Assembly-bez3_v12_2">
  <inertial>
    <origin xyz="0.02284504145700883 0.005329912793864702 0.029751383749166617" rpy="0 0 0"/>
    <mass value="0.32110352957731503"/>
    <inertia ixx="0.002137" iyy="0.002148" izz="0.000103" ixy="-3e-06" iyz="0.000175" ixz="1.6e-05"/>
  </inertial>
  <visual>
    <origin xyz="-0.152659 -0.075444 0.018544" rpy="0 0 0"/>
    <geometry>
      <mesh filename="package://bez2_description/meshes/Arm_Assembly-bez3_v12_2.stl" scale="0.001 0.001 0.001"/>
    </geometry>
    <material name="abs_white"/>
  </visual>
  <collision>
    <origin xyz="-0.152659 -0.075444 0.018544" rpy="0 0 0"/>
    <geometry>
      <mesh filename="package://bez2_description/meshes/Arm_Assembly-bez3_v12_2.stl" scale="0.001 0.001 0.001"/>
    </geometry>
  </collision>
</link>

<link name="biceps_v3_2">
  <inertial>
    <origin xyz="-0.026299609355872014 -1.0338333342185813e-07 -0.03838594777031868" rpy="0 0 0"/>
    <mass value="0.25825416029102555"/>
    <inertia ixx="0.000394" iyy="0.000437" izz="6.4e-05" ixy="-0.0" iyz="-0.0" ixz="-3.3e-05"/>
  </inertial>
  <visual>
    <origin xyz="0.000341 -0.075444 -0.072056" rpy="0 0 0"/>
    <geometry>
      <mesh filename="package://bez2_description/meshes/biceps_v3_2.stl" scale="0.001 0.001 0.001"/>
    </geometry>
    <material name="plastic_glossy_black"/>
  </visual>
  <collision>
    <origin xyz="0.000341 -0.075444 -0.072056" rpy="0 0 0"/>
    <geometry>
      <mesh filename="package://bez2_description/meshes/biceps_v3_2.stl" scale="0.001 0.001 0.001"/>
    </geometry>
  </collision>
</link>

<link name="Arm_Assembly-bez3_v12_1">
  <inertial>
    <origin xyz="-0.025828958542993025 0.005329912793873015 0.02975138374916475" rpy="0 0 0"/>
    <mass value="0.32110352957731503"/>
    <inertia ixx="0.002137" iyy="0.002148" izz="0.000103" ixy="-3e-06" iyz="0.000175" ixz="1.6e-05"/>
  </inertial>
  <visual>
    <origin xyz="0.008341 -0.075444 0.018544" rpy="0 0 0"/>
    <geometry>
      <mesh filename="package://bez2_description/meshes/Arm_Assembly-bez3_v12_1.stl" scale="0.001 0.001 0.001"/>
    </geometry>
    <material name="abs_white"/>
  </visual>
  <collision>
    <origin xyz="0.008341 -0.075444 0.018544" rpy="0 0 0"/>
    <geometry>
      <mesh filename="package://bez2_description/meshes/Arm_Assembly-bez3_v12_1.stl" scale="0.001 0.001 0.001"/>
    </geometry>
  </collision>
</link>

<link name="Hip_Printable_v2_v10_1">
  <inertial>
    <origin xyz="3.220301637574252e-07 -4.2278800908499004e-05 -0.014017264198397453" rpy="0 0 0"/>
    <mass value="0.010089224750638792"/>
    <inertia ixx="6e-06" iyy="2e-06" izz="5e-06" ixy="-0.0" iyz="-0.0" ixz="-0.0"/>
  </inertial>
  <visual>
    <origin xyz="-0.035359 -0.059474 0.072444" rpy="0 0 0"/>
    <geometry>
      <mesh filename="package://bez2_description/meshes/Hip_Printable_v2_v10_1.stl" scale="0.001 0.001 0.001"/>
    </geometry>
    <material name="abs_white"/>
  </visual>
  <collision>
    <origin xyz="-0.035359 -0.059474 0.072444" rpy="0 0 0"/>
    <geometry>
      <mesh filename="package://bez2_description/meshes/Hip_Printable_v2_v10_1.stl" scale="0.001 0.001 0.001"/>
    </geometry>
  </collision>
</link>

<link name="Hip_Printable_v2_v10_2">
  <inertial>
    <origin xyz="3.220301620365795e-07 -4.227880091287051e-05 -0.01401726419839748" rpy="0 0 0"/>
    <mass value="0.010089224750638792"/>
    <inertia ixx="6e-06" iyy="2e-06" izz="5e-06" ixy="-0.0" iyz="-0.0" ixz="-0.0"/>
  </inertial>
  <visual>
    <origin xyz="-0.109859 -0.059474 0.072444" rpy="0 0 0"/>
    <geometry>
      <mesh filename="package://bez2_description/meshes/Hip_Printable_v2_v10_2.stl" scale="0.001 0.001 0.001"/>
    </geometry>
    <material name="abs_white"/>
  </visual>
  <collision>
    <origin xyz="-0.109859 -0.059474 0.072444" rpy="0 0 0"/>
    <geometry>
      <mesh filename="package://bez2_description/meshes/Hip_Printable_v2_v10_2.stl" scale="0.001 0.001 0.001"/>
    </geometry>
  </collision>
</link>

<link name="hip_motors_v4_1">
  <inertial>
    <origin xyz="2.491527500980695e-07 -0.009088099875617373 -0.011907281385175342" rpy="0 0 0"/>
    <mass value="0.2728199051639206"/>
    <inertia ixx="0.000178" iyy="7.4e-05" izz="0.000153" ixy="0.0" iyz="1e-06" ixz="0.0"/>
  </inertial>
  <visual>
    <origin xyz="-0.035359 -0.082974 0.104444" rpy="0 0 0"/>
    <geometry>
      <mesh filename="package://bez2_description/meshes/hip_motors_v4_1.stl" scale="0.001 0.001 0.001"/>
    </geometry>
    <material name="silver_default"/>
  </visual>
  <collision>
    <origin xyz="-0.035359 -0.082974 0.104444" rpy="0 0 0"/>
    <geometry>
      <mesh filename="package://bez2_description/meshes/hip_motors_v4_1.stl" scale="0.001 0.001 0.001"/>
    </geometry>
  </collision>
</link>

<link name="hip_motors_v4_2">
  <inertial>
    <origin xyz="2.491527557740847e-07 -0.009088099875621716 -0.011907281385175342" rpy="0 0 0"/>
    <mass value="0.2728199051639206"/>
    <inertia ixx="0.000178" iyy="7.4e-05" izz="0.000153" ixy="0.0" iyz="1e-06" ixz="0.0"/>
  </inertial>
  <visual>
    <origin xyz="-0.109859 -0.084474 0.104444" rpy="0 0 0"/>
    <geometry>
      <mesh filename="package://bez2_description/meshes/hip_motors_v4_2.stl" scale="0.001 0.001 0.001"/>
    </geometry>
    <material name="silver_default"/>
  </visual>
  <collision>
    <origin xyz="-0.109859 -0.084474 0.104444" rpy="0 0 0"/>
    <geometry>
      <mesh filename="package://bez2_description/meshes/hip_motors_v4_2.stl" scale="0.001 0.001 0.001"/>
    </geometry>
  </collision>
</link>

<link name="Upper_left_leg_support__bottom__v8_1">
  <inertial>
    <origin xyz="0.019462816432113214 -1.0283150438106237e-07 -0.048113683972305823" rpy="0 0 0"/>
    <mass value="0.027169463894965433"/>
    <inertia ixx="2.2e-05" iyy="3.2e-05" izz="1.3e-05" ixy="-0.0" iyz="0.0" ixz="-0.0"/>
  </inertial>
  <visual>
    <origin xyz="-0.089859 -0.060824 0.104444" rpy="0 0 0"/>
    <geometry>
      <mesh filename="package://bez2_description/meshes/Upper_left_leg_support__bottom__v8_1.stl" scale="0.001 0.001 0.001"/>
    </geometry>
    <material name="abs_white"/>
  </visual>
  <collision>
    <origin xyz="-0.089859 -0.060824 0.104444" rpy="0 0 0"/>
    <geometry>
      <mesh filename="package://bez2_description/meshes/Upper_left_leg_support__bottom__v8_1.stl" scale="0.001 0.001 0.001"/>
    </geometry>
  </collision>
</link>

<link name="Upper_left_leg_support__bottom__v8_2">
  <inertial>
    <origin xyz="-0.019537183567898096 -1.028314992185253e-07 -0.048113683972305823" rpy="0 0 0"/>
    <mass value="0.027169463894965433"/>
    <inertia ixx="2.2e-05" iyy="3.2e-05" izz="1.3e-05" ixy="-0.0" iyz="0.0" ixz="-0.0"/>
  </inertial>
  <visual>
    <origin xyz="-0.055359 -0.059324 0.104444" rpy="0 0 0"/>
    <geometry>
      <mesh filename="package://bez2_description/meshes/Upper_left_leg_support__bottom__v8_2.stl" scale="0.001 0.001 0.001"/>
    </geometry>
    <material name="abs_white"/>
  </visual>
  <collision>
    <origin xyz="-0.055359 -0.059324 0.104444" rpy="0 0 0"/>
    <geometry>
      <mesh filename="package://bez2_description/meshes/Upper_left_leg_support__bottom__v8_2.stl" scale="0.001 0.001 0.001"/>
    </geometry>
  </collision>
</link>

<link name="New_left_foot_upperhalf_v5_1">
  <inertial>
    <origin xyz="-0.012180584726820248 -0.05139354649788158 -0.0217764734148449" rpy="0 0 0"/>
    <mass value="0.0588564551543425"/>
    <inertia ixx="0.000149" iyy="3.9e-05" izz="0.000178" ixy="0.0" iyz="0.0" ixz="-3e-06"/>
  </inertial>
  <visual>
    <origin xyz="-0.037059 -0.143624 0.304444" rpy="0 0 0"/>
    <geometry>
      <mesh filename="package://bez2_description/meshes/New_left_foot_upperhalf_v5_1.stl" scale="0.001 0.001 0.001"/>
    </geometry>
    <material name="abs_white"/>
  </visual>
  <collision>
    <origin xyz="-0.037059 -0.143624 0.304444" rpy="0 0 0"/>
    <geometry>
      <mesh filename="package://bez2_description/meshes/New_left_foot_upperhalf_v5_1.stl" scale="0.001 0.001 0.001"/>
    </geometry>
  </collision>
</link>

<link name="New_right_foot_upperhalf_v3_1">
  <inertial>
    <origin xyz="0.060000322030201225 -0.051393547332351824 -0.021776473414845232" rpy="0 0 0"/>
    <mass value="0.117712910308685"/>
    <inertia ixx="0.000297" iyy="0.000348" izz="0.000625" ixy="0.0" iyz="1e-06" ixz="0.0"/>
  </inertial>
  <visual>
    <origin xyz="-0.108159 -0.145124 0.304444" rpy="0 0 0"/>
    <geometry>
      <mesh filename="package://bez2_description/meshes/New_right_foot_upperhalf_v3_1.stl" scale="0.001 0.001 0.001"/>
    </geometry>
    <material name="abs_white"/>
  </visual>
  <collision>
    <origin xyz="-0.108159 -0.145124 0.304444" rpy="0 0 0"/>
    <geometry>
      <mesh filename="package://bez2_description/meshes/New_right_foot_upperhalf_v3_1.stl" scale="0.001 0.001 0.001"/>
    </geometry>
  </collision>
</link>

<link name="neck_v4_1">
  <inertial>
    <origin xyz="0.014999915739446909 0.012879582990262754 0.024886118937898494" rpy="0 0 0"/>
    <mass value="0.10655783809755558"/>
    <inertia ixx="3e-05" iyy="1.9e-05" izz="1.9e-05" ixy="-0.0" iyz="3e-06" ixz="0.0"/>
  </inertial>
  <visual>
    <origin xyz="-0.056826 -0.037694 -0.100556" rpy="0 0 0"/>
    <geometry>
      <mesh filename="package://bez2_description/meshes/neck_v4_1.stl" scale="0.001 0.001 0.001"/>
    </geometry>
    <material name="abs_white"/>
  </visual>
  <collision>
    <origin xyz="-0.056826 -0.037694 -0.100556" rpy="0 0 0"/>
    <geometry>
      <mesh filename="package://bez2_description/meshes/neck_v4_1.stl" scale="0.001 0.001 0.001"/>
    </geometry>
  </collision>
</link>

<link name="custom_servo_support__middle_neck__v9_1">
  <inertial>
    <origin xyz="0.0015600810093761297 -1.0333814156465726e-07 0.014703004853071633" rpy="0 0 0"/>
    <mass value="0.01959544470499754"/>
    <inertia ixx="6e-06" iyy="1.4e-05" izz="1.2e-05" ixy="0.0" iyz="0.0" ixz="0.0"/>
  </inertial>
  <visual>
    <origin xyz="-0.071826 -0.042194 -0.14723" rpy="0 0 0"/>
    <geometry>
      <mesh filename="package://bez2_description/meshes/custom_servo_support__middle_neck__v9_1.stl" scale="0.001 0.001 0.001"/>
    </geometry>
    <material name="abs_white"/>
  </visual>
  <collision>
    <origin xyz="-0.071826 -0.042194 -0.14723" rpy="0 0 0"/>
    <geometry>
      <mesh filename="package://bez2_description/meshes/custom_servo_support__middle_neck__v9_1.stl" scale="0.001 0.001 0.001"/>
    </geometry>
  </collision>
</link>

<link name="head_v4_1">
  <inertial>
    <origin xyz="0.024245597582648673 -0.0037488657746306553 0.024987900172004557" rpy="0 0 0"/>
    <mass value="0.29338454987270446"/>
    <inertia ixx="0.000239" iyy="0.00023" izz="0.000194" ixy="2e-06" iyz="7.6e-05" ixz="-1.1e-05"/>
  </inertial>
  <visual>
    <origin xyz="-0.049639 -0.042194 -0.181048" rpy="0 0 0"/>
    <geometry>
      <mesh filename="package://bez2_description/meshes/head_v4_1.stl" scale="0.001 0.001 0.001"/>
    </geometry>
    <material name="plastic_glossy_black"/>
  </visual>
  <collision>
    <origin xyz="-0.049639 -0.042194 -0.181048" rpy="0 0 0"/>
    <geometry>
      <mesh filename="package://bez2_description/meshes/head_v4_1.stl" scale="0.001 0.001 0.001"/>
    </geometry>
  </collision>
</link>

<link name="lower_leg_v4_1">
  <inertial>
    <origin xyz="-0.023191603027466604 -9.582728020818276e-08 -0.02213339724981117" rpy="0 0 0"/>
    <mass value="0.1476733120184745"/>
    <inertia ixx="0.000107" iyy="0.000124" izz="4.1e-05" ixy="-0.0" iyz="0.0" ixz="-2e-06"/>
  </inertial>
  <visual>
    <origin xyz="-0.059859 -0.059324 0.196144" rpy="0 0 0"/>
    <geometry>
      <mesh filename="package://bez2_description/meshes/lower_leg_v4_1.stl" scale="0.001 0.001 0.001"/>
    </geometry>
    <material name="abs_white"/>
  </visual>
  <collision>
    <origin xyz="-0.059859 -0.059324 0.196144" rpy="0 0 0"/>
    <geometry>
      <mesh filename="package://bez2_description/meshes/lower_leg_v4_1.stl" scale="0.001 0.001 0.001"/>
    </geometry>
  </collision>
</link>

<link name="lower_leg_v4_2">
  <inertial>
    <origin xyz="0.02319224708785829 -1.0983572364814398e-07 -0.02213339724981142" rpy="0 0 0"/>
    <mass value="0.1476733120184745"/>
    <inertia ixx="0.000107" iyy="0.000124" izz="4.1e-05" ixy="-0.0" iyz="-0.0" ixz="2e-06"/>
  </inertial>
  <visual>
    <origin xyz="-0.085359 -0.060824 0.196144" rpy="0 0 0"/>
    <geometry>
      <mesh filename="package://bez2_description/meshes/lower_leg_v4_2.stl" scale="0.001 0.001 0.001"/>
    </geometry>
    <material name="abs_white"/>
  </visual>
  <collision>
    <origin xyz="-0.085359 -0.060824 0.196144" rpy="0 0 0"/>
    <geometry>
      <mesh filename="package://bez2_description/meshes/lower_leg_v4_2.stl" scale="0.001 0.001 0.001"/>
    </geometry>
  </collision>
</link>

<link name="ankle_motors_v4_1">
  <inertial>
    <origin xyz="0.023300324626133573 0.020543270558517568 0.015062653184791719" rpy="0 0 0"/>
    <mass value="0.3955604131597503"/>
    <inertia ixx="0.000468" iyy="0.000155" izz="0.000419" ixy="-0.0" iyz="2e-06" ixz="-0.0"/>
  </inertial>
  <visual>
    <origin xyz="-0.084859 -0.060824 0.304444" rpy="0 0 0"/>
    <geometry>
      <mesh filename="package://bez2_description/meshes/ankle_motors_v4_1.stl" scale="0.001 0.001 0.001"/>
    </geometry>
    <material name="steel_satin"/>
  </visual>
  <collision>
    <origin xyz="-0.084859 -0.060824 0.304444" rpy="0 0 0"/>
    <geometry>
      <mesh filename="package://bez2_description/meshes/ankle_motors_v4_1.stl" scale="0.001 0.001 0.001"/>
    </geometry>
  </collision>
</link>

<link name="ankle_motors_v4_2">
  <inertial>
    <origin xyz="-0.023299675373877886 0.02054327139298781 0.01506265318479183" rpy="0 0 0"/>
    <mass value="0.3955604131597503"/>
    <inertia ixx="0.000468" iyy="0.000155" izz="0.000419" ixy="-0.0" iyz="2e-06" ixz="-0.0"/>
  </inertial>
  <visual>
    <origin xyz="-0.060359 -0.059324 0.304444" rpy="0 0 0"/>
    <geometry>
      <mesh filename="package://bez2_description/meshes/ankle_motors_v4_2.stl" scale="0.001 0.001 0.001"/>
    </geometry>
    <material name="steel_satin"/>
  </visual>
  <collision>
    <origin xyz="-0.060359 -0.059324 0.304444" rpy="0 0 0"/>
    <geometry>
      <mesh filename="package://bez2_description/meshes/ankle_motors_v4_2.stl" scale="0.001 0.001 0.001"/>
    </geometry>
  </collision>
</link>

<link name="camera_point_1">
  <inertial>
    <origin xyz="-1.1616073519737924e-08 0.000999895991307411 -4.265551301618764e-07" rpy="0 0 0"/>
    <mass value="0.0005023999999999976"/>
    <inertia ixx="0.0" iyy="0.0" izz="0.0" ixy="-0.0" iyz="-0.0" ixz="0.0"/>
  </inertial>
  <visual>
    <origin xyz="-0.075313 -0.007794 -0.229048" rpy="0 0 0"/>
    <geometry>
      <mesh filename="package://bez2_description/meshes/camera_point_1.stl" scale="0.001 0.001 0.001"/>
    </geometry>
    <material name="steel_satin"/>
  </visual>
  <collision>
    <origin xyz="-0.075313 -0.007794 -0.229048" rpy="0 0 0"/>
    <geometry>
      <mesh filename="package://bez2_description/meshes/camera_point_1.stl" scale="0.001 0.001 0.001"/>
    </geometry>
  </collision>
</link>

<link name="imu_1">
  <inertial>
    <origin xyz="3.220301867390418e-07 -0.04000010338284481 -0.04299989661715594" rpy="0 0 0"/>
    <mass value="0.0005024000000000008"/>
    <inertia ixx="0.0" iyy="0.0" izz="0.0" ixy="0.0" iyz="0.0" ixz="-0.0"/>
  </inertial>
  <visual>
    <origin xyz="-0.072159 -0.062444 -0.100556" rpy="0 0 0"/>
    <geometry>
      <mesh filename="package://bez2_description/meshes/imu_1.stl" scale="0.001 0.001 0.001"/>
    </geometry>
    <material name="steel_satin"/>
  </visual>
  <collision>
    <origin xyz="-0.072159 -0.062444 -0.100556" rpy="0 0 0"/>
    <geometry>
      <mesh filename="package://bez2_description/meshes/imu_1.stl" scale="0.001 0.001 0.001"/>
    </geometry>
  </collision>
</link>

<joint name="left_arm_motor_0" type="continuous">
  <origin xyz="0.144659 0.075444 0.072056" rpy="0 0 0"/>
  <parent link="base_link"/>
  <child link="biceps_v3_1"/>
  <axis xyz="-1.0 0.0 0.0"/>
</joint>

<joint name="left_arm_motor_1" type="continuous">
  <origin xyz="0.008 0.0 -0.0906" rpy="0 0 0"/>
  <parent link="biceps_v3_1"/>
  <child link="Arm_Assembly-bez3_v12_2"/>
  <axis xyz="-1.0 -0.0 0.0"/>
</joint>

<joint name="right_arm_motor_0" type="continuous">
  <origin xyz="-0.000341 0.075444 0.072056" rpy="0 0 0"/>
  <parent link="base_link"/>
  <child link="biceps_v3_2"/>
  <axis xyz="1.0 -0.0 -0.0"/>
</joint>

<joint name="right_arm_motor_1" type="continuous">
  <origin xyz="-0.008 0.0 -0.0906" rpy="0 0 0"/>
  <parent link="biceps_v3_2"/>
  <child link="Arm_Assembly-bez3_v12_1"/>
  <axis xyz="1.0 0.0 0.0"/>
</joint>

<joint name="right_leg_motor_0" type="continuous">
  <origin xyz="0.035359 0.059474 -0.072444" rpy="0 0 0"/>
  <parent link="base_link"/>
  <child link="Hip_Printable_v2_v10_1"/>
  <axis xyz="0.0 0.0 -1.0"/>
</joint>

<joint name="left_leg_motor_0" type="continuous">
  <origin xyz="0.109859 0.059474 -0.072444" rpy="0 0 0"/>
  <parent link="base_link"/>
  <child link="Hip_Printable_v2_v10_2"/>
  <axis xyz="0.0 0.0 -1.0"/>
</joint>

<joint name="right_leg_motor_1" type="continuous">
  <origin xyz="0.0 0.0235 -0.032" rpy="0 0 0"/>
  <parent link="Hip_Printable_v2_v10_1"/>
  <child link="hip_motors_v4_1"/>
  <axis xyz="-0.0 -1.0 -0.0"/>
</joint>

<joint name="left_leg_motor_1" type="continuous">
  <origin xyz="0.0 0.025 -0.032" rpy="0 0 0"/>
  <parent link="Hip_Printable_v2_v10_2"/>
  <child link="hip_motors_v4_2"/>
  <axis xyz="-0.0 -1.0 -0.0"/>
</joint>

<joint name="left_leg_motor_2" type="continuous">
  <origin xyz="-0.02 -0.02365 0.0" rpy="0 0 0"/>
  <parent link="hip_motors_v4_2"/>
  <child link="Upper_left_leg_support__bottom__v8_1"/>
  <axis xyz="-1.0 -0.0 0.0"/>
</joint>

<joint name="right_leg_motor_2" type="continuous">
  <origin xyz="0.02 -0.02365 0.0" rpy="0 0 0"/>
  <parent link="hip_motors_v4_1"/>
  <child link="Upper_left_leg_support__bottom__v8_2"/>
  <axis xyz="1.0 0.0 0.0"/>
</joint>

<joint name="right_leg_motor_5" type="continuous">
  <origin xyz="-0.0233 0.0843 0.0" rpy="0 0 0"/>
  <parent link="ankle_motors_v4_2"/>
  <child link="New_left_foot_upperhalf_v5_1"/>
  <axis xyz="0.0 -1.0 -0.0"/>
</joint>

<joint name="left_leg_motor_5" type="continuous">
  <origin xyz="0.0233 0.0843 0.0" rpy="0 0 0"/>
  <parent link="ankle_motors_v4_1"/>
  <child link="New_right_foot_upperhalf_v3_1"/>
  <axis xyz="0.0 -1.0 -0.0"/>
</joint>

<joint name="Rigid19" type="fixed">
  <origin xyz="0.056826 0.037694 0.100556" rpy="0 0 0"/>
  <parent link="base_link"/>
  <child link="neck_v4_1"/>
</joint>

<joint name="head_motor_0" type="continuous">
  <origin xyz="0.015 0.0045 0.046674" rpy="0 0 0"/>
  <parent link="neck_v4_1"/>
  <child link="custom_servo_support__middle_neck__v9_1"/>
  <axis xyz="0.0 -0.0 1.0"/>
</joint>

<joint name="head_motor_1" type="continuous">
  <origin xyz="-0.022187 0.0 0.033818" rpy="0 0 0"/>
  <parent link="custom_servo_support__middle_neck__v9_1"/>
  <child link="head_v4_1"/>
  <axis xyz="-1.0 0.0 0.0"/>
</joint>

<joint name="right_leg_motor_3" type="continuous">
  <origin xyz="0.0045 0.0 -0.0917" rpy="0 0 0"/>
  <parent link="Upper_left_leg_support__bottom__v8_2"/>
  <child link="lower_leg_v4_1"/>
  <axis xyz="1.0 0.0 0.0"/>
</joint>

<joint name="left_leg_motor_3" type="continuous">
  <origin xyz="-0.0045 0.0 -0.0917" rpy="0 0 0"/>
  <parent link="Upper_left_leg_support__bottom__v8_1"/>
  <child link="lower_leg_v4_2"/>
  <axis xyz="-1.0 -0.0 0.0"/>
</joint>

<joint name="left_leg_motor_4" type="continuous">
  <origin xyz="-0.0005 0.0 -0.1083" rpy="0 0 0"/>
  <parent link="lower_leg_v4_2"/>
  <child link="ankle_motors_v4_1"/>
  <axis xyz="-1.0 0.0 0.0"/>
</joint>

<joint name="right_leg_motor_4" type="continuous">
  <origin xyz="0.0005 0.0 -0.1083" rpy="0 0 0"/>
  <parent link="lower_leg_v4_1"/>
  <child link="ankle_motors_v4_2"/>
  <axis xyz="1.0 -0.0 0.0"/>
</joint>

<joint name="camera_joint" type="continuous">
  <origin xyz="0.025674 -0.0344 0.048" rpy="0 0 0"/>
  <parent link="head_v4_1"/>
  <child link="camera_point_1"/>
  <axis xyz="-0.0 -1.0 -0.0"/>
</joint>

<joint name="imu_joint" type="continuous">
  <origin xyz="0.072159 0.062444 0.100556" rpy="0 0 0"/>
  <parent link="base_link"/>
  <child link="imu_1"/>
  <axis xyz="-0.0 -0.0 1.0"/>
</joint>

</robot>
