<?xml version="1.0" ?>
<!-- =================================================================================== -->
<!-- |    This document was autogenerated by xacro from bez2.xacro                     | -->
<!-- |    EDITING THIS FILE BY HAND IS NOT RECOMMENDED                                 | -->
<!-- =================================================================================== -->
<robot name="bez2">
  <material name="white">
    <color rgba="1.0 1.0 1.0 1.0"/>
  </material>
  <material name="black">
    <color rgba="0.0 0.0 0.0 1.0"/>
  </material>
  <material name="silver">
    <color rgba="0.7 0.7 0.7 1.0"/>
  </material>
  <material name="yellow">
    <color rgba="0.9 0.9 0.0 1.0"/>
  </material>
  <material name="red">
    <color rgba="0.7 0.0 0.0 1.0"/>
  </material>
  <material name="green">
    <color rgba="0.0 0.7 0.0 1.0"/>
  </material>
  <material name="blue">
    <color rgba="0.0 0.0 0.7 1.0"/>
  </material>
  <material name="purple">
    <color rgba="0.7 0.0 0.7 1.0"/>
  </material>
  <material name="cyan">
    <color rgba="0.0 0.7 0.7 1.0"/>
  </material>
  <material name="silver_default">
    <color rgba="0.700 0.700 0.700 1.000"/>
  </material>
  <material name="steel_satin">
    <color rgba="0.6274509803921569 0.6274509803921569 0.6274509803921569 1.0"/>
  </material>
  <material name="plastic_matte_yellow">
    <color rgba="0.9098039215686274 0.6784313725490196 0.13725490196078433 1.0"/>
  </material>
  <link name="trunk">
    <inertial>
      <origin rpy="0 0 0" xyz="-2.6182166493521018e-05 0.0037391632790891283 -0.07310917852477573"/>
      <mass value="1.62191101903404"/>
      <inertia ixx="0.17522" ixy="0.000499" ixz="0.001818" iyy="0.126523" iyz="0.000833" izz="0.127074"/>
    </inertial>
    <visual>
      <origin rpy="0 0 0" xyz="0 0 0"/>
      <geometry>
        <mesh filename="../meshes/base_link.stl" scale="0.001 0.001 0.001"/>
      </geometry>
      <material name="steel_satin"/>
    </visual>
    <collision name="collision">
      <origin rpy="0.00000 0.00000 0.00000" xyz="0.00154 0.00254 -0.07057"/>
      <geometry>
        <box size="0.14440 0.20843 0.19912"/>
      </geometry>
    </collision>
  </link>
  <link name="neck">
    <inertial>
      <origin rpy="0 0 0" xyz="2.1597541578072255e-08 -0.005416430173761932 0.014254502404740514"/>
      <mass value="0.015549664333897642"/>
      <inertia ixx="8e-06" ixy="0.0" ixz="-0.0" iyy="3e-06" iyz="1e-06" izz="6e-06"/>
    </inertial>
    <visual>
      <origin rpy="0 0 0" xyz="-0.009539 -0.002537 -0.03138"/>
      <geometry>
        <mesh filename="../meshes/Head_Yaw_Assembly_v1_1.stl" scale="0.001 0.001 0.001"/>
      </geometry>
      <material name="plastic_matte_yellow"/>
    </visual>
    <collision>
      <origin rpy="0.00000 0.00000 0.00000" xyz="0.00000 0.00000 0.01900"/>
      <geometry>
        <box size="0.02200 0.05100 0.03800"/>
      </geometry>
    </collision>
  </link>
  <link name="head">
    <inertial>
      <origin rpy="0 0 0" xyz="-0.006768609392929565 0.018593066407664022 0.012723039586287177"/>
      <mass value="0.5407373847724953"/>
      <inertia ixx="0.000349" ixy="-0.0" ixz="-8.1e-05" iyy="0.000378" iyz="-4e-06" izz="0.000259"/>
    </inertial>
    <visual>
      <origin rpy="0 0 0" xyz="-0.009539 0.016963 -0.05638"/>
      <geometry>
        <mesh filename="../meshes/Head_Pitch_Assembly_v4_1.stl" scale="0.001 0.001 0.001"/>
      </geometry>
      <material name="plastic_matte_yellow"/>
    </visual>
    <collision>
      <origin rpy="0.00000 0.00000 0.00000" xyz="-0.00950 0.01920 0.02340"/>
      <geometry>
        <box size="0.07120 0.09400 0.07530"/>
      </geometry>
    </collision>
  </link>
  <link name="left_shoulder">
    <inertial>
      <origin rpy="0 0 0" xyz="9.49688693072442e-05 0.025391120875814188 -0.00710009103373208"/>
      <mass value="0.172653501389095"/>
      <inertia ixx="0.000136" ixy="0.0" ixz="3e-06" iyy="0.000137" iyz="1.8e-05" izz="0.000116"/>
    </inertial>
    <visual>
      <origin rpy="0 0 0" xyz="-0.006539 -0.112237 0.00062"/>
      <geometry>
        <mesh filename="../meshes/left_shoulder_v1_1.stl" scale="0.001 0.001 0.001"/>
      </geometry>
      <material name="steel_satin"/>
    </visual>
    <collision>
      <origin rpy="0.00000 0.00000 0.00000" xyz="0.00155 0.02365 -0.00750"/>
      <geometry>
        <box size="0.04360 0.04730 0.05100"/>
      </geometry>
    </collision>
  </link>
  <link name="left_bicep">
    <inertial>
      <origin rpy="0 0 0" xyz="-0.01931620093381984 0.0008375708488899958 -0.05229697639295136"/>
      <mass value="0.212120407883451"/>
      <inertia ixx="0.000601" ixy="-0.0" ixz="9e-06" iyy="0.000616" iyz="1.3e-05" izz="0.000236"/>
    </inertial>
    <visual>
      <origin rpy="0 0 0" xyz="-0.027039 -0.141737 0.02162"/>
      <geometry>
        <mesh filename="../meshes/bicep_v1_1.stl" scale="0.001 0.001 0.001"/>
      </geometry>
      <material name="steel_satin"/>
    </visual>
    <collision>
      <origin rpy="0.00000 0.00000 0.00000" xyz="-0.02000 0.00127 -0.04274"/>
      <geometry>
        <box size="0.05000 0.04703 0.11202"/>
      </geometry>
    </collision>
  </link>
  <link name="left_forearm">
    <inertial>
      <origin rpy="0 0 0" xyz="-0.02629981291315407 -0.02054181327377705 -0.07127075071519198"/>
      <mass value="0.06415483406403591"/>
      <inertia ixx="0.000265" ixy="-0.0" ixz="-7e-06" iyy="0.00026" iyz="-0.0" izz="2e-05"/>
    </inertial>
    <visual>
      <origin rpy="0 0 0" xyz="-0.008351 -0.163675 0.10837"/>
      <geometry>
        <mesh filename="../meshes/Bez1_forearm_v7_1.stl" scale="0.001 0.001 0.001"/>
      </geometry>
      <material name="plastic_matte_yellow"/>
    </visual>
    <collision>
      <origin rpy="0.00000 0.00000 0.00000" xyz="-0.01200 -0.02050 -0.08119"/>
      <geometry>
        <box size="0.04800 0.05300 0.18838"/>
      </geometry>
    </collision>
  </link>
  <link name="left_hip_side">
    <inertial>
      <origin rpy="0 0 0" xyz="2.104631423652248e-08 3.399354384647779e-07 -0.0077462434278427195"/>
      <mass value="0.120655957656288"/>
      <inertia ixx="3e-06" ixy="-0.0" ixz="0.0" iyy="8e-06" iyz="-0.0" izz="7e-06"/>
    </inertial>
    <visual>
      <origin rpy="0 0 0" xyz="-0.018839 -0.067737 0.20662"/>
      <geometry>
        <mesh filename="../meshes/fr12_h101_v1_2.stl" scale="0.001 0.001 0.001"/>
      </geometry>
      <material name="steel_satin"/>
    </visual>
    <collision>
      <origin rpy="0.00000 0.00000 0.00000" xyz="0.00000 0.00000 -0.01525"/>
      <geometry>
        <box size="0.04100 0.02400 0.03050"/>
      </geometry>
    </collision>
  </link>
  <link name="left_hip_front">
    <inertial>
      <origin rpy="0 0 0" xyz="0.0004996292549223533 0.0005421424160892835 -0.012131129108951588"/>
      <mass value="0.211645971103128"/>
      <inertia ixx="0.000195" ixy="-8e-06" ixz="-2e-06" iyy="0.000458" iyz="-1e-06" izz="0.000394"/>
    </inertial>
    <visual>
      <origin rpy="0 0 0" xyz="0.001661 -0.067737 0.23462"/>
      <geometry>
        <mesh filename="../meshes/hip_v1_1.stl" scale="0.001 0.001 0.001"/>
      </geometry>
      <material name="steel_satin"/>
    </visual>
    <collision>
      <origin rpy="0.00000 0.00000 0.00000" xyz="-0.00199 0.00180 -0.01200"/>
      <geometry>
        <box size="0.07402 0.04100 0.04650"/>
      </geometry>
    </collision>
  </link>
  <link name="left_thigh">
    <inertial>
      <origin rpy="0 0 0" xyz="2.1046150922715556e-08 -0.018793706652435974 -0.06540894904468947"/>
      <mass value="0.142301969468209"/>
      <inertia ixx="0.000159" ixy="-0.0" ixz="0.0" iyy="0.000121" iyz="1e-06" izz="6.9e-05"/>
    </inertial>
    <visual>
      <origin rpy="0 0 0" xyz="-0.01911 -0.088037 0.23462"/>
      <geometry>
        <mesh filename="../meshes/thigh_v1_1.stl" scale="0.001 0.001 0.001"/>
      </geometry>
      <material name="steel_satin"/>
    </visual>
    <collision>
      <origin rpy="0.00000 0.00000 0.00000" xyz="0.00000 -0.01823 -0.05825"/>
      <geometry>
        <box size="0.03300 0.05100 0.12150"/>
      </geometry>
    </collision>
  </link>
  <link name="left_calve">
    <inertial>
      <origin rpy="0 0 0" xyz="0.00034959081321023905 -0.023268493362085793 -0.030853501915197812"/>
      <mass value="0.143723171211077"/>
      <inertia ixx="0.000176" ixy="0.0" ixz="2e-06" iyy="0.00015" iyz="-2e-06" izz="6.2e-05"/>
    </inertial>
    <visual>
      <origin rpy="0 0 0" xyz="-0.01911 -0.093306 0.35062"/>
      <geometry>
        <mesh filename="../meshes/calf_v1_1.stl" scale="0.001 0.001 0.001"/>
      </geometry>
      <material name="steel_satin"/>
    </visual>
    <collision>
      <origin rpy="0.00000 0.00000 0.00000" xyz="-0.00005 -0.02225 -0.03850"/>
      <geometry>
        <box size="0.04030 0.05350 0.10500"/>
      </geometry>
    </collision>
  </link>
  <link name="left_ankle">
    <inertial>
      <origin rpy="0 0 0" xyz="-0.02065513049536576 -0.023057637545577894 -0.017838420955393897"/>
      <mass value="0.151468601936124"/>
      <inertia ixx="0.000102" ixy="-1e-06" ixz="-1.7e-05" iyy="0.000212" iyz="-2e-06" izz="0.000173"/>
    </inertial>
    <visual>
      <origin rpy="0 0 0" xyz="-0.02041 -0.093306 0.43862"/>
      <geometry>
        <mesh filename="../meshes/ankle_v2_1.stl" scale="0.001 0.001 0.001"/>
      </geometry>
      <material name="steel_satin"/>
    </visual>
    <collision>
      <origin rpy="0.00000 0.00000 0.00000" xyz="-0.02445 -0.02050 -0.01800"/>
      <geometry>
        <box size="0.08910 0.05000 0.06398"/>
      </geometry>
    </collision>
  </link>
  <link name="left_foot">
    <inertial>
      <origin rpy="0 0 0" xyz="0.0476419808535605 0.018106431082562213 -0.01978200152059173"/>
      <mass value="0.16613521684361"/>
      <inertia ixx="0.000247" ixy="-2.6e-05" ixz="1.4e-05" iyy="0.000905" iyz="5e-06" izz="0.001142"/>
    </inertial>
    <visual>
      <origin rpy="0 0 0" xyz="0.04409 -0.069806 0.47462"/>
      <geometry>
        <mesh filename="../meshes/left_foot_v2_1.stl" scale="0.001 0.001 0.001"/>
      </geometry>
      <material name="steel_satin"/>
    </visual>
    <collision>
      <origin rpy="0.00000 0.00000 0.00000" xyz="0.05150 0.01936 -0.00550"/>
      <geometry>
        <box size="0.17000 0.09000 0.03300"/>
      </geometry>
    </collision>
  </link>
  <link name="right_hip_side">
    <inertial>
      <origin rpy="0 0 0" xyz="2.1046314309380865e-08 3.3993543878396704e-07 -0.007746243427843552"/>
      <mass value="0.120655957656288"/>
      <inertia ixx="3e-06" ixy="-0.0" ixz="0.0" iyy="8e-06" iyz="-0.0" izz="7e-06"/>
    </inertial>
    <visual>
      <origin rpy="0 0 0" xyz="-0.018839 0.062663 0.20662"/>
      <geometry>
        <mesh filename="../meshes/fr12_h101_v1_1.stl" scale="0.001 0.001 0.001"/>
      </geometry>
      <material name="steel_satin"/>
    </visual>
    <collision>
      <origin rpy="0.00000 0.00000 0.00000" xyz="0.00000 0.00000 -0.01525"/>
      <geometry>
        <box size="0.04100 0.02400 0.03050"/>
      </geometry>
    </collision>
  </link>
  <link name="right_hip_front">
    <inertial>
      <origin rpy="0 0 0" xyz="0.0004996292549223817 0.0005421424160894084 -0.01213112910895231"/>
      <mass value="0.211645971103128"/>
      <inertia ixx="0.000195" ixy="-8e-06" ixz="-2e-06" iyy="0.000458" iyz="-1e-06" izz="0.000394"/>
    </inertial>
    <visual>
      <origin rpy="0 0 0" xyz="0.001661 0.062663 0.23462"/>
      <geometry>
        <mesh filename="../meshes/hip_v1_2.stl" scale="0.001 0.001 0.001"/>
      </geometry>
      <material name="steel_satin"/>
    </visual>
    <collision>
      <origin rpy="0.00000 0.00000 0.00000" xyz="-0.00199 0.00180 -0.01200"/>
      <geometry>
        <box size="0.07402 0.04100 0.04650"/>
      </geometry>
    </collision>
  </link>
  <link name="right_thigh">
    <inertial>
      <origin rpy="0 0 0" xyz="2.1046151002512836e-08 -0.018793706652437202 -0.0654089490446903"/>
      <mass value="0.142301969468209"/>
      <inertia ixx="0.000159" ixy="-0.0" ixz="0.0" iyy="0.000121" iyz="1e-06" izz="6.9e-05"/>
    </inertial>
    <visual>
      <origin rpy="0 0 0" xyz="-0.01911 0.042363 0.23462"/>
      <geometry>
        <mesh filename="../meshes/thigh_v1_2.stl" scale="0.001 0.001 0.001"/>
      </geometry>
      <material name="steel_satin"/>
    </visual>
    <collision>
      <origin rpy="0.00000 0.00000 0.00000" xyz="0.00000 -0.01823 -0.05825"/>
      <geometry>
        <box size="0.03300 0.05100 0.12150"/>
      </geometry>
    </collision>
  </link>
  <link name="right_calve">
    <inertial>
      <origin rpy="0 0 0" xyz="0.0003495908132103466 -0.023268493362087077 -0.030853501915198367"/>
      <mass value="0.143723171211077"/>
      <inertia ixx="0.000176" ixy="0.0" ixz="2e-06" iyy="0.00015" iyz="-2e-06" izz="6.2e-05"/>
    </inertial>
    <visual>
      <origin rpy="0 0 0" xyz="-0.01911 0.037094 0.35062"/>
      <geometry>
        <mesh filename="../meshes/calf_v1_2.stl" scale="0.001 0.001 0.001"/>
      </geometry>
      <material name="steel_satin"/>
    </visual>
    <collision>
      <origin rpy="0.00000 0.00000 0.00000" xyz="-0.00005 -0.02225 -0.03850"/>
      <geometry>
        <box size="0.04030 0.05350 0.10500"/>
      </geometry>
    </collision>
  </link>
  <link name="right_ankle">
    <inertial>
      <origin rpy="0 0 0" xyz="-0.020655130495365704 -0.023057637545579254 -0.017838420955394507"/>
      <mass value="0.151468601936124"/>
      <inertia ixx="0.000102" ixy="-1e-06" ixz="-1.7e-05" iyy="0.000212" iyz="-2e-06" izz="0.000173"/>
    </inertial>
    <visual>
      <origin rpy="0 0 0" xyz="-0.02041 0.037094 0.43862"/>
      <geometry>
        <mesh filename="../meshes/ankle_v2_2.stl" scale="0.001 0.001 0.001"/>
      </geometry>
      <material name="steel_satin"/>
    </visual>
    <collision>
      <origin rpy="0.00000 0.00000 0.00000" xyz="-0.02445 -0.02050 -0.01800"/>
      <geometry>
        <box size="0.08910 0.05000 0.06398"/>
      </geometry>
    </collision>
  </link>
  <link name="right_foot">
    <inertial>
      <origin rpy="0 0 0" xyz="0.047641980853560625 -0.018107232571891542 -0.019782001520592507"/>
      <mass value="0.16613521684361"/>
      <inertia ixx="0.000247" ixy="2.6e-05" ixz="1.4e-05" iyy="0.000905" iyz="-5e-06" izz="0.001142"/>
    </inertial>
    <visual>
      <origin rpy="0 0 0" xyz="0.04409 0.060594 0.47462"/>
      <geometry>
        <mesh filename="../meshes/right_foot_v2_1.stl" scale="0.001 0.001 0.001"/>
      </geometry>
      <material name="steel_satin"/>
    </visual>
    <collision>
      <origin rpy="0.00000 0.00000 0.00000" xyz="0.05150 -0.01936 -0.00550"/>
      <geometry>
        <box size="0.17000 0.09000 0.03300"/>
      </geometry>
    </collision>
  </link>
  <link name="right_shoulder">
    <inertial>
      <origin rpy="0 0 0" xyz="0.00042714569282304837 -0.025390436050570106 -0.007100091033732914"/>
      <mass value="0.172653501389095"/>
      <inertia ixx="0.000136" ixy="1e-06" ixz="4e-06" iyy="0.000137" iyz="-1.8e-05" izz="0.000116"/>
    </inertial>
    <visual>
      <origin rpy="0 0 0" xyz="-0.006539 0.107163 0.00062"/>
      <geometry>
        <mesh filename="../meshes/right_shoulder_v2_1.stl" scale="0.001 0.001 0.001"/>
      </geometry>
      <material name="steel_satin"/>
    </visual>
    <collision>
      <origin rpy="0.00000 0.00000 0.00000" xyz="0.00168 -0.02365 -0.00750"/>
      <geometry>
        <box size="0.04435 0.04730 0.05100"/>
      </geometry>
    </collision>
  </link>
  <link name="right_bicep">
    <inertial>
      <origin rpy="0 0 0" xyz="-0.02068375587119517 -0.0008368909778958267 -0.05229697639295197"/>
      <mass value="0.212120407883451"/>
      <inertia ixx="0.000601" ixy="-0.0" ixz="-9e-06" iyy="0.000616" iyz="-1.3e-05" izz="0.000236"/>
    </inertial>
    <visual>
      <origin rpy="0 0 0" xyz="-0.027539 0.136663 0.02162"/>
      <geometry>
        <mesh filename="../meshes/bicep_v1_2.stl" scale="0.001 0.001 0.001"/>
      </geometry>
      <material name="steel_satin"/>
    </visual>
    <collision>
      <origin rpy="0.00000 0.00000 0.00000" xyz="-0.02000 -0.00127 -0.04274"/>
      <geometry>
        <box size="0.05000 0.04703 0.11202"/>
      </geometry>
    </collision>
  </link>
  <link name="right_forearm">
    <inertial>
      <origin rpy="0 0 0" xyz="-0.026300599945598205 0.02045796215352269 -0.07127075071519248"/>
      <mass value="0.06415483406403591"/>
      <inertia ixx="0.000265" ixy="-0.0" ixz="-7e-06" iyy="0.00026" iyz="-0.0" izz="2e-05"/>
    </inertial>
    <visual>
      <origin rpy="0 0 0" xyz="-0.006227 0.1586 0.10837"/>
      <geometry>
        <mesh filename="../meshes/Bez1_forearm_v7_2.stl" scale="0.001 0.001 0.001"/>
      </geometry>
      <material name="plastic_matte_yellow"/>
    </visual>
    <collision>
      <origin rpy="0.00000 0.00000 0.00000" xyz="-0.01200 0.02050 -0.08119"/>
      <geometry>
        <box size="0.04800 0.05300 0.18838"/>
      </geometry>
    </collision>
  </link>
  <joint name="head_yaw" type="revolute">
    <origin rpy="0 0 0" xyz="0.009539 0.002537 0.03138"/>
    <parent link="trunk"/>
    <child link="neck"/>
    <axis xyz="0.0 0.0 -1.0"/>
    <dynamics damping="0" friction="0"/>
    <limit effort="1.5" lower="-1.5707963267948966" upper="1.5707963267948966" velocity="6.39"/>
  </joint>
  <joint name="head_pitch" type="revolute">
    <origin rpy="0 0 0" xyz="0.0 -0.0195 0.025"/>
    <parent link="neck"/>
    <child link="head"/>
    <axis xyz="0.0 1.0 0.0"/>
    <dynamics damping="0" friction="0"/>
    <limit effort="1.5" lower="0" upper="1.5707963267948966" velocity="6.39"/>
  </joint>
  <joint name="left_shoulder_pitch" type="revolute">
    <origin rpy="0 0 0" xyz="0.006539 0.112237 -0.00062"/>
    <parent link="trunk"/>
    <child link="left_shoulder"/>
    <axis xyz="-0.0 -1.0 0.0"/>
    <dynamics damping="0" friction="0"/>
    <limit effort="4.1" lower="-3.141592653589793" upper="3.9269908169872414" velocity="4.82"/>
  </joint>
  <joint name="left_shoulder_roll" type="revolute">
    <origin rpy="0 0 0" xyz="0.0205 0.0295 -0.021"/>
    <parent link="left_shoulder"/>
    <child link="left_bicep"/>
    <axis xyz="1.0 -0.0 0.0"/>
    <dynamics damping="0" friction="0"/>
    <limit effort="2.5" lower="0" upper="1.5707963267948966" velocity="5.76"/>
  </joint>
  <joint name="left_elbow" type="revolute">
    <origin rpy="0 0 0" xyz="-0.018688 0.021938 -0.08675"/>
    <parent link="left_bicep"/>
    <child link="left_forearm"/>
    <axis xyz="-0.0 -1.0 -0.0"/>
    <dynamics damping="0" friction="0"/>
    <limit effort="2.5" lower="0" upper="3.141592653589793" velocity="5.76"/>
  </joint>
  <joint name="left_hip_yaw" type="revolute">
    <origin rpy="0 0 0" xyz="0.018839 0.067737 -0.20662"/>
    <parent link="trunk"/>
    <child link="left_hip_side"/>
    <axis xyz="0.0 0.0 -1.0"/>
    <dynamics damping="0" friction="0"/>
    <limit effort="4.1" lower="-1.309" upper="0.524" velocity="4.82"/>
  </joint>
  <joint name="left_hip_roll" type="revolute">
    <origin rpy="0 0 0" xyz="-0.0205 0.0 -0.028"/>
    <parent link="left_hip_side"/>
    <child link="left_hip_front"/>
    <axis xyz="1.0 0.0 0.0"/>
    <dynamics damping="0" friction="0"/>
    <limit effort="4.1" lower="-0.7853981633974483" upper="1.5707963267948966" velocity="4.82"/>
  </joint>
  <joint name="left_hip_pitch" type="revolute">
    <origin rpy="0 0 0" xyz="0.020771 0.0203 0.0"/>
    <parent link="left_hip_front"/>
    <child link="left_thigh"/>
    <axis xyz="-0.0 -1.0 0.0"/>
    <dynamics damping="0" friction="0"/>
    <limit effort="4.1" lower="-0.7853981633974483" upper="2.356194490192345" velocity="4.82"/>
  </joint>
  <joint name="left_knee" type="revolute">
    <origin rpy="0 0 0" xyz="0.0 0.005269 -0.116"/>
    <parent link="left_thigh"/>
    <child link="left_calve"/>
    <axis xyz="-0.0 -1.0 0.0"/>
    <dynamics damping="0" friction="0"/>
    <limit effort="6.0" lower="-2.793" upper="0" velocity="6.6"/>
  </joint>
  <joint name="left_ankle_pitch" type="revolute">
    <origin rpy="0 0 0" xyz="0.0013 0.0 -0.088"/>
    <parent link="left_calve"/>
    <child link="left_ankle"/>
    <axis xyz="-0.0 -1.0 0.0"/>
    <dynamics damping="0" friction="0"/>
    <limit effort="6.0" lower="-0.7853981633974483" upper="1.5707963267948966" velocity="6.6"/>
  </joint>
  <joint name="left_ankle_roll" type="revolute">
    <origin rpy="0 0 0" xyz="0 -0.025 0 "/>
    <parent link="left_ankle"/>
    <child link="left_foot"/>
    <axis xyz="1.0 0.0 0.0"/>
    <dynamics damping="0" friction="0"/>
    <limit effort="6.0" lower="-0.7853981633974483" upper="0.7853981633974483" velocity="6.6"/>
  </joint>
  <joint name="right_shoulder_pitch" type="revolute">
    <origin rpy="0 0 0" xyz="0.006539 -0.107163 -0.00062"/>
    <parent link="trunk"/>
    <child link="right_shoulder"/>
    <axis xyz="0.0 -1.0 -0.0"/>
    <dynamics damping="0" friction="0"/>
    <limit effort="4.1" lower="-3.141592653589793" upper="3.9269908169872414" velocity="4.82"/>
  </joint>
  <joint name="right_shoulder_roll" type="revolute">
    <origin rpy="0 0 0" xyz="0.021 -0.0295 -0.021"/>
    <parent link="right_shoulder"/>
    <child link="right_bicep"/>
    <axis xyz="-1.0 0.0 0.0"/>
    <dynamics damping="0" friction="0"/>
    <limit effort="2.5" lower="0" upper="1.5707963267948966" velocity="5.76"/>
  </joint>
  <joint name="right_elbow" type="revolute">
    <origin rpy="0 0 0" xyz="-0.021312 -0.021937 -0.08675"/>
    <parent link="right_bicep"/>
    <child link="right_forearm"/>
    <axis xyz="0.0 -1.0 0.0"/>
    <dynamics damping="0" friction="0"/>
    <limit effort="2.5" lower="0" upper="3.141592653589793" velocity="5.76"/>
  </joint>
  <joint name="right_hip_yaw" type="revolute">
    <origin rpy="0 0 0" xyz="0.018839 -0.062663 -0.20662"/>
    <parent link="trunk"/>
    <child link="right_hip_side"/>
    <axis xyz="-0.0 -0.0 1.0"/>
    <dynamics damping="0" friction="0"/>
    <limit effort="4.1" lower="-1.309" upper="0.524" velocity="4.82"/>
  </joint>
  <joint name="right_hip_roll" type="revolute">
    <origin rpy="0 0 0" xyz="-0.0205 0.0 -0.028"/>
    <parent link="right_hip_side"/>
    <child link="right_hip_front"/>
    <axis xyz="-1.0 0.0 0.0"/>
    <dynamics damping="0" friction="0"/>
    <limit effort="4.1" lower="-0.7853981633974483" upper="1.5707963267948966" velocity="4.82"/>
  </joint>
  <joint name="right_hip_pitch" type="revolute">
    <origin rpy="0 0 0" xyz="0.020771 0.0203 0.0"/>
    <parent link="right_hip_front"/>
    <child link="right_thigh"/>
    <axis xyz="-0.0 -1.0 0.0"/>
    <dynamics damping="0" friction="0"/>
    <limit effort="4.1" lower="-0.7853981633974483" upper="2.356194490192345" velocity="4.82"/>
  </joint>
  <joint name="right_knee" type="revolute">
    <origin rpy="0 0 0" xyz="0.0 0.005269 -0.116"/>
    <parent link="right_thigh"/>
    <child link="right_calve"/>
    <axis xyz="-0.0 -1.0 0.0"/>
    <dynamics damping="0" friction="0"/>
    <limit effort="6.0" lower="-2.793" upper="0" velocity="6.6"/>
  </joint>
  <joint name="right_ankle_pitch" type="revolute">
    <origin rpy="0 0 0" xyz="0.0013 0.0 -0.088"/>
    <parent link="right_calve"/>
    <child link="right_ankle"/>
    <axis xyz="-0.0 -1.0 0.0"/>
    <dynamics damping="0" friction="0"/>
    <limit effort="6.0" lower="-0.7853981633974483" upper="1.5707963267948966" velocity="6.6"/>
  </joint>
  <joint name="right_ankle_roll" type="revolute">
    <origin rpy="0 0 0" xyz="0 -0.025 0"/>
    <parent link="right_ankle"/>
    <child link="right_foot"/>
    <axis xyz="-1.0 0.0 0.0"/>
    <dynamics damping="0" friction="0"/>
    <limit effort="6.0" lower="-0.7853981633974483" upper="0.7853981633974483" velocity="6.6"/>
  </joint>
  <link name="imu_link">
    <inertial>
      <mass value="0.01"/>
      <origin rpy="0  0  0" xyz="0 0 0"/>
      <inertia ixx="1e-9" ixy="0" ixz="0" iyy="1e-9" iyz="0" izz="1e-9"/>
    </inertial>
  </link>
  <joint name="torso_imu" type="fixed">
    <parent link="trunk"/>
    <child link="imu_link"/>
    <origin rpy="0 0 0" xyz="0.0 0 0.000"/>
    <axis xyz="0 0 0"/>
  </joint>

</robot>
